5:return {{["x"] = 0, ["y"] = 0, ["param1"] = 4, ["z"] = 7, ["name"] = "default:stone_block"}, {["x"] = 0, ["y"] = 0, ["param1"] = 4, ["z"] = 8, ["name"] = "default:stone_block"}, {["x"] = 0, ["y"] = 1, ["param1"] = 4, ["z"] = 7, ["name"] = "default:stone_block"}, {["x"] = 0, ["y"] = 1, ["param1"] = 4, ["z"] = 8, ["name"] = "default:stone_block"}, {["x"] = 0, ["y"] = 2, ["param1"] = 4, ["z"] = 7, ["name"] = "default:stone_block"}, {["x"] = 0, ["y"] = 2, ["param1"] = 4, ["z"] = 8, ["name"] = "default:stone_block"}, {["x"] = 1, ["param2"] = 1, ["y"] = 0, ["param1"] = 14, ["z"] = 6, ["name"] = "stairs:slab_cobble"}, {["x"] = 1, ["y"] = 0, ["param1"] = 4, ["z"] = 7, ["name"] = "default:stone_block"}, {["x"] = 1, ["y"] = 0, ["param1"] = 4, ["z"] = 8, ["name"] = "default:stone_block"}, {["x"] = 1, ["y"] = 1, ["param1"] = 4, ["z"] = 7, ["name"] = "default:stone_block"}, {["x"] = 1, ["y"] = 1, ["param1"] = 4, ["z"] = 8, ["name"] = "default:stone_block"}, {["x"] = 1, ["y"] = 2, ["param1"] = 4, ["z"] = 7, ["name"] = "default:stone_block"}, {["x"] = 1, ["y"] = 2, ["param1"] = 4, ["z"] = 8, ["name"] = "default:stone_block"}, {["x"] = 2, ["param2"] = 2, ["y"] = 0, ["param1"] = 14, ["z"] = 5, ["name"] = "stairs:slab_cobble"}, {["x"] = 2, ["param2"] = 1, ["y"] = 0, ["param1"] = 14, ["z"] = 6, ["name"] = "stairs:slab_cobble"}, {["x"] = 2, ["param2"] = 1, ["y"] = 0, ["param1"] = 14, ["z"] = 7, ["name"] = "stairs:slab_cobble"}, {["x"] = 2, ["y"] = 0, ["param1"] = 4, ["z"] = 8, ["name"] = "default:stone_block"}, {["x"] = 2, ["y"] = 1, ["param1"] = 4, ["z"] = 8, ["name"] = "default:stone_block"}, {["x"] = 2, ["y"] = 1, ["param1"] = 4, ["z"] = 9, ["name"] = "default:stone_block"}, {["x"] = 3, ["param2"] = 2, ["y"] = 0, ["param1"] = 14, ["z"] = 4, ["name"] = "stairs:slab_cobble"}, {["x"] = 3, ["param2"] = 1, ["y"] = 0, ["param1"] = 14, ["z"] = 5, ["name"] = "stairs:slab_cobble"}, {["x"] = 3, ["param2"] = 1, ["y"] = 0, ["param1"] = 14, ["z"] = 6, ["name"] = "stairs:slab_cobble"}, {["x"] = 3, ["param2"] = 1, ["y"] = 0, ["param1"] = 14, ["z"] = 7, ["name"] = "stairs:slab_cobble"}, {["x"] = 3, ["y"] = 0, ["param1"] = 2, ["z"] = 8, ["name"] = "default:cobble"}, {["x"] = 3, ["y"] = 0, ["param1"] = 4, ["z"] = 9, ["name"] = "default:stone_block"}, {["x"] = 3, ["y"] = 1, ["param1"] = 4, ["z"] = 9, ["name"] = "default:stone_block"}, {["x"] = 3, ["y"] = 1, ["param1"] = 4, ["z"] = 10, ["name"] = "default:stone_block"}, {["x"] = 3, ["param2"] = 3, ["y"] = 2, ["param1"] = 14, ["z"] = 10, ["name"] = "stairs:slab_stone_block"}, {["x"] = 4, ["param2"] = 2, ["y"] = 0, ["param1"] = 14, ["z"] = 3, ["name"] = "stairs:slab_cobble"}, {["x"] = 4, ["param2"] = 1, ["y"] = 0, ["param1"] = 14, ["z"] = 4, ["name"] = "stairs:slab_cobble"}, {["x"] = 4, ["param2"] = 1, ["y"] = 0, ["param1"] = 14, ["z"] = 5, ["name"] = "stairs:slab_cobble"}, {["x"] = 4, ["param2"] = 1, ["y"] = 0, ["param1"] = 14, ["z"] = 6, ["name"] = "stairs:slab_cobble"}, {["x"] = 4, ["y"] = 0, ["param1"] = 2, ["z"] = 7, ["name"] = "default:cobble"}, {["x"] = 4, ["y"] = 0, ["param1"] = 2, ["z"] = 8, ["name"] = "default:cobble"}, {["x"] = 4, ["y"] = 0, ["param1"] = 2, ["z"] = 9, ["name"] = "default:cobble"}, {["x"] = 4, ["y"] = 0, ["param1"] = 4, ["z"] = 10, ["name"] = "default:stone_block"}, {["x"] = 4, ["y"] = 1, ["param1"] = 4, ["z"] = 10, ["name"] = "default:stone_block"}, {["x"] = 4, ["y"] = 1, ["param1"] = 4, ["z"] = 11, ["name"] = "default:stone_block"}, {["x"] = 4, ["param2"] = 3, ["y"] = 2, ["param1"] = 14, ["z"] = 10, ["name"] = "stairs:slab_stone_block"}, {["x"] = 4, ["param2"] = 3, ["y"] = 2, ["param1"] = 14, ["z"] = 11, ["name"] = "stairs:slab_stone_block"}, {["x"] = 5, ["param2"] = 2, ["y"] = 0, ["param1"] = 14, ["z"] = 2, ["name"] = "stairs:slab_cobble"}, {["x"] = 5, ["param2"] = 2, ["y"] = 0, ["param1"] = 14, ["z"] = 3, ["name"] = "stairs:slab_cobble"}, {["x"] = 5, ["param2"] = 2, ["y"] = 0, ["param1"] = 14, ["z"] = 4, ["name"] = "stairs:slab_cobble"}, {["x"] = 5, ["param2"] = 2, ["y"] = 0, ["param1"] = 14, ["z"] = 5, ["name"] = "stairs:slab_cobble"}, {["x"] = 5, ["y"] = 0, ["param1"] = 2, ["z"] = 6, ["name"] = "default:cobble"}, {["x"] = 5, ["y"] = 0, ["param1"] = 2, ["z"] = 7, ["name"] = "default:cobble"}, {["x"] = 5, ["y"] = 0, ["param1"] = 2, ["z"] = 8, ["name"] = "default:cobble"}, {["x"] = 5, ["y"] = 0, ["param1"] = 2, ["z"] = 9, ["name"] = "default:cobble"}, {["x"] = 5, ["y"] = 0, ["param1"] = 4, ["z"] = 10, ["name"] = "default:stone_block"}, {["x"] = 5, ["y"] = 0, ["param1"] = 4, ["z"] = 11, ["name"] = "default:stone_block"}, {["x"] = 5, ["param2"] = 1, ["y"] = 1, ["param1"] = 14, ["z"] = 10, ["name"] = "stairs:slab_cobble"}, {["x"] = 5, ["y"] = 1, ["param1"] = 4, ["z"] = 11, ["name"] = "default:stone_block"}, {["x"] = 5, ["y"] = 1, ["param1"] = 4, ["z"] = 12, ["name"] = "default:stone_block"}, {["x"] = 5, ["param2"] = 3, ["y"] = 2, ["param1"] = 14, ["z"] = 11, ["name"] = "stairs:slab_stone_block"}, {["x"] = 5, ["y"] = 2, ["param1"] = 4, ["z"] = 12, ["name"] = "default:stone_block"}, {["x"] = 6, ["param2"] = 2, ["y"] = 0, ["param1"] = 14, ["z"] = 1, ["name"] = "stairs:slab_cobble"}, {["x"] = 6, ["param2"] = 2, ["y"] = 0, ["param1"] = 14, ["z"] = 2, ["name"] = "stairs:slab_cobble"}, {["x"] = 6, ["param2"] = 2, ["y"] = 0, ["param1"] = 14, ["z"] = 3, ["name"] = "stairs:slab_cobble"}, {["x"] = 6, ["param2"] = 2, ["y"] = 0, ["param1"] = 14, ["z"] = 4, ["name"] = "stairs:slab_cobble"}, {["x"] = 6, ["y"] = 0, ["param1"] = 2, ["z"] = 5, ["name"] = "default:cobble"}, {["x"] = 6, ["y"] = 0, ["param1"] = 2, ["z"] = 6, ["name"] = "default:cobble"}, {["x"] = 6, ["y"] = 0, ["param1"] = 2, ["z"] = 7, ["name"] = "default:cobble"}, {["x"] = 6, ["y"] = 0, ["param1"] = 2, ["z"] = 8, ["name"] = "default:cobble"}, {["x"] = 6, ["y"] = 0, ["param1"] = 4, ["z"] = 9, ["name"] = "default:stone_block"}, {["x"] = 6, ["y"] = 0, ["param1"] = 4, ["z"] = 10, ["name"] = "default:stone_block"}, {["x"] = 6, ["y"] = 0, ["param1"] = 4, ["z"] = 11, ["name"] = "default:stone_block"}, {["x"] = 6, ["y"] = 0, ["param1"] = 1, ["z"] = 12, ["name"] = "default:stone"}, {["x"] = 6, ["param2"] = 1, ["y"] = 1, ["param1"] = 14, ["z"] = 9, ["name"] = "stairs:slab_cobble"}, {["x"] = 6, ["param2"] = 1, ["y"] = 1, ["param1"] = 14, ["z"] = 10, ["name"] = "stairs:slab_cobble"}, {["x"] = 6, ["param2"] = 1, ["y"] = 1, ["param1"] = 14, ["z"] = 11, ["name"] = "stairs:slab_cobble"}, {["x"] = 6, ["y"] = 1, ["param1"] = 4, ["z"] = 12, ["name"] = "default:stone_block"}, {["x"] = 6, ["y"] = 1, ["param1"] = 4, ["z"] = 13, ["name"] = "default:stone_block"}, {["x"] = 6, ["y"] = 2, ["param1"] = 4, ["z"] = 12, ["name"] = "default:stone_block"}, {["x"] = 6, ["y"] = 2, ["param1"] = 4, ["z"] = 13, ["name"] = "default:stone_block"}, {["x"] = 7, ["y"] = 0, ["param1"] = 4, ["z"] = 0, ["name"] = "default:stone_block"}, {["x"] = 7, ["y"] = 0, ["param1"] = 4, ["z"] = 1, ["name"] = "default:stone_block"}, {["x"] = 7, ["param2"] = 2, ["y"] = 0, ["param1"] = 14, ["z"] = 2, ["name"] = "stairs:slab_cobble"}, {["x"] = 7, ["param2"] = 2, ["y"] = 0, ["param1"] = 14, ["z"] = 3, ["name"] = "stairs:slab_cobble"}, {["x"] = 7, ["y"] = 0, ["param1"] = 2, ["z"] = 4, ["name"] = "default:cobble"}, {["x"] = 7, ["y"] = 0, ["param1"] = 2, ["z"] = 5, ["name"] = "default:cobble"}, {["x"] = 7, ["y"] = 0, ["param1"] = 2, ["z"] = 6, ["name"] = "default:cobble"}, {["x"] = 7, ["y"] = 0, ["param1"] = 2, ["z"] = 7, ["name"] = "default:cobble"}, {["x"] = 7, ["y"] = 0, ["param1"] = 4, ["z"] = 8, ["name"] = "default:stone_block"}, {["x"] = 7, ["y"] = 0, ["param1"] = 4, ["z"] = 9, ["name"] = "default:stone_block"}, {["x"] = 7, ["y"] = 0, ["param1"] = 4, ["z"] = 10, ["name"] = "default:stone_block"}, {["x"] = 7, ["y"] = 0, ["param1"] = 1, ["z"] = 11, ["name"] = "default:stone"}, {["x"] = 7, ["y"] = 0, ["param1"] = 1, ["z"] = 12, ["name"] = "default:stone"}, {["x"] = 7, ["y"] = 0, ["param1"] = 1, ["z"] = 13, ["name"] = "default:stone"}, {["x"] = 7, ["y"] = 1, ["param1"] = 4, ["z"] = 0, ["name"] = "default:stone_block"}, {["x"] = 7, ["y"] = 1, ["param1"] = 4, ["z"] = 1, ["name"] = "default:stone_block"}, {["x"] = 7, ["param2"] = 2, ["y"] = 1, ["param1"] = 14, ["z"] = 8, ["name"] = "stairs:slab_cobble"}, {["x"] = 7, ["param2"] = 1, ["y"] = 1, ["param1"] = 14, ["z"] = 9, ["name"] = "stairs:slab_cobble"}, {["x"] = 7, ["param2"] = 1, ["y"] = 1, ["param1"] = 14, ["z"] = 10, ["name"] = "stairs:slab_cobble"}, {["x"] = 7, ["param2"] = 3, ["y"] = 1, ["param1"] = 14, ["z"] = 11, ["name"] = "stairs:slab_cobble"}, {["x"] = 7, ["y"] = 1, ["param1"] = 2, ["z"] = 12, ["name"] = "default:cobble"}, {["x"] = 7, ["y"] = 1, ["param1"] = 4, ["z"] = 13, ["name"] = "default:stone_block"}, {["x"] = 7, ["y"] = 2, ["param1"] = 4, ["z"] = 0, ["name"] = "default:stone_block"}, {["x"] = 7, ["y"] = 2, ["param1"] = 4, ["z"] = 1, ["name"] = "default:stone_block"}, {["x"] = 7, ["y"] = 2, ["param1"] = 4, ["z"] = 13, ["name"] = "default:stone_block"}, {["x"] = 7, ["y"] = 2, ["param1"] = 4, ["z"] = 14, ["name"] = "default:stone_block"}, {["x"] = 7, ["param2"] = 2, ["y"] = 3, ["param1"] = 14, ["z"] = 14, ["name"] = "stairs:slab_stone_block"}, {["x"] = 8, ["y"] = 0, ["param1"] = 4, ["z"] = 0, ["name"] = "default:stone_block"}, {["x"] = 8, ["y"] = 0, ["param1"] = 4, ["z"] = 1, ["name"] = "default:stone_block"}, {["x"] = 8, ["y"] = 0, ["param1"] = 4, ["z"] = 2, ["name"] = "default:stone_block"}, {["x"] = 8, ["y"] = 0, ["param1"] = 2, ["z"] = 3, ["name"] = "default:cobble"}, {["x"] = 8, ["y"] = 0, ["param1"] = 2, ["z"] = 4, ["name"] = "default:cobble"}, {["x"] = 8, ["y"] = 0, ["param1"] = 2, ["z"] = 5, ["name"] = "default:cobble"}, {["x"] = 8, ["y"] = 0, ["param1"] = 2, ["z"] = 6, ["name"] = "default:cobble"}, {["x"] = 8, ["y"] = 0, ["param1"] = 4, ["z"] = 7, ["name"] = "default:stone_block"}, {["x"] = 8, ["y"] = 0, ["param1"] = 4, ["z"] = 8, ["name"] = "default:stone_block"}, {["x"] = 8, ["y"] = 0, ["param1"] = 4, ["z"] = 9, ["name"] = "default:stone_block"}, {["x"] = 8, ["y"] = 0, ["param1"] = 1, ["z"] = 10, ["name"] = "default:stone"}, {["x"] = 8, ["y"] = 0, ["param1"] = 1, ["z"] = 11, ["name"] = "default:stone"}, {["x"] = 8, ["y"] = 0, ["param1"] = 1, ["z"] = 12, ["name"] = "default:stone"}, {["x"] = 8, ["y"] = 0, ["param1"] = 1, ["z"] = 13, ["name"] = "default:stone"}, {["x"] = 8, ["y"] = 1, ["param1"] = 4, ["z"] = 0, ["name"] = "default:stone_block"}, {["x"] = 8, ["y"] = 1, ["param1"] = 4, ["z"] = 1, ["name"] = "default:stone_block"}, {["x"] = 8, ["y"] = 1, ["param1"] = 4, ["z"] = 2, ["name"] = "default:stone_block"}, {["x"] = 8, ["param2"] = 2, ["y"] = 1, ["param1"] = 14, ["z"] = 7, ["name"] = "stairs:slab_cobble"}, {["x"] = 8, ["param2"] = 2, ["y"] = 1, ["param1"] = 14, ["z"] = 8, ["name"] = "stairs:slab_cobble"}, {["x"] = 8, ["param2"] = 3, ["y"] = 1, ["param1"] = 14, ["z"] = 9, ["name"] = "stairs:slab_cobble"}, {["x"] = 8, ["param2"] = 3, ["y"] = 1, ["param1"] = 14, ["z"] = 10, ["name"] = "stairs:slab_cobble"}, {["x"] = 8, ["y"] = 1, ["param1"] = 2, ["z"] = 11, ["name"] = "default:cobble"}, {["x"] = 8, ["y"] = 1, ["param1"] = 2, ["z"] = 12, ["name"] = "default:cobble"}, {["x"] = 8, ["y"] = 1, ["param1"] = 2, ["z"] = 13, ["name"] = "default:cobble"}, {["x"] = 8, ["y"] = 1, ["param1"] = 4, ["z"] = 14, ["name"] = "default:stone_block"}, {["x"] = 8, ["y"] = 2, ["param1"] = 4, ["z"] = 0, ["name"] = "default:stone_block"}, {["x"] = 8, ["y"] = 2, ["param1"] = 4, ["z"] = 1, ["name"] = "default:stone_block"}, {["x"] = 8, ["y"] = 2, ["param1"] = 4, ["z"] = 14, ["name"] = "default:stone_block"}, {["x"] = 8, ["y"] = 2, ["param1"] = 4, ["z"] = 15, ["name"] = "default:stone_block"}, {["x"] = 8, ["param2"] = 2, ["y"] = 3, ["param1"] = 14, ["z"] = 14, ["name"] = "stairs:slab_stone_block"}, {["x"] = 8, ["param2"] = 2, ["y"] = 3, ["param1"] = 14, ["z"] = 15, ["name"] = "stairs:slab_stone_block"}, {["x"] = 9, ["y"] = 0, ["param1"] = 4, ["z"] = 3, ["name"] = "default:stone_block"}, {["x"] = 9, ["y"] = 0, ["param1"] = 2, ["z"] = 4, ["name"] = "default:cobble"}, {["x"] = 9, ["y"] = 0, ["param1"] = 2, ["z"] = 5, ["name"] = "default:cobble"}, {["x"] = 9, ["y"] = 0, ["param1"] = 4, ["z"] = 6, ["name"] = "default:stone_block"}, {["x"] = 9, ["y"] = 0, ["param1"] = 4, ["z"] = 7, ["name"] = "default:stone_block"}, {["x"] = 9, ["y"] = 0, ["param1"] = 4, ["z"] = 8, ["name"] = "default:stone_block"}, {["x"] = 9, ["y"] = 0, ["param1"] = 1, ["z"] = 9, ["name"] = "default:stone"}, {["x"] = 9, ["y"] = 0, ["param1"] = 1, ["z"] = 10, ["name"] = "default:stone"}, {["x"] = 9, ["y"] = 0, ["param1"] = 1, ["z"] = 11, ["name"] = "default:stone"}, {["x"] = 9, ["y"] = 0, ["param1"] = 1, ["z"] = 12, ["name"] = "default:stone"}, {["x"] = 9, ["y"] = 0, ["param1"] = 1, ["z"] = 13, ["name"] = "default:stone"}, {["x"] = 9, ["y"] = 0, ["param1"] = 1, ["z"] = 14, ["name"] = "default:stone"}, {["x"] = 9, ["y"] = 1, ["param1"] = 4, ["z"] = 2, ["name"] = "default:stone_block"}, {["x"] = 9, ["y"] = 1, ["param1"] = 4, ["z"] = 3, ["name"] = "default:stone_block"}, {["x"] = 9, ["param2"] = 2, ["y"] = 1, ["param1"] = 14, ["z"] = 6, ["name"] = "stairs:slab_cobble"}, {["x"] = 9, ["param2"] = 2, ["y"] = 1, ["param1"] = 14, ["z"] = 7, ["name"] = "stairs:slab_cobble"}, {["x"] = 9, ["param2"] = 2, ["y"] = 1, ["param1"] = 14, ["z"] = 8, ["name"] = "stairs:slab_cobble"}, {["x"] = 9, ["param2"] = 2, ["y"] = 1, ["param1"] = 14, ["z"] = 9, ["name"] = "stairs:slab_cobble"}, {["x"] = 9, ["y"] = 1, ["param1"] = 2, ["z"] = 10, ["name"] = "default:cobble"}, {["x"] = 9, ["y"] = 1, ["param1"] = 2, ["z"] = 11, ["name"] = "default:cobble"}, {["x"] = 9, ["y"] = 1, ["param1"] = 2, ["z"] = 12, ["name"] = "default:cobble"}, {["x"] = 9, ["y"] = 1, ["param1"] = 2, ["z"] = 13, ["name"] = "default:cobble"}, {["x"] = 9, ["y"] = 1, ["param1"] = 4, ["z"] = 14, ["name"] = "default:stone_block"}, {["x"] = 9, ["y"] = 1, ["param1"] = 4, ["z"] = 15, ["name"] = "default:stone_block"}, {["x"] = 9, ["param2"] = 1, ["y"] = 2, ["param1"] = 14, ["z"] = 14, ["name"] = "stairs:slab_cobble"}, {["x"] = 9, ["y"] = 2, ["param1"] = 4, ["z"] = 15, ["name"] = "default:stone_block"}, {["x"] = 9, ["y"] = 2, ["param1"] = 4, ["z"] = 16, ["name"] = "default:stone_block"}, {["x"] = 9, ["param2"] = 1, ["y"] = 3, ["param1"] = 14, ["z"] = 15, ["name"] = "stairs:slab_stone_block"}, {["x"] = 9, ["y"] = 3, ["param1"] = 4, ["z"] = 16, ["name"] = "default:stone_block"}, {["x"] = 10, ["y"] = 0, ["param1"] = 4, ["z"] = 4, ["name"] = "default:stone_block"}, {["x"] = 10, ["y"] = 0, ["param1"] = 4, ["z"] = 5, ["name"] = "default:stone_block"}, {["x"] = 10, ["y"] = 0, ["param1"] = 4, ["z"] = 6, ["name"] = "default:stone_block"}, {["x"] = 10, ["y"] = 0, ["param1"] = 4, ["z"] = 7, ["name"] = "default:stone_block"}, {["x"] = 10, ["y"] = 0, ["param1"] = 1, ["z"] = 8, ["name"] = "default:stone"}, {["x"] = 10, ["y"] = 0, ["param1"] = 1, ["z"] = 9, ["name"] = "default:stone"}, {["x"] = 10, ["y"] = 0, ["param1"] = 1, ["z"] = 10, ["name"] = "default:stone"}, {["x"] = 10, ["y"] = 0, ["param1"] = 1, ["z"] = 11, ["name"] = "default:stone"}, {["x"] = 10, ["y"] = 0, ["param1"] = 1, ["z"] = 12, ["name"] = "default:stone"}, {["x"] = 10, ["y"] = 0, ["param1"] = 1, ["z"] = 13, ["name"] = "default:stone"}, {["x"] = 10, ["y"] = 0, ["param1"] = 1, ["z"] = 14, ["name"] = "default:stone"}, {["x"] = 10, ["y"] = 0, ["param1"] = 1, ["z"] = 15, ["name"] = "default:stone"}, {["x"] = 10, ["y"] = 1, ["param1"] = 4, ["z"] = 3, ["name"] = "default:stone_block"}, {["x"] = 10, ["y"] = 1, ["param1"] = 4, ["z"] = 4, ["name"] = "default:stone_block"}, {["x"] = 10, ["param2"] = 2, ["y"] = 1, ["param1"] = 14, ["z"] = 5, ["name"] = "stairs:slab_cobble"}, {["x"] = 10, ["param2"] = 2, ["y"] = 1, ["param1"] = 14, ["z"] = 6, ["name"] = "stairs:slab_cobble"}, {["x"] = 10, ["param2"] = 2, ["y"] = 1, ["param1"] = 14, ["z"] = 7, ["name"] = "stairs:slab_cobble"}, {["x"] = 10, ["param2"] = 2, ["y"] = 1, ["param1"] = 14, ["z"] = 8, ["name"] = "stairs:slab_cobble"}, {["x"] = 10, ["y"] = 1, ["param1"] = 2, ["z"] = 9, ["name"] = "default:cobble"}, {["x"] = 10, ["y"] = 1, ["param1"] = 2, ["z"] = 10, ["name"] = "default:cobble"}, {["x"] = 10, ["y"] = 1, ["param1"] = 2, ["z"] = 11, ["name"] = "default:cobble"}, {["x"] = 10, ["y"] = 1, ["param1"] = 2, ["z"] = 12, ["name"] = "default:cobble"}, {["x"] = 10, ["y"] = 1, ["param1"] = 4, ["z"] = 13, ["name"] = "default:stone_block"}, {["x"] = 10, ["y"] = 1, ["param1"] = 4, ["z"] = 14, ["name"] = "default:stone_block"}, {["x"] = 10, ["y"] = 1, ["param1"] = 4, ["z"] = 15, ["name"] = "default:stone_block"}, {["x"] = 10, ["y"] = 1, ["param1"] = 4, ["z"] = 16, ["name"] = "default:stone_block"}, {["x"] = 10, ["y"] = 2, ["param1"] = 14, ["z"] = 3, ["name"] = "stairs:slab_stone_block"}, {["x"] = 10, ["param2"] = 1, ["y"] = 2, ["param1"] = 14, ["z"] = 4, ["name"] = "stairs:slab_stone_block"}, {["x"] = 10, ["param2"] = 1, ["y"] = 2, ["param1"] = 14, ["z"] = 13, ["name"] = "stairs:slab_cobble"}, {["x"] = 10, ["param2"] = 1, ["y"] = 2, ["param1"] = 14, ["z"] = 14, ["name"] = "stairs:slab_cobble"}, {["x"] = 10, ["param2"] = 1, ["y"] = 2, ["param1"] = 14, ["z"] = 15, ["name"] = "stairs:slab_cobble"}, {["x"] = 10, ["y"] = 2, ["param1"] = 4, ["z"] = 16, ["name"] = "default:stone_block"}, {["x"] = 10, ["y"] = 2, ["param1"] = 4, ["z"] = 17, ["name"] = "default:stone_block"}, {["x"] = 10, ["y"] = 3, ["param1"] = 4, ["z"] = 16, ["name"] = "default:stone_block"}, {["x"] = 10, ["y"] = 3, ["param1"] = 4, ["z"] = 17, ["name"] = "default:stone_block"}, {["x"] = 11, ["y"] = 0, ["param1"] = 4, ["z"] = 5, ["name"] = "default:stone_block"}, {["x"] = 11, ["y"] = 0, ["param1"] = 4, ["z"] = 6, ["name"] = "default:stone_block"}, {["x"] = 11, ["y"] = 0, ["param1"] = 1, ["z"] = 7, ["name"] = "default:stone"}, {["x"] = 11, ["y"] = 0, ["param1"] = 1, ["z"] = 8, ["name"] = "default:stone"}, {["x"] = 11, ["y"] = 0, ["param1"] = 1, ["z"] = 9, ["name"] = "default:stone"}, {["x"] = 11, ["y"] = 0, ["param1"] = 1, ["z"] = 10, ["name"] = "default:stone"}, {["x"] = 11, ["y"] = 0, ["param1"] = 1, ["z"] = 11, ["name"] = "default:stone"}, {["x"] = 11, ["y"] = 0, ["param1"] = 1, ["z"] = 12, ["name"] = "default:stone"}, {["x"] = 11, ["y"] = 0, ["param1"] = 1, ["z"] = 13, ["name"] = "default:stone"}, {["x"] = 11, ["y"] = 0, ["param1"] = 1, ["z"] = 14, ["name"] = "default:stone"}, {["x"] = 11, ["y"] = 0, ["param1"] = 1, ["z"] = 15, ["name"] = "default:stone"}, {["x"] = 11, ["y"] = 0, ["param1"] = 1, ["z"] = 16, ["name"] = "default:stone"}, {["x"] = 11, ["y"] = 1, ["param1"] = 4, ["z"] = 4, ["name"] = "default:stone_block"}, {["x"] = 11, ["y"] = 1, ["param1"] = 4, ["z"] = 5, ["name"] = "default:stone_block"}, {["x"] = 11, ["param2"] = 2, ["y"] = 1, ["param1"] = 14, ["z"] = 6, ["name"] = "stairs:slab_cobble"}, {["x"] = 11, ["param2"] = 2, ["y"] = 1, ["param1"] = 14, ["z"] = 7, ["name"] = "stairs:slab_cobble"}, {["x"] = 11, ["y"] = 1, ["param1"] = 2, ["z"] = 8, ["name"] = "default:cobble"}, {["x"] = 11, ["y"] = 1, ["param1"] = 2, ["z"] = 9, ["name"] = "default:cobble"}, {["x"] = 11, ["y"] = 1, ["param1"] = 2, ["z"] = 10, ["name"] = "default:cobble"}, {["x"] = 11, ["y"] = 1, ["param1"] = 2, ["z"] = 11, ["name"] = "default:cobble"}, {["x"] = 11, ["y"] = 1, ["param1"] = 4, ["z"] = 12, ["name"] = "default:stone_block"}, {["x"] = 11, ["y"] = 1, ["param1"] = 4, ["z"] = 13, ["name"] = "default:stone_block"}, {["x"] = 11, ["y"] = 1, ["param1"] = 4, ["z"] = 14, ["name"] = "default:stone_block"}, {["x"] = 11, ["y"] = 1, ["param1"] = 4, ["z"] = 15, ["name"] = "default:stone_block"}, {["x"] = 11, ["y"] = 1, ["param1"] = 4, ["z"] = 16, ["name"] = "default:stone_block"}, {["x"] = 11, ["y"] = 1, ["param1"] = 4, ["z"] = 17, ["name"] = "default:stone_block"}, {["x"] = 11, ["param2"] = 1, ["y"] = 2, ["param1"] = 14, ["z"] = 4, ["name"] = "stairs:slab_stone_block"}, {["x"] = 11, ["param2"] = 1, ["y"] = 2, ["param1"] = 14, ["z"] = 5, ["name"] = "stairs:slab_stone_block"}, {["x"] = 11, ["param2"] = 2, ["y"] = 2, ["param1"] = 14, ["z"] = 12, ["name"] = "stairs:slab_cobble"}, {["x"] = 11, ["param2"] = 1, ["y"] = 2, ["param1"] = 14, ["z"] = 13, ["name"] = "stairs:slab_cobble"}, {["x"] = 11, ["param2"] = 1, ["y"] = 2, ["param1"] = 14, ["z"] = 14, ["name"] = "stairs:slab_cobble"}, {["x"] = 11, ["param2"] = 1, ["y"] = 2, ["param1"] = 14, ["z"] = 15, ["name"] = "stairs:slab_cobble"}, {["x"] = 11, ["y"] = 2, ["param1"] = 2, ["z"] = 16, ["name"] = "default:cobble"}, {["x"] = 11, ["y"] = 2, ["param1"] = 4, ["z"] = 17, ["name"] = "default:stone_block"}, {["x"] = 11, ["y"] = 2, ["param1"] = 4, ["z"] = 18, ["name"] = "default:stone_block"}, {["x"] = 11, ["y"] = 3, ["param1"] = 4, ["z"] = 17, ["name"] = "default:stone_block"}, {["x"] = 11, ["y"] = 3, ["param1"] = 4, ["z"] = 18, ["name"] = "default:stone_block"}, {["x"] = 12, ["y"] = 0, ["param1"] = 1, ["z"] = 6, ["name"] = "default:stone"}, {["x"] = 12, ["y"] = 0, ["param1"] = 1, ["z"] = 7, ["name"] = "default:stone"}, {["x"] = 12, ["y"] = 0, ["param1"] = 1, ["z"] = 8, ["name"] = "default:stone"}, {["x"] = 12, ["y"] = 0, ["param1"] = 1, ["z"] = 9, ["name"] = "default:stone"}, {["x"] = 12, ["y"] = 0, ["param1"] = 1, ["z"] = 10, ["name"] = "default:stone"}, {["x"] = 12, ["y"] = 0, ["param1"] = 1, ["z"] = 11, ["name"] = "default:stone"}, {["x"] = 12, ["y"] = 0, ["param1"] = 1, ["z"] = 12, ["name"] = "default:stone"}, {["x"] = 12, ["y"] = 0, ["param1"] = 1, ["z"] = 13, ["name"] = "default:stone"}, {["x"] = 12, ["y"] = 0, ["param1"] = 1, ["z"] = 14, ["name"] = "default:stone"}, {["x"] = 12, ["y"] = 0, ["param1"] = 1, ["z"] = 15, ["name"] = "default:stone"}, {["x"] = 12, ["y"] = 0, ["param1"] = 1, ["z"] = 16, ["name"] = "default:stone"}, {["x"] = 12, ["param2"] = 21, ["y"] = 0, ["param1"] = 12, ["z"] = 17, ["name"] = "stairs:slab_stone"}, {["x"] = 12, ["y"] = 1, ["param1"] = 4, ["z"] = 5, ["name"] = "default:stone_block"}, {["x"] = 12, ["y"] = 1, ["param1"] = 4, ["z"] = 6, ["name"] = "default:stone_block"}, {["x"] = 12, ["y"] = 1, ["param1"] = 2, ["z"] = 7, ["name"] = "default:cobble"}, {["x"] = 12, ["y"] = 1, ["param1"] = 2, ["z"] = 8, ["name"] = "default:cobble"}, {["x"] = 12, ["y"] = 1, ["param1"] = 2, ["z"] = 9, ["name"] = "default:cobble"}, {["x"] = 12, ["y"] = 1, ["param1"] = 2, ["z"] = 10, ["name"] = "default:cobble"}, {["x"] = 12, ["y"] = 1, ["param1"] = 4, ["z"] = 11, ["name"] = "default:stone_block"}, {["x"] = 12, ["y"] = 1, ["param1"] = 4, ["z"] = 12, ["name"] = "default:stone_block"}, {["x"] = 12, ["y"] = 1, ["param1"] = 4, ["z"] = 13, ["name"] = "default:stone_block"}, {["x"] = 12, ["y"] = 1, ["param1"] = 4, ["z"] = 14, ["name"] = "default:stone_block"}, {["x"] = 12, ["y"] = 1, ["param1"] = 4, ["z"] = 15, ["name"] = "default:stone_block"}, {["x"] = 12, ["y"] = 1, ["param1"] = 4, ["z"] = 16, ["name"] = "default:stone_block"}, {["x"] = 12, ["y"] = 1, ["param1"] = 4, ["z"] = 17, ["name"] = "default:stone_block"}, {["x"] = 12, ["y"] = 1, ["param1"] = 4, ["z"] = 18, ["name"] = "default:stone_block"}, {["x"] = 12, ["y"] = 2, ["param1"] = 4, ["z"] = 5, ["name"] = "default:stone_block"}, {["x"] = 12, ["y"] = 2, ["param1"] = 4, ["z"] = 6, ["name"] = "default:stone_block"}, {["x"] = 12, ["param2"] = 2, ["y"] = 2, ["param1"] = 14, ["z"] = 11, ["name"] = "stairs:slab_cobble"}, {["x"] = 12, ["param2"] = 2, ["y"] = 2, ["param1"] = 14, ["z"] = 12, ["name"] = "stairs:slab_cobble"}, {["x"] = 12, ["param2"] = 1, ["y"] = 2, ["param1"] = 14, ["z"] = 13, ["name"] = "stairs:slab_cobble"}, {["x"] = 12, ["param2"] = 1, ["y"] = 2, ["param1"] = 14, ["z"] = 14, ["name"] = "stairs:slab_cobble"}, {["x"] = 12, ["y"] = 2, ["param1"] = 2, ["z"] = 15, ["name"] = "default:cobble"}, {["x"] = 12, ["y"] = 2, ["param1"] = 2, ["z"] = 16, ["name"] = "default:cobble"}, {["x"] = 12, ["y"] = 2, ["param1"] = 2, ["z"] = 17, ["name"] = "default:cobble"}, {["x"] = 12, ["y"] = 2, ["param1"] = 4, ["z"] = 18, ["name"] = "default:stone_block"}, {["x"] = 12, ["y"] = 3, ["param1"] = 4, ["z"] = 18, ["name"] = "default:stone_block"}, {["x"] = 12, ["y"] = 3, ["param1"] = 4, ["z"] = 19, ["name"] = "default:stone_block"}, {["x"] = 12, ["param2"] = 2, ["y"] = 4, ["param1"] = 14, ["z"] = 19, ["name"] = "stairs:slab_stone_block"}, {["x"] = 13, ["y"] = 0, ["param1"] = 1, ["z"] = 7, ["name"] = "default:stone"}, {["x"] = 13, ["y"] = 0, ["param1"] = 1, ["z"] = 8, ["name"] = "default:stone"}, {["x"] = 13, ["y"] = 0, ["param1"] = 1, ["z"] = 9, ["name"] = "default:stone"}, {["x"] = 13, ["y"] = 0, ["param1"] = 1, ["z"] = 10, ["name"] = "default:stone"}, {["x"] = 13, ["y"] = 0, ["param1"] = 1, ["z"] = 11, ["name"] = "default:stone"}, {["x"] = 13, ["y"] = 0, ["param1"] = 1, ["z"] = 12, ["name"] = "default:stone"}, {["x"] = 13, ["y"] = 0, ["param1"] = 1, ["z"] = 13, ["name"] = "default:stone"}, {["x"] = 13, ["y"] = 0, ["param1"] = 1, ["z"] = 14, ["name"] = "default:stone"}, {["x"] = 13, ["y"] = 0, ["param1"] = 1, ["z"] = 15, ["name"] = "default:stone"}, {["x"] = 13, ["y"] = 0, ["param1"] = 1, ["z"] = 16, ["name"] = "default:stone"}, {["x"] = 13, ["param2"] = 21, ["y"] = 0, ["param1"] = 11, ["z"] = 17, ["name"] = "stairs:slab_stone"}, {["x"] = 13, ["y"] = 1, ["param1"] = 4, ["z"] = 6, ["name"] = "default:stone_block"}, {["x"] = 13, ["y"] = 1, ["param1"] = 4, ["z"] = 7, ["name"] = "default:stone_block"}, {["x"] = 13, ["y"] = 1, ["param1"] = 2, ["z"] = 8, ["name"] = "default:cobble"}, {["x"] = 13, ["y"] = 1, ["param1"] = 2, ["z"] = 9, ["name"] = "default:cobble"}, {["x"] = 13, ["y"] = 1, ["param1"] = 4, ["z"] = 10, ["name"] = "default:stone_block"}, {["x"] = 13, ["y"] = 1, ["param1"] = 4, ["z"] = 11, ["name"] = "default:stone_block"}, {["x"] = 13, ["y"] = 1, ["param1"] = 4, ["z"] = 12, ["name"] = "default:stone_block"}, {["x"] = 13, ["y"] = 1, ["param1"] = 4, ["z"] = 13, ["name"] = "default:stone_block"}, {["x"] = 13, ["y"] = 1, ["param1"] = 4, ["z"] = 14, ["name"] = "default:stone_block"}, {["x"] = 13, ["y"] = 1, ["param1"] = 4, ["z"] = 15, ["name"] = "default:stone_block"}, {["x"] = 13, ["y"] = 1, ["param1"] = 4, ["z"] = 16, ["name"] = "default:stone_block"}, {["x"] = 13, ["y"] = 1, ["param1"] = 4, ["z"] = 17, ["name"] = "default:stone_block"}, {["x"] = 13, ["y"] = 1, ["param1"] = 1, ["z"] = 18, ["name"] = "default:stone"}, {["x"] = 13, ["y"] = 2, ["param1"] = 4, ["z"] = 6, ["name"] = "default:stone_block"}, {["x"] = 13, ["y"] = 2, ["param1"] = 4, ["z"] = 7, ["name"] = "default:stone_block"}, {["x"] = 13, ["param2"] = 2, ["y"] = 2, ["param1"] = 14, ["z"] = 10, ["name"] = "stairs:slab_cobble"}, {["x"] = 13, ["param2"] = 2, ["y"] = 2, ["param1"] = 14, ["z"] = 11, ["name"] = "stairs:slab_cobble"}, {["x"] = 13, ["param2"] = 1, ["y"] = 2, ["param1"] = 14, ["z"] = 12, ["name"] = "stairs:slab_cobble"}, {["x"] = 13, ["param2"] = 1, ["y"] = 2, ["param1"] = 14, ["z"] = 13, ["name"] = "stairs:slab_cobble"}, {["x"] = 13, ["y"] = 2, ["param1"] = 2, ["z"] = 14, ["name"] = "default:cobble"}, {["x"] = 13, ["y"] = 2, ["param1"] = 2, ["z"] = 15, ["name"] = "default:cobble"}, {["x"] = 13, ["y"] = 2, ["param1"] = 2, ["z"] = 16, ["name"] = "default:cobble"}, {["x"] = 13, ["y"] = 2, ["param1"] = 2, ["z"] = 17, ["name"] = "default:cobble"}, {["x"] = 13, ["y"] = 2, ["param1"] = 2, ["z"] = 18, ["name"] = "default:cobble"}, {["x"] = 13, ["y"] = 2, ["param1"] = 4, ["z"] = 19, ["name"] = "default:stone_block"}, {["x"] = 13, ["y"] = 3, ["param1"] = 4, ["z"] = 19, ["name"] = "default:stone_block"}, {["x"] = 13, ["y"] = 3, ["param1"] = 4, ["z"] = 20, ["name"] = "default:stone_block"}, {["x"] = 13, ["param2"] = 2, ["y"] = 4, ["param1"] = 14, ["z"] = 19, ["name"] = "stairs:slab_stone_block"}, {["x"] = 13, ["param2"] = 2, ["y"] = 4, ["param1"] = 14, ["z"] = 20, ["name"] = "stairs:slab_stone_block"}, {["x"] = 14, ["y"] = 0, ["param1"] = 1, ["z"] = 9, ["name"] = "default:stone"}, {["x"] = 14, ["y"] = 0, ["param1"] = 1, ["z"] = 10, ["name"] = "default:stone"}, {["x"] = 14, ["y"] = 0, ["param1"] = 1, ["z"] = 11, ["name"] = "default:stone"}, {["x"] = 14, ["y"] = 0, ["param1"] = 1, ["z"] = 12, ["name"] = "default:stone"}, {["x"] = 14, ["y"] = 0, ["param1"] = 1, ["z"] = 13, ["name"] = "default:stone"}, {["x"] = 14, ["y"] = 0, ["param1"] = 1, ["z"] = 14, ["name"] = "default:stone"}, {["x"] = 14, ["y"] = 0, ["param1"] = 1, ["z"] = 15, ["name"] = "default:stone"}, {["x"] = 14, ["y"] = 0, ["param1"] = 1, ["z"] = 16, ["name"] = "default:stone"}, {["x"] = 14, ["param2"] = 21, ["y"] = 0, ["param1"] = 10, ["z"] = 17, ["name"] = "stairs:slab_stone"}, {["x"] = 14, ["y"] = 1, ["param1"] = 4, ["z"] = 8, ["name"] = "default:stone_block"}, {["x"] = 14, ["y"] = 1, ["param1"] = 4, ["z"] = 9, ["name"] = "default:stone_block"}, {["x"] = 14, ["y"] = 1, ["param1"] = 4, ["z"] = 10, ["name"] = "default:stone_block"}, {["x"] = 14, ["y"] = 1, ["param1"] = 4, ["z"] = 11, ["name"] = "default:stone_block"}, {["x"] = 14, ["y"] = 1, ["param1"] = 4, ["z"] = 12, ["name"] = "default:stone_block"}, {["x"] = 14, ["y"] = 1, ["param1"] = 1, ["z"] = 13, ["name"] = "default:stone"}, {["x"] = 14, ["y"] = 1, ["param1"] = 1, ["z"] = 14, ["name"] = "default:stone"}, {["x"] = 14, ["y"] = 1, ["param1"] = 1, ["z"] = 15, ["name"] = "default:stone"}, {["x"] = 14, ["y"] = 1, ["param1"] = 1, ["z"] = 16, ["name"] = "default:stone"}, {["x"] = 14, ["y"] = 1, ["param1"] = 1, ["z"] = 17, ["name"] = "default:stone"}, {["x"] = 14, ["y"] = 1, ["param1"] = 1, ["z"] = 18, ["name"] = "default:stone"}, {["x"] = 14, ["y"] = 2, ["param1"] = 4, ["z"] = 7, ["name"] = "default:stone_block"}, {["x"] = 14, ["y"] = 2, ["param1"] = 4, ["z"] = 8, ["name"] = "default:stone_block"}, {["x"] = 14, ["param2"] = 2, ["y"] = 2, ["param1"] = 14, ["z"] = 9, ["name"] = "stairs:slab_cobble"}, {["x"] = 14, ["param2"] = 2, ["y"] = 2, ["param1"] = 14, ["z"] = 10, ["name"] = "stairs:slab_cobble"}, {["x"] = 14, ["param2"] = 1, ["y"] = 2, ["param1"] = 14, ["z"] = 11, ["name"] = "stairs:slab_cobble"}, {["x"] = 14, ["param2"] = 2, ["y"] = 2, ["param1"] = 14, ["z"] = 12, ["name"] = "stairs:slab_cobble"}, {["x"] = 14, ["y"] = 2, ["param1"] = 2, ["z"] = 13, ["name"] = "default:cobble"}, {["x"] = 14, ["y"] = 2, ["param1"] = 2, ["z"] = 14, ["name"] = "default:cobble"}, {["x"] = 14, ["y"] = 2, ["param1"] = 2, ["z"] = 15, ["name"] = "default:cobble"}, {["x"] = 14, ["y"] = 2, ["param1"] = 2, ["z"] = 16, ["name"] = "default:cobble"}, {["x"] = 14, ["y"] = 2, ["param1"] = 2, ["z"] = 17, ["name"] = "default:cobble"}, {["x"] = 14, ["y"] = 2, ["param1"] = 2, ["z"] = 18, ["name"] = "default:cobble"}, {["x"] = 14, ["y"] = 2, ["param1"] = 4, ["z"] = 19, ["name"] = "default:stone_block"}, {["x"] = 14, ["y"] = 2, ["param1"] = 1, ["z"] = 20, ["name"] = "default:stone"}, {["x"] = 14, ["param2"] = 1, ["y"] = 3, ["param1"] = 14, ["z"] = 7, ["name"] = "stairs:slab_stone_block"}, {["x"] = 14, ["param2"] = 1, ["y"] = 3, ["param1"] = 14, ["z"] = 8, ["name"] = "stairs:slab_stone_block"}, {["x"] = 14, ["param2"] = 1, ["y"] = 3, ["param1"] = 14, ["z"] = 19, ["name"] = "stairs:slab_cobble"}, {["x"] = 14, ["y"] = 3, ["param1"] = 4, ["z"] = 20, ["name"] = "default:stone_block"}, {["x"] = 14, ["y"] = 3, ["param1"] = 4, ["z"] = 21, ["name"] = "default:stone_block"}, {["x"] = 14, ["param2"] = 2, ["y"] = 4, ["param1"] = 14, ["z"] = 20, ["name"] = "stairs:slab_stone_block"}, {["x"] = 14, ["param2"] = 2, ["y"] = 4, ["param1"] = 14, ["z"] = 21, ["name"] = "stairs:slab_stone_block"}, {["x"] = 15, ["y"] = 0, ["param1"] = 1, ["z"] = 10, ["name"] = "default:stone"}, {["x"] = 15, ["y"] = 0, ["param1"] = 1, ["z"] = 11, ["name"] = "default:stone"}, {["x"] = 15, ["y"] = 0, ["param1"] = 1, ["z"] = 12, ["name"] = "default:stone"}, {["x"] = 15, ["y"] = 0, ["param1"] = 1, ["z"] = 13, ["name"] = "default:stone"}, {["x"] = 15, ["y"] = 0, ["param1"] = 1, ["z"] = 14, ["name"] = "default:stone"}, {["x"] = 15, ["y"] = 0, ["param1"] = 1, ["z"] = 15, ["name"] = "default:stone"}, {["x"] = 15, ["y"] = 0, ["param1"] = 1, ["z"] = 16, ["name"] = "default:stone"}, {["x"] = 15, ["param2"] = 21, ["y"] = 0, ["param1"] = 9, ["z"] = 17, ["name"] = "stairs:slab_stone"}, {["x"] = 15, ["y"] = 1, ["param1"] = 4, ["z"] = 9, ["name"] = "default:stone_block"}, {["x"] = 15, ["y"] = 1, ["param1"] = 4, ["z"] = 10, ["name"] = "default:stone_block"}, {["x"] = 15, ["y"] = 1, ["param1"] = 4, ["z"] = 11, ["name"] = "default:stone_block"}, {["x"] = 15, ["y"] = 1, ["param1"] = 4, ["z"] = 12, ["name"] = "default:stone_block"}, {["x"] = 15, ["y"] = 1, ["param1"] = 1, ["z"] = 13, ["name"] = "default:stone"}, {["x"] = 15, ["y"] = 1, ["param1"] = 1, ["z"] = 14, ["name"] = "default:stone"}, {["x"] = 15, ["y"] = 1, ["param1"] = 1, ["z"] = 15, ["name"] = "default:stone"}, {["x"] = 15, ["y"] = 1, ["param1"] = 1, ["z"] = 16, ["name"] = "default:stone"}, {["x"] = 15, ["y"] = 1, ["param1"] = 1, ["z"] = 17, ["name"] = "default:stone"}, {["x"] = 15, ["y"] = 1, ["param1"] = 1, ["z"] = 18, ["name"] = "default:stone"}, {["x"] = 15, ["param2"] = 21, ["y"] = 1, ["param1"] = 11, ["z"] = 19, ["name"] = "stairs:slab_stone"}, {["x"] = 15, ["y"] = 2, ["param1"] = 4, ["z"] = 8, ["name"] = "default:stone_block"}, {["x"] = 15, ["y"] = 2, ["param1"] = 4, ["z"] = 9, ["name"] = "default:stone_block"}, {["x"] = 15, ["param2"] = 2, ["y"] = 2, ["param1"] = 14, ["z"] = 10, ["name"] = "stairs:slab_cobble"}, {["x"] = 15, ["param2"] = 2, ["y"] = 2, ["param1"] = 14, ["z"] = 11, ["name"] = "stairs:slab_cobble"}, {["x"] = 15, ["y"] = 2, ["param1"] = 2, ["z"] = 12, ["name"] = "default:cobble"}, {["x"] = 15, ["y"] = 2, ["param1"] = 2, ["z"] = 13, ["name"] = "default:cobble"}, {["x"] = 15, ["y"] = 2, ["param1"] = 2, ["z"] = 14, ["name"] = "default:cobble"}, {["x"] = 15, ["y"] = 2, ["param1"] = 2, ["z"] = 15, ["name"] = "default:cobble"}, {["x"] = 15, ["y"] = 2, ["param1"] = 2, ["z"] = 16, ["name"] = "default:cobble"}, {["x"] = 15, ["y"] = 2, ["param1"] = 2, ["z"] = 17, ["name"] = "default:cobble"}, {["x"] = 15, ["y"] = 2, ["param1"] = 4, ["z"] = 18, ["name"] = "default:stone_block"}, {["x"] = 15, ["y"] = 2, ["param1"] = 1, ["z"] = 19, ["name"] = "default:stone"}, {["x"] = 15, ["y"] = 2, ["param1"] = 1, ["z"] = 20, ["name"] = "default:stone"}, {["x"] = 15, ["y"] = 2, ["param1"] = 1, ["z"] = 21, ["name"] = "default:stone"}, {["x"] = 15, ["param2"] = 1, ["y"] = 3, ["param1"] = 14, ["z"] = 8, ["name"] = "stairs:slab_stone_block"}, {["x"] = 15, ["param2"] = 1, ["y"] = 3, ["param1"] = 14, ["z"] = 9, ["name"] = "stairs:slab_stone_block"}, {["x"] = 15, ["param2"] = 1, ["y"] = 3, ["param1"] = 14, ["z"] = 18, ["name"] = "stairs:slab_cobble"}, {["x"] = 15, ["param2"] = 1, ["y"] = 3, ["param1"] = 14, ["z"] = 19, ["name"] = "stairs:slab_cobble"}, {["x"] = 15, ["param2"] = 1, ["y"] = 3, ["param1"] = 14, ["z"] = 20, ["name"] = "stairs:slab_cobble"}, {["x"] = 15, ["y"] = 3, ["param1"] = 4, ["z"] = 21, ["name"] = "default:stone_block"}, {["x"] = 15, ["y"] = 3, ["param1"] = 4, ["z"] = 22, ["name"] = "default:stone_block"}, {["x"] = 15, ["param2"] = 1, ["y"] = 4, ["param1"] = 14, ["z"] = 21, ["name"] = "stairs:slab_stone_block"}, {["x"] = 15, ["y"] = 4, ["param1"] = 4, ["z"] = 22, ["name"] = "default:stone_block"}, {["x"] = 16, ["y"] = 0, ["param1"] = 1, ["z"] = 11, ["name"] = "default:stone"}, {["x"] = 16, ["y"] = 0, ["param1"] = 1, ["z"] = 12, ["name"] = "default:stone"}, {["x"] = 16, ["y"] = 0, ["param1"] = 1, ["z"] = 13, ["name"] = "default:stone"}, {["x"] = 16, ["y"] = 0, ["param1"] = 1, ["z"] = 14, ["name"] = "default:stone"}, {["x"] = 16, ["y"] = 0, ["param1"] = 1, ["z"] = 15, ["name"] = "default:stone"}, {["x"] = 16, ["y"] = 0, ["param1"] = 1, ["z"] = 16, ["name"] = "default:stone"}, {["x"] = 16, ["param2"] = 21, ["y"] = 0, ["param1"] = 8, ["z"] = 17, ["name"] = "stairs:slab_stone"}, {["x"] = 16, ["y"] = 1, ["param1"] = 4, ["z"] = 10, ["name"] = "default:stone_block"}, {["x"] = 16, ["y"] = 1, ["param1"] = 4, ["z"] = 11, ["name"] = "default:stone_block"}, {["x"] = 16, ["y"] = 1, ["param1"] = 4, ["z"] = 12, ["name"] = "default:stone_block"}, {["x"] = 16, ["y"] = 1, ["param1"] = 1, ["z"] = 13, ["name"] = "default:stone"}, {["x"] = 16, ["y"] = 1, ["param1"] = 1, ["z"] = 14, ["name"] = "default:stone"}, {["x"] = 16, ["y"] = 1, ["param1"] = 1, ["z"] = 15, ["name"] = "default:stone"}, {["x"] = 16, ["y"] = 1, ["param1"] = 1, ["z"] = 16, ["name"] = "default:stone"}, {["x"] = 16, ["y"] = 1, ["param1"] = 1, ["z"] = 17, ["name"] = "default:stone"}, {["x"] = 16, ["y"] = 1, ["param1"] = 1, ["z"] = 18, ["name"] = "default:stone"}, {["x"] = 16, ["param2"] = 21, ["y"] = 1, ["param1"] = 10, ["z"] = 19, ["name"] = "stairs:slab_stone"}, {["x"] = 16, ["y"] = 2, ["param1"] = 4, ["z"] = 9, ["name"] = "default:stone_block"}, {["x"] = 16, ["y"] = 2, ["param1"] = 4, ["z"] = 10, ["name"] = "default:stone_block"}, {["x"] = 16, ["y"] = 2, ["param1"] = 2, ["z"] = 11, ["name"] = "default:cobble"}, {["x"] = 16, ["y"] = 2, ["param1"] = 2, ["z"] = 12, ["name"] = "default:cobble"}, {["x"] = 16, ["y"] = 2, ["param1"] = 2, ["z"] = 13, ["name"] = "default:cobble"}, {["x"] = 16, ["y"] = 2, ["param1"] = 2, ["z"] = 14, ["name"] = "default:cobble"}, {["x"] = 16, ["y"] = 2, ["param1"] = 2, ["z"] = 15, ["name"] = "default:cobble"}, {["x"] = 16, ["y"] = 2, ["param1"] = 2, ["z"] = 16, ["name"] = "default:cobble"}, {["x"] = 16, ["y"] = 2, ["param1"] = 4, ["z"] = 17, ["name"] = "default:stone_block"}, {["x"] = 16, ["y"] = 2, ["param1"] = 1, ["z"] = 18, ["name"] = "default:stone"}, {["x"] = 16, ["y"] = 2, ["param1"] = 1, ["z"] = 19, ["name"] = "default:stone"}, {["x"] = 16, ["y"] = 2, ["param1"] = 1, ["z"] = 20, ["name"] = "default:stone"}, {["x"] = 16, ["y"] = 2, ["param1"] = 1, ["z"] = 21, ["name"] = "default:stone"}, {["x"] = 16, ["y"] = 2, ["param1"] = 1, ["z"] = 22, ["name"] = "default:stone"}, {["x"] = 16, ["y"] = 3, ["param1"] = 4, ["z"] = 9, ["name"] = "default:stone_block"}, {["x"] = 16, ["y"] = 3, ["param1"] = 4, ["z"] = 10, ["name"] = "default:stone_block"}, {["x"] = 16, ["y"] = 3, ["param1"] = 14, ["z"] = 17, ["name"] = "stairs:slab_cobble"}, {["x"] = 16, ["y"] = 3, ["param1"] = 14, ["z"] = 18, ["name"] = "stairs:slab_cobble"}, {["x"] = 16, ["param2"] = 1, ["y"] = 3, ["param1"] = 14, ["z"] = 19, ["name"] = "stairs:slab_cobble"}, {["x"] = 16, ["param2"] = 1, ["y"] = 3, ["param1"] = 14, ["z"] = 20, ["name"] = "stairs:slab_cobble"}, {["x"] = 16, ["param2"] = 1, ["y"] = 3, ["param1"] = 14, ["z"] = 21, ["name"] = "stairs:slab_cobble"}, {["x"] = 16, ["y"] = 3, ["param1"] = 4, ["z"] = 22, ["name"] = "default:stone_block"}, {["x"] = 16, ["y"] = 3, ["param1"] = 4, ["z"] = 23, ["name"] = "default:stone_block"}, {["x"] = 16, ["y"] = 4, ["param1"] = 4, ["z"] = 22, ["name"] = "default:stone_block"}, {["x"] = 16, ["y"] = 4, ["param1"] = 4, ["z"] = 23, ["name"] = "default:stone_block"}, {["x"] = 17, ["param2"] = 20, ["y"] = 0, ["param1"] = 12, ["z"] = 12, ["name"] = "stairs:slab_stone"}, {["x"] = 17, ["param2"] = 20, ["y"] = 0, ["param1"] = 11, ["z"] = 13, ["name"] = "stairs:slab_stone"}, {["x"] = 17, ["param2"] = 20, ["y"] = 0, ["param1"] = 10, ["z"] = 14, ["name"] = "stairs:slab_stone"}, {["x"] = 17, ["param2"] = 20, ["y"] = 0, ["param1"] = 9, ["z"] = 15, ["name"] = "stairs:slab_stone"}, {["x"] = 17, ["param2"] = 20, ["y"] = 0, ["param1"] = 8, ["z"] = 16, ["name"] = "stairs:slab_stone"}, {["x"] = 17, ["param2"] = 20, ["y"] = 0, ["param1"] = 7, ["z"] = 17, ["name"] = "stairs:slab_stone"}, {["x"] = 17, ["y"] = 1, ["param1"] = 4, ["z"] = 11, ["name"] = "default:stone_block"}, {["x"] = 17, ["y"] = 1, ["param1"] = 4, ["z"] = 12, ["name"] = "default:stone_block"}, {["x"] = 17, ["y"] = 1, ["param1"] = 1, ["z"] = 13, ["name"] = "default:stone"}, {["x"] = 17, ["y"] = 1, ["param1"] = 1, ["z"] = 14, ["name"] = "default:stone"}, {["x"] = 17, ["y"] = 1, ["param1"] = 1, ["z"] = 15, ["name"] = "default:stone"}, {["x"] = 17, ["y"] = 1, ["param1"] = 1, ["z"] = 16, ["name"] = "default:stone"}, {["x"] = 17, ["y"] = 1, ["param1"] = 1, ["z"] = 17, ["name"] = "default:stone"}, {["x"] = 17, ["y"] = 1, ["param1"] = 1, ["z"] = 18, ["name"] = "default:stone"}, {["x"] = 17, ["param2"] = 21, ["y"] = 1, ["param1"] = 9, ["z"] = 19, ["name"] = "stairs:slab_stone"}, {["x"] = 17, ["param2"] = 21, ["y"] = 1, ["param1"] = 10, ["z"] = 20, ["name"] = "stairs:slab_stone"}, {["x"] = 17, ["y"] = 2, ["param1"] = 4, ["z"] = 10, ["name"] = "default:stone_block"}, {["x"] = 17, ["y"] = 2, ["param1"] = 4, ["z"] = 11, ["name"] = "default:stone_block"}, {["x"] = 17, ["y"] = 2, ["param1"] = 2, ["z"] = 12, ["name"] = "default:cobble"}, {["x"] = 17, ["y"] = 2, ["param1"] = 2, ["z"] = 13, ["name"] = "default:cobble"}, {["x"] = 17, ["y"] = 2, ["param1"] = 2, ["z"] = 14, ["name"] = "default:cobble"}, {["x"] = 17, ["y"] = 2, ["param1"] = 2, ["z"] = 15, ["name"] = "default:cobble"}, {["x"] = 17, ["y"] = 2, ["param1"] = 4, ["z"] = 16, ["name"] = "default:stone_block"}, {["x"] = 17, ["y"] = 2, ["param1"] = 1, ["z"] = 17, ["name"] = "default:stone"}, {["x"] = 17, ["y"] = 2, ["param1"] = 1, ["z"] = 18, ["name"] = "default:stone"}, {["x"] = 17, ["y"] = 2, ["param1"] = 1, ["z"] = 19, ["name"] = "default:stone"}, {["x"] = 17, ["y"] = 2, ["param1"] = 1, ["z"] = 20, ["name"] = "default:stone"}, {["x"] = 17, ["y"] = 2, ["param1"] = 1, ["z"] = 21, ["name"] = "default:stone"}, {["x"] = 17, ["y"] = 2, ["param1"] = 1, ["z"] = 22, ["name"] = "default:stone"}, {["x"] = 17, ["y"] = 2, ["param1"] = 1, ["z"] = 23, ["name"] = "default:stone"}, {["x"] = 17, ["y"] = 3, ["param1"] = 4, ["z"] = 10, ["name"] = "default:stone_block"}, {["x"] = 17, ["y"] = 3, ["param1"] = 4, ["z"] = 11, ["name"] = "default:stone_block"}, {["x"] = 17, ["y"] = 3, ["param1"] = 14, ["z"] = 16, ["name"] = "stairs:slab_cobble"}, {["x"] = 17, ["y"] = 3, ["param1"] = 14, ["z"] = 17, ["name"] = "stairs:slab_cobble"}, {["x"] = 17, ["y"] = 3, ["param1"] = 14, ["z"] = 18, ["name"] = "stairs:slab_cobble"}, {["x"] = 17, ["param2"] = 1, ["y"] = 3, ["param1"] = 14, ["z"] = 19, ["name"] = "stairs:slab_cobble"}, {["x"] = 17, ["param2"] = 1, ["y"] = 3, ["param1"] = 14, ["z"] = 20, ["name"] = "stairs:slab_cobble"}, {["x"] = 17, ["param2"] = 1, ["y"] = 3, ["param1"] = 14, ["z"] = 21, ["name"] = "stairs:slab_cobble"}, {["x"] = 17, ["y"] = 3, ["param1"] = 2, ["z"] = 22, ["name"] = "default:cobble"}, {["x"] = 17, ["y"] = 3, ["param1"] = 4, ["z"] = 23, ["name"] = "default:stone_block"}, {["x"] = 17, ["y"] = 3, ["param1"] = 4, ["z"] = 24, ["name"] = "default:stone_block"}, {["x"] = 17, ["y"] = 4, ["param1"] = 4, ["z"] = 23, ["name"] = "default:stone_block"}, {["x"] = 17, ["y"] = 4, ["param1"] = 4, ["z"] = 24, ["name"] = "default:stone_block"}, {["x"] = 18, ["y"] = 1, ["param1"] = 4, ["z"] = 12, ["name"] = "default:stone_block"}, {["x"] = 18, ["y"] = 1, ["param1"] = 1, ["z"] = 13, ["name"] = "default:stone"}, {["x"] = 18, ["y"] = 1, ["param1"] = 1, ["z"] = 14, ["name"] = "default:stone"}, {["x"] = 18, ["y"] = 1, ["param1"] = 1, ["z"] = 15, ["name"] = "default:stone"}, {["x"] = 18, ["y"] = 1, ["param1"] = 1, ["z"] = 16, ["name"] = "default:stone"}, {["x"] = 18, ["y"] = 1, ["param1"] = 1, ["z"] = 17, ["name"] = "default:stone"}, {["x"] = 18, ["y"] = 1, ["param1"] = 1, ["z"] = 18, ["name"] = "default:stone"}, {["x"] = 18, ["param2"] = 21, ["y"] = 1, ["param1"] = 8, ["z"] = 19, ["name"] = "stairs:slab_stone"}, {["x"] = 18, ["param2"] = 22, ["y"] = 1, ["param1"] = 9, ["z"] = 20, ["name"] = "stairs:slab_stone"}, {["x"] = 18, ["param2"] = 22, ["y"] = 1, ["param1"] = 10, ["z"] = 21, ["name"] = "stairs:slab_stone"}, {["x"] = 18, ["y"] = 2, ["param1"] = 4, ["z"] = 11, ["name"] = "default:stone_block"}, {["x"] = 18, ["y"] = 2, ["param1"] = 4, ["z"] = 12, ["name"] = "default:stone_block"}, {["x"] = 18, ["y"] = 2, ["param1"] = 2, ["z"] = 13, ["name"] = "default:cobble"}, {["x"] = 18, ["y"] = 2, ["param1"] = 2, ["z"] = 14, ["name"] = "default:cobble"}, {["x"] = 18, ["y"] = 2, ["param1"] = 4, ["z"] = 15, ["name"] = "default:stone_block"}, {["x"] = 18, ["y"] = 2, ["param1"] = 1, ["z"] = 16, ["name"] = "default:stone"}, {["x"] = 18, ["y"] = 2, ["param1"] = 1, ["z"] = 17, ["name"] = "default:stone"}, {["x"] = 18, ["y"] = 2, ["param1"] = 1, ["z"] = 18, ["name"] = "default:stone"}, {["x"] = 18, ["y"] = 2, ["param1"] = 1, ["z"] = 19, ["name"] = "default:stone"}, {["x"] = 18, ["y"] = 2, ["param1"] = 1, ["z"] = 20, ["name"] = "default:stone"}, {["x"] = 18, ["y"] = 2, ["param1"] = 1, ["z"] = 21, ["name"] = "default:stone"}, {["x"] = 18, ["y"] = 2, ["param1"] = 1, ["z"] = 22, ["name"] = "default:stone"}, {["x"] = 18, ["y"] = 2, ["param1"] = 1, ["z"] = 23, ["name"] = "default:stone"}, {["x"] = 18, ["y"] = 2, ["param1"] = 1, ["z"] = 24, ["name"] = "default:stone"}, {["x"] = 18, ["y"] = 3, ["param1"] = 4, ["z"] = 11, ["name"] = "default:stone_block"}, {["x"] = 18, ["y"] = 3, ["param1"] = 4, ["z"] = 12, ["name"] = "default:stone_block"}, {["x"] = 18, ["param2"] = 2, ["y"] = 3, ["param1"] = 14, ["z"] = 15, ["name"] = "stairs:slab_cobble"}, {["x"] = 18, ["y"] = 3, ["param1"] = 14, ["z"] = 16, ["name"] = "stairs:slab_cobble"}, {["x"] = 18, ["y"] = 3, ["param1"] = 14, ["z"] = 17, ["name"] = "stairs:slab_cobble"}, {["x"] = 18, ["param2"] = 1, ["y"] = 3, ["param1"] = 14, ["z"] = 18, ["name"] = "stairs:slab_cobble"}, {["x"] = 18, ["param2"] = 1, ["y"] = 3, ["param1"] = 14, ["z"] = 19, ["name"] = "stairs:slab_cobble"}, {["x"] = 18, ["param2"] = 1, ["y"] = 3, ["param1"] = 14, ["z"] = 20, ["name"] = "stairs:slab_cobble"}, {["x"] = 18, ["y"] = 3, ["param1"] = 2, ["z"] = 21, ["name"] = "default:cobble"}, {["x"] = 18, ["y"] = 3, ["param1"] = 2, ["z"] = 22, ["name"] = "default:cobble"}, {["x"] = 18, ["y"] = 3, ["param1"] = 2, ["z"] = 23, ["name"] = "default:cobble"}, {["x"] = 18, ["y"] = 3, ["param1"] = 4, ["z"] = 24, ["name"] = "default:stone_block"}, {["x"] = 18, ["y"] = 4, ["param1"] = 4, ["z"] = 24, ["name"] = "default:stone_block"}, {["x"] = 18, ["y"] = 4, ["param1"] = 4, ["z"] = 25, ["name"] = "default:stone_block"}, {["x"] = 18, ["param2"] = 1, ["y"] = 5, ["param1"] = 14, ["z"] = 25, ["name"] = "stairs:slab_stone_block"}, {["x"] = 19, ["param2"] = 20, ["y"] = 1, ["param1"] = 11, ["z"] = 15, ["name"] = "stairs:slab_stone"}, {["x"] = 19, ["param2"] = 20, ["y"] = 1, ["param1"] = 10, ["z"] = 16, ["name"] = "stairs:slab_stone"}, {["x"] = 19, ["param2"] = 20, ["y"] = 1, ["param1"] = 9, ["z"] = 17, ["name"] = "stairs:slab_stone"}, {["x"] = 19, ["param2"] = 20, ["y"] = 1, ["param1"] = 8, ["z"] = 18, ["name"] = "stairs:slab_stone"}, {["x"] = 19, ["param2"] = 21, ["y"] = 1, ["param1"] = 7, ["z"] = 19, ["name"] = "stairs:slab_stone"}, {["x"] = 19, ["param2"] = 22, ["y"] = 1, ["param1"] = 8, ["z"] = 20, ["name"] = "stairs:slab_stone"}, {["x"] = 19, ["param2"] = 21, ["y"] = 1, ["param1"] = 9, ["z"] = 21, ["name"] = "stairs:slab_stone"}, {["x"] = 19, ["param2"] = 21, ["y"] = 1, ["param1"] = 10, ["z"] = 22, ["name"] = "stairs:slab_stone"}, {["x"] = 19, ["y"] = 2, ["param1"] = 4, ["z"] = 13, ["name"] = "default:stone_block"}, {["x"] = 19, ["y"] = 2, ["param1"] = 4, ["z"] = 14, ["name"] = "default:stone_block"}, {["x"] = 19, ["y"] = 2, ["param1"] = 1, ["z"] = 15, ["name"] = "default:stone"}, {["x"] = 19, ["y"] = 2, ["param1"] = 1, ["z"] = 16, ["name"] = "default:stone"}, {["x"] = 19, ["y"] = 2, ["param1"] = 1, ["z"] = 17, ["name"] = "default:stone"}, {["x"] = 19, ["y"] = 2, ["param1"] = 1, ["z"] = 18, ["name"] = "default:stone"}, {["x"] = 19, ["y"] = 2, ["param1"] = 1, ["z"] = 19, ["name"] = "default:stone"}, {["x"] = 19, ["y"] = 2, ["param1"] = 1, ["z"] = 20, ["name"] = "default:stone"}, {["x"] = 19, ["y"] = 2, ["param1"] = 1, ["z"] = 21, ["name"] = "default:stone"}, {["x"] = 19, ["y"] = 2, ["param1"] = 1, ["z"] = 22, ["name"] = "default:stone"}, {["x"] = 19, ["y"] = 2, ["param1"] = 1, ["z"] = 23, ["name"] = "default:stone"}, {["x"] = 19, ["y"] = 2, ["param1"] = 1, ["z"] = 24, ["name"] = "default:stone"}, {["x"] = 19, ["y"] = 3, ["param1"] = 4, ["z"] = 12, ["name"] = "default:stone_block"}, {["x"] = 19, ["y"] = 3, ["param1"] = 4, ["z"] = 13, ["name"] = "default:stone_block"}, {["x"] = 19, ["param2"] = 2, ["y"] = 3, ["param1"] = 14, ["z"] = 14, ["name"] = "stairs:slab_cobble"}, {["x"] = 19, ["y"] = 3, ["param1"] = 14, ["z"] = 15, ["name"] = "stairs:slab_cobble"}, {["x"] = 19, ["y"] = 3, ["param1"] = 14, ["z"] = 16, ["name"] = "stairs:slab_cobble"}, {["x"] = 19, ["param2"] = 1, ["y"] = 3, ["param1"] = 14, ["z"] = 17, ["name"] = "stairs:slab_cobble"}, {["x"] = 19, ["param2"] = 1, ["y"] = 3, ["param1"] = 14, ["z"] = 18, ["name"] = "stairs:slab_cobble"}, {["x"] = 19, ["param2"] = 1, ["y"] = 3, ["param1"] = 14, ["z"] = 19, ["name"] = "stairs:slab_cobble"}, {["x"] = 19, ["y"] = 3, ["param1"] = 2, ["z"] = 20, ["name"] = "default:cobble"}, {["x"] = 19, ["y"] = 3, ["param1"] = 2, ["z"] = 21, ["name"] = "default:cobble"}, {["x"] = 19, ["y"] = 3, ["param1"] = 2, ["z"] = 22, ["name"] = "default:cobble"}, {["x"] = 19, ["y"] = 3, ["param1"] = 2, ["z"] = 23, ["name"] = "default:cobble"}, {["x"] = 19, ["y"] = 3, ["param1"] = 2, ["z"] = 24, ["name"] = "default:cobble"}, {["x"] = 19, ["y"] = 3, ["param1"] = 4, ["z"] = 25, ["name"] = "default:stone_block"}, {["x"] = 19, ["param2"] = 3, ["y"] = 4, ["param1"] = 14, ["z"] = 12, ["name"] = "stairs:slab_stone_block"}, {["x"] = 19, ["param2"] = 3, ["y"] = 4, ["param1"] = 14, ["z"] = 13, ["name"] = "stairs:slab_stone_block"}, {["x"] = 19, ["y"] = 4, ["param1"] = 4, ["z"] = 25, ["name"] = "default:stone_block"}, {["x"] = 19, ["y"] = 4, ["param1"] = 4, ["z"] = 26, ["name"] = "default:stone_block"}, {["x"] = 19, ["param2"] = 2, ["y"] = 5, ["param1"] = 14, ["z"] = 25, ["name"] = "stairs:slab_stone_block"}, {["x"] = 19, ["param2"] = 1, ["y"] = 5, ["param1"] = 14, ["z"] = 26, ["name"] = "stairs:slab_stone_block"}, {["x"] = 20, ["y"] = 0, ["param1"] = 15, ["z"] = 5, ["name"] = "butterflies:hidden_butterfly_white"}, {["x"] = 20, ["param2"] = 20, ["y"] = 1, ["param1"] = 10, ["z"] = 17, ["name"] = "stairs:slab_stone"}, {["x"] = 20, ["param2"] = 20, ["y"] = 1, ["param1"] = 9, ["z"] = 18, ["name"] = "stairs:slab_stone"}, {["x"] = 20, ["param2"] = 21, ["y"] = 1, ["param1"] = 8, ["z"] = 19, ["name"] = "stairs:slab_stone"}, {["x"] = 20, ["param2"] = 20, ["y"] = 1, ["param1"] = 7, ["z"] = 20, ["name"] = "stairs:slab_stone"}, {["x"] = 20, ["param2"] = 21, ["y"] = 1, ["param1"] = 8, ["z"] = 21, ["name"] = "stairs:slab_stone"}, {["x"] = 20, ["param2"] = 21, ["y"] = 1, ["param1"] = 9, ["z"] = 22, ["name"] = "stairs:slab_stone"}, {["x"] = 20, ["y"] = 2, ["param1"] = 4, ["z"] = 14, ["name"] = "default:stone_block"}, {["x"] = 20, ["y"] = 2, ["param1"] = 1, ["z"] = 15, ["name"] = "default:stone"}, {["x"] = 20, ["y"] = 2, ["param1"] = 1, ["z"] = 16, ["name"] = "default:stone"}, {["x"] = 20, ["y"] = 2, ["param1"] = 1, ["z"] = 17, ["name"] = "default:stone"}, {["x"] = 20, ["y"] = 2, ["param1"] = 1, ["z"] = 18, ["name"] = "default:stone"}, {["x"] = 20, ["y"] = 2, ["param1"] = 1, ["z"] = 19, ["name"] = "default:stone"}, {["x"] = 20, ["y"] = 2, ["param1"] = 1, ["z"] = 20, ["name"] = "default:stone"}, {["x"] = 20, ["y"] = 2, ["param1"] = 1, ["z"] = 21, ["name"] = "default:stone"}, {["x"] = 20, ["y"] = 2, ["param1"] = 1, ["z"] = 22, ["name"] = "default:stone"}, {["x"] = 20, ["y"] = 2, ["param1"] = 1, ["z"] = 23, ["name"] = "default:stone"}, {["x"] = 20, ["y"] = 2, ["param1"] = 1, ["z"] = 24, ["name"] = "default:stone"}, {["x"] = 20, ["param2"] = 21, ["y"] = 2, ["param1"] = 12, ["z"] = 25, ["name"] = "stairs:slab_stone"}, {["x"] = 20, ["y"] = 3, ["param1"] = 4, ["z"] = 13, ["name"] = "default:stone_block"}, {["x"] = 20, ["y"] = 3, ["param1"] = 4, ["z"] = 14, ["name"] = "default:stone_block"}, {["x"] = 20, ["y"] = 3, ["param1"] = 14, ["z"] = 15, ["name"] = "stairs:slab_cobble"}, {["x"] = 20, ["param2"] = 2, ["y"] = 3, ["param1"] = 14, ["z"] = 16, ["name"] = "stairs:slab_cobble"}, {["x"] = 20, ["param2"] = 2, ["y"] = 3, ["param1"] = 14, ["z"] = 17, ["name"] = "stairs:slab_cobble"}, {["x"] = 20, ["param2"] = 1, ["y"] = 3, ["param1"] = 14, ["z"] = 18, ["name"] = "stairs:slab_cobble"}, {["x"] = 20, ["y"] = 3, ["param1"] = 2, ["z"] = 19, ["name"] = "default:cobble"}, {["x"] = 20, ["y"] = 3, ["param1"] = 2, ["z"] = 20, ["name"] = "default:cobble"}, {["x"] = 20, ["y"] = 3, ["param1"] = 2, ["z"] = 21, ["name"] = "default:cobble"}, {["x"] = 20, ["y"] = 3, ["param1"] = 2, ["z"] = 22, ["name"] = "default:cobble"}, {["x"] = 20, ["y"] = 3, ["param1"] = 2, ["z"] = 23, ["name"] = "default:cobble"}, {["x"] = 20, ["y"] = 3, ["param1"] = 2, ["z"] = 24, ["name"] = "default:cobble"}, {["x"] = 20, ["y"] = 3, ["param1"] = 4, ["z"] = 25, ["name"] = "default:stone_block"}, {["x"] = 20, ["y"] = 3, ["param1"] = 4, ["z"] = 26, ["name"] = "default:stone_block"}, {["x"] = 20, ["param2"] = 2, ["y"] = 4, ["param1"] = 14, ["z"] = 13, ["name"] = "stairs:slab_stone_block"}, {["x"] = 20, ["param2"] = 2, ["y"] = 4, ["param1"] = 14, ["z"] = 14, ["name"] = "stairs:slab_stone_block"}, {["x"] = 20, ["y"] = 4, ["param1"] = 14, ["z"] = 25, ["name"] = "stairs:slab_cobble"}, {["x"] = 20, ["y"] = 4, ["param1"] = 4, ["z"] = 26, ["name"] = "default:stone_block"}, {["x"] = 20, ["y"] = 4, ["param1"] = 4, ["z"] = 27, ["name"] = "default:stone_block"}, {["x"] = 20, ["param2"] = 2, ["y"] = 5, ["param1"] = 14, ["z"] = 26, ["name"] = "stairs:slab_stone_block"}, {["x"] = 20, ["param2"] = 1, ["y"] = 5, ["param1"] = 14, ["z"] = 27, ["name"] = "stairs:slab_stone_block"}, {["x"] = 21, ["param2"] = 20, ["y"] = 1, ["param1"] = 10, ["z"] = 18, ["name"] = "stairs:slab_stone"}, {["x"] = 21, ["param2"] = 21, ["y"] = 1, ["param1"] = 9, ["z"] = 19, ["name"] = "stairs:slab_stone"}, {["x"] = 21, ["param2"] = 20, ["y"] = 1, ["param1"] = 8, ["z"] = 20, ["name"] = "stairs:slab_stone"}, {["x"] = 21, ["param2"] = 20, ["y"] = 1, ["param1"] = 7, ["z"] = 21, ["name"] = "stairs:slab_stone"}, {["x"] = 21, ["param2"] = 21, ["y"] = 1, ["param1"] = 8, ["z"] = 22, ["name"] = "stairs:slab_stone"}, {["x"] = 21, ["y"] = 2, ["param1"] = 1, ["z"] = 15, ["name"] = "default:stone"}, {["x"] = 21, ["y"] = 2, ["param1"] = 1, ["z"] = 16, ["name"] = "default:stone"}, {["x"] = 21, ["y"] = 2, ["param1"] = 1, ["z"] = 17, ["name"] = "default:stone"}, {["x"] = 21, ["y"] = 2, ["param1"] = 1, ["z"] = 18, ["name"] = "default:stone"}, {["x"] = 21, ["y"] = 2, ["param1"] = 1, ["z"] = 19, ["name"] = "default:stone"}, {["x"] = 21, ["y"] = 2, ["param1"] = 1, ["z"] = 20, ["name"] = "default:stone"}, {["x"] = 21, ["y"] = 2, ["param1"] = 1, ["z"] = 21, ["name"] = "default:stone"}, {["x"] = 21, ["y"] = 2, ["param1"] = 1, ["z"] = 22, ["name"] = "default:stone"}, {["x"] = 21, ["y"] = 2, ["param1"] = 1, ["z"] = 23, ["name"] = "default:stone"}, {["x"] = 21, ["y"] = 2, ["param1"] = 1, ["z"] = 24, ["name"] = "default:stone"}, {["x"] = 21, ["param2"] = 21, ["y"] = 2, ["param1"] = 11, ["z"] = 25, ["name"] = "stairs:slab_stone"}, {["x"] = 21, ["y"] = 3, ["param1"] = 4, ["z"] = 14, ["name"] = "default:stone_block"}, {["x"] = 21, ["y"] = 3, ["param1"] = 4, ["z"] = 15, ["name"] = "default:stone_block"}, {["x"] = 21, ["param2"] = 2, ["y"] = 3, ["param1"] = 14, ["z"] = 16, ["name"] = "stairs:slab_cobble"}, {["x"] = 21, ["param2"] = 1, ["y"] = 3, ["param1"] = 14, ["z"] = 17, ["name"] = "stairs:slab_cobble"}, {["x"] = 21, ["y"] = 3, ["param1"] = 2, ["z"] = 18, ["name"] = "default:cobble"}, {["x"] = 21, ["y"] = 3, ["param1"] = 2, ["z"] = 19, ["name"] = "default:cobble"}, {["x"] = 21, ["y"] = 3, ["param1"] = 2, ["z"] = 20, ["name"] = "default:cobble"}, {["x"] = 21, ["y"] = 3, ["param1"] = 2, ["z"] = 21, ["name"] = "default:cobble"}, {["x"] = 21, ["y"] = 3, ["param1"] = 2, ["z"] = 22, ["name"] = "default:cobble"}, {["x"] = 21, ["y"] = 3, ["param1"] = 2, ["z"] = 23, ["name"] = "default:cobble"}, {["x"] = 21, ["y"] = 3, ["param1"] = 4, ["z"] = 24, ["name"] = "default:stone_block"}, {["x"] = 21, ["y"] = 3, ["param1"] = 4, ["z"] = 25, ["name"] = "default:stone_block"}, {["x"] = 21, ["y"] = 3, ["param1"] = 4, ["z"] = 26, ["name"] = "default:stone_block"}, {["x"] = 21, ["y"] = 3, ["param1"] = 4, ["z"] = 27, ["name"] = "default:stone_block"}, {["x"] = 21, ["param2"] = 2, ["y"] = 4, ["param1"] = 14, ["z"] = 14, ["name"] = "stairs:slab_stone_block"}, {["x"] = 21, ["param2"] = 2, ["y"] = 4, ["param1"] = 14, ["z"] = 15, ["name"] = "stairs:slab_stone_block"}, {["x"] = 21, ["y"] = 4, ["param1"] = 14, ["z"] = 24, ["name"] = "stairs:slab_cobble"}, {["x"] = 21, ["param2"] = 1, ["y"] = 4, ["param1"] = 14, ["z"] = 25, ["name"] = "stairs:slab_cobble"}, {["x"] = 21, ["param2"] = 1, ["y"] = 4, ["param1"] = 14, ["z"] = 26, ["name"] = "stairs:slab_cobble"}, {["x"] = 21, ["y"] = 4, ["param1"] = 4, ["z"] = 27, ["name"] = "default:stone_block"}, {["x"] = 21, ["y"] = 4, ["param1"] = 4, ["z"] = 28, ["name"] = "default:stone_block"}, {["x"] = 21, ["param2"] = 2, ["y"] = 5, ["param1"] = 14, ["z"] = 27, ["name"] = "stairs:slab_stone_block"}, {["x"] = 21, ["param2"] = 1, ["y"] = 5, ["param1"] = 14, ["z"] = 28, ["name"] = "stairs:slab_stone_block"}, {["x"] = 22, ["param2"] = 20, ["y"] = 1, ["param1"] = 10, ["z"] = 19, ["name"] = "stairs:slab_stone"}, {["x"] = 22, ["param2"] = 20, ["y"] = 1, ["param1"] = 9, ["z"] = 20, ["name"] = "stairs:slab_stone"}, {["x"] = 22, ["param2"] = 20, ["y"] = 1, ["param1"] = 8, ["z"] = 21, ["name"] = "stairs:slab_stone"}, {["x"] = 22, ["param2"] = 21, ["y"] = 1, ["param1"] = 7, ["z"] = 22, ["name"] = "stairs:slab_stone"}, {["x"] = 22, ["y"] = 2, ["param1"] = 1, ["z"] = 16, ["name"] = "default:stone"}, {["x"] = 22, ["y"] = 2, ["param1"] = 1, ["z"] = 17, ["name"] = "default:stone"}, {["x"] = 22, ["y"] = 2, ["param1"] = 1, ["z"] = 18, ["name"] = "default:stone"}, {["x"] = 22, ["y"] = 2, ["param1"] = 1, ["z"] = 19, ["name"] = "default:stone"}, {["x"] = 22, ["y"] = 2, ["param1"] = 1, ["z"] = 20, ["name"] = "default:stone"}, {["x"] = 22, ["y"] = 2, ["param1"] = 1, ["z"] = 21, ["name"] = "default:stone"}, {["x"] = 22, ["y"] = 2, ["param1"] = 1, ["z"] = 22, ["name"] = "default:stone"}, {["x"] = 22, ["y"] = 2, ["param1"] = 1, ["z"] = 23, ["name"] = "default:stone"}, {["x"] = 22, ["y"] = 2, ["param1"] = 1, ["z"] = 24, ["name"] = "default:stone"}, {["x"] = 22, ["param2"] = 21, ["y"] = 2, ["param1"] = 10, ["z"] = 25, ["name"] = "stairs:slab_stone"}, {["x"] = 22, ["param2"] = 21, ["y"] = 2, ["param1"] = 11, ["z"] = 26, ["name"] = "stairs:slab_stone"}, {["x"] = 22, ["y"] = 3, ["param1"] = 4, ["z"] = 15, ["name"] = "default:stone_block"}, {["x"] = 22, ["y"] = 3, ["param1"] = 4, ["z"] = 16, ["name"] = "default:stone_block"}, {["x"] = 22, ["y"] = 3, ["param1"] = 2, ["z"] = 17, ["name"] = "default:cobble"}, {["x"] = 22, ["y"] = 3, ["param1"] = 2, ["z"] = 18, ["name"] = "default:cobble"}, {["x"] = 22, ["y"] = 3, ["param1"] = 2, ["z"] = 19, ["name"] = "default:cobble"}, {["x"] = 22, ["y"] = 3, ["param1"] = 2, ["z"] = 20, ["name"] = "default:cobble"}, {["x"] = 22, ["y"] = 3, ["param1"] = 2, ["z"] = 21, ["name"] = "default:cobble"}, {["x"] = 22, ["y"] = 3, ["param1"] = 2, ["z"] = 22, ["name"] = "default:cobble"}, {["x"] = 22, ["y"] = 3, ["param1"] = 4, ["z"] = 23, ["name"] = "default:stone_block"}, {["x"] = 22, ["y"] = 3, ["param1"] = 4, ["z"] = 24, ["name"] = "default:stone_block"}, {["x"] = 22, ["y"] = 3, ["param1"] = 4, ["z"] = 25, ["name"] = "default:stone_block"}, {["x"] = 22, ["y"] = 3, ["param1"] = 4, ["z"] = 26, ["name"] = "default:stone_block"}, {["x"] = 22, ["y"] = 3, ["param1"] = 4, ["z"] = 27, ["name"] = "default:stone_block"}, {["x"] = 22, ["y"] = 3, ["param1"] = 4, ["z"] = 28, ["name"] = "default:stone_block"}, {["x"] = 22, ["y"] = 4, ["param1"] = 4, ["z"] = 15, ["name"] = "default:stone_block"}, {["x"] = 22, ["y"] = 4, ["param1"] = 4, ["z"] = 16, ["name"] = "default:stone_block"}, {["x"] = 22, ["param2"] = 1, ["y"] = 4, ["param1"] = 14, ["z"] = 23, ["name"] = "stairs:slab_cobble"}, {["x"] = 22, ["param2"] = 1, ["y"] = 4, ["param1"] = 14, ["z"] = 24, ["name"] = "stairs:slab_cobble"}, {["x"] = 22, ["param2"] = 1, ["y"] = 4, ["param1"] = 14, ["z"] = 25, ["name"] = "stairs:slab_cobble"}, {["x"] = 22, ["param2"] = 1, ["y"] = 4, ["param1"] = 14, ["z"] = 26, ["name"] = "stairs:slab_cobble"}, {["x"] = 22, ["param2"] = 1, ["y"] = 4, ["param1"] = 14, ["z"] = 27, ["name"] = "stairs:slab_cobble"}, {["x"] = 22, ["y"] = 4, ["param1"] = 4, ["z"] = 28, ["name"] = "default:stone_block"}, {["x"] = 22, ["y"] = 4, ["param1"] = 4, ["z"] = 29, ["name"] = "default:stone_block"}, {["x"] = 22, ["param2"] = 2, ["y"] = 5, ["param1"] = 14, ["z"] = 28, ["name"] = "stairs:slab_stone_block"}, {["x"] = 22, ["param2"] = 2, ["y"] = 5, ["param1"] = 14, ["z"] = 29, ["name"] = "stairs:slab_stone_block"}, {["x"] = 23, ["y"] = 2, ["param1"] = 1, ["z"] = 17, ["name"] = "default:stone"}, {["x"] = 23, ["y"] = 2, ["param1"] = 1, ["z"] = 18, ["name"] = "default:stone"}, {["x"] = 23, ["y"] = 2, ["param1"] = 1, ["z"] = 19, ["name"] = "default:stone"}, {["x"] = 23, ["y"] = 2, ["param1"] = 1, ["z"] = 20, ["name"] = "default:stone"}, {["x"] = 23, ["y"] = 2, ["param1"] = 1, ["z"] = 21, ["name"] = "default:stone"}, {["x"] = 23, ["y"] = 2, ["param1"] = 1, ["z"] = 22, ["name"] = "default:stone"}, {["x"] = 23, ["y"] = 2, ["param1"] = 1, ["z"] = 23, ["name"] = "default:stone"}, {["x"] = 23, ["y"] = 2, ["param1"] = 1, ["z"] = 24, ["name"] = "default:stone"}, {["x"] = 23, ["param2"] = 21, ["y"] = 2, ["param1"] = 9, ["z"] = 25, ["name"] = "stairs:slab_stone"}, {["x"] = 23, ["param2"] = 21, ["y"] = 2, ["param1"] = 10, ["z"] = 26, ["name"] = "stairs:slab_stone"}, {["x"] = 23, ["y"] = 3, ["param1"] = 4, ["z"] = 16, ["name"] = "default:stone_block"}, {["x"] = 23, ["y"] = 3, ["param1"] = 4, ["z"] = 17, ["name"] = "default:stone_block"}, {["x"] = 23, ["y"] = 3, ["param1"] = 2, ["z"] = 18, ["name"] = "default:cobble"}, {["x"] = 23, ["y"] = 3, ["param1"] = 2, ["z"] = 19, ["name"] = "default:cobble"}, {["x"] = 23, ["y"] = 3, ["param1"] = 2, ["z"] = 20, ["name"] = "default:cobble"}, {["x"] = 23, ["y"] = 3, ["param1"] = 2, ["z"] = 21, ["name"] = "default:cobble"}, {["x"] = 23, ["y"] = 3, ["param1"] = 4, ["z"] = 22, ["name"] = "default:stone_block"}, {["x"] = 23, ["y"] = 3, ["param1"] = 4, ["z"] = 23, ["name"] = "default:stone_block"}, {["x"] = 23, ["y"] = 3, ["param1"] = 4, ["z"] = 24, ["name"] = "default:stone_block"}, {["x"] = 23, ["y"] = 3, ["param1"] = 4, ["z"] = 25, ["name"] = "default:stone_block"}, {["x"] = 23, ["y"] = 3, ["param1"] = 4, ["z"] = 26, ["name"] = "default:stone_block"}, {["x"] = 23, ["y"] = 3, ["param1"] = 4, ["z"] = 27, ["name"] = "default:stone_block"}, {["x"] = 23, ["y"] = 3, ["param1"] = 4, ["z"] = 28, ["name"] = "default:stone_block"}, {["x"] = 23, ["y"] = 3, ["param1"] = 4, ["z"] = 29, ["name"] = "default:stone_block"}, {["x"] = 23, ["y"] = 4, ["param1"] = 4, ["z"] = 16, ["name"] = "default:stone_block"}, {["x"] = 23, ["y"] = 4, ["param1"] = 4, ["z"] = 17, ["name"] = "default:stone_block"}, {["x"] = 23, ["y"] = 4, ["param1"] = 14, ["z"] = 22, ["name"] = "stairs:slab_cobble"}, {["x"] = 23, ["param2"] = 1, ["y"] = 4, ["param1"] = 14, ["z"] = 23, ["name"] = "stairs:slab_cobble"}, {["x"] = 23, ["param2"] = 1, ["y"] = 4, ["param1"] = 14, ["z"] = 24, ["name"] = "stairs:slab_cobble"}, {["x"] = 23, ["param2"] = 1, ["y"] = 4, ["param1"] = 14, ["z"] = 25, ["name"] = "stairs:slab_cobble"}, {["x"] = 23, ["param2"] = 1, ["y"] = 4, ["param1"] = 14, ["z"] = 26, ["name"] = "stairs:slab_cobble"}, {["x"] = 23, ["param2"] = 1, ["y"] = 4, ["param1"] = 14, ["z"] = 27, ["name"] = "stairs:slab_cobble"}, {["x"] = 23, ["y"] = 4, ["param1"] = 14, ["z"] = 28, ["name"] = "stairs:slab_cobble"}, {["x"] = 23, ["y"] = 4, ["param1"] = 4, ["z"] = 29, ["name"] = "default:stone_block"}, {["x"] = 23, ["y"] = 4, ["param1"] = 4, ["z"] = 30, ["name"] = "default:stone_block"}, {["x"] = 23, ["param2"] = 1, ["y"] = 5, ["param1"] = 14, ["z"] = 29, ["name"] = "stairs:slab_stone_block"}, {["x"] = 23, ["param2"] = 1, ["y"] = 5, ["param1"] = 14, ["z"] = 30, ["name"] = "stairs:slab_stone_block"}, {["x"] = 24, ["y"] = 2, ["param1"] = 1, ["z"] = 18, ["name"] = "default:stone"}, {["x"] = 24, ["y"] = 2, ["param1"] = 1, ["z"] = 19, ["name"] = "default:stone"}, {["x"] = 24, ["y"] = 2, ["param1"] = 1, ["z"] = 20, ["name"] = "default:stone"}, {["x"] = 24, ["y"] = 2, ["param1"] = 1, ["z"] = 21, ["name"] = "default:stone"}, {["x"] = 24, ["y"] = 2, ["param1"] = 1, ["z"] = 22, ["name"] = "default:stone"}, {["x"] = 24, ["y"] = 2, ["param1"] = 1, ["z"] = 23, ["name"] = "default:stone"}, {["x"] = 24, ["y"] = 2, ["param1"] = 1, ["z"] = 24, ["name"] = "default:stone"}, {["x"] = 24, ["param2"] = 21, ["y"] = 2, ["param1"] = 8, ["z"] = 25, ["name"] = "stairs:slab_stone"}, {["x"] = 24, ["param2"] = 21, ["y"] = 2, ["param1"] = 9, ["z"] = 26, ["name"] = "stairs:slab_stone"}, {["x"] = 24, ["param2"] = 21, ["y"] = 2, ["param1"] = 10, ["z"] = 27, ["name"] = "stairs:slab_stone"}, {["x"] = 24, ["y"] = 3, ["param1"] = 4, ["z"] = 17, ["name"] = "default:stone_block"}, {["x"] = 24, ["y"] = 3, ["param1"] = 4, ["z"] = 18, ["name"] = "default:stone_block"}, {["x"] = 24, ["y"] = 3, ["param1"] = 2, ["z"] = 19, ["name"] = "default:cobble"}, {["x"] = 24, ["y"] = 3, ["param1"] = 2, ["z"] = 20, ["name"] = "default:cobble"}, {["x"] = 24, ["y"] = 3, ["param1"] = 4, ["z"] = 21, ["name"] = "default:stone_block"}, {["x"] = 24, ["y"] = 3, ["param1"] = 4, ["z"] = 22, ["name"] = "default:stone_block"}, {["x"] = 24, ["y"] = 3, ["param1"] = 4, ["z"] = 23, ["name"] = "default:stone_block"}, {["x"] = 24, ["y"] = 3, ["param1"] = 4, ["z"] = 24, ["name"] = "default:stone_block"}, {["x"] = 24, ["y"] = 3, ["param1"] = 4, ["z"] = 25, ["name"] = "default:stone_block"}, {["x"] = 24, ["y"] = 3, ["param1"] = 4, ["z"] = 26, ["name"] = "default:stone_block"}, {["x"] = 24, ["y"] = 3, ["param1"] = 4, ["z"] = 27, ["name"] = "default:stone_block"}, {["x"] = 24, ["y"] = 3, ["param1"] = 4, ["z"] = 28, ["name"] = "default:stone_block"}, {["x"] = 24, ["y"] = 3, ["param1"] = 4, ["z"] = 29, ["name"] = "default:stone_block"}, {["x"] = 24, ["y"] = 3, ["param1"] = 4, ["z"] = 30, ["name"] = "default:stone_block"}, {["x"] = 24, ["y"] = 4, ["param1"] = 4, ["z"] = 17, ["name"] = "default:stone_block"}, {["x"] = 24, ["y"] = 4, ["param1"] = 4, ["z"] = 18, ["name"] = "default:stone_block"}, {["x"] = 24, ["y"] = 4, ["param1"] = 14, ["z"] = 21, ["name"] = "stairs:slab_cobble"}, {["x"] = 24, ["y"] = 4, ["param1"] = 14, ["z"] = 22, ["name"] = "stairs:slab_cobble"}, {["x"] = 24, ["y"] = 4, ["param1"] = 14, ["z"] = 23, ["name"] = "stairs:slab_cobble"}, {["x"] = 24, ["y"] = 4, ["param1"] = 14, ["z"] = 24, ["name"] = "stairs:slab_cobble"}, {["x"] = 24, ["y"] = 4, ["param1"] = 14, ["z"] = 25, ["name"] = "stairs:slab_cobble"}, {["x"] = 24, ["param2"] = 1, ["y"] = 4, ["param1"] = 14, ["z"] = 26, ["name"] = "stairs:slab_cobble"}, {["x"] = 24, ["y"] = 4, ["param1"] = 14, ["z"] = 27, ["name"] = "stairs:slab_cobble"}, {["x"] = 24, ["y"] = 4, ["param1"] = 14, ["z"] = 28, ["name"] = "stairs:slab_cobble"}, {["x"] = 24, ["param2"] = 1, ["y"] = 4, ["param1"] = 14, ["z"] = 29, ["name"] = "stairs:slab_cobble"}, {["x"] = 24, ["y"] = 4, ["param1"] = 4, ["z"] = 30, ["name"] = "default:stone_block"}, {["x"] = 24, ["y"] = 4, ["param1"] = 4, ["z"] = 31, ["name"] = "default:stone_block"}, {["x"] = 24, ["param2"] = 1, ["y"] = 5, ["param1"] = 14, ["z"] = 30, ["name"] = "stairs:slab_stone_block"}, {["x"] = 24, ["y"] = 5, ["param1"] = 14, ["z"] = 31, ["name"] = "stairs:slab_stone_block"}, {["x"] = 25, ["param2"] = 23, ["y"] = 2, ["param1"] = 12, ["z"] = 20, ["name"] = "stairs:slab_stone"}, {["x"] = 25, ["param2"] = 23, ["y"] = 2, ["param1"] = 11, ["z"] = 21, ["name"] = "stairs:slab_stone"}, {["x"] = 25, ["param2"] = 20, ["y"] = 2, ["param1"] = 10, ["z"] = 22, ["name"] = "stairs:slab_stone"}, {["x"] = 25, ["param2"] = 20, ["y"] = 2, ["param1"] = 9, ["z"] = 23, ["name"] = "stairs:slab_stone"}, {["x"] = 25, ["param2"] = 20, ["y"] = 2, ["param1"] = 8, ["z"] = 24, ["name"] = "stairs:slab_stone"}, {["x"] = 25, ["param2"] = 20, ["y"] = 2, ["param1"] = 7, ["z"] = 25, ["name"] = "stairs:slab_stone"}, {["x"] = 25, ["param2"] = 21, ["y"] = 2, ["param1"] = 8, ["z"] = 26, ["name"] = "stairs:slab_stone"}, {["x"] = 25, ["param2"] = 22, ["y"] = 2, ["param1"] = 9, ["z"] = 27, ["name"] = "stairs:slab_stone"}, {["x"] = 25, ["y"] = 3, ["param1"] = 4, ["z"] = 19, ["name"] = "default:stone_block"}, {["x"] = 25, ["y"] = 3, ["param1"] = 4, ["z"] = 20, ["name"] = "default:stone_block"}, {["x"] = 25, ["y"] = 3, ["param1"] = 4, ["z"] = 21, ["name"] = "default:stone_block"}, {["x"] = 25, ["y"] = 3, ["param1"] = 4, ["z"] = 22, ["name"] = "default:stone_block"}, {["x"] = 25, ["y"] = 3, ["param1"] = 4, ["z"] = 23, ["name"] = "default:stone_block"}, {["x"] = 25, ["y"] = 3, ["param1"] = 4, ["z"] = 24, ["name"] = "default:stone_block"}, {["x"] = 25, ["y"] = 3, ["param1"] = 4, ["z"] = 25, ["name"] = "default:stone_block"}, {["x"] = 25, ["y"] = 3, ["param1"] = 4, ["z"] = 26, ["name"] = "default:stone_block"}, {["x"] = 25, ["y"] = 3, ["param1"] = 4, ["z"] = 27, ["name"] = "default:stone_block"}, {["x"] = 25, ["y"] = 3, ["param1"] = 4, ["z"] = 28, ["name"] = "default:stone_block"}, {["x"] = 25, ["y"] = 3, ["param1"] = 4, ["z"] = 29, ["name"] = "default:stone_block"}, {["x"] = 25, ["y"] = 3, ["param1"] = 4, ["z"] = 30, ["name"] = "default:stone_block"}, {["x"] = 25, ["y"] = 3, ["param1"] = 4, ["z"] = 31, ["name"] = "default:stone_block"}, {["x"] = 25, ["y"] = 4, ["param1"] = 4, ["z"] = 18, ["name"] = "default:stone_block"}, {["x"] = 25, ["y"] = 4, ["param1"] = 4, ["z"] = 19, ["name"] = "default:stone_block"}, {["x"] = 25, ["y"] = 4, ["param1"] = 14, ["z"] = 20, ["name"] = "stairs:slab_cobble"}, {["x"] = 25, ["y"] = 4, ["param1"] = 14, ["z"] = 21, ["name"] = "stairs:slab_cobble"}, {["x"] = 25, ["y"] = 4, ["param1"] = 14, ["z"] = 22, ["name"] = "stairs:slab_cobble"}, {["x"] = 25, ["y"] = 4, ["param1"] = 14, ["z"] = 23, ["name"] = "stairs:slab_cobble"}, {["x"] = 25, ["y"] = 4, ["param1"] = 14, ["z"] = 24, ["name"] = "stairs:slab_cobble"}, {["x"] = 25, ["param2"] = 1, ["y"] = 4, ["param1"] = 14, ["z"] = 25, ["name"] = "stairs:slab_cobble"}, {["x"] = 25, ["param2"] = 1, ["y"] = 4, ["param1"] = 14, ["z"] = 26, ["name"] = "stairs:slab_cobble"}, {["x"] = 25, ["y"] = 4, ["param1"] = 14, ["z"] = 27, ["name"] = "stairs:slab_cobble"}, {["x"] = 25, ["param2"] = 1, ["y"] = 4, ["param1"] = 14, ["z"] = 28, ["name"] = "stairs:slab_cobble"}, {["x"] = 25, ["param2"] = 1, ["y"] = 4, ["param1"] = 14, ["z"] = 29, ["name"] = "stairs:slab_cobble"}, {["x"] = 25, ["param2"] = 3, ["y"] = 4, ["param1"] = 14, ["z"] = 30, ["name"] = "stairs:slab_cobble"}, {["x"] = 25, ["y"] = 4, ["param1"] = 4, ["z"] = 31, ["name"] = "default:stone_block"}, {["x"] = 25, ["y"] = 4, ["param1"] = 4, ["z"] = 32, ["name"] = "default:stone_block"}, {["x"] = 25, ["param2"] = 2, ["y"] = 5, ["param1"] = 14, ["z"] = 18, ["name"] = "stairs:slab_stone_block"}, {["x"] = 25, ["param2"] = 2, ["y"] = 5, ["param1"] = 14, ["z"] = 19, ["name"] = "stairs:slab_stone_block"}, {["x"] = 25, ["y"] = 5, ["param1"] = 14, ["z"] = 31, ["name"] = "stairs:slab_stone_block"}, {["x"] = 25, ["y"] = 5, ["param1"] = 14, ["z"] = 32, ["name"] = "stairs:slab_stone_block"}, {["x"] = 26, ["param2"] = 20, ["y"] = 2, ["param1"] = 11, ["z"] = 22, ["name"] = "stairs:slab_stone"}, {["x"] = 26, ["param2"] = 20, ["y"] = 2, ["param1"] = 10, ["z"] = 23, ["name"] = "stairs:slab_stone"}, {["x"] = 26, ["param2"] = 23, ["y"] = 2, ["param1"] = 9, ["z"] = 24, ["name"] = "stairs:slab_stone"}, {["x"] = 26, ["param2"] = 23, ["y"] = 2, ["param1"] = 8, ["z"] = 25, ["name"] = "stairs:slab_stone"}, {["x"] = 26, ["param2"] = 20, ["y"] = 2, ["param1"] = 7, ["z"] = 26, ["name"] = "stairs:slab_stone"}, {["x"] = 26, ["param2"] = 22, ["y"] = 2, ["param1"] = 8, ["z"] = 27, ["name"] = "stairs:slab_stone"}, {["x"] = 26, ["param2"] = 23, ["y"] = 2, ["param1"] = 9, ["z"] = 28, ["name"] = "stairs:slab_stone"}, {["x"] = 26, ["y"] = 3, ["param1"] = 4, ["z"] = 20, ["name"] = "default:stone_block"}, {["x"] = 26, ["y"] = 3, ["param1"] = 4, ["z"] = 21, ["name"] = "default:stone_block"}, {["x"] = 26, ["y"] = 3, ["param1"] = 4, ["z"] = 22, ["name"] = "default:stone_block"}, {["x"] = 26, ["y"] = 3, ["param1"] = 4, ["z"] = 23, ["name"] = "default:stone_block"}, {["x"] = 26, ["y"] = 3, ["param1"] = 4, ["z"] = 24, ["name"] = "default:stone_block"}, {["x"] = 26, ["y"] = 3, ["param1"] = 4, ["z"] = 25, ["name"] = "default:stone_block"}, {["x"] = 26, ["y"] = 3, ["param1"] = 4, ["z"] = 26, ["name"] = "default:stone_block"}, {["x"] = 26, ["y"] = 3, ["param1"] = 4, ["z"] = 27, ["name"] = "default:stone_block"}, {["x"] = 26, ["y"] = 3, ["param1"] = 4, ["z"] = 28, ["name"] = "default:stone_block"}, {["x"] = 26, ["y"] = 3, ["param1"] = 4, ["z"] = 29, ["name"] = "default:stone_block"}, {["x"] = 26, ["y"] = 3, ["param1"] = 4, ["z"] = 30, ["name"] = "default:stone_block"}, {["x"] = 26, ["y"] = 3, ["param1"] = 4, ["z"] = 31, ["name"] = "default:stone_block"}, {["x"] = 26, ["y"] = 3, ["param1"] = 4, ["z"] = 32, ["name"] = "default:stone_block"}, {["x"] = 26, ["y"] = 4, ["param1"] = 4, ["z"] = 19, ["name"] = "default:stone_block"}, {["x"] = 26, ["y"] = 4, ["param1"] = 4, ["z"] = 20, ["name"] = "default:stone_block"}, {["x"] = 26, ["y"] = 4, ["param1"] = 14, ["z"] = 21, ["name"] = "stairs:slab_cobble"}, {["x"] = 26, ["y"] = 4, ["param1"] = 14, ["z"] = 22, ["name"] = "stairs:slab_cobble"}, {["x"] = 26, ["y"] = 4, ["param1"] = 14, ["z"] = 23, ["name"] = "stairs:slab_cobble"}, {["x"] = 26, ["param2"] = 1, ["y"] = 4, ["param1"] = 14, ["z"] = 24, ["name"] = "stairs:slab_cobble"}, {["x"] = 26, ["param2"] = 1, ["y"] = 4, ["param1"] = 14, ["z"] = 25, ["name"] = "stairs:slab_cobble"}, {["x"] = 26, ["param2"] = 1, ["y"] = 4, ["param1"] = 14, ["z"] = 26, ["name"] = "stairs:slab_cobble"}, {["x"] = 26, ["param2"] = 1, ["y"] = 4, ["param1"] = 14, ["z"] = 27, ["name"] = "stairs:slab_cobble"}, {["x"] = 26, ["param2"] = 1, ["y"] = 4, ["param1"] = 14, ["z"] = 28, ["name"] = "stairs:slab_cobble"}, {["x"] = 26, ["param2"] = 2, ["y"] = 4, ["param1"] = 14, ["z"] = 29, ["name"] = "stairs:slab_cobble"}, {["x"] = 26, ["param2"] = 3, ["y"] = 4, ["param1"] = 14, ["z"] = 30, ["name"] = "stairs:slab_cobble"}, {["x"] = 26, ["param2"] = 1, ["y"] = 4, ["param1"] = 14, ["z"] = 31, ["name"] = "stairs:slab_cobble"}, {["x"] = 26, ["y"] = 4, ["param1"] = 4, ["z"] = 32, ["name"] = "default:stone_block"}, {["x"] = 26, ["y"] = 4, ["param1"] = 4, ["z"] = 33, ["name"] = "default:stone_block"}, {["x"] = 26, ["param2"] = 2, ["y"] = 5, ["param1"] = 14, ["z"] = 19, ["name"] = "stairs:slab_stone_block"}, {["x"] = 26, ["param2"] = 2, ["y"] = 5, ["param1"] = 14, ["z"] = 20, ["name"] = "stairs:slab_stone_block"}, {["x"] = 26, ["param2"] = 2, ["y"] = 5, ["param1"] = 14, ["z"] = 32, ["name"] = "stairs:slab_stone_block"}, {["x"] = 26, ["param2"] = 2, ["y"] = 5, ["param1"] = 14, ["z"] = 33, ["name"] = "stairs:slab_stone_block"}, {["x"] = 27, ["param2"] = 22, ["y"] = 2, ["param1"] = 10, ["z"] = 24, ["name"] = "stairs:slab_stone"}, {["x"] = 27, ["param2"] = 23, ["y"] = 2, ["param1"] = 9, ["z"] = 25, ["name"] = "stairs:slab_stone"}, {["x"] = 27, ["param2"] = 23, ["y"] = 2, ["param1"] = 8, ["z"] = 26, ["name"] = "stairs:slab_stone"}, {["x"] = 27, ["param2"] = 23, ["y"] = 2, ["param1"] = 7, ["z"] = 27, ["name"] = "stairs:slab_stone"}, {["x"] = 27, ["param2"] = 20, ["y"] = 2, ["param1"] = 8, ["z"] = 28, ["name"] = "stairs:slab_stone"}, {["x"] = 27, ["param2"] = 20, ["y"] = 2, ["param1"] = 9, ["z"] = 29, ["name"] = "stairs:slab_stone"}, {["x"] = 27, ["y"] = 3, ["param1"] = 4, ["z"] = 21, ["name"] = "default:stone_block"}, {["x"] = 27, ["y"] = 3, ["param1"] = 4, ["z"] = 22, ["name"] = "default:stone_block"}, {["x"] = 27, ["y"] = 3, ["param1"] = 4, ["z"] = 23, ["name"] = "default:stone_block"}, {["x"] = 27, ["y"] = 3, ["param1"] = 4, ["z"] = 24, ["name"] = "default:stone_block"}, {["x"] = 27, ["y"] = 3, ["param1"] = 4, ["z"] = 25, ["name"] = "default:stone_block"}, {["x"] = 27, ["y"] = 3, ["param1"] = 4, ["z"] = 26, ["name"] = "default:stone_block"}, {["x"] = 27, ["y"] = 3, ["param1"] = 4, ["z"] = 27, ["name"] = "default:stone_block"}, {["x"] = 27, ["y"] = 3, ["param1"] = 4, ["z"] = 28, ["name"] = "default:stone_block"}, {["x"] = 27, ["y"] = 3, ["param1"] = 4, ["z"] = 29, ["name"] = "default:stone_block"}, {["x"] = 27, ["y"] = 3, ["param1"] = 4, ["z"] = 30, ["name"] = "default:stone_block"}, {["x"] = 27, ["y"] = 3, ["param1"] = 4, ["z"] = 31, ["name"] = "default:stone_block"}, {["x"] = 27, ["y"] = 3, ["param1"] = 4, ["z"] = 32, ["name"] = "default:stone_block"}, {["x"] = 27, ["y"] = 3, ["param1"] = 4, ["z"] = 33, ["name"] = "default:stone_block"}, {["x"] = 27, ["y"] = 4, ["param1"] = 4, ["z"] = 20, ["name"] = "default:stone_block"}, {["x"] = 27, ["y"] = 4, ["param1"] = 4, ["z"] = 21, ["name"] = "default:stone_block"}, {["x"] = 27, ["y"] = 4, ["param1"] = 14, ["z"] = 22, ["name"] = "stairs:slab_cobble"}, {["x"] = 27, ["y"] = 4, ["param1"] = 14, ["z"] = 23, ["name"] = "stairs:slab_cobble"}, {["x"] = 27, ["param2"] = 1, ["y"] = 4, ["param1"] = 14, ["z"] = 24, ["name"] = "stairs:slab_cobble"}, {["x"] = 27, ["param2"] = 1, ["y"] = 4, ["param1"] = 14, ["z"] = 25, ["name"] = "stairs:slab_cobble"}, {["x"] = 27, ["param2"] = 1, ["y"] = 4, ["param1"] = 14, ["z"] = 26, ["name"] = "stairs:slab_cobble"}, {["x"] = 27, ["param2"] = 1, ["y"] = 4, ["param1"] = 14, ["z"] = 27, ["name"] = "stairs:slab_cobble"}, {["x"] = 27, ["param2"] = 1, ["y"] = 4, ["param1"] = 14, ["z"] = 28, ["name"] = "stairs:slab_cobble"}, {["x"] = 27, ["param2"] = 2, ["y"] = 4, ["param1"] = 14, ["z"] = 29, ["name"] = "stairs:slab_cobble"}, {["x"] = 27, ["param2"] = 1, ["y"] = 4, ["param1"] = 14, ["z"] = 30, ["name"] = "stairs:slab_cobble"}, {["x"] = 27, ["param2"] = 1, ["y"] = 4, ["param1"] = 14, ["z"] = 31, ["name"] = "stairs:slab_cobble"}, {["x"] = 27, ["param2"] = 1, ["y"] = 4, ["param1"] = 14, ["z"] = 32, ["name"] = "stairs:slab_cobble"}, {["x"] = 27, ["y"] = 4, ["param1"] = 4, ["z"] = 33, ["name"] = "default:stone_block"}, {["x"] = 27, ["y"] = 4, ["param1"] = 4, ["z"] = 34, ["name"] = "default:stone_block"}, {["x"] = 27, ["param2"] = 2, ["y"] = 5, ["param1"] = 14, ["z"] = 20, ["name"] = "stairs:slab_stone_block"}, {["x"] = 27, ["param2"] = 2, ["y"] = 5, ["param1"] = 14, ["z"] = 21, ["name"] = "stairs:slab_stone_block"}, {["x"] = 27, ["param2"] = 2, ["y"] = 5, ["param1"] = 14, ["z"] = 33, ["name"] = "stairs:slab_stone_block"}, {["x"] = 27, ["param2"] = 2, ["y"] = 5, ["param1"] = 14, ["z"] = 34, ["name"] = "stairs:slab_stone_block"}, {["x"] = 28, ["param2"] = 22, ["y"] = 2, ["param1"] = 9, ["z"] = 26, ["name"] = "stairs:slab_stone"}, {["x"] = 28, ["param2"] = 22, ["y"] = 2, ["param1"] = 8, ["z"] = 27, ["name"] = "stairs:slab_stone"}, {["x"] = 28, ["param2"] = 21, ["y"] = 2, ["param1"] = 7, ["z"] = 28, ["name"] = "stairs:slab_stone"}, {["x"] = 28, ["param2"] = 21, ["y"] = 2, ["param1"] = 8, ["z"] = 29, ["name"] = "stairs:slab_stone"}, {["x"] = 28, ["param2"] = 23, ["y"] = 2, ["param1"] = 9, ["z"] = 30, ["name"] = "stairs:slab_stone"}, {["x"] = 28, ["param2"] = 23, ["y"] = 2, ["param1"] = 10, ["z"] = 31, ["name"] = "stairs:slab_stone"}, {["x"] = 28, ["y"] = 3, ["param1"] = 4, ["z"] = 22, ["name"] = "default:stone_block"}, {["x"] = 28, ["y"] = 3, ["param1"] = 4, ["z"] = 23, ["name"] = "default:stone_block"}, {["x"] = 28, ["y"] = 3, ["param1"] = 4, ["z"] = 24, ["name"] = "default:stone_block"}, {["x"] = 28, ["y"] = 3, ["param1"] = 4, ["z"] = 25, ["name"] = "default:stone_block"}, {["x"] = 28, ["y"] = 3, ["param1"] = 4, ["z"] = 26, ["name"] = "default:stone_block"}, {["x"] = 28, ["y"] = 3, ["param1"] = 4, ["z"] = 27, ["name"] = "default:stone_block"}, {["x"] = 28, ["y"] = 3, ["param1"] = 4, ["z"] = 28, ["name"] = "default:stone_block"}, {["x"] = 28, ["y"] = 3, ["param1"] = 4, ["z"] = 29, ["name"] = "default:stone_block"}, {["x"] = 28, ["y"] = 3, ["param1"] = 4, ["z"] = 30, ["name"] = "default:stone_block"}, {["x"] = 28, ["y"] = 3, ["param1"] = 4, ["z"] = 31, ["name"] = "default:stone_block"}, {["x"] = 28, ["y"] = 3, ["param1"] = 4, ["z"] = 32, ["name"] = "default:stone_block"}, {["x"] = 28, ["y"] = 3, ["param1"] = 4, ["z"] = 33, ["name"] = "default:stone_block"}, {["x"] = 28, ["y"] = 3, ["param1"] = 4, ["z"] = 34, ["name"] = "default:stone_block"}, {["x"] = 28, ["y"] = 4, ["param1"] = 4, ["z"] = 21, ["name"] = "default:stone_block"}, {["x"] = 28, ["y"] = 4, ["param1"] = 4, ["z"] = 22, ["name"] = "default:stone_block"}, {["x"] = 28, ["param2"] = 1, ["y"] = 4, ["param1"] = 14, ["z"] = 23, ["name"] = "stairs:slab_cobble"}, {["x"] = 28, ["param2"] = 1, ["y"] = 4, ["param1"] = 14, ["z"] = 24, ["name"] = "stairs:slab_cobble"}, {["x"] = 28, ["param2"] = 1, ["y"] = 4, ["param1"] = 14, ["z"] = 25, ["name"] = "stairs:slab_cobble"}, {["x"] = 28, ["param2"] = 1, ["y"] = 4, ["param1"] = 14, ["z"] = 26, ["name"] = "stairs:slab_cobble"}, {["x"] = 28, ["param2"] = 2, ["y"] = 4, ["param1"] = 14, ["z"] = 27, ["name"] = "stairs:slab_cobble"}, {["x"] = 28, ["param2"] = 2, ["y"] = 4, ["param1"] = 14, ["z"] = 28, ["name"] = "stairs:slab_cobble"}, {["x"] = 28, ["param2"] = 1, ["y"] = 4, ["param1"] = 14, ["z"] = 29, ["name"] = "stairs:slab_cobble"}, {["x"] = 28, ["param2"] = 1, ["y"] = 4, ["param1"] = 14, ["z"] = 30, ["name"] = "stairs:slab_cobble"}, {["x"] = 28, ["param2"] = 1, ["y"] = 4, ["param1"] = 14, ["z"] = 31, ["name"] = "stairs:slab_cobble"}, {["x"] = 28, ["y"] = 4, ["param1"] = 14, ["z"] = 32, ["name"] = "stairs:slab_cobble"}, {["x"] = 28, ["y"] = 4, ["param1"] = 14, ["z"] = 33, ["name"] = "stairs:slab_cobble"}, {["x"] = 28, ["y"] = 4, ["param1"] = 4, ["z"] = 34, ["name"] = "default:stone_block"}, {["x"] = 28, ["y"] = 4, ["param1"] = 4, ["z"] = 35, ["name"] = "default:stone_block"}, {["x"] = 28, ["param2"] = 2, ["y"] = 5, ["param1"] = 14, ["z"] = 21, ["name"] = "stairs:slab_stone_block"}, {["x"] = 28, ["param2"] = 2, ["y"] = 5, ["param1"] = 14, ["z"] = 22, ["name"] = "stairs:slab_stone_block"}, {["x"] = 28, ["param2"] = 2, ["y"] = 5, ["param1"] = 14, ["z"] = 34, ["name"] = "stairs:slab_stone_block"}, {["x"] = 28, ["param2"] = 2, ["y"] = 5, ["param1"] = 14, ["z"] = 35, ["name"] = "stairs:slab_stone_block"}, {["x"] = 29, ["param2"] = 21, ["y"] = 2, ["param1"] = 9, ["z"] = 27, ["name"] = "stairs:slab_stone"}, {["x"] = 29, ["param2"] = 20, ["y"] = 2, ["param1"] = 8, ["z"] = 28, ["name"] = "stairs:slab_stone"}, {["x"] = 29, ["param2"] = 20, ["y"] = 2, ["param1"] = 7, ["z"] = 29, ["name"] = "stairs:slab_stone"}, {["x"] = 29, ["param2"] = 23, ["y"] = 2, ["param1"] = 8, ["z"] = 30, ["name"] = "stairs:slab_stone"}, {["x"] = 29, ["param2"] = 23, ["y"] = 2, ["param1"] = 9, ["z"] = 31, ["name"] = "stairs:slab_stone"}, {["x"] = 29, ["param2"] = 20, ["y"] = 2, ["param1"] = 10, ["z"] = 32, ["name"] = "stairs:slab_stone"}, {["x"] = 29, ["param2"] = 20, ["y"] = 2, ["param1"] = 11, ["z"] = 33, ["name"] = "stairs:slab_stone"}, {["x"] = 29, ["y"] = 3, ["param1"] = 4, ["z"] = 23, ["name"] = "default:stone_block"}, {["x"] = 29, ["y"] = 3, ["param1"] = 4, ["z"] = 24, ["name"] = "default:stone_block"}, {["x"] = 29, ["y"] = 3, ["param1"] = 4, ["z"] = 25, ["name"] = "default:stone_block"}, {["x"] = 29, ["y"] = 3, ["param1"] = 4, ["z"] = 26, ["name"] = "default:stone_block"}, {["x"] = 29, ["y"] = 3, ["param1"] = 4, ["z"] = 27, ["name"] = "default:stone_block"}, {["x"] = 29, ["y"] = 3, ["param1"] = 4, ["z"] = 28, ["name"] = "default:stone_block"}, {["x"] = 29, ["y"] = 3, ["param1"] = 4, ["z"] = 29, ["name"] = "default:stone_block"}, {["x"] = 29, ["y"] = 3, ["param1"] = 4, ["z"] = 30, ["name"] = "default:stone_block"}, {["x"] = 29, ["y"] = 3, ["param1"] = 4, ["z"] = 31, ["name"] = "default:stone_block"}, {["x"] = 29, ["y"] = 3, ["param1"] = 4, ["z"] = 32, ["name"] = "default:stone_block"}, {["x"] = 29, ["y"] = 3, ["param1"] = 4, ["z"] = 33, ["name"] = "default:stone_block"}, {["x"] = 29, ["y"] = 3, ["param1"] = 4, ["z"] = 34, ["name"] = "default:stone_block"}, {["x"] = 29, ["y"] = 3, ["param1"] = 4, ["z"] = 35, ["name"] = "default:stone_block"}, {["x"] = 29, ["y"] = 4, ["param1"] = 4, ["z"] = 22, ["name"] = "default:stone_block"}, {["x"] = 29, ["y"] = 4, ["param1"] = 4, ["z"] = 23, ["name"] = "default:stone_block"}, {["x"] = 29, ["y"] = 4, ["param1"] = 14, ["z"] = 24, ["name"] = "stairs:slab_cobble"}, {["x"] = 29, ["y"] = 4, ["param1"] = 14, ["z"] = 25, ["name"] = "stairs:slab_cobble"}, {["x"] = 29, ["param2"] = 1, ["y"] = 4, ["param1"] = 14, ["z"] = 26, ["name"] = "stairs:slab_cobble"}, {["x"] = 29, ["param2"] = 1, ["y"] = 4, ["param1"] = 14, ["z"] = 27, ["name"] = "stairs:slab_cobble"}, {["x"] = 29, ["param2"] = 1, ["y"] = 4, ["param1"] = 14, ["z"] = 28, ["name"] = "stairs:slab_cobble"}, {["x"] = 29, ["param2"] = 1, ["y"] = 4, ["param1"] = 14, ["z"] = 29, ["name"] = "stairs:slab_cobble"}, {["x"] = 29, ["param2"] = 1, ["y"] = 4, ["param1"] = 14, ["z"] = 30, ["name"] = "stairs:slab_cobble"}, {["x"] = 29, ["param2"] = 1, ["y"] = 4, ["param1"] = 14, ["z"] = 31, ["name"] = "stairs:slab_cobble"}, {["x"] = 29, ["y"] = 4, ["param1"] = 14, ["z"] = 32, ["name"] = "stairs:slab_cobble"}, {["x"] = 29, ["y"] = 4, ["param1"] = 14, ["z"] = 33, ["name"] = "stairs:slab_cobble"}, {["x"] = 29, ["y"] = 4, ["param1"] = 14, ["z"] = 34, ["name"] = "stairs:slab_cobble"}, {["x"] = 29, ["y"] = 4, ["param1"] = 4, ["z"] = 35, ["name"] = "default:stone_block"}, {["x"] = 29, ["y"] = 4, ["param1"] = 4, ["z"] = 36, ["name"] = "default:stone_block"}, {["x"] = 29, ["param2"] = 2, ["y"] = 5, ["param1"] = 14, ["z"] = 22, ["name"] = "stairs:slab_stone_block"}, {["x"] = 29, ["param2"] = 2, ["y"] = 5, ["param1"] = 14, ["z"] = 23, ["name"] = "stairs:slab_stone_block"}, {["x"] = 29, ["param2"] = 2, ["y"] = 5, ["param1"] = 14, ["z"] = 35, ["name"] = "stairs:slab_stone_block"}, {["x"] = 29, ["param2"] = 2, ["y"] = 5, ["param1"] = 14, ["z"] = 36, ["name"] = "stairs:slab_stone_block"}, {["x"] = 30, ["param2"] = 20, ["y"] = 2, ["param1"] = 9, ["z"] = 28, ["name"] = "stairs:slab_stone"}, {["x"] = 30, ["param2"] = 21, ["y"] = 2, ["param1"] = 8, ["z"] = 29, ["name"] = "stairs:slab_stone"}, {["x"] = 30, ["param2"] = 20, ["y"] = 2, ["param1"] = 7, ["z"] = 30, ["name"] = "stairs:slab_stone"}, {["x"] = 30, ["param2"] = 20, ["y"] = 2, ["param1"] = 8, ["z"] = 31, ["name"] = "stairs:slab_stone"}, {["x"] = 30, ["param2"] = 20, ["y"] = 2, ["param1"] = 9, ["z"] = 32, ["name"] = "stairs:slab_stone"}, {["x"] = 30, ["param2"] = 20, ["y"] = 2, ["param1"] = 10, ["z"] = 33, ["name"] = "stairs:slab_stone"}, {["x"] = 30, ["param2"] = 23, ["y"] = 2, ["param1"] = 11, ["z"] = 34, ["name"] = "stairs:slab_stone"}, {["x"] = 30, ["param2"] = 23, ["y"] = 2, ["param1"] = 12, ["z"] = 35, ["name"] = "stairs:slab_stone"}, {["x"] = 30, ["y"] = 3, ["param1"] = 4, ["z"] = 24, ["name"] = "default:stone_block"}, {["x"] = 30, ["y"] = 3, ["param1"] = 4, ["z"] = 25, ["name"] = "default:stone_block"}, {["x"] = 30, ["y"] = 3, ["param1"] = 4, ["z"] = 26, ["name"] = "default:stone_block"}, {["x"] = 30, ["y"] = 3, ["param1"] = 4, ["z"] = 27, ["name"] = "default:stone_block"}, {["x"] = 30, ["y"] = 3, ["param1"] = 4, ["z"] = 28, ["name"] = "default:stone_block"}, {["x"] = 30, ["y"] = 3, ["param1"] = 4, ["z"] = 29, ["name"] = "default:stone_block"}, {["x"] = 30, ["y"] = 3, ["param1"] = 4, ["z"] = 30, ["name"] = "default:stone_block"}, {["x"] = 30, ["y"] = 3, ["param1"] = 4, ["z"] = 31, ["name"] = "default:stone_block"}, {["x"] = 30, ["y"] = 3, ["param1"] = 4, ["z"] = 32, ["name"] = "default:stone_block"}, {["x"] = 30, ["y"] = 3, ["param1"] = 4, ["z"] = 33, ["name"] = "default:stone_block"}, {["x"] = 30, ["y"] = 3, ["param1"] = 4, ["z"] = 34, ["name"] = "default:stone_block"}, {["x"] = 30, ["y"] = 3, ["param1"] = 4, ["z"] = 35, ["name"] = "default:stone_block"}, {["x"] = 30, ["y"] = 3, ["param1"] = 4, ["z"] = 36, ["name"] = "default:stone_block"}, {["x"] = 30, ["y"] = 4, ["param1"] = 4, ["z"] = 23, ["name"] = "default:stone_block"}, {["x"] = 30, ["y"] = 4, ["param1"] = 4, ["z"] = 24, ["name"] = "default:stone_block"}, {["x"] = 30, ["y"] = 4, ["param1"] = 14, ["z"] = 25, ["name"] = "stairs:slab_cobble"}, {["x"] = 30, ["param2"] = 1, ["y"] = 4, ["param1"] = 14, ["z"] = 26, ["name"] = "stairs:slab_cobble"}, {["x"] = 30, ["param2"] = 1, ["y"] = 4, ["param1"] = 14, ["z"] = 27, ["name"] = "stairs:slab_cobble"}, {["x"] = 30, ["y"] = 4, ["param1"] = 14, ["z"] = 28, ["name"] = "stairs:slab_cobble"}, {["x"] = 30, ["param2"] = 1, ["y"] = 4, ["param1"] = 14, ["z"] = 29, ["name"] = "stairs:slab_cobble"}, {["x"] = 30, ["param2"] = 1, ["y"] = 4, ["param1"] = 14, ["z"] = 30, ["name"] = "stairs:slab_cobble"}, {["x"] = 30, ["y"] = 4, ["param1"] = 14, ["z"] = 31, ["name"] = "stairs:slab_cobble"}, {["x"] = 30, ["y"] = 4, ["param1"] = 14, ["z"] = 32, ["name"] = "stairs:slab_cobble"}, {["x"] = 30, ["y"] = 4, ["param1"] = 14, ["z"] = 33, ["name"] = "stairs:slab_cobble"}, {["x"] = 30, ["y"] = 4, ["param1"] = 14, ["z"] = 34, ["name"] = "stairs:slab_cobble"}, {["x"] = 30, ["y"] = 4, ["param1"] = 14, ["z"] = 35, ["name"] = "stairs:slab_cobble"}, {["x"] = 30, ["y"] = 4, ["param1"] = 4, ["z"] = 36, ["name"] = "default:stone_block"}, {["x"] = 30, ["y"] = 4, ["param1"] = 4, ["z"] = 37, ["name"] = "default:stone_block"}, {["x"] = 30, ["param2"] = 2, ["y"] = 5, ["param1"] = 14, ["z"] = 23, ["name"] = "stairs:slab_stone_block"}, {["x"] = 30, ["param2"] = 2, ["y"] = 5, ["param1"] = 14, ["z"] = 24, ["name"] = "stairs:slab_stone_block"}, {["x"] = 30, ["param2"] = 2, ["y"] = 5, ["param1"] = 14, ["z"] = 36, ["name"] = "stairs:slab_stone_block"}, {["x"] = 30, ["param2"] = 2, ["y"] = 5, ["param1"] = 14, ["z"] = 37, ["name"] = "stairs:slab_stone_block"}, {["x"] = 31, ["param2"] = 21, ["y"] = 2, ["param1"] = 10, ["z"] = 28, ["name"] = "stairs:slab_stone"}, {["x"] = 31, ["param2"] = 21, ["y"] = 2, ["param1"] = 9, ["z"] = 29, ["name"] = "stairs:slab_stone"}, {["x"] = 31, ["param2"] = 21, ["y"] = 2, ["param1"] = 8, ["z"] = 30, ["name"] = "stairs:slab_stone"}, {["x"] = 31, ["y"] = 2, ["param1"] = 1, ["z"] = 31, ["name"] = "default:stone"}, {["x"] = 31, ["y"] = 2, ["param1"] = 1, ["z"] = 32, ["name"] = "default:stone"}, {["x"] = 31, ["y"] = 2, ["param1"] = 1, ["z"] = 33, ["name"] = "default:stone"}, {["x"] = 31, ["y"] = 2, ["param1"] = 1, ["z"] = 34, ["name"] = "default:stone"}, {["x"] = 31, ["y"] = 2, ["param1"] = 1, ["z"] = 35, ["name"] = "default:stone"}, {["x"] = 31, ["y"] = 2, ["param1"] = 1, ["z"] = 36, ["name"] = "default:stone"}, {["x"] = 31, ["y"] = 2, ["param1"] = 1, ["z"] = 37, ["name"] = "default:stone"}, {["x"] = 31, ["y"] = 3, ["param1"] = 4, ["z"] = 25, ["name"] = "default:stone_block"}, {["x"] = 31, ["y"] = 3, ["param1"] = 4, ["z"] = 26, ["name"] = "default:stone_block"}, {["x"] = 31, ["y"] = 3, ["param1"] = 4, ["z"] = 27, ["name"] = "default:stone_block"}, {["x"] = 31, ["y"] = 3, ["param1"] = 4, ["z"] = 28, ["name"] = "default:stone_block"}, {["x"] = 31, ["y"] = 3, ["param1"] = 4, ["z"] = 29, ["name"] = "default:stone_block"}, {["x"] = 31, ["y"] = 3, ["param1"] = 4, ["z"] = 30, ["name"] = "default:stone_block"}, {["x"] = 31, ["y"] = 3, ["param1"] = 4, ["z"] = 31, ["name"] = "default:stone_block"}, {["x"] = 31, ["y"] = 3, ["param1"] = 4, ["z"] = 32, ["name"] = "default:stone_block"}, {["x"] = 31, ["y"] = 3, ["param1"] = 4, ["z"] = 33, ["name"] = "default:stone_block"}, {["x"] = 31, ["y"] = 3, ["param1"] = 4, ["z"] = 34, ["name"] = "default:stone_block"}, {["x"] = 31, ["y"] = 3, ["param1"] = 2, ["z"] = 35, ["name"] = "default:cobble"}, {["x"] = 31, ["y"] = 3, ["param1"] = 2, ["z"] = 36, ["name"] = "default:cobble"}, {["x"] = 31, ["y"] = 3, ["param1"] = 4, ["z"] = 37, ["name"] = "default:stone_block"}, {["x"] = 31, ["y"] = 3, ["param1"] = 4, ["z"] = 38, ["name"] = "default:stone_block"}, {["x"] = 31, ["y"] = 4, ["param1"] = 4, ["z"] = 24, ["name"] = "default:stone_block"}, {["x"] = 31, ["y"] = 4, ["param1"] = 4, ["z"] = 25, ["name"] = "default:stone_block"}, {["x"] = 31, ["y"] = 4, ["param1"] = 14, ["z"] = 26, ["name"] = "stairs:slab_cobble"}, {["x"] = 31, ["y"] = 4, ["param1"] = 14, ["z"] = 27, ["name"] = "stairs:slab_cobble"}, {["x"] = 31, ["y"] = 4, ["param1"] = 14, ["z"] = 28, ["name"] = "stairs:slab_cobble"}, {["x"] = 31, ["param2"] = 1, ["y"] = 4, ["param1"] = 14, ["z"] = 29, ["name"] = "stairs:slab_cobble"}, {["x"] = 31, ["y"] = 4, ["param1"] = 14, ["z"] = 30, ["name"] = "stairs:slab_cobble"}, {["x"] = 31, ["y"] = 4, ["param1"] = 14, ["z"] = 31, ["name"] = "stairs:slab_cobble"}, {["x"] = 31, ["y"] = 4, ["param1"] = 14, ["z"] = 32, ["name"] = "stairs:slab_cobble"}, {["x"] = 31, ["y"] = 4, ["param1"] = 14, ["z"] = 33, ["name"] = "stairs:slab_cobble"}, {["x"] = 31, ["y"] = 4, ["param1"] = 14, ["z"] = 34, ["name"] = "stairs:slab_cobble"}, {["x"] = 31, ["y"] = 4, ["param1"] = 4, ["z"] = 37, ["name"] = "default:stone_block"}, {["x"] = 31, ["y"] = 4, ["param1"] = 4, ["z"] = 38, ["name"] = "default:stone_block"}, {["x"] = 31, ["param2"] = 2, ["y"] = 5, ["param1"] = 14, ["z"] = 24, ["name"] = "stairs:slab_stone_block"}, {["x"] = 31, ["param2"] = 2, ["y"] = 5, ["param1"] = 14, ["z"] = 25, ["name"] = "stairs:slab_stone_block"}, {["x"] = 32, ["param2"] = 21, ["y"] = 2, ["param1"] = 10, ["z"] = 29, ["name"] = "stairs:slab_stone"}, {["x"] = 32, ["param2"] = 21, ["y"] = 2, ["param1"] = 9, ["z"] = 30, ["name"] = "stairs:slab_stone"}, {["x"] = 32, ["y"] = 2, ["param1"] = 1, ["z"] = 31, ["name"] = "default:stone"}, {["x"] = 32, ["y"] = 2, ["param1"] = 1, ["z"] = 32, ["name"] = "default:stone"}, {["x"] = 32, ["y"] = 2, ["param1"] = 1, ["z"] = 33, ["name"] = "default:stone"}, {["x"] = 32, ["y"] = 2, ["param1"] = 1, ["z"] = 34, ["name"] = "default:stone"}, {["x"] = 32, ["y"] = 2, ["param1"] = 1, ["z"] = 35, ["name"] = "default:stone"}, {["x"] = 32, ["y"] = 2, ["param1"] = 1, ["z"] = 36, ["name"] = "default:stone"}, {["x"] = 32, ["y"] = 2, ["param1"] = 1, ["z"] = 37, ["name"] = "default:stone"}, {["x"] = 32, ["y"] = 2, ["param1"] = 1, ["z"] = 38, ["name"] = "default:stone"}, {["x"] = 32, ["y"] = 3, ["param1"] = 4, ["z"] = 26, ["name"] = "default:stone_block"}, {["x"] = 32, ["y"] = 3, ["param1"] = 4, ["z"] = 27, ["name"] = "default:stone_block"}, {["x"] = 32, ["y"] = 3, ["param1"] = 4, ["z"] = 28, ["name"] = "default:stone_block"}, {["x"] = 32, ["y"] = 3, ["param1"] = 4, ["z"] = 29, ["name"] = "default:stone_block"}, {["x"] = 32, ["y"] = 3, ["param1"] = 4, ["z"] = 30, ["name"] = "default:stone_block"}, {["x"] = 32, ["y"] = 3, ["param1"] = 4, ["z"] = 31, ["name"] = "default:stone_block"}, {["x"] = 32, ["y"] = 3, ["param1"] = 4, ["z"] = 32, ["name"] = "default:stone_block"}, {["x"] = 32, ["y"] = 3, ["param1"] = 4, ["z"] = 33, ["name"] = "default:stone_block"}, {["x"] = 32, ["y"] = 3, ["param1"] = 2, ["z"] = 34, ["name"] = "default:cobble"}, {["x"] = 32, ["y"] = 3, ["param1"] = 2, ["z"] = 35, ["name"] = "default:cobble"}, {["x"] = 32, ["y"] = 3, ["param1"] = 2, ["z"] = 36, ["name"] = "default:cobble"}, {["x"] = 32, ["y"] = 3, ["param1"] = 2, ["z"] = 37, ["name"] = "default:cobble"}, {["x"] = 32, ["y"] = 3, ["param1"] = 4, ["z"] = 38, ["name"] = "default:stone_block"}, {["x"] = 32, ["y"] = 3, ["param1"] = 4, ["z"] = 39, ["name"] = "default:stone_block"}, {["x"] = 32, ["y"] = 4, ["param1"] = 4, ["z"] = 25, ["name"] = "default:stone_block"}, {["x"] = 32, ["y"] = 4, ["param1"] = 4, ["z"] = 26, ["name"] = "default:stone_block"}, {["x"] = 32, ["y"] = 4, ["param1"] = 14, ["z"] = 27, ["name"] = "stairs:slab_cobble"}, {["x"] = 32, ["param2"] = 1, ["y"] = 4, ["param1"] = 14, ["z"] = 28, ["name"] = "stairs:slab_cobble"}, {["x"] = 32, ["param2"] = 1, ["y"] = 4, ["param1"] = 14, ["z"] = 29, ["name"] = "stairs:slab_cobble"}, {["x"] = 32, ["param2"] = 1, ["y"] = 4, ["param1"] = 14, ["z"] = 30, ["name"] = "stairs:slab_cobble"}, {["x"] = 32, ["param2"] = 1, ["y"] = 4, ["param1"] = 14, ["z"] = 31, ["name"] = "stairs:slab_cobble"}, {["x"] = 32, ["param2"] = 1, ["y"] = 4, ["param1"] = 14, ["z"] = 32, ["name"] = "stairs:slab_cobble"}, {["x"] = 32, ["y"] = 4, ["param1"] = 14, ["z"] = 33, ["name"] = "stairs:slab_cobble"}, {["x"] = 32, ["y"] = 4, ["param1"] = 4, ["z"] = 38, ["name"] = "default:stone_block"}, {["x"] = 32, ["y"] = 4, ["param1"] = 4, ["z"] = 39, ["name"] = "default:stone_block"}, {["x"] = 32, ["param2"] = 3, ["y"] = 5, ["param1"] = 14, ["z"] = 25, ["name"] = "stairs:slab_stone_block"}, {["x"] = 32, ["param2"] = 2, ["y"] = 5, ["param1"] = 14, ["z"] = 26, ["name"] = "stairs:slab_stone_block"}, {["x"] = 33, ["param2"] = 21, ["y"] = 1, ["param1"] = 7, ["z"] = 33, ["name"] = "stairs:slab_stone"}, {["x"] = 33, ["param2"] = 20, ["y"] = 1, ["param1"] = 8, ["z"] = 34, ["name"] = "stairs:slab_stone"}, {["x"] = 33, ["param2"] = 20, ["y"] = 1, ["param1"] = 9, ["z"] = 35, ["name"] = "stairs:slab_stone"}, {["x"] = 33, ["param2"] = 20, ["y"] = 1, ["param1"] = 10, ["z"] = 36, ["name"] = "stairs:slab_stone"}, {["x"] = 33, ["param2"] = 21, ["y"] = 2, ["param1"] = 11, ["z"] = 29, ["name"] = "stairs:slab_stone"}, {["x"] = 33, ["param2"] = 21, ["y"] = 2, ["param1"] = 10, ["z"] = 30, ["name"] = "stairs:slab_stone"}, {["x"] = 33, ["y"] = 2, ["param1"] = 1, ["z"] = 31, ["name"] = "default:stone"}, {["x"] = 33, ["y"] = 2, ["param1"] = 1, ["z"] = 32, ["name"] = "default:stone"}, {["x"] = 33, ["y"] = 2, ["param1"] = 1, ["z"] = 33, ["name"] = "default:stone"}, {["x"] = 33, ["y"] = 2, ["param1"] = 1, ["z"] = 34, ["name"] = "default:stone"}, {["x"] = 33, ["y"] = 2, ["param1"] = 1, ["z"] = 35, ["name"] = "default:stone"}, {["x"] = 33, ["y"] = 2, ["param1"] = 1, ["z"] = 36, ["name"] = "default:stone"}, {["x"] = 33, ["y"] = 2, ["param1"] = 1, ["z"] = 37, ["name"] = "default:stone"}, {["x"] = 33, ["y"] = 2, ["param1"] = 1, ["z"] = 38, ["name"] = "default:stone"}, {["x"] = 33, ["y"] = 2, ["param1"] = 1, ["z"] = 39, ["name"] = "default:stone"}, {["x"] = 33, ["y"] = 3, ["param1"] = 4, ["z"] = 27, ["name"] = "default:stone_block"}, {["x"] = 33, ["y"] = 3, ["param1"] = 4, ["z"] = 28, ["name"] = "default:stone_block"}, {["x"] = 33, ["y"] = 3, ["param1"] = 4, ["z"] = 29, ["name"] = "default:stone_block"}, {["x"] = 33, ["y"] = 3, ["param1"] = 4, ["z"] = 30, ["name"] = "default:stone_block"}, {["x"] = 33, ["y"] = 3, ["param1"] = 4, ["z"] = 31, ["name"] = "default:stone_block"}, {["x"] = 33, ["y"] = 3, ["param1"] = 4, ["z"] = 32, ["name"] = "default:stone_block"}, {["x"] = 33, ["y"] = 3, ["param1"] = 2, ["z"] = 33, ["name"] = "default:cobble"}, {["x"] = 33, ["y"] = 3, ["param1"] = 2, ["z"] = 34, ["name"] = "default:cobble"}, {["x"] = 33, ["y"] = 3, ["param1"] = 2, ["z"] = 35, ["name"] = "default:cobble"}, {["x"] = 33, ["y"] = 3, ["param1"] = 2, ["z"] = 36, ["name"] = "default:cobble"}, {["x"] = 33, ["y"] = 3, ["param1"] = 2, ["z"] = 37, ["name"] = "default:cobble"}, {["x"] = 33, ["y"] = 3, ["param1"] = 2, ["z"] = 38, ["name"] = "default:cobble"}, {["x"] = 33, ["y"] = 3, ["param1"] = 4, ["z"] = 39, ["name"] = "default:stone_block"}, {["x"] = 33, ["y"] = 3, ["param1"] = 4, ["z"] = 40, ["name"] = "default:stone_block"}, {["x"] = 33, ["y"] = 4, ["param1"] = 4, ["z"] = 26, ["name"] = "default:stone_block"}, {["x"] = 33, ["y"] = 4, ["param1"] = 4, ["z"] = 27, ["name"] = "default:stone_block"}, {["x"] = 33, ["param2"] = 1, ["y"] = 4, ["param1"] = 14, ["z"] = 28, ["name"] = "stairs:slab_cobble"}, {["x"] = 33, ["param2"] = 1, ["y"] = 4, ["param1"] = 14, ["z"] = 29, ["name"] = "stairs:slab_cobble"}, {["x"] = 33, ["param2"] = 1, ["y"] = 4, ["param1"] = 14, ["z"] = 30, ["name"] = "stairs:slab_cobble"}, {["x"] = 33, ["param2"] = 1, ["y"] = 4, ["param1"] = 14, ["z"] = 31, ["name"] = "stairs:slab_cobble"}, {["x"] = 33, ["param2"] = 1, ["y"] = 4, ["param1"] = 14, ["z"] = 32, ["name"] = "stairs:slab_cobble"}, {["x"] = 33, ["y"] = 4, ["param1"] = 4, ["z"] = 39, ["name"] = "default:stone_block"}, {["x"] = 33, ["y"] = 4, ["param1"] = 4, ["z"] = 40, ["name"] = "default:stone_block"}, {["x"] = 33, ["param2"] = 1, ["y"] = 5, ["param1"] = 14, ["z"] = 26, ["name"] = "stairs:slab_stone_block"}, {["x"] = 33, ["param2"] = 2, ["y"] = 5, ["param1"] = 14, ["z"] = 27, ["name"] = "stairs:slab_stone_block"}, {["x"] = 34, ["param2"] = 21, ["y"] = 1, ["param1"] = 8, ["z"] = 33, ["name"] = "stairs:slab_stone"}, {["x"] = 34, ["param2"] = 20, ["y"] = 1, ["param1"] = 7, ["z"] = 34, ["name"] = "stairs:slab_stone"}, {["x"] = 34, ["param2"] = 20, ["y"] = 1, ["param1"] = 8, ["z"] = 35, ["name"] = "stairs:slab_stone"}, {["x"] = 34, ["param2"] = 21, ["y"] = 1, ["param1"] = 9, ["z"] = 36, ["name"] = "stairs:slab_stone"}, {["x"] = 34, ["param2"] = 20, ["y"] = 1, ["param1"] = 10, ["z"] = 37, ["name"] = "stairs:slab_stone"}, {["x"] = 34, ["param2"] = 21, ["y"] = 2, ["param1"] = 11, ["z"] = 30, ["name"] = "stairs:slab_stone"},