5:return {{["x"] = 0, ["meta"] = {["fields"] = {}, ["inventory"] = {}}, ["y"] = 0, ["param1"] = 4, ["z"] = 0, ["name"] = "default:stone_block"}, {["x"] = 0, ["meta"] = {["fields"] = {}, ["inventory"] = {}}, ["param2"] = 1, ["y"] = 0, ["param1"] = 14, ["z"] = 1, ["name"] = "stairs:slab_stonebrick"}, {["x"] = 0, ["meta"] = {["fields"] = {}, ["inventory"] = {}}, ["param2"] = 1, ["y"] = 0, ["param1"] = 14, ["z"] = 2, ["name"] = "stairs:slab_stonebrick"}, {["x"] = 0, ["meta"] = {["fields"] = {}, ["inventory"] = {}}, ["param2"] = 1, ["y"] = 0, ["param1"] = 14, ["z"] = 3, ["name"] = "stairs:slab_stonebrick"}, {["x"] = 0, ["meta"] = {["fields"] = {}, ["inventory"] = {}}, ["param2"] = 1, ["y"] = 0, ["param1"] = 14, ["z"] = 4, ["name"] = "stairs:slab_stonebrick"}, {["x"] = 0, ["meta"] = {["fields"] = {}, ["inventory"] = {}}, ["param2"] = 1, ["y"] = 0, ["param1"] = 14, ["z"] = 5, ["name"] = "stairs:slab_stonebrick"}, {["x"] = 0, ["meta"] = {["fields"] = {}, ["inventory"] = {}}, ["param2"] = 1, ["y"] = 0, ["param1"] = 14, ["z"] = 6, ["name"] = "stairs:slab_stonebrick"}, {["x"] = 0, ["meta"] = {["fields"] = {}, ["inventory"] = {}}, ["param2"] = 1, ["y"] = 0, ["param1"] = 14, ["z"] = 7, ["name"] = "stairs:slab_stonebrick"}, {["x"] = 0, ["meta"] = {["fields"] = {}, ["inventory"] = {}}, ["y"] = 0, ["param1"] = 4, ["z"] = 8, ["name"] = "default:stone_block"}, {["x"] = 0, ["param2"] = 1, ["y"] = 1, ["param1"] = 14, ["z"] = 0, ["name"] = "stairs:slab_stone_block"}, {["x"] = 0, ["param2"] = 1, ["y"] = 1, ["param1"] = 14, ["z"] = 8, ["name"] = "stairs:slab_stone_block"}, {["x"] = 1, ["meta"] = {["fields"] = {}, ["inventory"] = {}}, ["y"] = 0, ["param1"] = 4, ["z"] = 0, ["name"] = "default:stone_block"}, {["x"] = 1, ["meta"] = {["fields"] = {}, ["inventory"] = {}}, ["param2"] = 1, ["y"] = 0, ["param1"] = 3, ["z"] = 1, ["name"] = "default:stonebrick"}, {["x"] = 1, ["meta"] = {["fields"] = {}, ["inventory"] = {}}, ["param2"] = 1, ["y"] = 0, ["param1"] = 3, ["z"] = 2, ["name"] = "default:stonebrick"}, {["x"] = 1, ["meta"] = {["fields"] = {}, ["inventory"] = {}}, ["param2"] = 1, ["y"] = 0, ["param1"] = 3, ["z"] = 3, ["name"] = "default:stonebrick"}, {["x"] = 1, ["meta"] = {["fields"] = {}, ["inventory"] = {}}, ["param2"] = 1, ["y"] = 0, ["param1"] = 3, ["z"] = 4, ["name"] = "default:stonebrick"}, {["x"] = 1, ["meta"] = {["fields"] = {}, ["inventory"] = {}}, ["param2"] = 1, ["y"] = 0, ["param1"] = 3, ["z"] = 5, ["name"] = "default:stonebrick"}, {["x"] = 1, ["meta"] = {["fields"] = {}, ["inventory"] = {}}, ["param2"] = 1, ["y"] = 0, ["param1"] = 3, ["z"] = 6, ["name"] = "default:stonebrick"}, {["x"] = 1, ["meta"] = {["fields"] = {}, ["inventory"] = {}}, ["param2"] = 1, ["y"] = 0, ["param1"] = 3, ["z"] = 7, ["name"] = "default:stonebrick"}, {["x"] = 1, ["meta"] = {["fields"] = {}, ["inventory"] = {}}, ["y"] = 0, ["param1"] = 4, ["z"] = 8, ["name"] = "default:stone_block"}, {["x"] = 1, ["meta"] = {["fields"] = {}, ["inventory"] = {}}, ["y"] = 1, ["param1"] = 4, ["z"] = 0, ["name"] = "default:stone_block"}, {["x"] = 1, ["meta"] = {["fields"] = {}, ["inventory"] = {}}, ["y"] = 1, ["param1"] = 4, ["z"] = 8, ["name"] = "default:stone_block"}, {["x"] = 2, ["meta"] = {["fields"] = {}, ["inventory"] = {}}, ["y"] = 0, ["param1"] = 4, ["z"] = 0, ["name"] = "default:stone_block"}, {["x"] = 2, ["meta"] = {["fields"] = {}, ["inventory"] = {}}, ["param2"] = 1, ["y"] = 0, ["param1"] = 3, ["z"] = 1, ["name"] = "default:stonebrick"}, {["x"] = 2, ["meta"] = {["fields"] = {}, ["inventory"] = {}}, ["param2"] = 1, ["y"] = 0, ["param1"] = 3, ["z"] = 2, ["name"] = "default:stonebrick"}, {["x"] = 2, ["meta"] = {["fields"] = {}, ["inventory"] = {}}, ["param2"] = 1, ["y"] = 0, ["param1"] = 3, ["z"] = 3, ["name"] = "default:stonebrick"}, {["x"] = 2, ["meta"] = {["fields"] = {}, ["inventory"] = {}}, ["param2"] = 1, ["y"] = 0, ["param1"] = 3, ["z"] = 4, ["name"] = "default:stonebrick"}, {["x"] = 2, ["meta"] = {["fields"] = {}, ["inventory"] = {}}, ["param2"] = 1, ["y"] = 0, ["param1"] = 3, ["z"] = 5, ["name"] = "default:stonebrick"}, {["x"] = 2, ["meta"] = {["fields"] = {}, ["inventory"] = {}}, ["param2"] = 1, ["y"] = 0, ["param1"] = 3, ["z"] = 6, ["name"] = "default:stonebrick"}, {["x"] = 2, ["meta"] = {["fields"] = {}, ["inventory"] = {}}, ["param2"] = 1, ["y"] = 0, ["param1"] = 3, ["z"] = 7, ["name"] = "default:stonebrick"}, {["x"] = 2, ["meta"] = {["fields"] = {}, ["inventory"] = {}}, ["y"] = 0, ["param1"] = 4, ["z"] = 8, ["name"] = "default:stone_block"}, {["x"] = 2, ["meta"] = {["fields"] = {}, ["inventory"] = {}}, ["y"] = 1, ["param1"] = 4, ["z"] = 0, ["name"] = "default:stone_block"}, {["x"] = 2, ["meta"] = {["fields"] = {}, ["inventory"] = {}}, ["param2"] = 1, ["y"] = 1, ["param1"] = 14, ["z"] = 1, ["name"] = "stairs:slab_stonebrick"}, {["x"] = 2, ["meta"] = {["fields"] = {}, ["inventory"] = {}}, ["param2"] = 1, ["y"] = 1, ["param1"] = 14, ["z"] = 2, ["name"] = "stairs:slab_stonebrick"}, {["x"] = 2, ["meta"] = {["fields"] = {}, ["inventory"] = {}}, ["param2"] = 1, ["y"] = 1, ["param1"] = 14, ["z"] = 3, ["name"] = "stairs:slab_stonebrick"}, {["x"] = 2, ["meta"] = {["fields"] = {}, ["inventory"] = {}}, ["param2"] = 1, ["y"] = 1, ["param1"] = 14, ["z"] = 4, ["name"] = "stairs:slab_stonebrick"}, {["x"] = 2, ["meta"] = {["fields"] = {}, ["inventory"] = {}}, ["param2"] = 1, ["y"] = 1, ["param1"] = 14, ["z"] = 5, ["name"] = "stairs:slab_stonebrick"}, {["x"] = 2, ["meta"] = {["fields"] = {}, ["inventory"] = {}}, ["param2"] = 1, ["y"] = 1, ["param1"] = 14, ["z"] = 6, ["name"] = "stairs:slab_stonebrick"}, {["x"] = 2, ["meta"] = {["fields"] = {}, ["inventory"] = {}}, ["param2"] = 1, ["y"] = 1, ["param1"] = 14, ["z"] = 7, ["name"] = "stairs:slab_stonebrick"}, {["x"] = 2, ["meta"] = {["fields"] = {}, ["inventory"] = {}}, ["y"] = 1, ["param1"] = 4, ["z"] = 8, ["name"] = "default:stone_block"}, {["x"] = 2, ["meta"] = {["fields"] = {}, ["inventory"] = {}}, ["param2"] = 1, ["y"] = 2, ["param1"] = 14, ["z"] = 0, ["name"] = "stairs:slab_stone_block"}, {["x"] = 2, ["meta"] = {["fields"] = {}, ["inventory"] = {}}, ["y"] = 2, ["param1"] = 14, ["z"] = 8, ["name"] = "stairs:slab_stone_block"}, {["x"] = 3, ["meta"] = {["fields"] = {}, ["inventory"] = {}}, ["y"] = 0, ["param1"] = 4, ["z"] = 0, ["name"] = "default:stone_block"}, {["x"] = 3, ["meta"] = {["fields"] = {}, ["inventory"] = {}}, ["param2"] = 1, ["y"] = 0, ["param1"] = 3, ["z"] = 1, ["name"] = "default:stonebrick"}, {["x"] = 3, ["meta"] = {["fields"] = {}, ["inventory"] = {}}, ["param2"] = 1, ["y"] = 0, ["param1"] = 3, ["z"] = 2, ["name"] = "default:stonebrick"}, {["x"] = 3, ["meta"] = {["fields"] = {}, ["inventory"] = {}}, ["param2"] = 1, ["y"] = 0, ["param1"] = 3, ["z"] = 3, ["name"] = "default:stonebrick"}, {["x"] = 3, ["meta"] = {["fields"] = {}, ["inventory"] = {}}, ["param2"] = 1, ["y"] = 0, ["param1"] = 3, ["z"] = 4, ["name"] = "default:stonebrick"}, {["x"] = 3, ["meta"] = {["fields"] = {}, ["inventory"] = {}}, ["param2"] = 1, ["y"] = 0, ["param1"] = 3, ["z"] = 5, ["name"] = "default:stonebrick"}, {["x"] = 3, ["meta"] = {["fields"] = {}, ["inventory"] = {}}, ["param2"] = 1, ["y"] = 0, ["param1"] = 3, ["z"] = 6, ["name"] = "default:stonebrick"}, {["x"] = 3, ["meta"] = {["fields"] = {}, ["inventory"] = {}}, ["param2"] = 1, ["y"] = 0, ["param1"] = 3, ["z"] = 7, ["name"] = "default:stonebrick"}, {["x"] = 3, ["meta"] = {["fields"] = {}, ["inventory"] = {}}, ["y"] = 0, ["param1"] = 4, ["z"] = 8, ["name"] = "default:stone_block"}, {["x"] = 3, ["meta"] = {["fields"] = {}, ["inventory"] = {}}, ["y"] = 1, ["param1"] = 4, ["z"] = 0, ["name"] = "default:stone_block"}, {["x"] = 3, ["meta"] = {["fields"] = {}, ["inventory"] = {}}, ["param2"] = 1, ["y"] = 1, ["param1"] = 3, ["z"] = 1, ["name"] = "default:stonebrick"}, {["x"] = 3, ["meta"] = {["fields"] = {}, ["inventory"] = {}}, ["param2"] = 1, ["y"] = 1, ["param1"] = 3, ["z"] = 2, ["name"] = "default:stonebrick"}, {["x"] = 3, ["meta"] = {["fields"] = {}, ["inventory"] = {}}, ["param2"] = 1, ["y"] = 1, ["param1"] = 3, ["z"] = 3, ["name"] = "default:stonebrick"}, {["x"] = 3, ["meta"] = {["fields"] = {}, ["inventory"] = {}}, ["param2"] = 1, ["y"] = 1, ["param1"] = 3, ["z"] = 4, ["name"] = "default:stonebrick"}, {["x"] = 3, ["meta"] = {["fields"] = {}, ["inventory"] = {}}, ["param2"] = 1, ["y"] = 1, ["param1"] = 3, ["z"] = 5, ["name"] = "default:stonebrick"}, {["x"] = 3, ["meta"] = {["fields"] = {}, ["inventory"] = {}}, ["param2"] = 1, ["y"] = 1, ["param1"] = 3, ["z"] = 6, ["name"] = "default:stonebrick"}, {["x"] = 3, ["meta"] = {["fields"] = {}, ["inventory"] = {}}, ["param2"] = 1, ["y"] = 1, ["param1"] = 3, ["z"] = 7, ["name"] = "default:stonebrick"}, {["x"] = 3, ["meta"] = {["fields"] = {}, ["inventory"] = {}}, ["y"] = 1, ["param1"] = 4, ["z"] = 8, ["name"] = "default:stone_block"}, {["x"] = 3, ["meta"] = {["fields"] = {}, ["inventory"] = {}}, ["y"] = 2, ["param1"] = 4, ["z"] = 0, ["name"] = "default:stone_block"}, {["x"] = 3, ["meta"] = {["fields"] = {}, ["inventory"] = {}}, ["y"] = 2, ["param1"] = 4, ["z"] = 8, ["name"] = "default:stone_block"}, {["x"] = 4, ["meta"] = {["fields"] = {}, ["inventory"] = {}}, ["y"] = 0, ["param1"] = 1, ["z"] = 0, ["name"] = "default:stone"}, {["x"] = 4, ["meta"] = {["fields"] = {}, ["inventory"] = {}}, ["y"] = 0, ["param1"] = 1, ["z"] = 1, ["name"] = "default:stone"}, {["x"] = 4, ["meta"] = {["fields"] = {}, ["inventory"] = {}}, ["y"] = 0, ["param1"] = 1, ["z"] = 2, ["name"] = "default:stone"}, {["x"] = 4, ["meta"] = {["fields"] = {}, ["inventory"] = {}}, ["y"] = 0, ["param1"] = 1, ["z"] = 3, ["name"] = "default:stone"}, {["x"] = 4, ["meta"] = {["fields"] = {}, ["inventory"] = {}}, ["y"] = 0, ["param1"] = 1, ["z"] = 4, ["name"] = "default:stone"}, {["x"] = 4, ["meta"] = {["fields"] = {}, ["inventory"] = {}}, ["y"] = 0, ["param1"] = 1, ["z"] = 5, ["name"] = "default:stone"}, {["x"] = 4, ["meta"] = {["fields"] = {}, ["inventory"] = {}}, ["y"] = 0, ["param1"] = 1, ["z"] = 6, ["name"] = "default:stone"}, {["x"] = 4, ["meta"] = {["fields"] = {}, ["inventory"] = {}}, ["y"] = 0, ["param1"] = 1, ["z"] = 7, ["name"] = "default:stone"}, {["x"] = 4, ["meta"] = {["fields"] = {}, ["inventory"] = {}}, ["y"] = 0, ["param1"] = 1, ["z"] = 8, ["name"] = "default:stone"}, {["x"] = 4, ["meta"] = {["fields"] = {}, ["inventory"] = {}}, ["y"] = 1, ["param1"] = 1, ["z"] = 0, ["name"] = "default:stone"}, {["x"] = 4, ["meta"] = {["fields"] = {}, ["inventory"] = {}}, ["y"] = 1, ["param1"] = 1, ["z"] = 1, ["name"] = "default:stone"}, {["x"] = 4, ["meta"] = {["fields"] = {}, ["inventory"] = {}}, ["y"] = 1, ["param1"] = 1, ["z"] = 2, ["name"] = "default:stone"}, {["x"] = 4, ["meta"] = {["fields"] = {}, ["inventory"] = {}}, ["y"] = 1, ["param1"] = 1, ["z"] = 3, ["name"] = "default:stone"}, {["x"] = 4, ["meta"] = {["fields"] = {}, ["inventory"] = {}}, ["y"] = 1, ["param1"] = 1, ["z"] = 4, ["name"] = "default:stone"}, {["x"] = 4, ["meta"] = {["fields"] = {}, ["inventory"] = {}}, ["y"] = 1, ["param1"] = 1, ["z"] = 5, ["name"] = "default:stone"}, {["x"] = 4, ["meta"] = {["fields"] = {}, ["inventory"] = {}}, ["y"] = 1, ["param1"] = 1, ["z"] = 6, ["name"] = "default:stone"}, {["x"] = 4, ["meta"] = {["fields"] = {}, ["inventory"] = {}}, ["y"] = 1, ["param1"] = 1, ["z"] = 7, ["name"] = "default:stone"}, {["x"] = 4, ["meta"] = {["fields"] = {}, ["inventory"] = {}}, ["y"] = 1, ["param1"] = 1, ["z"] = 8, ["name"] = "default:stone"}, {["x"] = 4, ["meta"] = {["fields"] = {}, ["inventory"] = {}}, ["y"] = 2, ["param1"] = 4, ["z"] = 0, ["name"] = "default:stone_block"}, {["x"] = 4, ["meta"] = {["fields"] = {}, ["inventory"] = {}}, ["param2"] = 1, ["y"] = 2, ["param1"] = 14, ["z"] = 1, ["name"] = "stairs:slab_stonebrick"}, {["x"] = 4, ["meta"] = {["fields"] = {}, ["inventory"] = {}}, ["param2"] = 1, ["y"] = 2, ["param1"] = 14, ["z"] = 2, ["name"] = "stairs:slab_stonebrick"}, {["x"] = 4, ["meta"] = {["fields"] = {}, ["inventory"] = {}}, ["param2"] = 1, ["y"] = 2, ["param1"] = 14, ["z"] = 3, ["name"] = "stairs:slab_stonebrick"}, {["x"] = 4, ["meta"] = {["fields"] = {}, ["inventory"] = {}}, ["param2"] = 1, ["y"] = 2, ["param1"] = 14, ["z"] = 4, ["name"] = "stairs:slab_stonebrick"}, {["x"] = 4, ["meta"] = {["fields"] = {}, ["inventory"] = {}}, ["param2"] = 1, ["y"] = 2, ["param1"] = 14, ["z"] = 5, ["name"] = "stairs:slab_stonebrick"}, {["x"] = 4, ["meta"] = {["fields"] = {}, ["inventory"] = {}}, ["param2"] = 1, ["y"] = 2, ["param1"] = 14, ["z"] = 6, ["name"] = "stairs:slab_stonebrick"}, {["x"] = 4, ["meta"] = {["fields"] = {}, ["inventory"] = {}}, ["param2"] = 1, ["y"] = 2, ["param1"] = 14, ["z"] = 7, ["name"] = "stairs:slab_stonebrick"}, {["x"] = 4, ["meta"] = {["fields"] = {}, ["inventory"] = {}}, ["y"] = 2, ["param1"] = 4, ["z"] = 8, ["name"] = "default:stone_block"}, {["x"] = 4, ["meta"] = {["fields"] = {}, ["inventory"] = {}}, ["param2"] = 1, ["y"] = 3, ["param1"] = 14, ["z"] = 0, ["name"] = "stairs:slab_stone_block"}, {["x"] = 4, ["meta"] = {["fields"] = {}, ["inventory"] = {}}, ["param2"] = 1, ["y"] = 3, ["param1"] = 14, ["z"] = 8, ["name"] = "stairs:slab_stone_block"}, {["x"] = 5, ["meta"] = {["fields"] = {}, ["inventory"] = {}}, ["y"] = 0, ["param1"] = 1, ["z"] = 0, ["name"] = "default:stone"}, {["x"] = 5, ["meta"] = {["fields"] = {}, ["inventory"] = {}}, ["y"] = 0, ["param1"] = 1, ["z"] = 1, ["name"] = "default:stone"}, {["x"] = 5, ["meta"] = {["fields"] = {}, ["inventory"] = {}}, ["y"] = 0, ["param1"] = 1, ["z"] = 2, ["name"] = "default:stone"}, {["x"] = 5, ["meta"] = {["fields"] = {}, ["inventory"] = {}}, ["y"] = 0, ["param1"] = 1, ["z"] = 3, ["name"] = "default:stone"}, {["x"] = 5, ["meta"] = {["fields"] = {}, ["inventory"] = {}}, ["y"] = 0, ["param1"] = 1, ["z"] = 4, ["name"] = "default:stone"}, {["x"] = 5, ["meta"] = {["fields"] = {}, ["inventory"] = {}}, ["y"] = 0, ["param1"] = 1, ["z"] = 5, ["name"] = "default:stone"}, {["x"] = 5, ["meta"] = {["fields"] = {}, ["inventory"] = {}}, ["y"] = 0, ["param1"] = 1, ["z"] = 6, ["name"] = "default:stone"}, {["x"] = 5, ["meta"] = {["fields"] = {}, ["inventory"] = {}}, ["y"] = 0, ["param1"] = 1, ["z"] = 7, ["name"] = "default:stone"}, {["x"] = 5, ["meta"] = {["fields"] = {}, ["inventory"] = {}}, ["y"] = 0, ["param1"] = 1, ["z"] = 8, ["name"] = "default:stone"}, {["x"] = 5, ["meta"] = {["fields"] = {}, ["inventory"] = {}}, ["y"] = 1, ["param1"] = 1, ["z"] = 0, ["name"] = "default:stone"}, {["x"] = 5, ["meta"] = {["fields"] = {}, ["inventory"] = {}}, ["y"] = 1, ["param1"] = 1, ["z"] = 1, ["name"] = "default:stone"}, {["x"] = 5, ["meta"] = {["fields"] = {}, ["inventory"] = {}}, ["y"] = 1, ["param1"] = 1, ["z"] = 2, ["name"] = "default:stone"}, {["x"] = 5, ["meta"] = {["fields"] = {}, ["inventory"] = {}}, ["y"] = 1, ["param1"] = 1, ["z"] = 3, ["name"] = "default:stone"}, {["x"] = 5, ["meta"] = {["fields"] = {}, ["inventory"] = {}}, ["y"] = 1, ["param1"] = 1, ["z"] = 4, ["name"] = "default:stone"}, {["x"] = 5, ["meta"] = {["fields"] = {}, ["inventory"] = {}}, ["y"] = 1, ["param1"] = 1, ["z"] = 5, ["name"] = "default:stone"}, {["x"] = 5, ["meta"] = {["fields"] = {}, ["inventory"] = {}}, ["y"] = 1, ["param1"] = 1, ["z"] = 6, ["name"] = "default:stone"}, {["x"] = 5, ["meta"] = {["fields"] = {}, ["inventory"] = {}}, ["y"] = 1, ["param1"] = 1, ["z"] = 7, ["name"] = "default:stone"}, {["x"] = 5, ["meta"] = {["fields"] = {}, ["inventory"] = {}}, ["y"] = 1, ["param1"] = 1, ["z"] = 8, ["name"] = "default:stone"}, {["x"] = 5, ["meta"] = {["fields"] = {}, ["inventory"] = {}}, ["y"] = 2, ["param1"] = 4, ["z"] = 0, ["name"] = "default:stone_block"}, {["x"] = 5, ["meta"] = {["fields"] = {}, ["inventory"] = {}}, ["param2"] = 1, ["y"] = 2, ["param1"] = 14, ["z"] = 1, ["name"] = "stairs:slab_stonebrick"}, {["x"] = 5, ["meta"] = {["fields"] = {}, ["inventory"] = {}}, ["param2"] = 1, ["y"] = 2, ["param1"] = 14, ["z"] = 2, ["name"] = "stairs:slab_stonebrick"}, {["x"] = 5, ["meta"] = {["fields"] = {}, ["inventory"] = {}}, ["param2"] = 1, ["y"] = 2, ["param1"] = 14, ["z"] = 3, ["name"] = "stairs:slab_stonebrick"}, {["x"] = 5, ["meta"] = {["fields"] = {}, ["inventory"] = {}}, ["param2"] = 1, ["y"] = 2, ["param1"] = 14, ["z"] = 4, ["name"] = "stairs:slab_stonebrick"}, {["x"] = 5, ["meta"] = {["fields"] = {}, ["inventory"] = {}}, ["param2"] = 1, ["y"] = 2, ["param1"] = 14, ["z"] = 5, ["name"] = "stairs:slab_stonebrick"}, {["x"] = 5, ["meta"] = {["fields"] = {}, ["inventory"] = {}}, ["param2"] = 1, ["y"] = 2, ["param1"] = 14, ["z"] = 6, ["name"] = "stairs:slab_stonebrick"}, {["x"] = 5, ["meta"] = {["fields"] = {}, ["inventory"] = {}}, ["param2"] = 1, ["y"] = 2, ["param1"] = 14, ["z"] = 7, ["name"] = "stairs:slab_stonebrick"}, {["x"] = 5, ["meta"] = {["fields"] = {}, ["inventory"] = {}}, ["y"] = 2, ["param1"] = 4, ["z"] = 8, ["name"] = "default:stone_block"}, {["x"] = 5, ["meta"] = {["fields"] = {}, ["inventory"] = {}}, ["param2"] = 1, ["y"] = 3, ["param1"] = 14, ["z"] = 0, ["name"] = "stairs:slab_stone_block"}, {["x"] = 5, ["meta"] = {["fields"] = {}, ["inventory"] = {}}, ["param2"] = 1, ["y"] = 3, ["param1"] = 14, ["z"] = 8, ["name"] = "stairs:slab_stone_block"}, {["x"] = 6, ["meta"] = {["fields"] = {}, ["inventory"] = {}}, ["y"] = 0, ["param1"] = 1, ["z"] = 0, ["name"] = "default:stone"}, {["x"] = 6, ["meta"] = {["fields"] = {}, ["inventory"] = {}}, ["y"] = 0, ["param1"] = 1, ["z"] = 1, ["name"] = "default:stone"}, {["x"] = 6, ["meta"] = {["fields"] = {}, ["inventory"] = {}}, ["y"] = 0, ["param1"] = 1, ["z"] = 2, ["name"] = "default:stone"}, {["x"] = 6, ["meta"] = {["fields"] = {}, ["inventory"] = {}}, ["y"] = 0, ["param1"] = 1, ["z"] = 3, ["name"] = "default:stone"}, {["x"] = 6, ["meta"] = {["fields"] = {}, ["inventory"] = {}}, ["y"] = 0, ["param1"] = 1, ["z"] = 4, ["name"] = "default:stone"}, {["x"] = 6, ["meta"] = {["fields"] = {}, ["inventory"] = {}}, ["y"] = 0, ["param1"] = 1, ["z"] = 5, ["name"] = "default:stone"}, {["x"] = 6, ["meta"] = {["fields"] = {}, ["inventory"] = {}}, ["y"] = 0, ["param1"] = 1, ["z"] = 6, ["name"] = "default:stone"}, {["x"] = 6, ["meta"] = {["fields"] = {}, ["inventory"] = {}}, ["y"] = 0, ["param1"] = 1, ["z"] = 7, ["name"] = "default:stone"}, {["x"] = 6, ["meta"] = {["fields"] = {}, ["inventory"] = {}}, ["y"] = 0, ["param1"] = 1, ["z"] = 8, ["name"] = "default:stone"}, {["x"] = 6, ["meta"] = {["fields"] = {}, ["inventory"] = {}}, ["y"] = 1, ["param1"] = 1, ["z"] = 0, ["name"] = "default:stone"}, {["x"] = 6, ["meta"] = {["fields"] = {}, ["inventory"] = {}}, ["y"] = 1, ["param1"] = 1, ["z"] = 1, ["name"] = "default:stone"}, {["x"] = 6, ["meta"] = {["fields"] = {}, ["inventory"] = {}}, ["y"] = 1, ["param1"] = 1, ["z"] = 2, ["name"] = "default:stone"}, {["x"] = 6, ["meta"] = {["fields"] = {}, ["inventory"] = {}}, ["y"] = 1, ["param1"] = 1, ["z"] = 3, ["name"] = "default:stone"}, {["x"] = 6, ["meta"] = {["fields"] = {}, ["inventory"] = {}}, ["y"] = 1, ["param1"] = 1, ["z"] = 4, ["name"] = "default:stone"}, {["x"] = 6, ["meta"] = {["fields"] = {}, ["inventory"] = {}}, ["y"] = 1, ["param1"] = 1, ["z"] = 5, ["name"] = "default:stone"}, {["x"] = 6, ["meta"] = {["fields"] = {}, ["inventory"] = {}}, ["y"] = 1, ["param1"] = 1, ["z"] = 6, ["name"] = "default:stone"}, {["x"] = 6, ["meta"] = {["fields"] = {}, ["inventory"] = {}}, ["y"] = 1, ["param1"] = 1, ["z"] = 7, ["name"] = "default:stone"}, {["x"] = 6, ["meta"] = {["fields"] = {}, ["inventory"] = {}}, ["y"] = 1, ["param1"] = 1, ["z"] = 8, ["name"] = "default:stone"}, {["x"] = 6, ["meta"] = {["fields"] = {}, ["inventory"] = {}}, ["y"] = 2, ["param1"] = 4, ["z"] = 0, ["name"] = "default:stone_block"}, {["x"] = 6, ["meta"] = {["fields"] = {}, ["inventory"] = {}}, ["param2"] = 1, ["y"] = 2, ["param1"] = 3, ["z"] = 1, ["name"] = "default:stonebrick"}, {["x"] = 6, ["meta"] = {["fields"] = {}, ["inventory"] = {}}, ["param2"] = 1, ["y"] = 2, ["param1"] = 3, ["z"] = 2, ["name"] = "default:stonebrick"}, {["x"] = 6, ["meta"] = {["fields"] = {}, ["inventory"] = {}}, ["param2"] = 1, ["y"] = 2, ["param1"] = 3, ["z"] = 3, ["name"] = "default:stonebrick"}, {["x"] = 6, ["meta"] = {["fields"] = {}, ["inventory"] = {}}, ["param2"] = 1, ["y"] = 2, ["param1"] = 3, ["z"] = 4, ["name"] = "default:stonebrick"}, {["x"] = 6, ["meta"] = {["fields"] = {}, ["inventory"] = {}}, ["param2"] = 1, ["y"] = 2, ["param1"] = 3, ["z"] = 5, ["name"] = "default:stonebrick"}, {["x"] = 6, ["meta"] = {["fields"] = {}, ["inventory"] = {}}, ["param2"] = 1, ["y"] = 2, ["param1"] = 3, ["z"] = 6, ["name"] = "default:stonebrick"}, {["x"] = 6, ["meta"] = {["fields"] = {}, ["inventory"] = {}}, ["param2"] = 1, ["y"] = 2, ["param1"] = 3, ["z"] = 7, ["name"] = "default:stonebrick"}, {["x"] = 6, ["meta"] = {["fields"] = {}, ["inventory"] = {}}, ["y"] = 2, ["param1"] = 4, ["z"] = 8, ["name"] = "default:stone_block"}, {["x"] = 6, ["meta"] = {["fields"] = {}, ["inventory"] = {}}, ["y"] = 3, ["param1"] = 4, ["z"] = 0, ["name"] = "default:stone_block"}, {["x"] = 6, ["meta"] = {["fields"] = {}, ["inventory"] = {}}, ["y"] = 3, ["param1"] = 4, ["z"] = 8, ["name"] = "default:stone_block"}, {["x"] = 7, ["meta"] = {["fields"] = {}, ["inventory"] = {}}, ["y"] = 0, ["param1"] = 1, ["z"] = 0, ["name"] = "default:stone"}, {["x"] = 7, ["meta"] = {["fields"] = {}, ["inventory"] = {}}, ["y"] = 0, ["param1"] = 1, ["z"] = 1, ["name"] = "default:stone"}, {["x"] = 7, ["meta"] = {["fields"] = {}, ["inventory"] = {}}, ["y"] = 0, ["param1"] = 1, ["z"] = 2, ["name"] = "default:stone"}, {["x"] = 7, ["meta"] = {["fields"] = {}, ["inventory"] = {}}, ["y"] = 0, ["param1"] = 1, ["z"] = 3, ["name"] = "default:stone"}, {["x"] = 7, ["meta"] = {["fields"] = {}, ["inventory"] = {}}, ["y"] = 0, ["param1"] = 1, ["z"] = 4, ["name"] = "default:stone"}, {["x"] = 7, ["meta"] = {["fields"] = {}, ["inventory"] = {}}, ["y"] = 0, ["param1"] = 1, ["z"] = 5, ["name"] = "default:stone"}, {["x"] = 7, ["meta"] = {["fields"] = {}, ["inventory"] = {}}, ["y"] = 0, ["param1"] = 1, ["z"] = 6, ["name"] = "default:stone"}, {["x"] = 7, ["meta"] = {["fields"] = {}, ["inventory"] = {}}, ["y"] = 0, ["param1"] = 1, ["z"] = 7, ["name"] = "default:stone"}, {["x"] = 7, ["meta"] = {["fields"] = {}, ["inventory"] = {}}, ["y"] = 0, ["param1"] = 1, ["z"] = 8, ["name"] = "default:stone"}, {["x"] = 7, ["meta"] = {["fields"] = {}, ["inventory"] = {}}, ["y"] = 1, ["param1"] = 1, ["z"] = 0, ["name"] = "default:stone"}, {["x"] = 7, ["meta"] = {["fields"] = {}, ["inventory"] = {}}, ["y"] = 1, ["param1"] = 1, ["z"] = 1, ["name"] = "default:stone"}, {["x"] = 7, ["meta"] = {["fields"] = {}, ["inventory"] = {}}, ["y"] = 1, ["param1"] = 1, ["z"] = 2, ["name"] = "default:stone"}, {["x"] = 7, ["meta"] = {["fields"] = {}, ["inventory"] = {}}, ["y"] = 1, ["param1"] = 1, ["z"] = 3, ["name"] = "default:stone"}, {["x"] = 7, ["meta"] = {["fields"] = {}, ["inventory"] = {}}, ["y"] = 1, ["param1"] = 1, ["z"] = 4, ["name"] = "default:stone"}, {["x"] = 7, ["meta"] = {["fields"] = {}, ["inventory"] = {}}, ["y"] = 1, ["param1"] = 1, ["z"] = 5, ["name"] = "default:stone"}, {["x"] = 7, ["meta"] = {["fields"] = {}, ["inventory"] = {}}, ["y"] = 1, ["param1"] = 1, ["z"] = 6, ["name"] = "default:stone"}, {["x"] = 7, ["meta"] = {["fields"] = {}, ["inventory"] = {}}, ["y"] = 1, ["param1"] = 1, ["z"] = 7, ["name"] = "default:stone"}, {["x"] = 7, ["meta"] = {["fields"] = {}, ["inventory"] = {}}, ["y"] = 1, ["param1"] = 1, ["z"] = 8, ["name"] = "default:stone"}, {["x"] = 7, ["meta"] = {["fields"] = {}, ["inventory"] = {}}, ["y"] = 2, ["param1"] = 4, ["z"] = 0, ["name"] = "default:stone_block"}, {["x"] = 7, ["meta"] = {["fields"] = {}, ["inventory"] = {}}, ["param2"] = 1, ["y"] = 2, ["param1"] = 3, ["z"] = 1, ["name"] = "default:stonebrick"}, {["x"] = 7, ["meta"] = {["fields"] = {}, ["inventory"] = {}}, ["param2"] = 1, ["y"] = 2, ["param1"] = 3, ["z"] = 2, ["name"] = "default:stonebrick"}, {["x"] = 7, ["meta"] = {["fields"] = {}, ["inventory"] = {}}, ["param2"] = 1, ["y"] = 2, ["param1"] = 3, ["z"] = 3, ["name"] = "default:stonebrick"}, {["x"] = 7, ["meta"] = {["fields"] = {}, ["inventory"] = {}}, ["param2"] = 1, ["y"] = 2, ["param1"] = 3, ["z"] = 4, ["name"] = "default:stonebrick"}, {["x"] = 7, ["meta"] = {["fields"] = {}, ["inventory"] = {}}, ["param2"] = 1, ["y"] = 2, ["param1"] = 3, ["z"] = 5, ["name"] = "default:stonebrick"}, {["x"] = 7, ["meta"] = {["fields"] = {}, ["inventory"] = {}}, ["param2"] = 1, ["y"] = 2, ["param1"] = 3, ["z"] = 6, ["name"] = "default:stonebrick"}, {["x"] = 7, ["meta"] = {["fields"] = {}, ["inventory"] = {}}, ["param2"] = 1, ["y"] = 2, ["param1"] = 3, ["z"] = 7, ["name"] = "default:stonebrick"}, {["x"] = 7, ["meta"] = {["fields"] = {}, ["inventory"] = {}}, ["y"] = 2, ["param1"] = 4, ["z"] = 8, ["name"] = "default:stone_block"}, {["x"] = 7, ["meta"] = {["fields"] = {}, ["inventory"] = {}}, ["y"] = 3, ["param1"] = 4, ["z"] = 0, ["name"] = "default:stone_block"}, {["x"] = 7, ["meta"] = {["fields"] = {}, ["inventory"] = {}}, ["y"] = 3, ["param1"] = 4, ["z"] = 8, ["name"] = "default:stone_block"}, {["x"] = 8, ["meta"] = {["fields"] = {}, ["inventory"] = {}}, ["y"] = 0, ["param1"] = 1, ["z"] = 0, ["name"] = "default:stone"}, {["x"] = 8, ["meta"] = {["fields"] = {}, ["inventory"] = {}}, ["y"] = 0, ["param1"] = 1, ["z"] = 1, ["name"] = "default:stone"}, {["x"] = 8, ["meta"] = {["fields"] = {}, ["inventory"] = {}}, ["y"] = 0, ["param1"] = 1, ["z"] = 2, ["name"] = "default:stone"}, {["x"] = 8, ["meta"] = {["fields"] = {}, ["inventory"] = {}}, ["y"] = 0, ["param1"] = 1, ["z"] = 3, ["name"] = "default:stone"}, {["x"] = 8, ["meta"] = {["fields"] = {}, ["inventory"] = {}}, ["y"] = 0, ["param1"] = 1, ["z"] = 4, ["name"] = "default:stone"}, {["x"] = 8, ["meta"] = {["fields"] = {}, ["inventory"] = {}}, ["y"] = 0, ["param1"] = 1, ["z"] = 5, ["name"] = "default:stone"}, {["x"] = 8, ["meta"] = {["fields"] = {}, ["inventory"] = {}}, ["y"] = 0, ["param1"] = 1, ["z"] = 6, ["name"] = "default:stone"}, {["x"] = 8, ["meta"] = {["fields"] = {}, ["inventory"] = {}}, ["y"] = 0, ["param1"] = 1, ["z"] = 7, ["name"] = "default:stone"}, {["x"] = 8, ["meta"] = {["fields"] = {}, ["inventory"] = {}}, ["y"] = 0, ["param1"] = 1, ["z"] = 8, ["name"] = "default:stone"}, {["x"] = 8, ["meta"] = {["fields"] = {}, ["inventory"] = {}}, ["y"] = 1, ["param1"] = 1, ["z"] = 0, ["name"] = "default:stone"}, {["x"] = 8, ["meta"] = {["fields"] = {}, ["inventory"] = {}}, ["y"] = 1, ["param1"] = 1, ["z"] = 1, ["name"] = "default:stone"}, {["x"] = 8, ["meta"] = {["fields"] = {}, ["inventory"] = {}}, ["y"] = 1, ["param1"] = 1, ["z"] = 2, ["name"] = "default:stone"}, {["x"] = 8, ["meta"] = {["fields"] = {}, ["inventory"] = {}}, ["y"] = 1, ["param1"] = 1, ["z"] = 3, ["name"] = "default:stone"}, {["x"] = 8, ["meta"] = {["fields"] = {}, ["inventory"] = {}}, ["y"] = 1, ["param1"] = 1, ["z"] = 4, ["name"] = "default:stone"}, {["x"] = 8, ["meta"] = {["fields"] = {}, ["inventory"] = {}}, ["y"] = 1, ["param1"] = 1, ["z"] = 5, ["name"] = "default:stone"}, {["x"] = 8, ["meta"] = {["fields"] = {}, ["inventory"] = {}}, ["y"] = 1, ["param1"] = 1, ["z"] = 6, ["name"] = "default:stone"}, {["x"] = 8, ["meta"] = {["fields"] = {}, ["inventory"] = {}}, ["y"] = 1, ["param1"] = 1, ["z"] = 7, ["name"] = "default:stone"}, {["x"] = 8, ["meta"] = {["fields"] = {}, ["inventory"] = {}}, ["y"] = 1, ["param1"] = 1, ["z"] = 8, ["name"] = "default:stone"}, {["x"] = 8, ["meta"] = {["fields"] = {}, ["inventory"] = {}}, ["y"] = 2, ["param1"] = 1, ["z"] = 0, ["name"] = "default:stone"}, {["x"] = 8, ["meta"] = {["fields"] = {}, ["inventory"] = {}}, ["y"] = 2, ["param1"] = 1, ["z"] = 1, ["name"] = "default:stone"}, {["x"] = 8, ["meta"] = {["fields"] = {}, ["inventory"] = {}}, ["y"] = 2, ["param1"] = 1, ["z"] = 2, ["name"] = "default:stone"}, {["x"] = 8, ["meta"] = {["fields"] = {}, ["inventory"] = {}}, ["y"] = 2, ["param1"] = 1, ["z"] = 3, ["name"] = "default:stone"}, {["x"] = 8, ["meta"] = {["fields"] = {}, ["inventory"] = {}}, ["y"] = 2, ["param1"] = 1, ["z"] = 4, ["name"] = "default:stone"}, {["x"] = 8, ["meta"] = {["fields"] = {}, ["inventory"] = {}}, ["y"] = 2, ["param1"] = 1, ["z"] = 5, ["name"] = "default:stone"}, {["x"] = 8, ["meta"] = {["fields"] = {}, ["inventory"] = {}}, ["y"] = 2, ["param1"] = 1, ["z"] = 6, ["name"] = "default:stone"}, {["x"] = 8, ["meta"] = {["fields"] = {}, ["inventory"] = {}}, ["y"] = 2, ["param1"] = 1, ["z"] = 7, ["name"] = "default:stone"}, {["x"] = 8, ["meta"] = {["fields"] = {}, ["inventory"] = {}}, ["y"] = 2, ["param1"] = 1, ["z"] = 8, ["name"] = "default:stone"}, {["x"] = 8, ["meta"] = {["fields"] = {}, ["inventory"] = {}}, ["y"] = 3, ["param1"] = 4, ["z"] = 0, ["name"] = "default:stone_block"}, {["x"] = 8, ["meta"] = {["fields"] = {}, ["inventory"] = {}}, ["param2"] = 1, ["y"] = 3, ["param1"] = 14, ["z"] = 1, ["name"] = "stairs:slab_stonebrick"}, {["x"] = 8, ["meta"] = {["fields"] = {}, ["inventory"] = {}}, ["param2"] = 1, ["y"] = 3, ["param1"] = 14, ["z"] = 2, ["name"] = "stairs:slab_stonebrick"}, {["x"] = 8, ["meta"] = {["fields"] = {}, ["inventory"] = {}}, ["param2"] = 1, ["y"] = 3, ["param1"] = 14, ["z"] = 3, ["name"] = "stairs:slab_stonebrick"}, {["x"] = 8, ["meta"] = {["fields"] = {}, ["inventory"] = {}}, ["param2"] = 1, ["y"] = 3, ["param1"] = 14, ["z"] = 4, ["name"] = "stairs:slab_stonebrick"}, {["x"] = 8, ["meta"] = {["fields"] = {}, ["inventory"] = {}}, ["param2"] = 1, ["y"] = 3, ["param1"] = 14, ["z"] = 5, ["name"] = "stairs:slab_stonebrick"}, {["x"] = 8, ["meta"] = {["fields"] = {}, ["inventory"] = {}}, ["param2"] = 1, ["y"] = 3, ["param1"] = 14, ["z"] = 6, ["name"] = "stairs:slab_stonebrick"}, {["x"] = 8, ["meta"] = {["fields"] = {}, ["inventory"] = {}}, ["param2"] = 1, ["y"] = 3, ["param1"] = 14, ["z"] = 7, ["name"] = "stairs:slab_stonebrick"}, {["x"] = 8, ["meta"] = {["fields"] = {}, ["inventory"] = {}}, ["y"] = 3, ["param1"] = 4, ["z"] = 8, ["name"] = "default:stone_block"}, {["x"] = 8, ["meta"] = {["fields"] = {}, ["inventory"] = {}}, ["param2"] = 1, ["y"] = 4, ["param1"] = 14, ["z"] = 0, ["name"] = "stairs:slab_stone_block"}, {["x"] = 8, ["meta"] = {["fields"] = {}, ["inventory"] = {}}, ["param2"] = 1, ["y"] = 4, ["param1"] = 14, ["z"] = 8, ["name"] = "stairs:slab_stone_block"}, {["x"] = 9, ["meta"] = {["fields"] = {}, ["inventory"] = {}}, ["y"] = 0, ["param1"] = 1, ["z"] = 1, ["name"] = "default:stone"}, {["x"] = 9, ["meta"] = {["fields"] = {}, ["inventory"] = {}}, ["y"] = 0, ["param1"] = 1, ["z"] = 2, ["name"] = "default:stone"}, {["x"] = 9, ["meta"] = {["fields"] = {}, ["inventory"] = {}}, ["y"] = 0, ["param1"] = 1, ["z"] = 3, ["name"] = "default:stone"}, {["x"] = 9, ["meta"] = {["fields"] = {}, ["inventory"] = {}}, ["y"] = 0, ["param1"] = 1, ["z"] = 4, ["name"] = "default:stone"}, {["x"] = 9, ["meta"] = {["fields"] = {}, ["inventory"] = {}}, ["y"] = 0, ["param1"] = 1, ["z"] = 5, ["name"] = "default:stone"}, {["x"] = 9, ["meta"] = {["fields"] = {}, ["inventory"] = {}}, ["y"] = 0, ["param1"] = 1, ["z"] = 6, ["name"] = "default:stone"}, {["x"] = 9, ["meta"] = {["fields"] = {}, ["inventory"] = {}}, ["y"] = 0, ["param1"] = 1, ["z"] = 7, ["name"] = "default:stone"}, {["x"] = 9, ["meta"] = {["fields"] = {}, ["inventory"] = {}}, ["y"] = 1, ["param1"] = 1, ["z"] = 0, ["name"] = "default:stone"}, {["x"] = 9, ["meta"] = {["fields"] = {}, ["inventory"] = {}}, ["y"] = 1, ["param1"] = 1, ["z"] = 1, ["name"] = "default:stone"}, {["x"] = 9, ["meta"] = {["fields"] = {}, ["inventory"] = {}}, ["y"] = 1, ["param1"] = 1, ["z"] = 2, ["name"] = "default:stone"}, {["x"] = 9, ["meta"] = {["fields"] = {}, ["inventory"] = {}}, ["y"] = 1, ["param1"] = 1, ["z"] = 3, ["name"] = "default:stone"}, {["x"] = 9, ["meta"] = {["fields"] = {}, ["inventory"] = {}}, ["y"] = 1, ["param1"] = 1, ["z"] = 4, ["name"] = "default:stone"}, {["x"] = 9, ["meta"] = {["fields"] = {}, ["inventory"] = {}}, ["y"] = 1, ["param1"] = 1, ["z"] = 5, ["name"] = "default:stone"}, {["x"] = 9, ["meta"] = {["fields"] = {}, ["inventory"] = {}}, ["y"] = 1, ["param1"] = 1, ["z"] = 6, ["name"] = "default:stone"}, {["x"] = 9, ["meta"] = {["fields"] = {}, ["inventory"] = {}}, ["y"] = 1, ["param1"] = 1, ["z"] = 7, ["name"] = "default:stone"}, {["x"] = 9, ["meta"] = {["fields"] = {}, ["inventory"] = {}}, ["y"] = 1, ["param1"] = 1, ["z"] = 8, ["name"] = "default:stone"}, {["x"] = 9, ["meta"] = {["fields"] = {}, ["inventory"] = {}}, ["y"] = 2, ["param1"] = 1, ["z"] = 0, ["name"] = "default:stone"}, {["x"] = 9, ["meta"] = {["fields"] = {}, ["inventory"] = {}}, ["y"] = 2, ["param1"] = 1, ["z"] = 1, ["name"] = "default:stone"}, {["x"] = 9, ["meta"] = {["fields"] = {}, ["inventory"] = {}}, ["y"] = 2, ["param1"] = 1, ["z"] = 2, ["name"] = "default:stone"}, {["x"] = 9, ["meta"] = {["fields"] = {}, ["inventory"] = {}}, ["y"] = 2, ["param1"] = 1, ["z"] = 3, ["name"] = "default:stone"}, {["x"] = 9, ["meta"] = {["fields"] = {}, ["inventory"] = {}}, ["y"] = 2, ["param1"] = 1, ["z"] = 4, ["name"] = "default:stone"}, {["x"] = 9, ["meta"] = {["fields"] = {}, ["inventory"] = {}}, ["y"] = 2, ["param1"] = 1, ["z"] = 5, ["name"] = "default:stone"}, {["x"] = 9, ["meta"] = {["fields"] = {}, ["inventory"] = {}}, ["y"] = 2, ["param1"] = 1, ["z"] = 6, ["name"] = "default:stone"}, {["x"] = 9, ["meta"] = {["fields"] = {}, ["inventory"] = {}}, ["y"] = 2, ["param1"] = 1, ["z"] = 7, ["name"] = "default:stone"}, {["x"] = 9, ["meta"] = {["fields"] = {}, ["inventory"] = {}}, ["y"] = 2, ["param1"] = 1, ["z"] = 8, ["name"] = "default:stone"}, {["x"] = 9, ["meta"] = {["fields"] = {}, ["inventory"] = {}}, ["y"] = 3, ["param1"] = 4, ["z"] = 0, ["name"] = "default:stone_block"}, {["x"] = 9, ["meta"] = {["fields"] = {}, ["inventory"] = {}}, ["param2"] = 1, ["y"] = 3, ["param1"] = 14, ["z"] = 1, ["name"] = "stairs:slab_stonebrick"}, {["x"] = 9, ["meta"] = {["fields"] = {}, ["inventory"] = {}}, ["param2"] = 1, ["y"] = 3, ["param1"] = 14, ["z"] = 2, ["name"] = "stairs:slab_stonebrick"}, {["x"] = 9, ["meta"] = {["fields"] = {}, ["inventory"] = {}}, ["param2"] = 1, ["y"] = 3, ["param1"] = 14, ["z"] = 3, ["name"] = "stairs:slab_stonebrick"}, {["x"] = 9, ["meta"] = {["fields"] = {}, ["inventory"] = {}}, ["param2"] = 1, ["y"] = 3, ["param1"] = 14, ["z"] = 4, ["name"] = "stairs:slab_stonebrick"}, {["x"] = 9, ["meta"] = {["fields"] = {}, ["inventory"] = {}}, ["param2"] = 1, ["y"] = 3, ["param1"] = 14, ["z"] = 5, ["name"] = "stairs:slab_stonebrick"}, {["x"] = 9, ["meta"] = {["fields"] = {}, ["inventory"] = {}}, ["param2"] = 1, ["y"] = 3, ["param1"] = 14, ["z"] = 6, ["name"] = "stairs:slab_stonebrick"}, {["x"] = 9, ["meta"] = {["fields"] = {}, ["inventory"] = {}}, ["param2"] = 1, ["y"] = 3, ["param1"] = 14, ["z"] = 7, ["name"] = "stairs:slab_stonebrick"}, {["x"] = 9, ["meta"] = {["fields"] = {}, ["inventory"] = {}}, ["y"] = 3, ["param1"] = 4, ["z"] = 8, ["name"] = "default:stone_block"}, {["x"] = 9, ["meta"] = {["fields"] = {}, ["inventory"] = {}}, ["param2"] = 1, ["y"] = 4, ["param1"] = 14, ["z"] = 0, ["name"] = "stairs:slab_stone_block"}, {["x"] = 9, ["meta"] = {["fields"] = {}, ["inventory"] = {}}, ["param2"] = 1, ["y"] = 4, ["param1"] = 14, ["z"] = 8, ["name"] = "stairs:slab_stone_block"}, {["x"] = 10, ["meta"] = {["fields"] = {}, ["inventory"] = {}}, ["y"] = 0, ["param1"] = 1, ["z"] = 1, ["name"] = "default:stone"}, {["x"] = 10, ["meta"] = {["fields"] = {}, ["inventory"] = {}}, ["y"] = 0, ["param1"] = 1, ["z"] = 2, ["name"] = "default:stone"}, {["x"] = 10, ["meta"] = {["fields"] = {}, ["inventory"] = {}}, ["y"] = 0, ["param1"] = 1, ["z"] = 3, ["name"] = "default:stone"}, {["x"] = 10, ["meta"] = {["fields"] = {}, ["inventory"] = {}}, ["y"] = 0, ["param1"] = 1, ["z"] = 4, ["name"] = "default:stone"}, {["x"] = 10, ["meta"] = {["fields"] = {}, ["inventory"] = {}}, ["y"] = 0, ["param1"] = 1, ["z"] = 5, ["name"] = "default:stone"}, {["x"] = 10, ["meta"] = {["fields"] = {}, ["inventory"] = {}}, ["y"] = 0, ["param1"] = 1, ["z"] = 6, ["name"] = "default:stone"}, {["x"] = 10, ["meta"] = {["fields"] = {}, ["inventory"] = {}}, ["y"] = 0, ["param1"] = 1, ["z"] = 7, ["name"] = "default:stone"}, {["x"] = 10, ["meta"] = {["fields"] = {}, ["inventory"] = {}}, ["param2"] = 20, ["y"] = 1, ["param1"] = 14, ["z"] = 0, ["name"] = "stairs:slab_stone"}, {["x"] = 10, ["meta"] = {["fields"] = {}, ["inventory"] = {}}, ["y"] = 1, ["param1"] = 1, ["z"] = 1, ["name"] = "default:stone"}, {["x"] = 10, ["meta"] = {["fields"] = {}, ["inventory"] = {}}, ["y"] = 1, ["param1"] = 1, ["z"] = 2, ["name"] = "default:stone"}, {["x"] = 10, ["meta"] = {["fields"] = {}, ["inventory"] = {}}, ["y"] = 1, ["param1"] = 1, ["z"] = 3, ["name"] = "default:stone"}, {["x"] = 10, ["meta"] = {["fields"] = {}, ["inventory"] = {}}, ["y"] = 1, ["param1"] = 1, ["z"] = 4, ["name"] = "default:stone"}, {["x"] = 10, ["meta"] = {["fields"] = {}, ["inventory"] = {}}, ["y"] = 1, ["param1"] = 1, ["z"] = 5, ["name"] = "default:stone"}, {["x"] = 10, ["meta"] = {["fields"] = {}, ["inventory"] = {}}, ["y"] = 1, ["param1"] = 1, ["z"] = 6, ["name"] = "default:stone"}, {["x"] = 10, ["meta"] = {["fields"] = {}, ["inventory"] = {}}, ["y"] = 1, ["param1"] = 1, ["z"] = 7, ["name"] = "default:stone"}, {["x"] = 10, ["meta"] = {["fields"] = {}, ["inventory"] = {}}, ["param2"] = 22, ["y"] = 1, ["param1"] = 14, ["z"] = 8, ["name"] = "stairs:slab_stone"}, {["x"] = 10, ["meta"] = {["fields"] = {}, ["inventory"] = {}}, ["y"] = 2, ["param1"] = 1, ["z"] = 0, ["name"] = "default:stone"}, {["x"] = 10, ["meta"] = {["fields"] = {}, ["inventory"] = {}}, ["y"] = 2, ["param1"] = 1, ["z"] = 1, ["name"] = "default:stone"}, {["x"] = 10, ["meta"] = {["fields"] = {}, ["inventory"] = {}}, ["y"] = 2, ["param1"] = 1, ["z"] = 2, ["name"] = "default:stone"}, {["x"] = 10, ["meta"] = {["fields"] = {}, ["inventory"] = {}}, ["y"] = 2, ["param1"] = 1, ["z"] = 3, ["name"] = "default:stone"}, {["x"] = 10, ["meta"] = {["fields"] = {}, ["inventory"] = {}}, ["y"] = 2, ["param1"] = 1, ["z"] = 4, ["name"] = "default:stone"}, {["x"] = 10, ["meta"] = {["fields"] = {}, ["inventory"] = {}}, ["y"] = 2, ["param1"] = 1, ["z"] = 5, ["name"] = "default:stone"}, {["x"] = 10, ["meta"] = {["fields"] = {}, ["inventory"] = {}}, ["y"] = 2, ["param1"] = 1, ["z"] = 6, ["name"] = "default:stone"}, {["x"] = 10, ["meta"] = {["fields"] = {}, ["inventory"] = {}}, ["y"] = 2, ["param1"] = 1, ["z"] = 7, ["name"] = "default:stone"}, {["x"] = 10, ["meta"] = {["fields"] = {}, ["inventory"] = {}}, ["y"] = 2, ["param1"] = 1, ["z"] = 8, ["name"] = "default:stone"}, {["x"] = 10, ["meta"] = {["fields"] = {}, ["inventory"] = {}}, ["y"] = 3, ["param1"] = 1, ["z"] = 0, ["name"] = "default:stone"}, {["x"] = 10, ["meta"] = {["fields"] = {}, ["inventory"] = {}}, ["param2"] = 1, ["y"] = 3, ["param1"] = 3, ["z"] = 1, ["name"] = "default:stonebrick"}, {["x"] = 10, ["meta"] = {["fields"] = {}, ["inventory"] = {}}, ["param2"] = 1, ["y"] = 3, ["param1"] = 3, ["z"] = 2, ["name"] = "default:stonebrick"}, {["x"] = 10, ["meta"] = {["fields"] = {}, ["inventory"] = {}}, ["param2"] = 1, ["y"] = 3, ["param1"] = 3, ["z"] = 3, ["name"] = "default:stonebrick"}, {["x"] = 10, ["meta"] = {["fields"] = {}, ["inventory"] = {}}, ["param2"] = 1, ["y"] = 3, ["param1"] = 3, ["z"] = 4, ["name"] = "default:stonebrick"}, {["x"] = 10, ["meta"] = {["fields"] = {}, ["inventory"] = {}}, ["param2"] = 1, ["y"] = 3, ["param1"] = 3, ["z"] = 5, ["name"] = "default:stonebrick"}, {["x"] = 10, ["meta"] = {["fields"] = {}, ["inventory"] = {}}, ["param2"] = 1, ["y"] = 3, ["param1"] = 3, ["z"] = 6, ["name"] = "default:stonebrick"}, {["x"] = 10, ["meta"] = {["fields"] = {}, ["inventory"] = {}}, ["param2"] = 1, ["y"] = 3, ["param1"] = 3, ["z"] = 7, ["name"] = "default:stonebrick"}, {["x"] = 10, ["meta"] = {["fields"] = {}, ["inventory"] = {}}, ["y"] = 3, ["param1"] = 1, ["z"] = 8, ["name"] = "default:stone"}, {["x"] = 10, ["meta"] = {["fields"] = {}, ["inventory"] = {}}, ["y"] = 4, ["param1"] = 4, ["z"] = 0, ["name"] = "default:stone_block"}, {["x"] = 10, ["meta"] = {["fields"] = {}, ["inventory"] = {}}, ["y"] = 4, ["param1"] = 4, ["z"] = 8, ["name"] = "default:stone_block"}, {["x"] = 11, ["meta"] = {["fields"] = {}, ["inventory"] = {}}, ["y"] = 0, ["param1"] = 1, ["z"] = 2, ["name"] = "default:stone"}, {["x"] = 11, ["meta"] = {["fields"] = {}, ["inventory"] = {}}, ["y"] = 0, ["param1"] = 1, ["z"] = 3, ["name"] = "default:stone"}, {["x"] = 11, ["meta"] = {["fields"] = {}, ["inventory"] = {}}, ["y"] = 0, ["param1"] = 1, ["z"] = 4, ["name"] = "default:stone"}, {["x"] = 11, ["meta"] = {["fields"] = {}, ["inventory"] = {}}, ["y"] = 0, ["param1"] = 1, ["z"] = 5, ["name"] = "default:stone"}, {["x"] = 11, ["meta"] = {["fields"] = {}, ["inventory"] = {}}, ["y"] = 0, ["param1"] = 1, ["z"] = 6, ["name"] = "default:stone"}, {["x"] = 11, ["meta"] = {["fields"] = {}, ["inventory"] = {}}, ["y"] = 1, ["param1"] = 1, ["z"] = 1, ["name"] = "default:stone"}, {["x"] = 11, ["meta"] = {["fields"] = {}, ["inventory"] = {}}, ["y"] = 1, ["param1"] = 1, ["z"] = 2, ["name"] = "default:stone"}, {["x"] = 11, ["meta"] = {["fields"] = {}, ["inventory"] = {}}, ["y"] = 1, ["param1"] = 1, ["z"] = 3, ["name"] = "default:stone"}, {["x"] = 11, ["meta"] = {["fields"] = {}, ["inventory"] = {}}, ["y"] = 1, ["param1"] = 1, ["z"] = 4, ["name"] = "default:stone"}, {["x"] = 11, ["meta"] = {["fields"] = {}, ["inventory"] = {}}, ["y"] = 1, ["param1"] = 1, ["z"] = 5, ["name"] = "default:stone"}, {["x"] = 11, ["meta"] = {["fields"] = {}, ["inventory"] = {}}, ["y"] = 1, ["param1"] = 1, ["z"] = 6, ["name"] = "default:stone"}, {["x"] = 11, ["meta"] = {["fields"] = {}, ["inventory"] = {}}, ["y"] = 1, ["param1"] = 1, ["z"] = 7, ["name"] = "default:stone"}, {["x"] = 11, ["meta"] = {["fields"] = {}, ["inventory"] = {}}, ["y"] = 2, ["param1"] = 1, ["z"] = 0, ["name"] = "default:stone"}, {["x"] = 11, ["meta"] = {["fields"] = {}, ["inventory"] = {}}, ["y"] = 2, ["param1"] = 1, ["z"] = 1, ["name"] = "default:stone"}, {["x"] = 11, ["meta"] = {["fields"] = {}, ["inventory"] = {}}, ["y"] = 2, ["param1"] = 1, ["z"] = 2, ["name"] = "default:stone"}, {["x"] = 11, ["meta"] = {["fields"] = {}, ["inventory"] = {}}, ["y"] = 2, ["param1"] = 1, ["z"] = 3, ["name"] = "default:stone"}, {["x"] = 11, ["meta"] = {["fields"] = {}, ["inventory"] = {}}, ["y"] = 2, ["param1"] = 1, ["z"] = 4, ["name"] = "default:stone"}, {["x"] = 11, ["meta"] = {["fields"] = {}, ["inventory"] = {}}, ["y"] = 2, ["param1"] = 1, ["z"] = 5, ["name"] = "default:stone"}, {["x"] = 11, ["meta"] = {["fields"] = {}, ["inventory"] = {}}, ["y"] = 2, ["param1"] = 1, ["z"] = 6, ["name"] = "default:stone"}, {["x"] = 11, ["meta"] = {["fields"] = {}, ["inventory"] = {}}, ["y"] = 2, ["param1"] = 1, ["z"] = 7, ["name"] = "default:stone"}, {["x"] = 11, ["meta"] = {["fields"] = {}, ["inventory"] = {}}, ["y"] = 2, ["param1"] = 1, ["z"] = 8, ["name"] = "default:stone"}, {["x"] = 11, ["meta"] = {["fields"] = {}, ["inventory"] = {}}, ["y"] = 3, ["param1"] = 1, ["z"] = 0, ["name"] = "default:stone"}, {["x"] = 11, ["meta"] = {["fields"] = {}, ["inventory"] = {}}, ["param2"] = 1, ["y"] = 3, ["param1"] = 3, ["z"] = 1, ["name"] = "default:stonebrick"}, {["x"] = 11, ["meta"] = {["fields"] = {}, ["inventory"] = {}}, ["param2"] = 1, ["y"] = 3, ["param1"] = 3, ["z"] = 2, ["name"] = "default:stonebrick"}, {["x"] = 11, ["meta"] = {["fields"] = {}, ["inventory"] = {}}, ["param2"] = 1, ["y"] = 3, ["param1"] = 3, ["z"] = 3, ["name"] = "default:stonebrick"}, {["x"] = 11, ["meta"] = {["fields"] = {}, ["inventory"] = {}}, ["param2"] = 1, ["y"] = 3, ["param1"] = 3, ["z"] = 4, ["name"] = "default:stonebrick"}, {["x"] = 11, ["meta"] = {["fields"] = {}, ["inventory"] = {}}, ["param2"] = 1, ["y"] = 3, ["param1"] = 3, ["z"] = 5, ["name"] = "default:stonebrick"}, {["x"] = 11, ["meta"] = {["fields"] = {}, ["inventory"] = {}}, ["param2"] = 1, ["y"] = 3, ["param1"] = 3, ["z"] = 6, ["name"] = "default:stonebrick"}, {["x"] = 11, ["meta"] = {["fields"] = {}, ["inventory"] = {}}, ["param2"] = 1, ["y"] = 3, ["param1"] = 3, ["z"] = 7, ["name"] = "default:stonebrick"}, {["x"] = 11, ["meta"] = {["fields"] = {}, ["inventory"] = {}}, ["y"] = 3, ["param1"] = 1, ["z"] = 8, ["name"] = "default:stone"}, {["x"] = 11, ["meta"] = {["fields"] = {}, ["inventory"] = {}}, ["y"] = 4, ["param1"] = 4, ["z"] = 0, ["name"] = "default:stone_block"}, {["x"] = 11, ["meta"] = {["fields"] = {}, ["inventory"] = {}}, ["y"] = 4, ["param1"] = 4, ["z"] = 8, ["name"] = "default:stone_block"}, {["x"] = 12, ["meta"] = {["fields"] = {}, ["inventory"] = {}}, ["param2"] = 21, ["y"] = 0, ["param1"] = 11, ["z"] = 3, ["name"] = "stairs:slab_stone"}, {["x"] = 12, ["meta"] = {["fields"] = {}, ["inventory"] = {}}, ["y"] = 0, ["param1"] = 1, ["z"] = 4, ["name"] = "default:stone"}, {["x"] = 12, ["meta"] = {["fields"] = {}, ["inventory"] = {}}, ["param2"] = 21, ["y"] = 0, ["param1"] = 11, ["z"] = 5, ["name"] = "stairs:slab_stone"}, {["x"] = 12, ["meta"] = {["fields"] = {}, ["inventory"] = {}}, ["param2"] = 20, ["y"] = 1, ["param1"] = 13, ["z"] = 1, ["name"] = "stairs:slab_stone"}, {["x"] = 12, ["meta"] = {["fields"] = {}, ["inventory"] = {}}, ["y"] = 1, ["param1"] = 1, ["z"] = 2, ["name"] = "default:stone"}, {["x"] = 12, ["meta"] = {["fields"] = {}, ["inventory"] = {}}, ["y"] = 1, ["param1"] = 1, ["z"] = 3, ["name"] = "default:stone"}, {["x"] = 12, ["meta"] = {["fields"] = {}, ["inventory"] = {}}, ["y"] = 1, ["param1"] = 1, ["z"] = 4, ["name"] = "default:stone"}, {["x"] = 12, ["meta"] = {["fields"] = {}, ["inventory"] = {}}, ["y"] = 1, ["param1"] = 1, ["z"] = 5, ["name"] = "default:stone"}, {["x"] = 12, ["meta"] = {["fields"] = {}, ["inventory"] = {}}, ["y"] = 1, ["param1"] = 1, ["z"] = 6, ["name"] = "default:stone"}, {["x"] = 12, ["meta"] = {["fields"] = {}, ["inventory"] = {}}, ["param2"] = 22, ["y"] = 1, ["param1"] = 13, ["z"] = 7, ["name"] = "stairs:slab_stone"}, {["x"] = 12, ["meta"] = {["fields"] = {}, ["inventory"] = {}}, ["y"] = 2, ["param1"] = 1, ["z"] = 0, ["name"] = "default:stone"}, {["x"] = 12, ["meta"] = {["fields"] = {}, ["inventory"] = {}}, ["y"] = 2, ["param1"] = 1, ["z"] = 1, ["name"] = "default:stone"}, {["x"] = 12, ["meta"] = {["fields"] = {}, ["inventory"] = {}}, ["y"] = 2, ["param1"] = 1, ["z"] = 2, ["name"] = "default:stone"}, {["x"] = 12, ["meta"] = {["fields"] = {}, ["inventory"] = {}}, ["y"] = 2, ["param1"] = 1, ["z"] = 3, ["name"] = "default:stone"}, {["x"] = 12, ["meta"] = {["fields"] = {}, ["inventory"] = {}}, ["y"] = 2, ["param1"] = 1, ["z"] = 4, ["name"] = "default:stone"}, {["x"] = 12, ["meta"] = {["fields"] = {}, ["inventory"] = {}}, ["y"] = 2, ["param1"] = 1, ["z"] = 5, ["name"] = "default:stone"}, {["x"] = 12, ["meta"] = {["fields"] = {}, ["inventory"] = {}}, ["y"] = 2, ["param1"] = 1, ["z"] = 6, ["name"] = "default:stone"}, {["x"] = 12, ["meta"] = {["fields"] = {}, ["inventory"] = {}}, ["y"] = 2, ["param1"] = 1, ["z"] = 7, ["name"] = "default:stone"}, {["x"] = 12, ["meta"] = {["fields"] = {}, ["inventory"] = {}}, ["y"] = 2, ["param1"] = 1, ["z"] = 8, ["name"] = "default:stone"}, {["x"] = 12, ["meta"] = {["fields"] = {}, ["inventory"] = {}}, ["y"] = 3, ["param1"] = 1, ["z"] = 0, ["name"] = "default:stone"}, {["x"] = 12, ["meta"] = {["fields"] = {}, ["inventory"] = {}}, ["param2"] = 1, ["y"] = 3, ["param1"] = 3, ["z"] = 1, ["name"] = "default:stonebrick"}, {["x"] = 12, ["meta"] = {["fields"] = {}, ["inventory"] = {}}, ["param2"] = 1, ["y"] = 3, ["param1"] = 3, ["z"] = 2, ["name"] = "default:stonebrick"}, {["x"] = 12, ["meta"] = {["fields"] = {}, ["inventory"] = {}}, ["param2"] = 1, ["y"] = 3, ["param1"] = 3, ["z"] = 3, ["name"] = "default:stonebrick"}, {["x"] = 12, ["meta"] = {["fields"] = {}, ["inventory"] = {}}, ["param2"] = 1, ["y"] = 3, ["param1"] = 3, ["z"] = 4, ["name"] = "default:stonebrick"}, {["x"] = 12, ["meta"] = {["fields"] = {}, ["inventory"] = {}}, ["param2"] = 1, ["y"] = 3, ["param1"] = 3, ["z"] = 5, ["name"] = "default:stonebrick"}, {["x"] = 12, ["meta"] = {["fields"] = {}, ["inventory"] = {}}, ["param2"] = 1, ["y"] = 3, ["param1"] = 3, ["z"] = 6, ["name"] = "default:stonebrick"}, {["x"] = 12, ["meta"] = {["fields"] = {}, ["inventory"] = {}}, ["param2"] = 1, ["y"] = 3, ["param1"] = 3, ["z"] = 7, ["name"] = "default:stonebrick"}, {["x"] = 12, ["meta"] = {["fields"] = {}, ["inventory"] = {}}, ["y"] = 3, ["param1"] = 1, ["z"] = 8, ["name"] = "default:stone"}, {["x"] = 12, ["meta"] = {["fields"] = {}, ["inventory"] = {}}, ["y"] = 4, ["param1"] = 4, ["z"] = 0, ["name"] = "default:stone_block"}, {["x"] = 12, ["meta"] = {["fields"] = {}, ["inventory"] = {}}, ["y"] = 4, ["param1"] = 4, ["z"] = 8, ["name"] = "default:stone_block"}, {["x"] = 13, ["meta"] = {["fields"] = {}, ["inventory"] = {}}, ["param2"] = 21, ["y"] = 0, ["param1"] = 10, ["z"] = 4, ["name"] = "stairs:slab_stone"}, {["x"] = 13, ["meta"] = {["fields"] = {}, ["inventory"] = {}}, ["param2"] = 22, ["y"] = 1, ["param1"] = 12, ["z"] = 2, ["name"] = "stairs:slab_stone"}, {["x"] = 13, ["meta"] = {["fields"] = {}, ["inventory"] = {}}, ["y"] = 1, ["param1"] = 1, ["z"] = 3, ["name"] = "default:stone"}, {["x"] = 13, ["meta"] = {["fields"] = {}, ["inventory"] = {}}, ["y"] = 1, ["param1"] = 1, ["z"] = 4, ["name"] = "default:stone"}, {["x"] = 13, ["meta"] = {["fields"] = {}, ["inventory"] = {}}, ["y"] = 1, ["param1"] = 1, ["z"] = 5, ["name"] = "default:stone"}, {["x"] = 13, ["meta"] = {["fields"] = {}, ["inventory"] = {}}, ["param2"] = 20, ["y"] = 1, ["param1"] = 12, ["z"] = 6, ["name"] = "stairs:slab_stone"}, {["x"] = 13, ["meta"] = {["fields"] = {}, ["inventory"] = {}}, ["param2"] = 20, ["y"] = 2, ["param1"] = 14, ["z"] = 0, ["name"] = "stairs:slab_stone"}, {["x"] = 13, ["meta"] = {["fields"] = {}, ["inventory"] = {}}, ["y"] = 2, ["param1"] = 1, ["z"] = 1, ["name"] = "default:stone"}, {["x"] = 13, ["meta"] = {["fields"] = {}, ["inventory"] = {}}, ["y"] = 2, ["param1"] = 1, ["z"] = 2, ["name"] = "default:stone"}, {["x"] = 13, ["meta"] = {["fields"] = {}, ["inventory"] = {}}, ["y"] = 2, ["param1"] = 1, ["z"] = 3, ["name"] = "default:stone"}, {["x"] = 13, ["meta"] = {["fields"] = {}, ["inventory"] = {}}, ["y"] = 2, ["param1"] = 1, ["z"] = 4, ["name"] = "default:stone"}, {["x"] = 13, ["meta"] = {["fields"] = {}, ["inventory"] = {}}, ["y"] = 2, ["param1"] = 1, ["z"] = 5, ["name"] = "default:stone"}, {["x"] = 13, ["meta"] = {["fields"] = {}, ["inventory"] = {}}, ["y"] = 2, ["param1"] = 1, ["z"] = 6, ["name"] = "default:stone"}, {["x"] = 13, ["meta"] = {["fields"] = {}, ["inventory"] = {}}, ["y"] = 2, ["param1"] = 1, ["z"] = 7, ["name"] = "default:stone"}, {["x"] = 13, ["meta"] = {["fields"] = {}, ["inventory"] = {}}, ["param2"] = 21, ["y"] = 2, ["param1"] = 14, ["z"] = 8, ["name"] = "stairs:slab_stone"}, {["x"] = 13, ["meta"] = {["fields"] = {}, ["inventory"] = {}}, ["y"] = 3, ["param1"] = 1, ["z"] = 0, ["name"] = "default:stone"}, {["x"] = 13, ["meta"] = {["fields"] = {}, ["inventory"] = {}}, ["y"] = 3, ["param1"] = 1, ["z"] = 1, ["name"] = "default:stone"}, {["x"] = 13, ["meta"] = {["fields"] = {}, ["inventory"] = {}}, ["y"] = 3, ["param1"] = 1, ["z"] = 2, ["name"] = "default:stone"}, {["x"] = 13, ["meta"] = {["fields"] = {}, ["inventory"] = {}}, ["y"] = 3, ["param1"] = 1, ["z"] = 3, ["name"] = "default:stone"}, {["x"] = 13, ["meta"] = {["fields"] = {}, ["inventory"] = {}}, ["y"] = 3, ["param1"] = 1, ["z"] = 4, ["name"] = "default:stone"}, {["x"] = 13, ["meta"] = {["fields"] = {}, ["inventory"] = {}}, ["y"] = 3, ["param1"] = 1, ["z"] = 5, ["name"] = "default:stone"}, {["x"] = 13, ["meta"] = {["fields"] = {}, ["inventory"] = {}}, ["y"] = 3, ["param1"] = 1, ["z"] = 6, ["name"] = "default:stone"}, {["x"] = 13, ["meta"] = {["fields"] = {}, ["inventory"] = {}}, ["y"] = 3, ["param1"] = 1, ["z"] = 7, ["name"] = "default:stone"}, {["x"] = 13, ["meta"] = {["fields"] = {}, ["inventory"] = {}}, ["y"] = 3, ["param1"] = 1, ["z"] = 8, ["name"] = "default:stone"}, {["x"] = 13, ["meta"] = {["fields"] = {}, ["inventory"] = {}}, ["y"] = 4, ["param1"] = 4, ["z"] = 0, ["name"] = "default:stone_block"}, {["x"] = 13, ["meta"] = {["fields"] = {}, ["inventory"] = {}}, ["param2"] = 1, ["y"] = 4, ["param1"] = 14, ["z"] = 1, ["name"] = "stairs:slab_stonebrick"}, {["x"] = 13, ["meta"] = {["fields"] = {}, ["inventory"] = {}}, ["param2"] = 1, ["y"] = 4, ["param1"] = 14, ["z"] = 2, ["name"] = "stairs:slab_stonebrick"}, {["x"] = 13, ["meta"] = {["fields"] = {}, ["inventory"] = {}}, ["param2"] = 1, ["y"] = 4, ["param1"] = 14, ["z"] = 3, ["name"] = "stairs:slab_stonebrick"}, {["x"] = 13, ["meta"] = {["fields"] = {}, ["inventory"] = {}}, ["param2"] = 1, ["y"] = 4, ["param1"] = 14, ["z"] = 4, ["name"] = "stairs:slab_stonebrick"}, {["x"] = 13, ["meta"] = {["fields"] = {}, ["inventory"] = {}}, ["param2"] = 1, ["y"] = 4, ["param1"] = 14, ["z"] = 5, ["name"] = "stairs:slab_stonebrick"}, {["x"] = 13, ["meta"] = {["fields"] = {}, ["inventory"] = {}}, ["param2"] = 1, ["y"] = 4, ["param1"] = 14, ["z"] = 6, ["name"] = "stairs:slab_stonebrick"}, {["x"] = 13, ["meta"] = {["fields"] = {}, ["inventory"] = {}}, ["param2"] = 1, ["y"] = 4, ["param1"] = 14, ["z"] = 7, ["name"] = "stairs:slab_stonebrick"}, {["x"] = 13, ["meta"] = {["fields"] = {}, ["inventory"] = {}}, ["y"] = 4, ["param1"] = 4, ["z"] = 8, ["name"] = "default:stone_block"}, {["x"] = 13, ["meta"] = {["fields"] = {}, ["inventory"] = {}}, ["param2"] = 1, ["y"] = 5, ["param1"] = 14, ["z"] = 0, ["name"] = "stairs:slab_stone_block"}, {["x"] = 13, ["meta"] = {["fields"] = {}, ["inventory"] = {}}, ["param2"] = 1, ["y"] = 5, ["param1"] = 14, ["z"] = 8, ["name"] = "stairs:slab_stone_block"}, {["x"] = 14, ["meta"] = {["fields"] = {}, ["inventory"] = {}}, ["param2"] = 21, ["y"] = 1, ["param1"] = 11, ["z"] = 3, ["name"] = "stairs:slab_stone"}, {["x"] = 14, ["meta"] = {["fields"] = {}, ["inventory"] = {}}, ["y"] = 1, ["param1"] = 1, ["z"] = 4, ["name"] = "default:stone"}, {["x"] = 14, ["meta"] = {["fields"] = {}, ["inventory"] = {}}, ["param2"] = 21, ["y"] = 1, ["param1"] = 11, ["z"] = 5, ["name"] = "stairs:slab_stone"}, {["x"] = 14, ["meta"] = {["fields"] = {}, ["inventory"] = {}}, ["param2"] = 20, ["y"] = 2, ["param1"] = 14, ["z"] = 0, ["name"] = "stairs:slab_stone"}, {["x"] = 14, ["meta"] = {["fields"] = {}, ["inventory"] = {}}, ["y"] = 2, ["param1"] = 1, ["z"] = 1, ["name"] = "default:stone"}, {["x"] = 14, ["meta"] = {["fields"] = {}, ["inventory"] = {}}, ["y"] = 2, ["param1"] = 1, ["z"] = 2, ["name"] = "default:stone"}, {["x"] = 14, ["meta"] = {["fields"] = {}, ["inventory"] = {}}, ["y"] = 2, ["param1"] = 1, ["z"] = 3, ["name"] = "default:stone"}, {["x"] = 14, ["meta"] = {["fields"] = {}, ["inventory"] = {}}, ["y"] = 2, ["param1"] = 1, ["z"] = 4, ["name"] = "default:stone"}, {["x"] = 14, ["meta"] = {["fields"] = {}, ["inventory"] = {}}, ["y"] = 2, ["param1"] = 1, ["z"] = 5, ["name"] = "default:stone"}, {["x"] = 14, ["meta"] = {["fields"] = {}, ["inventory"] = {}}, ["y"] = 2, ["param1"] = 1, ["z"] = 6, ["name"] = "default:stone"}, {["x"] = 14, ["meta"] = {["fields"] = {}, ["inventory"] = {}}, ["y"] = 2, ["param1"] = 1, ["z"] = 7, ["name"] = "default:stone"}, {["x"] = 14, ["meta"] = {["fields"] = {}, ["inventory"] = {}}, ["param2"] = 21, ["y"] = 2, ["param1"] = 14, ["z"] = 8, ["name"] = "stairs:slab_stone"}, {["x"] = 14, ["meta"] = {["fields"] = {}, ["inventory"] = {}}, ["y"] = 3, ["param1"] = 1, ["z"] = 0, ["name"] = "default:stone"}, {["x"] = 14, ["meta"] = {["fields"] = {}, ["inventory"] = {}}, ["y"] = 3, ["param1"] = 1, ["z"] = 1, ["name"] = "default:stone"}, {["x"] = 14, ["meta"] = {["fields"] = {}, ["inventory"] = {}}, ["y"] = 3, ["param1"] = 1, ["z"] = 2, ["name"] = "default:stone"}, {["x"] = 14, ["meta"] = {["fields"] = {}, ["inventory"] = {}}, ["y"] = 3, ["param1"] = 1, ["z"] = 3, ["name"] = "default:stone"}, {["x"] = 14, ["meta"] = {["fields"] = {}, ["inventory"] = {}}, ["y"] = 3, ["param1"] = 1, ["z"] = 4, ["name"] = "default:stone"}, {["x"] = 14, ["meta"] = {["fields"] = {}, ["inventory"] = {}}, ["y"] = 3, ["param1"] = 1, ["z"] = 5, ["name"] = "default:stone"}, {["x"] = 14, ["meta"] = {["fields"] = {}, ["inventory"] = {}}, ["y"] = 3, ["param1"] = 1, ["z"] = 6, ["name"] = "default:stone"}, {["x"] = 14, ["meta"] = {["fields"] = {}, ["inventory"] = {}}, ["y"] = 3, ["param1"] = 1, ["z"] = 7, ["name"] = "default:stone"}, {["x"] = 14, ["meta"] = {["fields"] = {}, ["inventory"] = {}}, ["y"] = 3, ["param1"] = 1, ["z"] = 8, ["name"] = "default:stone"}, {["x"] = 14, ["meta"] = {["fields"] = {}, ["inventory"] = {}}, ["y"] = 4, ["param1"] = 4, ["z"] = 0, ["name"] = "default:stone_block"}, {["x"] = 14, ["meta"] = {["fields"] = {}, ["inventory"] = {}}, ["param2"] = 1, ["y"] = 4, ["param1"] = 14, ["z"] = 1, ["name"] = "stairs:slab_stonebrick"}, {["x"] = 14, ["meta"] = {["fields"] = {}, ["inventory"] = {}}, ["param2"] = 1, ["y"] = 4, ["param1"] = 14, ["z"] = 2, ["name"] = "stairs:slab_stonebrick"}, {["x"] = 14, ["meta"] = {["fields"] = {}, ["inventory"] = {}}, ["param2"] = 1, ["y"] = 4, ["param1"] = 14, ["z"] = 3, ["name"] = "stairs:slab_stonebrick"}, {["x"] = 14, ["meta"] = {["fields"] = {}, ["inventory"] = {}}, ["param2"] = 1, ["y"] = 4, ["param1"] = 14, ["z"] = 4, ["name"] = "stairs:slab_stonebrick"}, {["x"] = 14, ["meta"] = {["fields"] = {}, ["inventory"] = {}}, ["param2"] = 1, ["y"] = 4, ["param1"] = 14, ["z"] = 5, ["name"] = "stairs:slab_stonebrick"}, {["x"] = 14, ["meta"] = {["fields"] = {}, ["inventory"] = {}}, ["param2"] = 1, ["y"] = 4, ["param1"] = 14, ["z"] = 6, ["name"] = "stairs:slab_stonebrick"}, {["x"] = 14, ["meta"] = {["fields"] = {}, ["inventory"] = {}}, ["param2"] = 1, ["y"] = 4, ["param1"] = 14, ["z"] = 7, ["name"] = "stairs:slab_stonebrick"}, {["x"] = 14, ["meta"] = {["fields"] = {}, ["inventory"] = {}}, ["y"] = 4, ["param1"] = 4, ["z"] = 8, ["name"] = "default:stone_block"}, {["x"] = 14, ["meta"] = {["fields"] = {}, ["inventory"] = {}}, ["param2"] = 1, ["y"] = 5, ["param1"] = 14, ["z"] = 0, ["name"] = "stairs:slab_stone_block"}, {["x"] = 14, ["meta"] = {["fields"] = {}, ["inventory"] = {}}, ["param2"] = 1, ["y"] = 5, ["param1"] = 14, ["z"] = 8, ["name"] = "stairs:slab_stone_block"}, {["x"] = 15, ["meta"] = {["fields"] = {}, ["inventory"] = {}}, ["param2"] = 21, ["y"] = 1, ["param1"] = 11, ["z"] = 3, ["name"] = "stairs:slab_stone"}, {["x"] = 15, ["meta"] = {["fields"] = {}, ["inventory"] = {}}, ["param2"] = 21, ["y"] = 1, ["param1"] = 10, ["z"] = 4, ["name"] = "stairs:slab_stone"}, {["x"] = 15, ["meta"] = {["fields"] = {}, ["inventory"] = {}}, ["param2"] = 21, ["y"] = 1, ["param1"] = 11, ["z"] = 5, ["name"] = "stairs:slab_stone"}, {["x"] = 15, ["meta"] = {["fields"] = {}, ["inventory"] = {}}, ["param2"] = 20, ["y"] = 2, ["param1"] = 13, ["z"] = 1, ["name"] = "stairs:slab_stone"}, {["x"] = 15, ["meta"] = {["fields"] = {}, ["inventory"] = {}}, ["y"] = 2, ["param1"] = 1, ["z"] = 2, ["name"] = "default:stone"}, {["x"] = 15, ["meta"] = {["fields"] = {}, ["inventory"] = {}}, ["y"] = 2, ["param1"] = 1, ["z"] = 3, ["name"] = "default:stone"}, {["x"] = 15, ["meta"] = {["fields"] = {}, ["inventory"] = {}}, ["y"] = 2, ["param1"] = 1, ["z"] = 4, ["name"] = "default:stone"}, {["x"] = 15, ["meta"] = {["fields"] = {}, ["inventory"] = {}}, ["y"] = 2, ["param1"] = 1, ["z"] = 5, ["name"] = "default:stone"}, {["x"] = 15, ["meta"] = {["fields"] = {}, ["inventory"] = {}}, ["y"] = 2, ["param1"] = 1, ["z"] = 6, ["name"] = "default:stone"}, {["x"] = 15, ["meta"] = {["fields"] = {}, ["inventory"] = {}}, ["param2"] = 21, ["y"] = 2, ["param1"] = 13, ["z"] = 7, ["name"] = "stairs:slab_stone"}, {["x"] = 15, ["meta"] = {["fields"] = {}, ["inventory"] = {}}, ["y"] = 3, ["param1"] = 1, ["z"] = 0, ["name"] = "default:stone"}, {["x"] = 15, ["meta"] = {["fields"] = {}, ["inventory"] = {}}, ["y"] = 3, ["param1"] = 1, ["z"] = 1, ["name"] = "default:stone"}, {["x"] = 15, ["meta"] = {["fields"] = {}, ["inventory"] = {}}, ["y"] = 3, ["param1"] = 1, ["z"] = 2, ["name"] = "default:stone"}, {["x"] = 15, ["meta"] = {["fields"] = {}, ["inventory"] = {}}, ["y"] = 3, ["param1"] = 1, ["z"] = 3, ["name"] = "default:stone"}, {["x"] = 15, ["meta"] = {["fields"] = {}, ["inventory"] = {}}, ["y"] = 3, ["param1"] = 1, ["z"] = 4, ["name"] = "default:stone"}, {["x"] = 15, ["meta"] = {["fields"] = {}, ["inventory"] = {}}, ["y"] = 3, ["param1"] = 1, ["z"] = 5, ["name"] = "default:stone"}, {["x"] = 15, ["meta"] = {["fields"] = {}, ["inventory"] = {}}, ["y"] = 3, ["param1"] = 1, ["z"] = 6, ["name"] = "default:stone"}, {["x"] = 15, ["meta"] = {["fields"] = {}, ["inventory"] = {}}, ["y"] = 3, ["param1"] = 1, ["z"] = 7, ["name"] = "default:stone"}, {["x"] = 15, ["meta"] = {["fields"] = {}, ["inventory"] = {}}, ["y"] = 3, ["param1"] = 1, ["z"] = 8, ["name"] = "default:stone"}, {["x"] = 15, ["meta"] = {["fields"] = {}, ["inventory"] = {}}, ["y"] = 4, ["param1"] = 4, ["z"] = 0, ["name"] = "default:stone_block"}, {["x"] = 15, ["meta"] = {["fields"] = {}, ["inventory"] = {}}, ["param2"] = 1, ["y"] = 4, ["param1"] = 14, ["z"] = 1, ["name"] = "stairs:slab_stonebrick"}, {["x"] = 15, ["meta"] = {["fields"] = {}, ["inventory"] = {}}, ["param2"] = 1, ["y"] = 4, ["param1"] = 14, ["z"] = 2, ["name"] = "stairs:slab_stonebrick"}, {["x"] = 15, ["meta"] = {["fields"] = {}, ["inventory"] = {}}, ["param2"] = 1, ["y"] = 4, ["param1"] = 14, ["z"] = 3, ["name"] = "stairs:slab_stonebrick"}, {["x"] = 15, ["meta"] = {["fields"] = {}, ["inventory"] = {}}, ["param2"] = 1, ["y"] = 4, ["param1"] = 14, ["z"] = 4, ["name"] = "stairs:slab_stonebrick"}, {["x"] = 15, ["meta"] = {["fields"] = {}, ["inventory"] = {}}, ["param2"] = 1, ["y"] = 4, ["param1"] = 14, ["z"] = 5, ["name"] = "stairs:slab_stonebrick"}, {["x"] = 15, ["meta"] = {["fields"] = {}, ["inventory"] = {}}, ["param2"] = 1, ["y"] = 4, ["param1"] = 14, ["z"] = 6, ["name"] = "stairs:slab_stonebrick"}, {["x"] = 15, ["meta"] = {["fields"] = {}, ["inventory"] = {}}, ["param2"] = 1, ["y"] = 4, ["param1"] = 14, ["z"] = 7, ["name"] = "stairs:slab_stonebrick"}, {["x"] = 15, ["meta"] = {["fields"] = {}, ["inventory"] = {}}, ["y"] = 4, ["param1"] = 4, ["z"] = 8, ["name"] = "default:stone_block"}, {["x"] = 15, ["meta"] = {["fields"] = {}, ["inventory"] = {}}, ["param2"] = 1, ["y"] = 5, ["param1"] = 14, ["z"] = 0, ["name"] = "stairs:slab_stone_block"}, {["x"] = 15, ["meta"] = {["fields"] = {}, ["inventory"] = {}}, ["param2"] = 1, ["y"] = 5, ["param1"] = 14, ["z"] = 8, ["name"] = "stairs:slab_stone_block"}, {["x"] = 16, ["meta"] = {["fields"] = {}, ["inventory"] = {}}, ["param2"] = 21, ["y"] = 1, ["param1"] = 11, ["z"] = 3, ["name"] = "stairs:slab_stone"}, {["x"] = 16, ["meta"] = {["fields"] = {}, ["inventory"] = {}}, ["param2"] = 21, ["y"] = 1, ["param1"] = 10, ["z"] = 4, ["name"] = "stairs:slab_stone"}, {["x"] = 16, ["meta"] = {["fields"] = {}, ["inventory"] = {}}, ["param2"] = 21, ["y"] = 1, ["param1"] = 11, ["z"] = 5, ["name"] = "stairs:slab_stone"}, {["x"] = 16, ["meta"] = {["fields"] = {}, ["inventory"] = {}}, ["param2"] = 20, ["y"] = 2, ["param1"] = 13, ["z"] = 1, ["name"] = "stairs:slab_stone"}, {["x"] = 16, ["meta"] = {["fields"] = {}, ["inventory"] = {}}, ["y"] = 2, ["param1"] = 1, ["z"] = 2, ["name"] = "default:stone"}, {["x"] = 16, ["meta"] = {["fields"] = {}, ["inventory"] = {}}, ["y"] = 2, ["param1"] = 1, ["z"] = 3, ["name"] = "default:stone"}, {["x"] = 16, ["meta"] = {["fields"] = {}, ["inventory"] = {}}, ["y"] = 2, ["param1"] = 1, ["z"] = 4, ["name"] = "default:stone"}, {["x"] = 16, ["meta"] = {["fields"] = {}, ["inventory"] = {}}, ["y"] = 2, ["param1"] = 1, ["z"] = 5, ["name"] = "default:stone"}, {["x"] = 16, ["meta"] = {["fields"] = {}, ["inventory"] = {}}, ["y"] = 2, ["param1"] = 1, ["z"] = 6, ["name"] = "default:stone"}, {["x"] = 16, ["meta"] = {["fields"] = {}, ["inventory"] = {}}, ["param2"] = 21, ["y"] = 2, ["param1"] = 13, ["z"] = 7, ["name"] = "stairs:slab_stone"}, {["x"] = 16, ["meta"] = {["fields"] = {}, ["inventory"] = {}}, ["y"] = 3, ["param1"] = 1, ["z"] = 0, ["name"] = "default:stone"}, {["x"] = 16, ["meta"] = {["fields"] = {}, ["inventory"] = {}}, ["y"] = 3, ["param1"] = 1, ["z"] = 1, ["name"] = "default:stone"}, {["x"] = 16, ["meta"] = {["fields"] = {}, ["inventory"] = {}}, ["y"] = 3, ["param1"] = 1, ["z"] = 2, ["name"] = "default:stone"}, {["x"] = 16, ["meta"] = {["fields"] = {}, ["inventory"] = {}}, ["y"] = 3, ["param1"] = 1, ["z"] = 3, ["name"] = "default:stone"}, {["x"] = 16, ["meta"] = {["fields"] = {}, ["inventory"] = {}}, ["y"] = 3, ["param1"] = 1, ["z"] = 4, ["name"] = "default:stone"}, {["x"] = 16, ["meta"] = {["fields"] = {}, ["inventory"] = {}}, ["y"] = 3, ["param1"] = 1, ["z"] = 5, ["name"] = "default:stone"}, {["x"] = 16, ["meta"] = {["fields"] = {}, ["inventory"] = {}}, ["y"] = 3, ["param1"] = 1, ["z"] = 6, ["name"] = "default:stone"}, {["x"] = 16, ["meta"] = {["fields"] = {}, ["inventory"] = {}}, ["y"] = 3, ["param1"] = 1, ["z"] = 7, ["name"] = "default:stone"}, {["x"] = 16, ["meta"] = {["fields"] = {}, ["inventory"] = {}}, ["y"] = 3, ["param1"] = 1, ["z"] = 8, ["name"] = "default:stone"}, {["x"] = 16, ["meta"] = {["fields"] = {}, ["inventory"] = {}}, ["y"] = 4, ["param1"] = 1, ["z"] = 0, ["name"] = "default:stone"}, {["x"] = 16, ["meta"] = {["fields"] = {}, ["inventory"] = {}}, ["param2"] = 1, ["y"] = 4, ["param1"] = 3, ["z"] = 1, ["name"] = "default:stonebrick"}, {["x"] = 16, ["meta"] = {["fields"] = {}, ["inventory"] = {}}, ["param2"] = 1, ["y"] = 4, ["param1"] = 3, ["z"] = 2, ["name"] = "default:stonebrick"}, {["x"] = 16, ["meta"] = {["fields"] = {}, ["inventory"] = {}}, ["param2"] = 1, ["y"] = 4, ["param1"] = 3, ["z"] = 3, ["name"] = "default:stonebrick"}, {["x"] = 16, ["meta"] = {["fields"] = {}, ["inventory"] = {}}, ["param2"] = 1, ["y"] = 4, ["param1"] = 3, ["z"] = 4, ["name"] = "default:stonebrick"}, {["x"] = 16, ["meta"] = {["fields"] = {}, ["inventory"] = {}}, ["param2"] = 1, ["y"] = 4, ["param1"] = 3, ["z"] = 5, ["name"] = "default:stonebrick"}, {["x"] = 16, ["meta"] = {["fields"] = {}, ["inventory"] = {}}, ["param2"] = 1, ["y"] = 4, ["param1"] = 3, ["z"] = 6, ["name"] = "default:stonebrick"}, {["x"] = 16, ["meta"] = {["fields"] = {}, ["inventory"] = {}}, ["param2"] = 1, ["y"] = 4, ["param1"] = 3, ["z"] = 7, ["name"] = "default:stonebrick"}, {["x"] = 16, ["meta"] = {["fields"] = {}, ["inventory"] = {}}, ["y"] = 4, ["param1"] = 1, ["z"] = 8, ["name"] = "default:stone"}, {["x"] = 16, ["meta"] = {["fields"] = {}, ["inventory"] = {}}, ["y"] = 5, ["param1"] = 4, ["z"] = 0, ["name"] = "default:stone_block"}, {["x"] = 16, ["meta"] = {["fields"] = {}, ["inventory"] = {}}, ["y"] = 5, ["param1"] = 4, ["z"] = 8, ["name"] = "default:stone_block"}, {["x"] = 17, ["meta"] = {["fields"] = {}, ["inventory"] = {}}, ["param2"] = 21, ["y"] = 1, ["param1"] = 10, ["z"] = 4, ["name"] = "stairs:slab_stone"}, {["x"] = 17, ["meta"] = {["fields"] = {}, ["inventory"] = {}}, ["param2"] = 22, ["y"] = 2, ["param1"] = 12, ["z"] = 2, ["name"] = "stairs:slab_stone"}, {["x"] = 17, ["meta"] = {["fields"] = {}, ["inventory"] = {}}, ["y"] = 2, ["param1"] = 1, ["z"] = 3, ["name"] = "default:stone"}, {["x"] = 17, ["meta"] = {["fields"] = {}, ["inventory"] = {}}, ["y"] = 2, ["param1"] = 1, ["z"] = 4, ["name"] = "default:stone"}, {["x"] = 17, ["meta"] = {["fields"] = {}, ["inventory"] = {}}, ["y"] = 2, ["param1"] = 1, ["z"] = 5, ["name"] = "default:stone"}, {["x"] = 17, ["meta"] = {["fields"] = {}, ["inventory"] = {}}, ["param2"] = 22, ["y"] = 2, ["param1"] = 12, ["z"] = 6, ["name"] = "stairs:slab_stone"}, {["x"] = 17, ["meta"] = {["fields"] = {}, ["inventory"] = {}}, ["y"] = 3, ["param1"] = 1, ["z"] = 0, ["name"] = "default:stone"}, {["x"] = 17, ["meta"] = {["fields"] = {}, ["inventory"] = {}}, ["y"] = 3, ["param1"] = 1, ["z"] = 1, ["name"] = "default:stone"}, {["x"] = 17, ["meta"] = {["fields"] = {}, ["inventory"] = {}}, ["y"] = 3, ["param1"] = 1, ["z"] = 2, ["name"] = "default:stone"}, {["x"] = 17, ["meta"] = {["fields"] = {}, ["inventory"] = {}}, ["y"] = 3, ["param1"] = 1, ["z"] = 3, ["name"] = "default:stone"}, {["x"] = 17, ["meta"] = {["fields"] = {}, ["inventory"] = {}}, ["y"] = 3, ["param1"] = 1, ["z"] = 4, ["name"] = "default:stone"}, {["x"] = 17, ["meta"] = {["fields"] = {}, ["inventory"] = {}}, ["y"] = 3, ["param1"] = 1, ["z"] = 5, ["name"] = "default:stone"}, {["x"] = 17, ["meta"] = {["fields"] = {}, ["inventory"] = {}}, ["y"] = 3, ["param1"] = 1, ["z"] = 6, ["name"] = "default:stone"}, {["x"] = 17, ["meta"] = {["fields"] = {}, ["inventory"] = {}}, ["y"] = 3, ["param1"] = 1, ["z"] = 7, ["name"] = "default:stone"}, {["x"] = 17, ["meta"] = {["fields"] = {}, ["inventory"] = {}}, ["y"] = 3, ["param1"] = 1, ["z"] = 8, ["name"] = "default:stone"}, {["x"] = 17, ["meta"] = {["fields"] = {}, ["inventory"] = {}}, ["y"] = 4, ["param1"] = 1, ["z"] = 0, ["name"] = "default:stone"}, {["x"] = 17, ["meta"] = {["fields"] = {}, ["inventory"] = {}}, ["param2"] = 1, ["y"] = 4, ["param1"] = 3, ["z"] = 1, ["name"] = "default:stonebrick"}, {["x"] = 17, ["meta"] = {["fields"] = {}, ["inventory"] = {}}, ["param2"] = 1, ["y"] = 4, ["param1"] = 3, ["z"] = 2, ["name"] = "default:stonebrick"}, {["x"] = 17, ["meta"] = {["fields"] = {}, ["inventory"] = {}}, ["param2"] = 1, ["y"] = 4, ["param1"] = 3, ["z"] = 3, ["name"] = "default:stonebrick"}, {["x"] = 17, ["meta"] = {["fields"] = {}, ["inventory"] = {}}, ["param2"] = 1, ["y"] = 4, ["param1"] = 3, ["z"] = 4, ["name"] = "default:stonebrick"}, {["x"] = 17, ["meta"] = {["fields"] = {}, ["inventory"] = {}}, ["param2"] = 1, ["y"] = 4, ["param1"] = 3, ["z"] = 5, ["name"] = "default:stonebrick"}, {["x"] = 17, ["meta"] = {["fields"] = {}, ["inventory"] = {}}, ["param2"] = 1, ["y"] = 4, ["param1"] = 3, ["z"] = 6, ["name"] = "default:stonebrick"}, {["x"] = 17, ["meta"] = {["fields"] = {}, ["inventory"] = {}}, ["param2"] = 1, ["y"] = 4, ["param1"] = 3, ["z"] = 7, ["name"] = "default:stonebrick"}, {["x"] = 17, ["meta"] = {["fields"] = {}, ["inventory"] = {}}, ["y"] = 4, ["param1"] = 1, ["z"] = 8, ["name"] = "default:stone"}, {["x"] = 17, ["meta"] = {["fields"] = {}, ["inventory"] = {}}, ["y"] = 5, ["param1"] = 4, ["z"] = 0, ["name"] = "default:stone_block"}, {["x"] = 17, ["meta"] = {["fields"] = {}, ["inventory"] = {}}, ["y"] = 5, ["param1"] = 4, ["z"] = 8, ["name"] = "default:stone_block"}, {["x"] = 18, ["meta"] = {["fields"] = {}, ["inventory"] = {}}, ["param2"] = 22, ["y"] = 2, ["param1"] = 12, ["z"] = 2, ["name"] = "stairs:slab_stone"}, {["x"] = 18, ["meta"] = {["fields"] = {}, ["inventory"] = {}}, ["y"] = 2, ["param1"] = 1, ["z"] = 3, ["name"] = "default:stone"}, {["x"] = 18, ["meta"] = {["fields"] = {}, ["inventory"] = {}}, ["y"] = 2, ["param1"] = 1, ["z"] = 4, ["name"] = "default:stone"}, {["x"] = 18, ["meta"] = {["fields"] = {}, ["inventory"] = {}}, ["y"] = 2, ["param1"] = 1, ["z"] = 5, ["name"] = "default:stone"}, {["x"] = 18, ["meta"] = {["fields"] = {}, ["inventory"] = {}}, ["param2"] = 22, ["y"] = 2, ["param1"] = 12, ["z"] = 6, ["name"] = "stairs:slab_stone"}, {["x"] = 18, ["meta"] = {["fields"] = {}, ["inventory"] = {}}, ["y"] = 3, ["param1"] = 1, ["z"] = 0, ["name"] = "default:stone"}, {["x"] = 18, ["meta"] = {["fields"] = {}, ["inventory"] = {}}, ["y"] = 3, ["param1"] = 1, ["z"] = 1, ["name"] = "default:stone"}, {["x"] = 18, ["meta"] = {["fields"] = {}, ["inventory"] = {}}, ["y"] = 3, ["param1"] = 1, ["z"] = 2, ["name"] = "default:stone"}, {["x"] = 18, ["meta"] = {["fields"] = {}, ["inventory"] = {}}, ["y"] = 3, ["param1"] = 1, ["z"] = 3, ["name"] = "default:stone"}, {["x"] = 18, ["meta"] = {["fields"] = {}, ["inventory"] = {}}, ["y"] = 3, ["param1"] = 1, ["z"] = 4, ["name"] = "default:stone"}, {["x"] = 18, ["meta"] = {["fields"] = {}, ["inventory"] = {}}, ["y"] = 3, ["param1"] = 1, ["z"] = 5, ["name"] = "default:stone"}, {["x"] = 18, ["meta"] = {["fields"] = {}, ["inventory"] = {}}, ["y"] = 3, ["param1"] = 1, ["z"] = 6, ["name"] = "default:stone"}, {["x"] = 18, ["meta"] = {["fields"] = {}, ["inventory"] = {}}, ["y"] = 3, ["param1"] = 1, ["z"] = 7, ["name"] = "default:stone"}, {["x"] = 18, ["meta"] = {["fields"] = {}, ["inventory"] = {}}, ["y"] = 3, ["param1"] = 1, ["z"] = 8, ["name"] = "default:stone"}, {["x"] = 18, ["meta"] = {["fields"] = {}, ["inventory"] = {}}, ["y"] = 4, ["param1"] = 1, ["z"] = 0, ["name"] = "default:stone"}, {["x"] = 18, ["meta"] = {["fields"] = {}, ["inventory"] = {}}, ["param2"] = 1, ["y"] = 4, ["param1"] = 3, ["z"] = 1, ["name"] = "default:stonebrick"}, {["x"] = 18, ["meta"] = {["fields"] = {}, ["inventory"] = {}}, ["param2"] = 1, ["y"] = 4, ["param1"] = 3, ["z"] = 2, ["name"] = "default:stonebrick"}, {["x"] = 18, ["meta"] = {["fields"] = {}, ["inventory"] = {}}, ["param2"] = 1, ["y"] = 4, ["param1"] = 3, ["z"] = 3, ["name"] = "default:stonebrick"}, {["x"] = 18, ["meta"] = {["fields"] = {}, ["inventory"] = {}}, ["param2"] = 1, ["y"] = 4, ["param1"] = 3, ["z"] = 4, ["name"] = "default:stonebrick"}, {["x"] = 18, ["meta"] = {["fields"] = {}, ["inventory"] = {}}, ["param2"] = 1, ["y"] = 4, ["param1"] = 3, ["z"] = 5, ["name"] = "default:stonebrick"}, {["x"] = 18, ["meta"] = {["fields"] = {}, ["inventory"] = {}}, ["param2"] = 1, ["y"] = 4, ["param1"] = 3, ["z"] = 6, ["name"] = "default:stonebrick"}, {["x"] = 18, ["meta"] = {["fields"] = {}, ["inventory"] = {}}, ["param2"] = 1, ["y"] = 4, ["param1"] = 3, ["z"] = 7, ["name"] = "default:stonebrick"}, {["x"] = 18, ["meta"] = {["fields"] = {}, ["inventory"] = {}}, ["y"] = 4, ["param1"] = 1, ["z"] = 8, ["name"] = "default:stone"}, {["x"] = 18, ["meta"] = {["fields"] = {}, ["inventory"] = {}}, ["y"] = 5, ["param1"] = 4, ["z"] = 0, ["name"] = "default:stone_block"}, {["x"] = 18, ["meta"] = {["fields"] = {}, ["inventory"] = {}}, ["y"] = 5, ["param1"] = 4, ["z"] = 8, ["name"] = "default:stone_block"}, {["x"] = 19, ["meta"] = {["fields"] = {}, ["inventory"] = {}}, ["param2"] = 22, ["y"] = 2, ["param1"] = 12, ["z"] = 2, ["name"] = "stairs:slab_stone"}, {["x"] = 19, ["param2"] = 20, ["y"] = 2, ["param1"] = 11, ["z"] = 3, ["name"] = "stairs:slab_stone"}, {["x"] = 19, ["meta"] = {["fields"] = {}, ["inventory"] = {}}, ["y"] = 2, ["param1"] = 1, ["z"] = 4, ["name"] = "default:stone"}, {["x"] = 19, ["param2"] = 22, ["y"] = 2, ["param1"] = 11, ["z"] = 5, ["name"] = "stairs:slab_stone"}, {["x"] = 19, ["meta"] = {["fields"] = {}, ["inventory"] = {}}, ["param2"] = 22, ["y"] = 2, ["param1"] = 12, ["z"] = 6, ["name"] = "stairs:slab_stone"}, {["x"] = 19, ["meta"] = {["fields"] = {}, ["inventory"] = {}}, ["param2"] = 20, ["y"] = 3, ["param1"] = 14, ["z"] = 0, ["name"] = "stairs:slab_stone"}, {["x"] = 19, ["meta"] = {["fields"] = {}, ["inventory"] = {}}, ["y"] = 3, ["param1"] = 1, ["z"] = 1, ["name"] = "default:stone"}, {["x"] = 19, ["meta"] = {["fields"] = {}, ["inventory"] = {}}, ["y"] = 3, ["param1"] = 1, ["z"] = 2, ["name"] = "default:stone"}, {["x"] = 19, ["meta"] = {["fields"] = {}, ["inventory"] = {}}, ["y"] = 3, ["param1"] = 1, ["z"] = 3, ["name"] = "default:stone"}, {["x"] = 19, ["meta"] = {["fields"] = {}, ["inventory"] = {}}, ["y"] = 3, ["param1"] = 1, ["z"] = 4, ["name"] = "default:stone"}, {["x"] = 19, ["meta"] = {["fields"] = {}, ["inventory"] = {}}, ["y"] = 3, ["param1"] = 1, ["z"] = 5, ["name"] = "default:stone"}, {["x"] = 19, ["meta"] = {["fields"] = {}, ["inventory"] = {}}, ["y"] = 3, ["param1"] = 1, ["z"] = 6, ["name"] = "default:stone"}, {["x"] = 19, ["meta"] = {["fields"] = {}, ["inventory"] = {}}, ["y"] = 3, ["param1"] = 1, ["z"] = 7, ["name"] = "default:stone"}, {["x"] = 19, ["meta"] = {["fields"] = {}, ["inventory"] = {}}, ["param2"] = 21, ["y"] = 3, ["param1"] = 14, ["z"] = 8, ["name"] = "stairs:slab_stone"}, {["x"] = 19, ["meta"] = {["fields"] = {}, ["inventory"] = {}}, ["y"] = 4, ["param1"] = 1, ["z"] = 0, ["name"] = "default:stone"}, {["x"] = 19, ["meta"] = {["fields"] = {}, ["inventory"] = {}}, ["y"] = 4, ["param1"] = 1, ["z"] = 1, ["name"] = "default:stone"}, {["x"] = 19, ["meta"] = {["fields"] = {}, ["inventory"] = {}}, ["y"] = 4, ["param1"] = 1, ["z"] = 2, ["name"] = "default:stone"}, {["x"] = 19, ["meta"] = {["fields"] = {}, ["inventory"] = {}}, ["y"] = 4, ["param1"] = 1, ["z"] = 3, ["name"] = "default:stone"}, {["x"] = 19, ["meta"] = {["fields"] = {}, ["inventory"] = {}}, ["y"] = 4, ["param1"] = 1, ["z"] = 4, ["name"] = "default:stone"}, {["x"] = 19, ["meta"] = {["fields"] = {}, ["inventory"] = {}}, ["y"] = 4, ["param1"] = 1, ["z"] = 5, ["name"] = "default:stone"}, {["x"] = 19, ["meta"] = {["fields"] = {}, ["inventory"] = {}}, ["y"] = 4, ["param1"] = 1, ["z"] = 6, ["name"] = "default:stone"}, {["x"] = 19, ["meta"] = {["fields"] = {}, ["inventory"] = {}}, ["y"] = 4, ["param1"] = 1, ["z"] = 7, ["name"] = "default:stone"}, {["x"] = 19, ["meta"] = {["fields"] = {}, ["inventory"] = {}}, ["y"] = 4, ["param1"] = 1, ["z"] = 8, ["name"] = "default:stone"}, {["x"] = 19, ["meta"] = {["fields"] = {}, ["inventory"] = {}}, ["y"] = 5, ["param1"] = 4, ["z"] = 0, ["name"] = "default:stone_block"}, {["x"] = 19, ["meta"] = {["fields"] = {}, ["inventory"] = {}}, ["param2"] = 1, ["y"] = 5, ["param1"] = 14, ["z"] = 1, ["name"] = "stairs:slab_stonebrick"}, {["x"] = 19, ["meta"] = {["fields"] = {}, ["inventory"] = {}}, ["param2"] = 1, ["y"] = 5, ["param1"] = 14, ["z"] = 2, ["name"] = "stairs:slab_stonebrick"}, {["x"] = 19, ["meta"] = {["fields"] = {}, ["inventory"] = {}}, ["param2"] = 1, ["y"] = 5, ["param1"] = 14, ["z"] = 3, ["name"] = "stairs:slab_stonebrick"}, {["x"] = 19, ["meta"] = {["fields"] = {}, ["inventory"] = {}}, ["param2"] = 1, ["y"] = 5, ["param1"] = 14, ["z"] = 4, ["name"] = "stairs:slab_stonebrick"}, {["x"] = 19, ["meta"] = {["fields"] = {}, ["inventory"] = {}}, ["param2"] = 1, ["y"] = 5, ["param1"] = 14, ["z"] = 5, ["name"] = "stairs:slab_stonebrick"}, {["x"] = 19, ["meta"] = {["fields"] = {}, ["inventory"] = {}}, ["param2"] = 1, ["y"] = 5, ["param1"] = 14, ["z"] = 6, ["name"] = "stairs:slab_stonebrick"}, {["x"] = 19, ["meta"] = {["fields"] = {}, ["inventory"] = {}}, ["param2"] = 1, ["y"] = 5, ["param1"] = 14, ["z"] = 7, ["name"] = "stairs:slab_stonebrick"}, {["x"] = 19, ["meta"] = {["fields"] = {}, ["inventory"] = {}}, ["y"] = 5, ["param1"] = 4, ["z"] = 8, ["name"] = "default:stone_block"}, {["x"] = 19, ["meta"] = {["fields"] = {}, ["inventory"] = {}}, ["y"] = 6, ["param1"] = 14, ["z"] = 0, ["name"] = "stairs:slab_stone_block"}, {["x"] = 19, ["meta"] = {["fields"] = {}, ["inventory"] = {}}, ["y"] = 6, ["param1"] = 14, ["z"] = 8, ["name"] = "stairs:slab_stone_block"}, {["x"] = 20, ["meta"] = {["fields"] = {}, ["inventory"] = {}}, ["param2"] = 21, ["y"] = 2, ["param1"] = 11, ["z"] = 3, ["name"] = "stairs:slab_stone"}, {["x"] = 20, ["meta"] = {["fields"] = {}, ["inventory"] = {}}, ["y"] = 2, ["param1"] = 1, ["z"] = 4, ["name"] = "default:stone"}, {["x"] = 20, ["meta"] = {["fields"] = {}, ["inventory"] = {}}, ["param2"] = 21, ["y"] = 2, ["param1"] = 11, ["z"] = 5, ["name"] = "stairs:slab_stone"}, {["x"] = 20, ["meta"] = {["fields"] = {}, ["inventory"] = {}}, ["param2"] = 20, ["y"] = 3, ["param1"] = 14, ["z"] = 0, ["name"] = "stairs:slab_stone"}, {["x"] = 20, ["meta"] = {["fields"] = {}, ["inventory"] = {}}, ["y"] = 3, ["param1"] = 1, ["z"] = 1, ["name"] = "default:stone"}, {["x"] = 20, ["meta"] = {["fields"] = {}, ["inventory"] = {}}, ["y"] = 3, ["param1"] = 1, ["z"] = 2, ["name"] = "default:stone"}, {["x"] = 20, ["meta"] = {["fields"] = {}, ["inventory"] = {}}, ["y"] = 3, ["param1"] = 1, ["z"] = 3, ["name"] = "default:stone"}, {["x"] = 20, ["meta"] = {["fields"] = {}, ["inventory"] = {}}, ["y"] = 3, ["param1"] = 1, ["z"] = 4, ["name"] = "default:stone"}, {["x"] = 20, ["meta"] = {["fields"] = {}, ["inventory"] = {}}, ["y"] = 3, ["param1"] = 1, ["z"] = 5, ["name"] = "default:stone"}, {["x"] = 20, ["meta"] = {["fields"] = {}, ["inventory"] = {}}, ["y"] = 3, ["param1"] = 1, ["z"] = 6, ["name"] = "default:stone"}, {["x"] = 20, ["meta"] = {["fields"] = {}, ["inventory"] = {}}, ["y"] = 3, ["param1"] = 1, ["z"] = 7, ["name"] = "default:stone"}, {["x"] = 20, ["meta"] = {["fields"] = {}, ["inventory"] = {}}, ["param2"] = 21, ["y"] = 3, ["param1"] = 14, ["z"] = 8, ["name"] = "stairs:slab_stone"}, {["x"] = 20, ["meta"] = {["fields"] = {}, ["inventory"] = {}}, ["y"] = 4, ["param1"] = 1, ["z"] = 0, ["name"] = "default:stone"}, {["x"] = 20, ["meta"] = {["fields"] = {}, ["inventory"] = {}}, ["y"] = 4, ["param1"] = 1, ["z"] = 1, ["name"] = "default:stone"}, {["x"] = 20, ["meta"] = {["fields"] = {}, ["inventory"] = {}}, ["y"] = 4, ["param1"] = 1, ["z"] = 2, ["name"] = "default:stone"}, {["x"] = 20, ["meta"] = {["fields"] = {}, ["inventory"] = {}}, ["y"] = 4, ["param1"] = 1, ["z"] = 3, ["name"] = "default:stone"}, {["x"] = 20, ["meta"] = {["fields"] = {}, ["inventory"] = {}}, ["y"] = 4, ["param1"] = 1, ["z"] = 4, ["name"] = "default:stone"}, {["x"] = 20, ["meta"] = {["fields"] = {}, ["inventory"] = {}}, ["y"] = 4, ["param1"] = 1, ["z"] = 5, ["name"] = "default:stone"}, {["x"] = 20, ["meta"] = {["fields"] = {}, ["inventory"] = {}}, ["y"] = 4, ["param1"] = 1, ["z"] = 6, ["name"] = "default:stone"}, {["x"] = 20, ["meta"] = {["fields"] = {}, ["inventory"] = {}}, ["y"] = 4, ["param1"] = 1, ["z"] = 7, ["name"] = "default:stone"}, {["x"] = 20, ["meta"] = {["fields"] = {}, ["inventory"] = {}}, ["y"] = 4, ["param1"] = 1, ["z"] = 8, ["name"] = "default:stone"}, {["x"] = 20, ["meta"] = {["fields"] = {}, ["inventory"] = {}}, ["y"] = 5, ["param1"] = 4, ["z"] = 0, ["name"] = "default:stone_block"}, {["x"] = 20, ["meta"] = {["fields"] = {}, ["inventory"] = {}}, ["param2"] = 1, ["y"] = 5, ["param1"] = 14, ["z"] = 1, ["name"] = "stairs:slab_stonebrick"}, {["x"] = 20, ["meta"] = {["fields"] = {}, ["inventory"] = {}}, ["param2"] = 1, ["y"] = 5, ["param1"] = 14, ["z"] = 2, ["name"] = "stairs:slab_stonebrick"}, {["x"] = 20, ["meta"] = {["fields"] = {}, ["inventory"] = {}}, ["param2"] = 1, ["y"] = 5, ["param1"] = 14, ["z"] = 3, ["name"] = "stairs:slab_stonebrick"}, {["x"] = 20, ["meta"] = {["fields"] = {}, ["inventory"] = {}}, ["param2"] = 1, ["y"] = 5, ["param1"] = 14, ["z"] = 4, ["name"] = "stairs:slab_stonebrick"}, {["x"] = 20, ["meta"] = {["fields"] = {}, ["inventory"] = {}}, ["param2"] = 1, ["y"] = 5, ["param1"] = 14, ["z"] = 5, ["name"] = "stairs:slab_stonebrick"}, {["x"] = 20, ["meta"] = {["fields"] = {}, ["inventory"] = {}}, ["param2"] = 1, ["y"] = 5, ["param1"] = 14, ["z"] = 6, ["name"] = "stairs:slab_stonebrick"}, {["x"] = 20, ["meta"] = {["fields"] = {}, ["inventory"] = {}}, ["param2"] = 1, ["y"] = 5, ["param1"] = 14, ["z"] = 7, ["name"] = "stairs:slab_stonebrick"}, {["x"] = 20, ["meta"] = {["fields"] = {}, ["inventory"] = {}}, ["y"] = 5, ["param1"] = 4, ["z"] = 8, ["name"] = "default:stone_block"}, {["x"] = 20, ["meta"] = {["fields"] = {}, ["inventory"] = {}}, ["y"] = 6, ["param1"] = 14, ["z"] = 0, ["name"] = "stairs:slab_stone_block"}, {["x"] = 20, ["meta"] = {["fields"] = {}, ["inventory"] = {}}, ["y"] = 6, ["param1"] = 14, ["z"] = 8, ["name"] = "stairs:slab_stone_block"}, {["x"] = 21, ["meta"] = {["fields"] = {}, ["inventory"] = {}}, ["param2"] = 21, ["y"] = 2, ["param1"] = 11, ["z"] = 3, ["name"] = "stairs:slab_stone"}, {["x"] = 21, ["y"] = 2, ["z"] = 4, ["name"] = "default:stone"}, {["x"] = 21, ["meta"] = {["fields"] = {}, ["inventory"] = {}}, ["param2"] = 21, ["y"] = 2, ["param1"] = 11, ["z"] = 5, ["name"] = "stairs:slab_stone"}, {["x"] = 21, ["meta"] = {["fields"] = {}, ["inventory"] = {}}, ["param2"] = 21, ["y"] = 3, ["param1"] = 13, ["z"] = 1, ["name"] = "stairs:slab_stone"}, {["x"] = 21, ["meta"] = {["fields"] = {}, ["inventory"] = {}}, ["y"] = 3, ["param1"] = 1, ["z"] = 2, ["name"] = "default:stone"}, {["x"] = 21, ["meta"] = {["fields"] = {}, ["inventory"] = {}}, ["y"] = 3, ["param1"] = 1, ["z"] = 3, ["name"] = "default:stone"}, {["x"] = 21, ["meta"] = {["fields"] = {}, ["inventory"] = {}}, ["y"] = 3, ["param1"] = 1, ["z"] = 4, ["name"] = "default:stone"}, {["x"] = 21, ["meta"] = {["fields"] = {}, ["inventory"] = {}}, ["y"] = 3, ["param1"] = 1, ["z"] = 5, ["name"] = "default:stone"}, {["x"] = 21, ["meta"] = {["fields"] = {}, ["inventory"] = {}}, ["y"] = 3, ["param1"] = 1, ["z"] = 6, ["name"] = "default:stone"}, {["x"] = 21, ["meta"] = {["fields"] = {}, ["inventory"] = {}}, ["param2"] = 22, ["y"] = 3, ["param1"] = 13, ["z"] = 7, ["name"] = "stairs:slab_stone"}, {["x"] = 21, ["meta"] = {["fields"] = {}, ["inventory"] = {}}, ["y"] = 4, ["param1"] = 1, ["z"] = 0, ["name"] = "default:stone"}, {["x"] = 21, ["meta"] = {["fields"] = {}, ["inventory"] = {}}, ["y"] = 4, ["param1"] = 1, ["z"] = 1, ["name"] = "default:stone"}, {["x"] = 21, ["meta"] = {["fields"] = {}, ["inventory"] = {}}, ["y"] = 4, ["param1"] = 1, ["z"] = 2, ["name"] = "default:stone"}, {["x"] = 21, ["meta"] = {["fields"] = {}, ["inventory"] = {}}, ["y"] = 4, ["param1"] = 1, ["z"] = 3, ["name"] = "default:stone"}, {["x"] = 21, ["meta"] = {["fields"] = {}, ["inventory"] = {}}, ["y"] = 4, ["param1"] = 1, ["z"] = 4, ["name"] = "default:stone"}, {["x"] = 21, ["meta"] = {["fields"] = {}, ["inventory"] = {}}, ["y"] = 4, ["param1"] = 1, ["z"] = 5, ["name"] = "default:stone"}, {["x"] = 21, ["meta"] = {["fields"] = {}, ["inventory"] = {}}, ["y"] = 4, ["param1"] = 1, ["z"] = 6, ["name"] = "default:stone"}, {["x"] = 21, ["meta"] = {["fields"] = {}, ["inventory"] = {}}, ["y"] = 4, ["param1"] = 1, ["z"] = 7, ["name"] = "default:stone"}, {["x"] = 21, ["meta"] = {["fields"] = {}, ["inventory"] = {}}, ["y"] = 4, ["param1"] = 1, ["z"] = 8, ["name"] = "default:stone"}, {["x"] = 21, ["meta"] = {["fields"] = {}, ["inventory"] = {}}, ["y"] = 5, ["param1"] = 4, ["z"] = 0, ["name"] = "default:stone_block"}, {["x"] = 21, ["meta"] = {["fields"] = {}, ["inventory"] = {}}, ["param2"] = 1, ["y"] = 5, ["param1"] = 14, ["z"] = 1, ["name"] = "stairs:slab_stonebrick"}, {["x"] = 21, ["meta"] = {["fields"] = {}, ["inventory"] = {}}, ["param2"] = 1, ["y"] = 5, ["param1"] = 14, ["z"] = 2, ["name"] = "stairs:slab_stonebrick"}, {["x"] = 21, ["meta"] = {["fields"] = {}, ["inventory"] = {}}, ["param2"] = 1, ["y"] = 5, ["param1"] = 14, ["z"] = 3, ["name"] = "stairs:slab_stonebrick"}, {["x"] = 21, ["meta"] = {["fields"] = {}, ["inventory"] = {}}, ["param2"] = 1, ["y"] = 5, ["param1"] = 14, ["z"] = 4, ["name"] = "stairs:slab_stonebrick"}, {["x"] = 21, ["meta"] = {["fields"] = {}, ["inventory"] = {}}, ["param2"] = 1, ["y"] = 5, ["param1"] = 14, ["z"] = 5, ["name"] = "stairs:slab_stonebrick"}, {["x"] = 21, ["meta"] = {["fields"] = {}, ["inventory"] = {}}, ["param2"] = 1, ["y"] = 5, ["param1"] = 14, ["z"] = 6, ["name"] = "stairs:slab_stonebrick"}, {["x"] = 21, ["meta"] = {["fields"] = {}, ["inventory"] = {}}, ["param2"] = 1, ["y"] = 5, ["param1"] = 14, ["z"] = 7, ["name"] = "stairs:slab_stonebrick"}, {["x"] = 21, ["meta"] = {["fields"] = {}, ["inventory"] = {}}, ["y"] = 5, ["param1"] = 4, ["z"] = 8, ["name"] = "default:stone_block"}, {["x"] = 21, ["meta"] = {["fields"] = {}, ["inventory"] = {}}, ["y"] = 6, ["param1"] = 14, ["z"] = 0, ["name"] = "stairs:slab_stone_block"}, {["x"] = 21, ["meta"] = {["fields"] = {}, ["inventory"] = {}}, ["y"] = 6, ["param1"] = 14, ["z"] = 8, ["name"] = "stairs:slab_stone_block"}, {["x"] = 22, ["param2"] = 23, ["y"] = 2, ["param1"] = 11, ["z"] = 3, ["name"] = "stairs:slab_stone"}, {["x"] = 22, ["y"] = 2, ["z"] = 4, ["name"] = "default:stone"}, {["x"] = 22, ["param2"] = 23, ["y"] = 2, ["param1"] = 11, ["z"] = 5, ["name"] = "stairs:slab_stone"}, {["x"] = 22, ["param2"] = 20, ["y"] = 3, ["param1"] = 13, ["z"] = 1, ["name"] = "stairs:slab_stone"}, {["x"] = 22, ["y"] = 3, ["param1"] = 1, ["z"] = 2, ["name"] = "default:stone"}, {["x"] = 22, ["y"] = 3, ["param1"] = 1, ["z"] = 3, ["name"] = "default:stone"}, {["x"] = 22, ["y"] = 3, ["param1"] = 1, ["z"] = 4, ["name"] = "default:stone"}, {["x"] = 22, ["y"] = 3, ["param1"] = 1, ["z"] = 5, ["name"] = "default:stone"}, {["x"] = 22, ["y"] = 3, ["param1"] = 1, ["z"] = 6, ["name"] = "default:stone"}, {["x"] = 22, ["param2"] = 22, ["y"] = 3, ["param1"] = 13, ["z"] = 7, ["name"] = "stairs:slab_stone"}, {["x"] = 22, ["y"] = 4, ["param1"] = 1, ["z"] = 0, ["name"] = "default:stone"}, {["x"] = 22, ["y"] = 4, ["param1"] = 1, ["z"] = 1, ["name"] = "default:stone"}, {["x"] = 22, ["y"] = 4, ["param1"] = 1, ["z"] = 2, ["name"] = "default:stone"}, {["x"] = 22, ["y"] = 4, ["param1"] = 1, ["z"] = 3, ["name"] = "default:stone"}, {["x"] = 22, ["y"] = 4, ["param1"] = 1, ["z"] = 4, ["name"] = "default:stone"}, {["x"] = 22, ["y"] = 4, ["param1"] = 1, ["z"] = 5, ["name"] = "default:stone"}, {["x"] = 22, ["y"] = 4, ["param1"] = 1, ["z"] = 6, ["name"] = "default:stone"}, {["x"] = 22, ["y"] = 4, ["param1"] = 1, ["z"] = 7, ["name"] = "default:stone"}, {["x"] = 22, ["y"] = 4, ["param1"] = 1, ["z"] = 8, ["name"] = "default:stone"}, {["x"] = 22, ["y"] = 5, ["param1"] = 4, ["z"] = 0, ["name"] = "default:stone_block"}, {["x"] = 22, ["param2"] = 1, ["y"] = 5, ["param1"] = 14, ["z"] = 1, ["name"] = "stairs:slab_stonebrick"}, {["x"] = 22, ["param2"] = 1, ["y"] = 5, ["param1"] = 14, ["z"] = 2, ["name"] = "stairs:slab_stonebrick"}, {["x"] = 22, ["param2"] = 1, ["y"] = 5, ["param1"] = 14, ["z"] = 3, ["name"] = "stairs:slab_stonebrick"}, {["x"] = 22, ["param2"] = 1, ["y"] = 5, ["param1"] = 14, ["z"] = 4, ["name"] = "stairs:slab_stonebrick"}, {["x"] = 22, ["param2"] = 1, ["y"] = 5, ["param1"] = 14, ["z"] = 5, ["name"] = "stairs:slab_stonebrick"}, {["x"] = 22, ["param2"] = 1, ["y"] = 5, ["param1"] = 14, ["z"] = 6, ["name"] = "stairs:slab_stonebrick"}, {["x"] = 22, ["param2"] = 1, ["y"] = 5, ["param1"] = 14, ["z"] = 7, ["name"] = "stairs:slab_stonebrick"}, {["x"] = 22, ["y"] = 5, ["param1"] = 4, ["z"] = 8, ["name"] = "default:stone_block"}, {["x"] = 22, ["param2"] = 2, ["y"] = 6, ["param1"] = 14, ["z"] = 0, ["name"] = "stairs:slab_stone_block"}, {["x"] = 22, ["y"] = 6, ["param1"] = 14, ["z"] = 8, ["name"] = "stairs:slab_stone_block"}, {["x"] = 23, ["param2"] = 23, ["y"] = 2, ["param1"] = 11, ["z"] = 3, ["name"] = "stairs:slab_stone"}, {["x"] = 23, ["y"] = 2, ["z"] = 4, ["name"] = "default:stone"}, {["x"] = 23, ["param2"] = 23, ["y"] = 2, ["param1"] = 11, ["z"] = 5, ["name"] = "stairs:slab_stone"}, {["x"] = 23, ["param2"] = 20, ["y"] = 3, ["param1"] = 13, ["z"] = 1, ["name"] = "stairs:slab_stone"}, {["x"] = 23, ["y"] = 3, ["param1"] = 1, ["z"] = 2, ["name"] = "default:stone"}, {["x"] = 23, ["y"] = 3, ["param1"] = 1, ["z"] = 3, ["name"] = "default:stone"}, {["x"] = 23, ["y"] = 3, ["param1"] = 1, ["z"] = 4, ["name"] = "default:stone"}, {["x"] = 23, ["y"] = 3, ["param1"] = 1, ["z"] = 5, ["name"] = "default:stone"}, {["x"] = 23, ["y"] = 3, ["param1"] = 1, ["z"] = 6, ["name"] = "default:stone"}, {["x"] = 23, ["param2"] = 22, ["y"] = 3, ["param1"] = 13, ["z"] = 7, ["name"] = "stairs:slab_stone"}, {["x"] = 23, ["y"] = 4, ["param1"] = 1, ["z"] = 0, ["name"] = "default:stone"}, {["x"] = 23, ["y"] = 4, ["param1"] = 1, ["z"] = 1, ["name"] = "default:stone"}, {["x"] = 23, ["y"] = 4, ["param1"] = 1, ["z"] = 2, ["name"] = "default:stone"}, {["x"] = 23, ["y"] = 4, ["param1"] = 1, ["z"] = 3, ["name"] = "default:stone"}, {["x"] = 23, ["y"] = 4, ["param1"] = 1, ["z"] = 4, ["name"] = "default:stone"}, {["x"] = 23, ["y"] = 4, ["param1"] = 1, ["z"] = 5, ["name"] = "default:stone"}, {["x"] = 23, ["y"] = 4, ["param1"] = 1, ["z"] = 6, ["name"] = "default:stone"}, {["x"] = 23, ["y"] = 4, ["param1"] = 1, ["z"] = 7, ["name"] = "default:stone"}, {["x"] = 23, ["y"] = 4, ["param1"] = 1, ["z"] = 8, ["name"] = "default:stone"}, {["x"] = 23, ["y"] = 5, ["param1"] = 4, ["z"] = 0, ["name"] = "default:stone_block"}, {["x"] = 23, ["param2"] = 1, ["y"] = 5, ["param1"] = 14, ["z"] = 1, ["name"] = "stairs:slab_stonebrick"}, {["x"] = 23, ["param2"] = 1, ["y"] = 5, ["param1"] = 14, ["z"] = 2, ["name"] = "stairs:slab_stonebrick"}, {["x"] = 23, ["param2"] = 1, ["y"] = 5, ["param1"] = 14, ["z"] = 3, ["name"] = "stairs:slab_stonebrick"}, {["x"] = 23, ["param2"] = 1, ["y"] = 5, ["param1"] = 14, ["z"] = 4, ["name"] = "stairs:slab_stonebrick"}, {["x"] = 23, ["param2"] = 1, ["y"] = 5, ["param1"] = 14, ["z"] = 5, ["name"] = "stairs:slab_stonebrick"}, {["x"] = 23, ["param2"] = 1, ["y"] = 5, ["param1"] = 14, ["z"] = 6, ["name"] = "stairs:slab_stonebrick"}, {["x"] = 23, ["param2"] = 1, ["y"] = 5, ["param1"] = 14, ["z"] = 7, ["name"] = "stairs:slab_stonebrick"}, {["x"] = 23, ["y"] = 5, ["param1"] = 4, ["z"] = 8, ["name"] = "default:stone_block"}, {["x"] = 23, ["param2"] = 2, ["y"] = 6, ["param1"] = 14, ["z"] = 0, ["name"] = "stairs:slab_stone_block"}, {["x"] = 23, ["param2"] = 2, ["y"] = 6, ["param1"] = 14, ["z"] = 8, ["name"] = "stairs:slab_stone_block"}, {["x"] = 24, ["param2"] = 23, ["y"] = 2, ["param1"] = 11, ["z"] = 3, ["name"] = "stairs:slab_stone"}, {["x"] = 24, ["y"] = 2, ["param1"] = 1, ["z"] = 4, ["name"] = "default:stone"}, {["x"] = 24, ["param2"] = 23, ["y"] = 2, ["param1"] = 11, ["z"] = 5, ["name"] = "stairs:slab_stone"}, {["x"] = 24, ["param2"] = 20, ["y"] = 3, ["param1"] = 14, ["z"] = 0, ["name"] = "stairs:slab_stone"}, {["x"] = 24, ["y"] = 3, ["param1"] = 1, ["z"] = 1, ["name"] = "default:stone"}, {["x"] = 24, ["y"] = 3, ["param1"] = 1, ["z"] = 2, ["name"] = "default:stone"}, {["x"] = 24, ["y"] = 3, ["param1"] = 1, ["z"] = 3, ["name"] = "default:stone"}, {["x"] = 24, ["y"] = 3, ["param1"] = 1, ["z"] = 4, ["name"] = "default:stone"}, {["x"] = 24, ["y"] = 3, ["param1"] = 1, ["z"] = 5, ["name"] = "default:stone"}, {["x"] = 24, ["y"] = 3, ["param1"] = 1, ["z"] = 6, ["name"] = "default:stone"}, {["x"] = 24, ["y"] = 3, ["param1"] = 1, ["z"] = 7, ["name"] = "default:stone"}, {["x"] = 24, ["param2"] = 22, ["y"] = 3, ["param1"] = 14, ["z"] = 8, ["name"] = "stairs:slab_stone"}, {["x"] = 24, ["y"] = 4, ["param1"] = 1, ["z"] = 0, ["name"] = "default:stone"}, {["x"] = 24, ["y"] = 4, ["param1"] = 1, ["z"] = 1, ["name"] = "default:stone"}, {["x"] = 24, ["y"] = 4, ["param1"] = 1, ["z"] = 2, ["name"] = "default:stone"}, {["x"] = 24, ["y"] = 4, ["param1"] = 1, ["z"] = 3, ["name"] = "default:stone"}, {["x"] = 24, ["y"] = 4, ["param1"] = 1, ["z"] = 4, ["name"] = "default:stone"}, {["x"] = 24, ["y"] = 4, ["param1"] = 1, ["z"] = 5, ["name"] = "default:stone"}, {["x"] = 24, ["y"] = 4, ["param1"] = 1, ["z"] = 6, ["name"] = "default:stone"}, {["x"] = 24, ["y"] = 4, ["param1"] = 1, ["z"] = 7, ["name"] = "default:stone"}, {["x"] = 24, ["y"] = 4, ["param1"] = 1, ["z"] = 8, ["name"] = "default:stone"}, {["x"] = 24, ["y"] = 5, ["param1"] = 4, ["z"] = 0, ["name"] = "default:stone_block"}, {["x"] = 24, ["param2"] = 1, ["y"] = 5, ["param1"] = 14, ["z"] = 1, ["name"] = "stairs:slab_stonebrick"}, {["x"] = 24, ["param2"] = 1, ["y"] = 5, ["param1"] = 14, ["z"] = 2, ["name"] = "stairs:slab_stonebrick"}, {["x"] = 24, ["param2"] = 1, ["y"] = 5, ["param1"] = 14, ["z"] = 3, ["name"] = "stairs:slab_stonebrick"}, {["x"] = 24, ["param2"] = 1, ["y"] = 5, ["param1"] = 14, ["z"] = 4, ["name"] = "stairs:slab_stonebrick"}, {["x"] = 24, ["param2"] = 1, ["y"] = 5, ["param1"] = 14, ["z"] = 5, ["name"] = "stairs:slab_stonebrick"}, {["x"] = 24, ["param2"] = 1, ["y"] = 5, ["param1"] = 14, ["z"] = 6, ["name"] = "stairs:slab_stonebrick"}, {["x"] = 24, ["param2"] = 1, ["y"] = 5, ["param1"] = 14, ["z"] = 7, ["name"] = "stairs:slab_stonebrick"}, {["x"] = 24, ["y"] = 5, ["param1"] = 4, ["z"] = 8, ["name"] = "default:stone_block"}, {["x"] = 24, ["param2"] = 2, ["y"] = 6, ["param1"] = 14, ["z"] = 0, ["name"] = "stairs:slab_stone_block"}, {["x"] = 24, ["param2"] = 2, ["y"] = 6, ["param1"] = 14, ["z"] = 8, ["name"] = "stairs:slab_stone_block"}, {["x"] = 25, ["param2"] = 22, ["y"] = 2, ["param1"] = 12, ["z"] = 2, ["name"] = "stairs:slab_stone"}, {["x"] = 25, ["param2"] = 20, ["y"] = 2, ["param1"] = 11, ["z"] = 3, ["name"] = "stairs:slab_stone"}, {["x"] = 25, ["y"] = 2, ["param1"] = 1, ["z"] = 4, ["name"] = "default:stone"}, {["x"] = 25, ["param2"] = 22, ["y"] = 2, ["param1"] = 11, ["z"] = 5, ["name"] = "stairs:slab_stone"}, {["x"] = 25, ["param2"] = 22, ["y"] = 2, ["param1"] = 12, ["z"] = 6, ["name"] = "stairs:slab_stone"}, {["x"] = 25, ["param2"] = 23, ["y"] = 3, ["param1"] = 14, ["z"] = 0, ["name"] = "stairs:slab_stone"}, {["x"] = 25, ["y"] = 3, ["param1"] = 1, ["z"] = 1, ["name"] = "default:stone"}, {["x"] = 25, ["y"] = 3, ["param1"] = 1, ["z"] = 2, ["name"] = "default:stone"}, {["x"] = 25, ["y"] = 3, ["param1"] = 1, ["z"] = 3, ["name"] = "default:stone"}, {["x"] = 25, ["y"] = 3, ["param1"] = 1, ["z"] = 4, ["name"] = "default:stone"}, {["x"] = 25, ["y"] = 3, ["param1"] = 1, ["z"] = 5, ["name"] = "default:stone"}, {["x"] = 25, ["y"] = 3, ["param1"] = 1, ["z"] = 6, ["name"] = "default:stone"}, {["x"] = 25, ["y"] = 3, ["param1"] = 1, ["z"] = 7, ["name"] = "default:stone"}, {["x"] = 25, ["param2"] = 22, ["y"] = 3, ["param1"] = 14, ["z"] = 8, ["name"] = "stairs:slab_stone"}, {["x"] = 25, ["y"] = 4, ["param1"] = 1, ["z"] = 0, ["name"] = "default:stone"}, {["x"] = 25, ["y"] = 4, ["param1"] = 1, ["z"] = 1, ["name"] = "default:stone"}, {["x"] = 25, ["y"] = 4, ["param1"] = 1, ["z"] = 2, ["name"] = "default:stone"}, {["x"] = 25, ["y"] = 4, ["param1"] = 1, ["z"] = 3, ["name"] = "default:stone"}, {["x"] = 25, ["y"] = 4, ["param1"] = 1, ["z"] = 4, ["name"] = "default:stone"}, {["x"] = 25, ["y"] = 4, ["param1"] = 1, ["z"] = 5, ["name"] = "default:stone"}, {["x"] = 25, ["y"] = 4, ["param1"] = 1, ["z"] = 6, ["name"] = "default:stone"}, {["x"] = 25, ["y"] = 4, ["param1"] = 1, ["z"] = 7, ["name"] = "default:stone"}, {["x"] = 25, ["y"] = 4, ["param1"] = 1, ["z"] = 8, ["name"] = "default:stone"}, {["x"] = 25, ["y"] = 5, ["param1"] = 4, ["z"] = 0, ["name"] = "default:stone_block"}, {["x"] = 25, ["param2"] = 1, ["y"] = 5, ["param1"] = 14, ["z"] = 1, ["name"] = "stairs:slab_stonebrick"}, {["x"] = 25, ["param2"] = 1, ["y"] = 5, ["param1"] = 14, ["z"] = 2, ["name"] = "stairs:slab_stonebrick"}, {["x"] = 25, ["param2"] = 1, ["y"] = 5, ["param1"] = 14, ["z"] = 3, ["name"] = "stairs:slab_stonebrick"}, {["x"] = 25, ["param2"] = 1, ["y"] = 5, ["param1"] = 14, ["z"] = 4, ["name"] = "stairs:slab_stonebrick"}, {["x"] = 25, ["param2"] = 1, ["y"] = 5, ["param1"] = 14, ["z"] = 5, ["name"] = "stairs:slab_stonebrick"}, {["x"] = 25, ["param2"] = 1, ["y"] = 5, ["param1"] = 14, ["z"] = 6, ["name"] = "stairs:slab_stonebrick"}, {["x"] = 25, ["param2"] = 1, ["y"] = 5, ["param1"] = 14, ["z"] = 7, ["name"] = "stairs:slab_stonebrick"}, {["x"] = 25, ["y"] = 5, ["param1"] = 4, ["z"] = 8, ["name"] = "default:stone_block"}, {["x"] = 25, ["param2"] = 2, ["y"] = 6, ["param1"] = 14, ["z"] = 0, ["name"] = "stairs:slab_stone_block"}, {["x"] = 25, ["param2"] = 2, ["y"] = 6, ["param1"] = 14, ["z"] = 8, ["name"] = "stairs:slab_stone_block"}, {["x"] = 26, ["param2"] = 22, ["y"] = 2, ["param1"] = 12, ["z"] = 2, ["name"] = "stairs:slab_stone"}, {["x"] = 26, ["y"] = 2, ["param1"] = 1, ["z"] = 3, ["name"] = "default:stone"}, {["x"] = 26, ["y"] = 2, ["param1"] = 1, ["z"] = 4, ["name"] = "default:stone"}, {["x"] = 26, ["y"] = 2, ["param1"] = 1, ["z"] = 5, ["name"] = "default:stone"}, {["x"] = 26, ["param2"] = 22, ["y"] = 2, ["param1"] = 12, ["z"] = 6, ["name"] = "stairs:slab_stone"}, {["x"] = 26, ["y"] = 3, ["param1"] = 1, ["z"] = 0, ["name"] = "default:stone"}, {["x"] = 26, ["y"] = 3, ["param1"] = 1, ["z"] = 1, ["name"] = "default:stone"}, {["x"] = 26, ["y"] = 3, ["param1"] = 1, ["z"] = 2, ["name"] = "default:stone"}, {["x"] = 26, ["y"] = 3, ["param1"] = 1, ["z"] = 3, ["name"] = "default:stone"}, {["x"] = 26, ["y"] = 3, ["param1"] = 1, ["z"] = 4, ["name"] = "default:stone"}, {["x"] = 26, ["y"] = 3, ["param1"] = 1, ["z"] = 5, ["name"] = "default:stone"}, {["x"] = 26, ["y"] = 3, ["param1"] = 1, ["z"] = 6, ["name"] = "default:stone"}, {["x"] = 26, ["y"] = 3, ["param1"] = 1, ["z"] = 7, ["name"] = "default:stone"}, {["x"] = 26, ["y"] = 3, ["param1"] = 1, ["z"] = 8, ["name"] = "default:stone"}, {["x"] = 26, ["y"] = 4, ["param1"] = 1, ["z"] = 0, ["name"] = "default:stone"}, {["x"] = 26, ["param2"] = 1, ["y"] = 4, ["param1"] = 3, ["z"] = 1, ["name"] = "default:stonebrick"}, {["x"] = 26, ["param2"] = 1, ["y"] = 4, ["param1"] = 3, ["z"] = 2, ["name"] = "default:stonebrick"}, {["x"] = 26, ["param2"] = 1, ["y"] = 4, ["param1"] = 3, ["z"] = 3, ["name"] = "default:stonebrick"}, {["x"] = 26, ["param2"] = 1, ["y"] = 4, ["param1"] = 3, ["z"] = 4, ["name"] = "default:stonebrick"}, {["x"] = 26, ["param2"] = 1, ["y"] = 4, ["param1"] = 3, ["z"] = 5, ["name"] = "default:stonebrick"}, {["x"] = 26, ["param2"] = 1, ["y"] = 4, ["param1"] = 3, ["z"] = 6, ["name"] = "default:stonebrick"}, {["x"] = 26, ["param2"] = 1, ["y"] = 4, ["param1"] = 3, ["z"] = 7, ["name"] = "default:stonebrick"}, {["x"] = 26, ["y"] = 4, ["param1"] = 1, ["z"] = 8, ["name"] = "default:stone"}, {["x"] = 26, ["y"] = 5, ["param1"] = 4, ["z"] = 0, ["name"] = "default:stone_block"},