5:return {{["x"] = 0, ["y"] = 0, ["z"] = 0, ["name"] = "default:stone_block"}, {["x"] = 0, ["y"] = 0, ["z"] = 1, ["name"] = "default:stone_block"}, {["x"] = 0, ["param2"] = 1, ["y"] = 0, ["param1"] = 14, ["z"] = 2, ["name"] = "stairs:slab_stonebrick"}, {["x"] = 0, ["param2"] = 1, ["y"] = 0, ["param1"] = 14, ["z"] = 3, ["name"] = "stairs:slab_stonebrick"}, {["x"] = 0, ["param2"] = 1, ["y"] = 0, ["param1"] = 14, ["z"] = 4, ["name"] = "stairs:slab_stonebrick"}, {["x"] = 0, ["param2"] = 1, ["y"] = 0, ["param1"] = 14, ["z"] = 5, ["name"] = "stairs:slab_stonebrick"}, {["x"] = 0, ["param2"] = 1, ["y"] = 0, ["param1"] = 14, ["z"] = 6, ["name"] = "stairs:slab_stonebrick"}, {["x"] = 0, ["param2"] = 1, ["y"] = 0, ["param1"] = 14, ["z"] = 7, ["name"] = "stairs:slab_stonebrick"}, {["x"] = 0, ["param2"] = 1, ["y"] = 0, ["param1"] = 14, ["z"] = 8, ["name"] = "stairs:slab_stonebrick"}, {["x"] = 0, ["y"] = 0, ["z"] = 9, ["name"] = "default:stone_block"}, {["x"] = 0, ["y"] = 0, ["z"] = 10, ["name"] = "default:stone_block"}, {["x"] = 0, ["y"] = 1, ["z"] = 0, ["name"] = "default:stone_block"}, {["x"] = 0, ["y"] = 1, ["z"] = 1, ["name"] = "default:stone_block"}, {["x"] = 0, ["y"] = 1, ["z"] = 9, ["name"] = "default:stone_block"}, {["x"] = 0, ["y"] = 1, ["z"] = 10, ["name"] = "default:stone_block"}, {["x"] = 0, ["y"] = 2, ["z"] = 0, ["name"] = "default:stone_block"}, {["x"] = 0, ["y"] = 2, ["z"] = 1, ["name"] = "default:stone_block"}, {["x"] = 0, ["y"] = 2, ["z"] = 9, ["name"] = "default:stone_block"}, {["x"] = 0, ["y"] = 2, ["z"] = 10, ["name"] = "default:stone_block"}, {["x"] = 1, ["y"] = 0, ["z"] = 0, ["name"] = "default:stone_block"}, {["x"] = 1, ["y"] = 0, ["z"] = 1, ["name"] = "default:stone_block"}, {["x"] = 1, ["param2"] = 1, ["y"] = 0, ["param1"] = 14, ["z"] = 2, ["name"] = "stairs:slab_stonebrick"}, {["x"] = 1, ["param2"] = 1, ["y"] = 0, ["param1"] = 14, ["z"] = 3, ["name"] = "stairs:slab_stonebrick"}, {["x"] = 1, ["param2"] = 1, ["y"] = 0, ["param1"] = 14, ["z"] = 4, ["name"] = "stairs:slab_stonebrick"}, {["x"] = 1, ["param2"] = 1, ["y"] = 0, ["param1"] = 14, ["z"] = 5, ["name"] = "stairs:slab_stonebrick"}, {["x"] = 1, ["param2"] = 1, ["y"] = 0, ["param1"] = 14, ["z"] = 6, ["name"] = "stairs:slab_stonebrick"}, {["x"] = 1, ["param2"] = 1, ["y"] = 0, ["param1"] = 14, ["z"] = 7, ["name"] = "stairs:slab_stonebrick"}, {["x"] = 1, ["param2"] = 1, ["y"] = 0, ["param1"] = 14, ["z"] = 8, ["name"] = "stairs:slab_stonebrick"}, {["x"] = 1, ["y"] = 0, ["z"] = 9, ["name"] = "default:stone_block"}, {["x"] = 1, ["y"] = 0, ["z"] = 10, ["name"] = "default:stone_block"}, {["x"] = 1, ["y"] = 1, ["z"] = 0, ["name"] = "default:stone_block"}, {["x"] = 1, ["y"] = 1, ["z"] = 1, ["name"] = "default:stone_block"}, {["x"] = 1, ["y"] = 1, ["z"] = 9, ["name"] = "default:stone_block"}, {["x"] = 1, ["y"] = 1, ["z"] = 10, ["name"] = "default:stone_block"}, {["x"] = 1, ["y"] = 2, ["z"] = 0, ["name"] = "default:stone_block"}, {["x"] = 1, ["y"] = 2, ["z"] = 1, ["name"] = "default:stone_block"}, {["x"] = 1, ["y"] = 2, ["z"] = 9, ["name"] = "default:stone_block"}, {["x"] = 1, ["y"] = 2, ["z"] = 10, ["name"] = "default:stone_block"}, {["x"] = 2, ["y"] = 0, ["z"] = 1, ["name"] = "default:stone_block"}, {["x"] = 2, ["param2"] = 1, ["y"] = 0, ["z"] = 2, ["name"] = "default:stonebrick"}, {["x"] = 2, ["param2"] = 1, ["y"] = 0, ["z"] = 3, ["name"] = "default:stonebrick"}, {["x"] = 2, ["param2"] = 1, ["y"] = 0, ["z"] = 4, ["name"] = "default:stonebrick"}, {["x"] = 2, ["param2"] = 1, ["y"] = 0, ["z"] = 5, ["name"] = "default:stonebrick"}, {["x"] = 2, ["param2"] = 1, ["y"] = 0, ["z"] = 6, ["name"] = "default:stonebrick"}, {["x"] = 2, ["param2"] = 1, ["y"] = 0, ["z"] = 7, ["name"] = "default:stonebrick"}, {["x"] = 2, ["param2"] = 1, ["y"] = 0, ["z"] = 8, ["name"] = "default:stonebrick"}, {["x"] = 2, ["y"] = 0, ["z"] = 9, ["name"] = "default:stone_block"}, {["x"] = 2, ["y"] = 1, ["z"] = 1, ["name"] = "default:stone_block"}, {["x"] = 2, ["y"] = 1, ["z"] = 9, ["name"] = "default:stone_block"}, {["x"] = 3, ["y"] = 0, ["z"] = 1, ["name"] = "default:stone_block"}, {["x"] = 3, ["param2"] = 1, ["y"] = 0, ["z"] = 2, ["name"] = "default:stonebrick"}, {["x"] = 3, ["param2"] = 1, ["y"] = 0, ["z"] = 3, ["name"] = "default:stonebrick"}, {["x"] = 3, ["param2"] = 1, ["y"] = 0, ["z"] = 4, ["name"] = "default:stonebrick"}, {["x"] = 3, ["param2"] = 1, ["y"] = 0, ["z"] = 5, ["name"] = "default:stonebrick"}, {["x"] = 3, ["param2"] = 1, ["y"] = 0, ["z"] = 6, ["name"] = "default:stonebrick"}, {["x"] = 3, ["param2"] = 1, ["y"] = 0, ["z"] = 7, ["name"] = "default:stonebrick"}, {["x"] = 3, ["param2"] = 1, ["y"] = 0, ["z"] = 8, ["name"] = "default:stonebrick"}, {["x"] = 3, ["y"] = 0, ["z"] = 9, ["name"] = "default:stone_block"}, {["x"] = 3, ["y"] = 1, ["z"] = 1, ["name"] = "default:stone_block"}, {["x"] = 3, ["y"] = 1, ["z"] = 9, ["name"] = "default:stone_block"}, {["x"] = 4, ["y"] = 0, ["z"] = 1, ["name"] = "default:stone_block"}, {["x"] = 4, ["param2"] = 1, ["y"] = 0, ["z"] = 2, ["name"] = "default:stonebrick"}, {["x"] = 4, ["param2"] = 1, ["y"] = 0, ["z"] = 3, ["name"] = "default:stonebrick"}, {["x"] = 4, ["param2"] = 1, ["y"] = 0, ["z"] = 4, ["name"] = "default:stonebrick"}, {["x"] = 4, ["param2"] = 1, ["y"] = 0, ["z"] = 5, ["name"] = "default:stonebrick"}, {["x"] = 4, ["param2"] = 1, ["y"] = 0, ["z"] = 6, ["name"] = "default:stonebrick"}, {["x"] = 4, ["param2"] = 1, ["y"] = 0, ["z"] = 7, ["name"] = "default:stonebrick"}, {["x"] = 4, ["param2"] = 1, ["y"] = 0, ["z"] = 8, ["name"] = "default:stonebrick"}, {["x"] = 4, ["y"] = 0, ["z"] = 9, ["name"] = "default:stone_block"}, {["x"] = 4, ["y"] = 1, ["z"] = 1, ["name"] = "default:stone_block"}, {["x"] = 4, ["param2"] = 1, ["y"] = 1, ["param1"] = 14, ["z"] = 2, ["name"] = "stairs:slab_stonebrick"}, {["x"] = 4, ["param2"] = 1, ["y"] = 1, ["param1"] = 14, ["z"] = 3, ["name"] = "stairs:slab_stonebrick"}, {["x"] = 4, ["param2"] = 1, ["y"] = 1, ["param1"] = 14, ["z"] = 4, ["name"] = "stairs:slab_stonebrick"}, {["x"] = 4, ["param2"] = 1, ["y"] = 1, ["param1"] = 14, ["z"] = 5, ["name"] = "stairs:slab_stonebrick"}, {["x"] = 4, ["param2"] = 1, ["y"] = 1, ["param1"] = 14, ["z"] = 6, ["name"] = "stairs:slab_stonebrick"}, {["x"] = 4, ["param2"] = 1, ["y"] = 1, ["param1"] = 14, ["z"] = 7, ["name"] = "stairs:slab_stonebrick"}, {["x"] = 4, ["param2"] = 1, ["y"] = 1, ["param1"] = 14, ["z"] = 8, ["name"] = "stairs:slab_stonebrick"}, {["x"] = 4, ["y"] = 1, ["z"] = 9, ["name"] = "default:stone_block"}, {["x"] = 4, ["param2"] = 1, ["y"] = 2, ["param1"] = 14, ["z"] = 1, ["name"] = "stairs:slab_stone_block"}, {["x"] = 4, ["y"] = 2, ["param1"] = 14, ["z"] = 9, ["name"] = "stairs:slab_stone_block"}, {["x"] = 5, ["y"] = 0, ["z"] = 1, ["name"] = "default:stone_block"}, {["x"] = 5, ["param2"] = 1, ["y"] = 0, ["z"] = 2, ["name"] = "default:stonebrick"}, {["x"] = 5, ["param2"] = 1, ["y"] = 0, ["z"] = 3, ["name"] = "default:stonebrick"}, {["x"] = 5, ["param2"] = 1, ["y"] = 0, ["z"] = 4, ["name"] = "default:stonebrick"}, {["x"] = 5, ["param2"] = 1, ["y"] = 0, ["z"] = 5, ["name"] = "default:stonebrick"}, {["x"] = 5, ["param2"] = 1, ["y"] = 0, ["z"] = 6, ["name"] = "default:stonebrick"}, {["x"] = 5, ["param2"] = 1, ["y"] = 0, ["z"] = 7, ["name"] = "default:stonebrick"}, {["x"] = 5, ["param2"] = 1, ["y"] = 0, ["z"] = 8, ["name"] = "default:stonebrick"}, {["x"] = 5, ["y"] = 0, ["z"] = 9, ["name"] = "default:stone_block"}, {["x"] = 5, ["y"] = 1, ["z"] = 1, ["name"] = "default:stone_block"}, {["x"] = 5, ["param2"] = 1, ["y"] = 1, ["param1"] = 14, ["z"] = 2, ["name"] = "stairs:slab_stonebrick"}, {["x"] = 5, ["param2"] = 1, ["y"] = 1, ["param1"] = 14, ["z"] = 3, ["name"] = "stairs:slab_stonebrick"}, {["x"] = 5, ["param2"] = 1, ["y"] = 1, ["param1"] = 14, ["z"] = 4, ["name"] = "stairs:slab_stonebrick"}, {["x"] = 5, ["param2"] = 1, ["y"] = 1, ["param1"] = 14, ["z"] = 5, ["name"] = "stairs:slab_stonebrick"}, {["x"] = 5, ["param2"] = 1, ["y"] = 1, ["param1"] = 14, ["z"] = 6, ["name"] = "stairs:slab_stonebrick"}, {["x"] = 5, ["param2"] = 1, ["y"] = 1, ["param1"] = 14, ["z"] = 7, ["name"] = "stairs:slab_stonebrick"}, {["x"] = 5, ["param2"] = 1, ["y"] = 1, ["param1"] = 14, ["z"] = 8, ["name"] = "stairs:slab_stonebrick"}, {["x"] = 5, ["y"] = 1, ["z"] = 9, ["name"] = "default:stone_block"}, {["x"] = 5, ["param2"] = 1, ["y"] = 2, ["param1"] = 14, ["z"] = 1, ["name"] = "stairs:slab_stone_block"}, {["x"] = 5, ["y"] = 2, ["param1"] = 14, ["z"] = 9, ["name"] = "stairs:slab_stone_block"}, {["x"] = 6, ["y"] = 0, ["z"] = 1, ["name"] = "default:stone_block"}, {["x"] = 6, ["param2"] = 1, ["y"] = 0, ["z"] = 2, ["name"] = "default:stonebrick"}, {["x"] = 6, ["param2"] = 1, ["y"] = 0, ["z"] = 3, ["name"] = "default:stonebrick"}, {["x"] = 6, ["param2"] = 1, ["y"] = 0, ["z"] = 4, ["name"] = "default:stonebrick"}, {["x"] = 6, ["param2"] = 1, ["y"] = 0, ["z"] = 5, ["name"] = "default:stonebrick"}, {["x"] = 6, ["param2"] = 1, ["y"] = 0, ["z"] = 6, ["name"] = "default:stonebrick"}, {["x"] = 6, ["param2"] = 1, ["y"] = 0, ["z"] = 7, ["name"] = "default:stonebrick"}, {["x"] = 6, ["param2"] = 1, ["y"] = 0, ["z"] = 8, ["name"] = "default:stonebrick"}, {["x"] = 6, ["y"] = 0, ["z"] = 9, ["name"] = "default:stone_block"}, {["x"] = 6, ["y"] = 1, ["z"] = 1, ["name"] = "default:stone_block"}, {["x"] = 6, ["param2"] = 1, ["y"] = 1, ["z"] = 2, ["name"] = "default:stonebrick"}, {["x"] = 6, ["param2"] = 1, ["y"] = 1, ["z"] = 3, ["name"] = "default:stonebrick"}, {["x"] = 6, ["param2"] = 1, ["y"] = 1, ["z"] = 4, ["name"] = "default:stonebrick"}, {["x"] = 6, ["param2"] = 1, ["y"] = 1, ["z"] = 5, ["name"] = "default:stonebrick"}, {["x"] = 6, ["param2"] = 1, ["y"] = 1, ["z"] = 6, ["name"] = "default:stonebrick"}, {["x"] = 6, ["param2"] = 1, ["y"] = 1, ["z"] = 7, ["name"] = "default:stonebrick"}, {["x"] = 6, ["param2"] = 1, ["y"] = 1, ["z"] = 8, ["name"] = "default:stonebrick"}, {["x"] = 6, ["y"] = 1, ["z"] = 9, ["name"] = "default:stone_block"}, {["x"] = 6, ["y"] = 2, ["z"] = 1, ["name"] = "default:stone_block"}, {["x"] = 6, ["y"] = 2, ["z"] = 9, ["name"] = "default:stone_block"}, {["x"] = 7, ["y"] = 0, ["z"] = 1, ["name"] = "default:stone_block"}, {["x"] = 7, ["param2"] = 1, ["y"] = 0, ["z"] = 2, ["name"] = "default:stonebrick"}, {["x"] = 7, ["param2"] = 1, ["y"] = 0, ["z"] = 3, ["name"] = "default:stonebrick"}, {["x"] = 7, ["param2"] = 1, ["y"] = 0, ["z"] = 4, ["name"] = "default:stonebrick"}, {["x"] = 7, ["param2"] = 1, ["y"] = 0, ["z"] = 5, ["name"] = "default:stonebrick"}, {["x"] = 7, ["param2"] = 1, ["y"] = 0, ["z"] = 6, ["name"] = "default:stonebrick"}, {["x"] = 7, ["param2"] = 1, ["y"] = 0, ["z"] = 7, ["name"] = "default:stonebrick"}, {["x"] = 7, ["param2"] = 1, ["y"] = 0, ["z"] = 8, ["name"] = "default:stonebrick"}, {["x"] = 7, ["y"] = 0, ["z"] = 9, ["name"] = "default:stone_block"}, {["x"] = 7, ["y"] = 1, ["z"] = 1, ["name"] = "default:stone_block"}, {["x"] = 7, ["param2"] = 1, ["y"] = 1, ["z"] = 2, ["name"] = "default:stonebrick"}, {["x"] = 7, ["param2"] = 1, ["y"] = 1, ["z"] = 3, ["name"] = "default:stonebrick"}, {["x"] = 7, ["param2"] = 1, ["y"] = 1, ["z"] = 4, ["name"] = "default:stonebrick"}, {["x"] = 7, ["param2"] = 1, ["y"] = 1, ["z"] = 5, ["name"] = "default:stonebrick"}, {["x"] = 7, ["param2"] = 1, ["y"] = 1, ["z"] = 6, ["name"] = "default:stonebrick"}, {["x"] = 7, ["param2"] = 1, ["y"] = 1, ["z"] = 7, ["name"] = "default:stonebrick"}, {["x"] = 7, ["param2"] = 1, ["y"] = 1, ["z"] = 8, ["name"] = "default:stonebrick"}, {["x"] = 7, ["y"] = 1, ["z"] = 9, ["name"] = "default:stone_block"}, {["x"] = 7, ["y"] = 2, ["z"] = 1, ["name"] = "default:stone_block"}, {["x"] = 7, ["y"] = 2, ["z"] = 9, ["name"] = "default:stone_block"}, {["x"] = 8, ["y"] = 0, ["z"] = 1, ["name"] = "default:stone"}, {["x"] = 8, ["y"] = 0, ["z"] = 2, ["name"] = "default:stone"}, {["x"] = 8, ["y"] = 0, ["z"] = 3, ["name"] = "default:stone"}, {["x"] = 8, ["y"] = 0, ["z"] = 4, ["name"] = "default:stone"}, {["x"] = 8, ["y"] = 0, ["z"] = 5, ["name"] = "default:stone"}, {["x"] = 8, ["y"] = 0, ["z"] = 6, ["name"] = "default:stone"}, {["x"] = 8, ["y"] = 0, ["z"] = 7, ["name"] = "default:stone"}, {["x"] = 8, ["y"] = 0, ["z"] = 8, ["name"] = "default:stone"}, {["x"] = 8, ["y"] = 0, ["z"] = 9, ["name"] = "default:stone"}, {["x"] = 8, ["y"] = 1, ["z"] = 1, ["name"] = "default:stone"}, {["x"] = 8, ["y"] = 1, ["z"] = 2, ["name"] = "default:stone"}, {["x"] = 8, ["y"] = 1, ["z"] = 3, ["name"] = "default:stone"}, {["x"] = 8, ["y"] = 1, ["z"] = 4, ["name"] = "default:stone"}, {["x"] = 8, ["y"] = 1, ["z"] = 5, ["name"] = "default:stone"}, {["x"] = 8, ["y"] = 1, ["z"] = 6, ["name"] = "default:stone"}, {["x"] = 8, ["y"] = 1, ["z"] = 7, ["name"] = "default:stone"}, {["x"] = 8, ["y"] = 1, ["z"] = 8, ["name"] = "default:stone"}, {["x"] = 8, ["y"] = 1, ["z"] = 9, ["name"] = "default:stone"}, {["x"] = 8, ["y"] = 2, ["z"] = 1, ["name"] = "default:stone_block"}, {["x"] = 8, ["param2"] = 1, ["y"] = 2, ["param1"] = 14, ["z"] = 2, ["name"] = "stairs:slab_stonebrick"}, {["x"] = 8, ["param2"] = 1, ["y"] = 2, ["param1"] = 14, ["z"] = 3, ["name"] = "stairs:slab_stonebrick"}, {["x"] = 8, ["param2"] = 1, ["y"] = 2, ["param1"] = 14, ["z"] = 4, ["name"] = "stairs:slab_stonebrick"}, {["x"] = 8, ["param2"] = 1, ["y"] = 2, ["param1"] = 14, ["z"] = 5, ["name"] = "stairs:slab_stonebrick"}, {["x"] = 8, ["param2"] = 1, ["y"] = 2, ["param1"] = 14, ["z"] = 6, ["name"] = "stairs:slab_stonebrick"}, {["x"] = 8, ["param2"] = 1, ["y"] = 2, ["param1"] = 14, ["z"] = 7, ["name"] = "stairs:slab_stonebrick"}, {["x"] = 8, ["param2"] = 1, ["y"] = 2, ["param1"] = 14, ["z"] = 8, ["name"] = "stairs:slab_stonebrick"}, {["x"] = 8, ["y"] = 2, ["z"] = 9, ["name"] = "default:stone_block"}, {["x"] = 8, ["param2"] = 1, ["y"] = 3, ["param1"] = 14, ["z"] = 1, ["name"] = "stairs:slab_stone_block"}, {["x"] = 8, ["param2"] = 1, ["y"] = 3, ["param1"] = 14, ["z"] = 9, ["name"] = "stairs:slab_stone_block"}, {["x"] = 9, ["y"] = 0, ["z"] = 1, ["name"] = "default:stone"}, {["x"] = 9, ["y"] = 0, ["z"] = 2, ["name"] = "default:stone"}, {["x"] = 9, ["y"] = 0, ["z"] = 3, ["name"] = "default:stone"}, {["x"] = 9, ["y"] = 0, ["z"] = 4, ["name"] = "default:stone"}, {["x"] = 9, ["y"] = 0, ["z"] = 5, ["name"] = "default:stone"}, {["x"] = 9, ["y"] = 0, ["z"] = 6, ["name"] = "default:stone"}, {["x"] = 9, ["y"] = 0, ["z"] = 7, ["name"] = "default:stone"}, {["x"] = 9, ["y"] = 0, ["z"] = 8, ["name"] = "default:stone"}, {["x"] = 9, ["y"] = 0, ["z"] = 9, ["name"] = "default:stone"}, {["x"] = 9, ["y"] = 1, ["z"] = 1, ["name"] = "default:stone"}, {["x"] = 9, ["y"] = 1, ["z"] = 2, ["name"] = "default:stone"}, {["x"] = 9, ["y"] = 1, ["z"] = 3, ["name"] = "default:stone"}, {["x"] = 9, ["y"] = 1, ["z"] = 4, ["name"] = "default:stone"}, {["x"] = 9, ["y"] = 1, ["z"] = 5, ["name"] = "default:stone"}, {["x"] = 9, ["y"] = 1, ["z"] = 6, ["name"] = "default:stone"}, {["x"] = 9, ["y"] = 1, ["z"] = 7, ["name"] = "default:stone"}, {["x"] = 9, ["y"] = 1, ["z"] = 8, ["name"] = "default:stone"}, {["x"] = 9, ["y"] = 1, ["z"] = 9, ["name"] = "default:stone"}, {["x"] = 9, ["y"] = 2, ["z"] = 1, ["name"] = "default:stone_block"}, {["x"] = 9, ["param2"] = 1, ["y"] = 2, ["param1"] = 14, ["z"] = 2, ["name"] = "stairs:slab_stonebrick"}, {["x"] = 9, ["param2"] = 1, ["y"] = 2, ["param1"] = 14, ["z"] = 3, ["name"] = "stairs:slab_stonebrick"}, {["x"] = 9, ["param2"] = 1, ["y"] = 2, ["param1"] = 14, ["z"] = 4, ["name"] = "stairs:slab_stonebrick"}, {["x"] = 9, ["param2"] = 1, ["y"] = 2, ["param1"] = 14, ["z"] = 5, ["name"] = "stairs:slab_stonebrick"}, {["x"] = 9, ["param2"] = 1, ["y"] = 2, ["param1"] = 14, ["z"] = 6, ["name"] = "stairs:slab_stonebrick"}, {["x"] = 9, ["param2"] = 1, ["y"] = 2, ["param1"] = 14, ["z"] = 7, ["name"] = "stairs:slab_stonebrick"}, {["x"] = 9, ["param2"] = 1, ["y"] = 2, ["param1"] = 14, ["z"] = 8, ["name"] = "stairs:slab_stonebrick"}, {["x"] = 9, ["y"] = 2, ["z"] = 9, ["name"] = "default:stone_block"}, {["x"] = 9, ["param2"] = 1, ["y"] = 3, ["param1"] = 14, ["z"] = 1, ["name"] = "stairs:slab_stone_block"}, {["x"] = 9, ["param2"] = 1, ["y"] = 3, ["param1"] = 14, ["z"] = 9, ["name"] = "stairs:slab_stone_block"}, {["x"] = 10, ["y"] = 0, ["z"] = 1, ["name"] = "default:stone"}, {["x"] = 10, ["y"] = 0, ["z"] = 2, ["name"] = "default:stone"}, {["x"] = 10, ["y"] = 0, ["z"] = 3, ["name"] = "default:stone"}, {["x"] = 10, ["y"] = 0, ["z"] = 4, ["name"] = "default:stone"}, {["x"] = 10, ["y"] = 0, ["z"] = 5, ["name"] = "default:stone"}, {["x"] = 10, ["y"] = 0, ["z"] = 6, ["name"] = "default:stone"}, {["x"] = 10, ["y"] = 0, ["z"] = 7, ["name"] = "default:stone"}, {["x"] = 10, ["y"] = 0, ["z"] = 8, ["name"] = "default:stone"}, {["x"] = 10, ["y"] = 0, ["z"] = 9, ["name"] = "default:stone"}, {["x"] = 10, ["y"] = 1, ["z"] = 1, ["name"] = "default:stone"}, {["x"] = 10, ["y"] = 1, ["z"] = 2, ["name"] = "default:stone"}, {["x"] = 10, ["y"] = 1, ["z"] = 3, ["name"] = "default:stone"}, {["x"] = 10, ["y"] = 1, ["z"] = 4, ["name"] = "default:stone"}, {["x"] = 10, ["y"] = 1, ["z"] = 5, ["name"] = "default:stone"}, {["x"] = 10, ["y"] = 1, ["z"] = 6, ["name"] = "default:stone"}, {["x"] = 10, ["y"] = 1, ["z"] = 7, ["name"] = "default:stone"}, {["x"] = 10, ["y"] = 1, ["z"] = 8, ["name"] = "default:stone"}, {["x"] = 10, ["y"] = 1, ["z"] = 9, ["name"] = "default:stone"}, {["x"] = 10, ["y"] = 2, ["z"] = 1, ["name"] = "default:stone_block"}, {["x"] = 10, ["param2"] = 1, ["y"] = 2, ["z"] = 2, ["name"] = "default:stonebrick"}, {["x"] = 10, ["param2"] = 1, ["y"] = 2, ["z"] = 3, ["name"] = "default:stonebrick"}, {["x"] = 10, ["param2"] = 1, ["y"] = 2, ["z"] = 4, ["name"] = "default:stonebrick"}, {["x"] = 10, ["param2"] = 1, ["y"] = 2, ["z"] = 5, ["name"] = "default:stonebrick"}, {["x"] = 10, ["param2"] = 1, ["y"] = 2, ["z"] = 6, ["name"] = "default:stonebrick"}, {["x"] = 10, ["param2"] = 1, ["y"] = 2, ["z"] = 7, ["name"] = "default:stonebrick"}, {["x"] = 10, ["param2"] = 1, ["y"] = 2, ["z"] = 8, ["name"] = "default:stonebrick"}, {["x"] = 10, ["y"] = 2, ["z"] = 9, ["name"] = "default:stone_block"}, {["x"] = 10, ["y"] = 3, ["z"] = 1, ["name"] = "default:stone_block"}, {["x"] = 10, ["y"] = 3, ["z"] = 9, ["name"] = "default:stone_block"}, {["x"] = 11, ["y"] = 0, ["z"] = 1, ["name"] = "default:stone"}, {["x"] = 11, ["y"] = 0, ["z"] = 2, ["name"] = "default:stone"}, {["x"] = 11, ["y"] = 0, ["z"] = 3, ["name"] = "default:stone"}, {["x"] = 11, ["y"] = 0, ["z"] = 4, ["name"] = "default:stone"}, {["x"] = 11, ["y"] = 0, ["z"] = 5, ["name"] = "default:stone"}, {["x"] = 11, ["y"] = 0, ["z"] = 6, ["name"] = "default:stone"}, {["x"] = 11, ["y"] = 0, ["z"] = 7, ["name"] = "default:stone"}, {["x"] = 11, ["y"] = 0, ["z"] = 8, ["name"] = "default:stone"}, {["x"] = 11, ["y"] = 0, ["z"] = 9, ["name"] = "default:stone"}, {["x"] = 11, ["y"] = 1, ["z"] = 1, ["name"] = "default:stone"}, {["x"] = 11, ["y"] = 1, ["z"] = 2, ["name"] = "default:stone"}, {["x"] = 11, ["y"] = 1, ["z"] = 3, ["name"] = "default:stone"}, {["x"] = 11, ["y"] = 1, ["z"] = 4, ["name"] = "default:stone"}, {["x"] = 11, ["y"] = 1, ["z"] = 5, ["name"] = "default:stone"}, {["x"] = 11, ["y"] = 1, ["z"] = 6, ["name"] = "default:stone"}, {["x"] = 11, ["y"] = 1, ["z"] = 7, ["name"] = "default:stone"}, {["x"] = 11, ["y"] = 1, ["z"] = 8, ["name"] = "default:stone"}, {["x"] = 11, ["y"] = 1, ["z"] = 9, ["name"] = "default:stone"}, {["x"] = 11, ["y"] = 2, ["z"] = 1, ["name"] = "default:stone_block"}, {["x"] = 11, ["param2"] = 1, ["y"] = 2, ["z"] = 2, ["name"] = "default:stonebrick"}, {["x"] = 11, ["param2"] = 1, ["y"] = 2, ["z"] = 3, ["name"] = "default:stonebrick"}, {["x"] = 11, ["param2"] = 1, ["y"] = 2, ["z"] = 4, ["name"] = "default:stonebrick"}, {["x"] = 11, ["param2"] = 1, ["y"] = 2, ["z"] = 5, ["name"] = "default:stonebrick"}, {["x"] = 11, ["param2"] = 1, ["y"] = 2, ["z"] = 6, ["name"] = "default:stonebrick"}, {["x"] = 11, ["param2"] = 1, ["y"] = 2, ["z"] = 7, ["name"] = "default:stonebrick"}, {["x"] = 11, ["param2"] = 1, ["y"] = 2, ["z"] = 8, ["name"] = "default:stonebrick"}, {["x"] = 11, ["y"] = 2, ["z"] = 9, ["name"] = "default:stone_block"}, {["x"] = 11, ["y"] = 3, ["z"] = 1, ["name"] = "default:stone_block"}, {["x"] = 11, ["y"] = 3, ["z"] = 9, ["name"] = "default:stone_block"}, {["x"] = 12, ["y"] = 0, ["z"] = 1, ["name"] = "default:stone"}, {["x"] = 12, ["y"] = 0, ["z"] = 2, ["name"] = "default:stone"}, {["x"] = 12, ["y"] = 0, ["z"] = 3, ["name"] = "default:stone"}, {["x"] = 12, ["y"] = 0, ["z"] = 4, ["name"] = "default:stone"}, {["x"] = 12, ["y"] = 0, ["z"] = 5, ["name"] = "default:stone"}, {["x"] = 12, ["y"] = 0, ["z"] = 6, ["name"] = "default:stone"}, {["x"] = 12, ["y"] = 0, ["z"] = 7, ["name"] = "default:stone"}, {["x"] = 12, ["y"] = 0, ["z"] = 8, ["name"] = "default:stone"}, {["x"] = 12, ["y"] = 0, ["z"] = 9, ["name"] = "default:stone"}, {["x"] = 12, ["y"] = 1, ["z"] = 1, ["name"] = "default:stone"}, {["x"] = 12, ["y"] = 1, ["z"] = 2, ["name"] = "default:stone"}, {["x"] = 12, ["y"] = 1, ["z"] = 3, ["name"] = "default:stone"}, {["x"] = 12, ["y"] = 1, ["z"] = 4, ["name"] = "default:stone"}, {["x"] = 12, ["y"] = 1, ["z"] = 5, ["name"] = "default:stone"}, {["x"] = 12, ["y"] = 1, ["z"] = 6, ["name"] = "default:stone"}, {["x"] = 12, ["y"] = 1, ["z"] = 7, ["name"] = "default:stone"}, {["x"] = 12, ["y"] = 1, ["z"] = 8, ["name"] = "default:stone"}, {["x"] = 12, ["y"] = 1, ["z"] = 9, ["name"] = "default:stone"}, {["x"] = 12, ["y"] = 2, ["z"] = 1, ["name"] = "default:stone"}, {["x"] = 12, ["y"] = 2, ["z"] = 2, ["name"] = "default:stone"}, {["x"] = 12, ["y"] = 2, ["z"] = 3, ["name"] = "default:stone"}, {["x"] = 12, ["y"] = 2, ["z"] = 4, ["name"] = "default:stone"}, {["x"] = 12, ["y"] = 2, ["z"] = 5, ["name"] = "default:stone"}, {["x"] = 12, ["y"] = 2, ["z"] = 6, ["name"] = "default:stone"}, {["x"] = 12, ["y"] = 2, ["z"] = 7, ["name"] = "default:stone"}, {["x"] = 12, ["y"] = 2, ["z"] = 8, ["name"] = "default:stone"}, {["x"] = 12, ["y"] = 2, ["z"] = 9, ["name"] = "default:stone"}, {["x"] = 12, ["y"] = 3, ["z"] = 1, ["name"] = "default:stone_block"}, {["x"] = 12, ["param2"] = 1, ["y"] = 3, ["param1"] = 14, ["z"] = 2, ["name"] = "stairs:slab_stonebrick"}, {["x"] = 12, ["param2"] = 1, ["y"] = 3, ["param1"] = 14, ["z"] = 3, ["name"] = "stairs:slab_stonebrick"}, {["x"] = 12, ["param2"] = 1, ["y"] = 3, ["param1"] = 14, ["z"] = 4, ["name"] = "stairs:slab_stonebrick"}, {["x"] = 12, ["param2"] = 1, ["y"] = 3, ["param1"] = 14, ["z"] = 5, ["name"] = "stairs:slab_stonebrick"}, {["x"] = 12, ["param2"] = 1, ["y"] = 3, ["param1"] = 14, ["z"] = 6, ["name"] = "stairs:slab_stonebrick"}, {["x"] = 12, ["param2"] = 1, ["y"] = 3, ["param1"] = 14, ["z"] = 7, ["name"] = "stairs:slab_stonebrick"}, {["x"] = 12, ["param2"] = 1, ["y"] = 3, ["param1"] = 14, ["z"] = 8, ["name"] = "stairs:slab_stonebrick"}, {["x"] = 12, ["y"] = 3, ["z"] = 9, ["name"] = "default:stone_block"}, {["x"] = 12, ["param2"] = 1, ["y"] = 4, ["param1"] = 14, ["z"] = 1, ["name"] = "stairs:slab_stone_block"}, {["x"] = 12, ["param2"] = 1, ["y"] = 4, ["param1"] = 14, ["z"] = 9, ["name"] = "stairs:slab_stone_block"}, {["x"] = 13, ["y"] = 0, ["z"] = 1, ["name"] = "default:stone"}, {["x"] = 13, ["y"] = 0, ["z"] = 2, ["name"] = "default:stone"}, {["x"] = 13, ["y"] = 0, ["z"] = 3, ["name"] = "default:stone"}, {["x"] = 13, ["y"] = 0, ["z"] = 4, ["name"] = "default:stone"}, {["x"] = 13, ["y"] = 0, ["z"] = 5, ["name"] = "default:stone"}, {["x"] = 13, ["y"] = 0, ["z"] = 6, ["name"] = "default:stone"}, {["x"] = 13, ["y"] = 0, ["z"] = 7, ["name"] = "default:stone"}, {["x"] = 13, ["y"] = 0, ["z"] = 8, ["name"] = "default:stone"}, {["x"] = 13, ["y"] = 0, ["z"] = 9, ["name"] = "default:stone"}, {["x"] = 13, ["y"] = 1, ["z"] = 1, ["name"] = "default:stone"}, {["x"] = 13, ["y"] = 1, ["z"] = 2, ["name"] = "default:stone"}, {["x"] = 13, ["y"] = 1, ["z"] = 3, ["name"] = "default:stone"}, {["x"] = 13, ["y"] = 1, ["z"] = 4, ["name"] = "default:stone"}, {["x"] = 13, ["y"] = 1, ["z"] = 5, ["name"] = "default:stone"}, {["x"] = 13, ["y"] = 1, ["z"] = 6, ["name"] = "default:stone"}, {["x"] = 13, ["y"] = 1, ["z"] = 7, ["name"] = "default:stone"}, {["x"] = 13, ["y"] = 1, ["z"] = 8, ["name"] = "default:stone"}, {["x"] = 13, ["y"] = 1, ["z"] = 9, ["name"] = "default:stone"}, {["x"] = 13, ["y"] = 2, ["z"] = 1, ["name"] = "default:stone"}, {["x"] = 13, ["y"] = 2, ["z"] = 2, ["name"] = "default:stone"}, {["x"] = 13, ["y"] = 2, ["z"] = 3, ["name"] = "default:stone"}, {["x"] = 13, ["y"] = 2, ["z"] = 4, ["name"] = "default:stone"}, {["x"] = 13, ["y"] = 2, ["z"] = 5, ["name"] = "default:stone"}, {["x"] = 13, ["y"] = 2, ["z"] = 6, ["name"] = "default:stone"}, {["x"] = 13, ["y"] = 2, ["z"] = 7, ["name"] = "default:stone"}, {["x"] = 13, ["y"] = 2, ["z"] = 8, ["name"] = "default:stone"}, {["x"] = 13, ["y"] = 2, ["z"] = 9, ["name"] = "default:stone"}, {["x"] = 13, ["y"] = 3, ["z"] = 1, ["name"] = "default:stone_block"}, {["x"] = 13, ["param2"] = 1, ["y"] = 3, ["param1"] = 14, ["z"] = 2, ["name"] = "stairs:slab_stonebrick"}, {["x"] = 13, ["param2"] = 1, ["y"] = 3, ["param1"] = 14, ["z"] = 3, ["name"] = "stairs:slab_stonebrick"}, {["x"] = 13, ["param2"] = 1, ["y"] = 3, ["param1"] = 14, ["z"] = 4, ["name"] = "stairs:slab_stonebrick"}, {["x"] = 13, ["param2"] = 1, ["y"] = 3, ["param1"] = 14, ["z"] = 5, ["name"] = "stairs:slab_stonebrick"}, {["x"] = 13, ["param2"] = 1, ["y"] = 3, ["param1"] = 14, ["z"] = 6, ["name"] = "stairs:slab_stonebrick"}, {["x"] = 13, ["param2"] = 1, ["y"] = 3, ["param1"] = 14, ["z"] = 7, ["name"] = "stairs:slab_stonebrick"}, {["x"] = 13, ["param2"] = 1, ["y"] = 3, ["param1"] = 14, ["z"] = 8, ["name"] = "stairs:slab_stonebrick"}, {["x"] = 13, ["y"] = 3, ["z"] = 9, ["name"] = "default:stone_block"}, {["x"] = 13, ["param2"] = 1, ["y"] = 4, ["param1"] = 14, ["z"] = 1, ["name"] = "stairs:slab_stone_block"}, {["x"] = 13, ["param2"] = 1, ["y"] = 4, ["param1"] = 14, ["z"] = 9, ["name"] = "stairs:slab_stone_block"}, {["x"] = 14, ["y"] = 0, ["z"] = 2, ["name"] = "default:stone"}, {["x"] = 14, ["y"] = 0, ["z"] = 3, ["name"] = "default:stone"}, {["x"] = 14, ["y"] = 0, ["z"] = 4, ["name"] = "default:stone"}, {["x"] = 14, ["y"] = 0, ["z"] = 5, ["name"] = "default:stone"}, {["x"] = 14, ["y"] = 0, ["z"] = 6, ["name"] = "default:stone"}, {["x"] = 14, ["y"] = 0, ["z"] = 7, ["name"] = "default:stone"}, {["x"] = 14, ["y"] = 0, ["z"] = 8, ["name"] = "default:stone"}, {["x"] = 14, ["y"] = 1, ["z"] = 1, ["name"] = "default:stone"}, {["x"] = 14, ["y"] = 1, ["z"] = 2, ["name"] = "default:stone"}, {["x"] = 14, ["y"] = 1, ["z"] = 3, ["name"] = "default:stone"}, {["x"] = 14, ["y"] = 1, ["z"] = 4, ["name"] = "default:stone"}, {["x"] = 14, ["y"] = 1, ["z"] = 5, ["name"] = "default:stone"}, {["x"] = 14, ["y"] = 1, ["z"] = 6, ["name"] = "default:stone"}, {["x"] = 14, ["y"] = 1, ["z"] = 7, ["name"] = "default:stone"}, {["x"] = 14, ["y"] = 1, ["z"] = 8, ["name"] = "default:stone"}, {["x"] = 14, ["y"] = 1, ["z"] = 9, ["name"] = "default:stone"}, {["x"] = 14, ["y"] = 2, ["z"] = 1, ["name"] = "default:stone"}, {["x"] = 14, ["y"] = 2, ["z"] = 2, ["name"] = "default:stone"}, {["x"] = 14, ["y"] = 2, ["z"] = 3, ["name"] = "default:stone"}, {["x"] = 14, ["y"] = 2, ["z"] = 4, ["name"] = "default:stone"}, {["x"] = 14, ["y"] = 2, ["z"] = 5, ["name"] = "default:stone"}, {["x"] = 14, ["y"] = 2, ["z"] = 6, ["name"] = "default:stone"}, {["x"] = 14, ["y"] = 2, ["z"] = 7, ["name"] = "default:stone"}, {["x"] = 14, ["y"] = 2, ["z"] = 8, ["name"] = "default:stone"}, {["x"] = 14, ["y"] = 2, ["z"] = 9, ["name"] = "default:stone"}, {["x"] = 14, ["y"] = 3, ["z"] = 1, ["name"] = "default:stone_block"}, {["x"] = 14, ["param2"] = 1, ["y"] = 3, ["param1"] = 14, ["z"] = 2, ["name"] = "stairs:slab_stonebrick"}, {["x"] = 14, ["param2"] = 1, ["y"] = 3, ["param1"] = 14, ["z"] = 3, ["name"] = "stairs:slab_stonebrick"}, {["x"] = 14, ["param2"] = 1, ["y"] = 3, ["param1"] = 14, ["z"] = 4, ["name"] = "stairs:slab_stonebrick"}, {["x"] = 14, ["param2"] = 1, ["y"] = 3, ["param1"] = 14, ["z"] = 5, ["name"] = "stairs:slab_stonebrick"}, {["x"] = 14, ["param2"] = 1, ["y"] = 3, ["param1"] = 14, ["z"] = 6, ["name"] = "stairs:slab_stonebrick"}, {["x"] = 14, ["param2"] = 1, ["y"] = 3, ["param1"] = 14, ["z"] = 7, ["name"] = "stairs:slab_stonebrick"}, {["x"] = 14, ["param2"] = 1, ["y"] = 3, ["param1"] = 14, ["z"] = 8, ["name"] = "stairs:slab_stonebrick"}, {["x"] = 14, ["y"] = 3, ["z"] = 9, ["name"] = "default:stone_block"}, {["x"] = 14, ["param2"] = 1, ["y"] = 4, ["param1"] = 14, ["z"] = 1, ["name"] = "stairs:slab_stone_block"}, {["x"] = 14, ["param2"] = 1, ["y"] = 4, ["param1"] = 14, ["z"] = 9, ["name"] = "stairs:slab_stone_block"}, {["x"] = 15, ["y"] = 0, ["z"] = 2, ["name"] = "default:stone"}, {["x"] = 15, ["y"] = 0, ["z"] = 3, ["name"] = "default:stone"}, {["x"] = 15, ["y"] = 0, ["z"] = 4, ["name"] = "default:stone"}, {["x"] = 15, ["y"] = 0, ["z"] = 5, ["name"] = "default:stone"}, {["x"] = 15, ["y"] = 0, ["z"] = 6, ["name"] = "default:stone"}, {["x"] = 15, ["y"] = 0, ["z"] = 7, ["name"] = "default:stone"}, {["x"] = 15, ["y"] = 0, ["z"] = 8, ["name"] = "default:stone"}, {["x"] = 15, ["param2"] = 20, ["y"] = 1, ["param1"] = 14, ["z"] = 1, ["name"] = "stairs:slab_stone"}, {["x"] = 15, ["y"] = 1, ["z"] = 2, ["name"] = "default:stone"}, {["x"] = 15, ["y"] = 1, ["z"] = 3, ["name"] = "default:stone"}, {["x"] = 15, ["y"] = 1, ["z"] = 4, ["name"] = "default:stone"}, {["x"] = 15, ["y"] = 1, ["z"] = 5, ["name"] = "default:stone"}, {["x"] = 15, ["y"] = 1, ["z"] = 6, ["name"] = "default:stone"}, {["x"] = 15, ["y"] = 1, ["z"] = 7, ["name"] = "default:stone"}, {["x"] = 15, ["y"] = 1, ["z"] = 8, ["name"] = "default:stone"}, {["x"] = 15, ["param2"] = 22, ["y"] = 1, ["param1"] = 14, ["z"] = 9, ["name"] = "stairs:slab_stone"}, {["x"] = 15, ["y"] = 2, ["z"] = 1, ["name"] = "default:stone"}, {["x"] = 15, ["y"] = 2, ["z"] = 2, ["name"] = "default:stone"}, {["x"] = 15, ["y"] = 2, ["z"] = 3, ["name"] = "default:stone"}, {["x"] = 15, ["y"] = 2, ["z"] = 4, ["name"] = "default:stone"}, {["x"] = 15, ["y"] = 2, ["z"] = 5, ["name"] = "default:stone"}, {["x"] = 15, ["y"] = 2, ["z"] = 6, ["name"] = "default:stone"}, {["x"] = 15, ["y"] = 2, ["z"] = 7, ["name"] = "default:stone"}, {["x"] = 15, ["y"] = 2, ["z"] = 8, ["name"] = "default:stone"}, {["x"] = 15, ["y"] = 2, ["z"] = 9, ["name"] = "default:stone"}, {["x"] = 15, ["y"] = 3, ["z"] = 1, ["name"] = "default:stone"}, {["x"] = 15, ["param2"] = 1, ["y"] = 3, ["z"] = 2, ["name"] = "default:stonebrick"}, {["x"] = 15, ["param2"] = 1, ["y"] = 3, ["z"] = 3, ["name"] = "default:stonebrick"}, {["x"] = 15, ["param2"] = 1, ["y"] = 3, ["z"] = 4, ["name"] = "default:stonebrick"}, {["x"] = 15, ["param2"] = 1, ["y"] = 3, ["z"] = 5, ["name"] = "default:stonebrick"}, {["x"] = 15, ["param2"] = 1, ["y"] = 3, ["z"] = 6, ["name"] = "default:stonebrick"}, {["x"] = 15, ["param2"] = 1, ["y"] = 3, ["z"] = 7, ["name"] = "default:stonebrick"}, {["x"] = 15, ["param2"] = 1, ["y"] = 3, ["z"] = 8, ["name"] = "default:stonebrick"}, {["x"] = 15, ["y"] = 3, ["z"] = 9, ["name"] = "default:stone"}, {["x"] = 15, ["y"] = 4, ["z"] = 1, ["name"] = "default:stone_block"}, {["x"] = 15, ["y"] = 4, ["z"] = 9, ["name"] = "default:stone_block"}, {["x"] = 16, ["y"] = 0, ["z"] = 3, ["name"] = "default:stone"}, {["x"] = 16, ["y"] = 0, ["z"] = 4, ["name"] = "default:stone"}, {["x"] = 16, ["y"] = 0, ["z"] = 5, ["name"] = "default:stone"}, {["x"] = 16, ["y"] = 0, ["z"] = 6, ["name"] = "default:stone"}, {["x"] = 16, ["y"] = 0, ["z"] = 7, ["name"] = "default:stone"}, {["x"] = 16, ["y"] = 1, ["z"] = 2, ["name"] = "default:stone"}, {["x"] = 16, ["y"] = 1, ["z"] = 3, ["name"] = "default:stone"}, {["x"] = 16, ["y"] = 1, ["z"] = 4, ["name"] = "default:stone"}, {["x"] = 16, ["y"] = 1, ["z"] = 5, ["name"] = "default:stone"}, {["x"] = 16, ["y"] = 1, ["z"] = 6, ["name"] = "default:stone"}, {["x"] = 16, ["y"] = 1, ["z"] = 7, ["name"] = "default:stone"}, {["x"] = 16, ["y"] = 1, ["z"] = 8, ["name"] = "default:stone"}, {["x"] = 16, ["y"] = 2, ["z"] = 1, ["name"] = "default:stone"}, {["x"] = 16, ["y"] = 2, ["z"] = 2, ["name"] = "default:stone"}, {["x"] = 16, ["y"] = 2, ["z"] = 3, ["name"] = "default:stone"}, {["x"] = 16, ["y"] = 2, ["z"] = 4, ["name"] = "default:stone"}, {["x"] = 16, ["y"] = 2, ["z"] = 5, ["name"] = "default:stone"}, {["x"] = 16, ["y"] = 2, ["z"] = 6, ["name"] = "default:stone"}, {["x"] = 16, ["y"] = 2, ["z"] = 7, ["name"] = "default:stone"}, {["x"] = 16, ["y"] = 2, ["z"] = 8, ["name"] = "default:stone"}, {["x"] = 16, ["y"] = 2, ["z"] = 9, ["name"] = "default:stone"}, {["x"] = 16, ["y"] = 3, ["z"] = 1, ["name"] = "default:stone"}, {["x"] = 16, ["param2"] = 1, ["y"] = 3, ["z"] = 2, ["name"] = "default:stonebrick"}, {["x"] = 16, ["param2"] = 1, ["y"] = 3, ["z"] = 3, ["name"] = "default:stonebrick"}, {["x"] = 16, ["param2"] = 1, ["y"] = 3, ["z"] = 4, ["name"] = "default:stonebrick"}, {["x"] = 16, ["param2"] = 1, ["y"] = 3, ["z"] = 5, ["name"] = "default:stonebrick"}, {["x"] = 16, ["param2"] = 1, ["y"] = 3, ["z"] = 6, ["name"] = "default:stonebrick"}, {["x"] = 16, ["param2"] = 1, ["y"] = 3, ["z"] = 7, ["name"] = "default:stonebrick"}, {["x"] = 16, ["param2"] = 1, ["y"] = 3, ["z"] = 8, ["name"] = "default:stonebrick"}, {["x"] = 16, ["y"] = 3, ["z"] = 9, ["name"] = "default:stone"}, {["x"] = 16, ["y"] = 4, ["z"] = 1, ["name"] = "default:stone_block"}, {["x"] = 16, ["y"] = 4, ["z"] = 9, ["name"] = "default:stone_block"}, {["x"] = 17, ["param2"] = 21, ["y"] = 0, ["param1"] = 11, ["z"] = 4, ["name"] = "stairs:slab_stone"}, {["x"] = 17, ["y"] = 0, ["z"] = 5, ["name"] = "default:stone"}, {["x"] = 17, ["param2"] = 21, ["y"] = 0, ["param1"] = 11, ["z"] = 6, ["name"] = "stairs:slab_stone"}, {["x"] = 17, ["param2"] = 20, ["y"] = 1, ["param1"] = 13, ["z"] = 2, ["name"] = "stairs:slab_stone"}, {["x"] = 17, ["y"] = 1, ["z"] = 3, ["name"] = "default:stone"}, {["x"] = 17, ["y"] = 1, ["z"] = 4, ["name"] = "default:stone"}, {["x"] = 17, ["y"] = 1, ["z"] = 5, ["name"] = "default:stone"}, {["x"] = 17, ["y"] = 1, ["z"] = 6, ["name"] = "default:stone"}, {["x"] = 17, ["y"] = 1, ["z"] = 7, ["name"] = "default:stone"}, {["x"] = 17, ["param2"] = 22, ["y"] = 1, ["param1"] = 13, ["z"] = 8, ["name"] = "stairs:slab_stone"}, {["x"] = 17, ["y"] = 2, ["z"] = 1, ["name"] = "default:stone"}, {["x"] = 17, ["y"] = 2, ["z"] = 2, ["name"] = "default:stone"}, {["x"] = 17, ["y"] = 2, ["z"] = 3, ["name"] = "default:stone"}, {["x"] = 17, ["y"] = 2, ["z"] = 4, ["name"] = "default:stone"}, {["x"] = 17, ["y"] = 2, ["z"] = 5, ["name"] = "default:stone"}, {["x"] = 17, ["y"] = 2, ["z"] = 6, ["name"] = "default:stone"}, {["x"] = 17, ["y"] = 2, ["z"] = 7, ["name"] = "default:stone"}, {["x"] = 17, ["y"] = 2, ["z"] = 8, ["name"] = "default:stone"}, {["x"] = 17, ["y"] = 2, ["z"] = 9, ["name"] = "default:stone"}, {["x"] = 17, ["y"] = 3, ["z"] = 1, ["name"] = "default:stone"}, {["x"] = 17, ["param2"] = 1, ["y"] = 3, ["z"] = 2, ["name"] = "default:stonebrick"}, {["x"] = 17, ["param2"] = 1, ["y"] = 3, ["z"] = 3, ["name"] = "default:stonebrick"}, {["x"] = 17, ["param2"] = 1, ["y"] = 3, ["z"] = 4, ["name"] = "default:stonebrick"}, {["x"] = 17, ["param2"] = 1, ["y"] = 3, ["z"] = 5, ["name"] = "default:stonebrick"}, {["x"] = 17, ["param2"] = 1, ["y"] = 3, ["z"] = 6, ["name"] = "default:stonebrick"}, {["x"] = 17, ["param2"] = 1, ["y"] = 3, ["z"] = 7, ["name"] = "default:stonebrick"}, {["x"] = 17, ["param2"] = 1, ["y"] = 3, ["z"] = 8, ["name"] = "default:stonebrick"}, {["x"] = 17, ["y"] = 3, ["z"] = 9, ["name"] = "default:stone"}, {["x"] = 17, ["y"] = 4, ["z"] = 1, ["name"] = "default:stone_block"}, {["x"] = 17, ["y"] = 4, ["z"] = 9, ["name"] = "default:stone_block"}, {["x"] = 18, ["param2"] = 21, ["y"] = 0, ["param1"] = 10, ["z"] = 5, ["name"] = "stairs:slab_stone"}, {["x"] = 18, ["param2"] = 22, ["y"] = 1, ["param1"] = 12, ["z"] = 3, ["name"] = "stairs:slab_stone"}, {["x"] = 18, ["y"] = 1, ["z"] = 4, ["name"] = "default:stone"}, {["x"] = 18, ["y"] = 1, ["z"] = 5, ["name"] = "default:stone"}, {["x"] = 18, ["y"] = 1, ["z"] = 6, ["name"] = "default:stone"}, {["x"] = 18, ["param2"] = 20, ["y"] = 1, ["param1"] = 12, ["z"] = 7, ["name"] = "stairs:slab_stone"}, {["x"] = 18, ["param2"] = 20, ["y"] = 2, ["param1"] = 14, ["z"] = 1, ["name"] = "stairs:slab_stone"}, {["x"] = 18, ["y"] = 2, ["z"] = 2, ["name"] = "default:stone"}, {["x"] = 18, ["y"] = 2, ["z"] = 3, ["name"] = "default:stone"}, {["x"] = 18, ["y"] = 2, ["z"] = 4, ["name"] = "default:stone"}, {["x"] = 18, ["y"] = 2, ["z"] = 5, ["name"] = "default:stone"}, {["x"] = 18, ["y"] = 2, ["z"] = 6, ["name"] = "default:stone"}, {["x"] = 18, ["y"] = 2, ["z"] = 7, ["name"] = "default:stone"}, {["x"] = 18, ["y"] = 2, ["z"] = 8, ["name"] = "default:stone"}, {["x"] = 18, ["param2"] = 21, ["y"] = 2, ["param1"] = 14, ["z"] = 9, ["name"] = "stairs:slab_stone"}, {["x"] = 18, ["y"] = 3, ["z"] = 1, ["name"] = "default:stone"}, {["x"] = 18, ["y"] = 3, ["z"] = 2, ["name"] = "default:stone"}, {["x"] = 18, ["y"] = 3, ["z"] = 3, ["name"] = "default:stone"}, {["x"] = 18, ["y"] = 3, ["z"] = 4, ["name"] = "default:stone"}, {["x"] = 18, ["y"] = 3, ["z"] = 5, ["name"] = "default:stone"}, {["x"] = 18, ["y"] = 3, ["z"] = 6, ["name"] = "default:stone"}, {["x"] = 18, ["y"] = 3, ["z"] = 7, ["name"] = "default:stone"}, {["x"] = 18, ["y"] = 3, ["z"] = 8, ["name"] = "default:stone"}, {["x"] = 18, ["y"] = 3, ["z"] = 9, ["name"] = "default:stone"}, {["x"] = 18, ["y"] = 4, ["z"] = 1, ["name"] = "default:stone_block"}, {["x"] = 18, ["param2"] = 1, ["y"] = 4, ["param1"] = 14, ["z"] = 2, ["name"] = "stairs:slab_stonebrick"}, {["x"] = 18, ["param2"] = 1, ["y"] = 4, ["param1"] = 14, ["z"] = 3, ["name"] = "stairs:slab_stonebrick"}, {["x"] = 18, ["param2"] = 1, ["y"] = 4, ["param1"] = 14, ["z"] = 4, ["name"] = "stairs:slab_stonebrick"}, {["x"] = 18, ["param2"] = 1, ["y"] = 4, ["param1"] = 14, ["z"] = 5, ["name"] = "stairs:slab_stonebrick"}, {["x"] = 18, ["param2"] = 1, ["y"] = 4, ["param1"] = 14, ["z"] = 6, ["name"] = "stairs:slab_stonebrick"}, {["x"] = 18, ["param2"] = 1, ["y"] = 4, ["param1"] = 14, ["z"] = 7, ["name"] = "stairs:slab_stonebrick"}, {["x"] = 18, ["param2"] = 1, ["y"] = 4, ["param1"] = 14, ["z"] = 8, ["name"] = "stairs:slab_stonebrick"}, {["x"] = 18, ["y"] = 4, ["z"] = 9, ["name"] = "default:stone_block"}, {["x"] = 18, ["param2"] = 1, ["y"] = 5, ["param1"] = 14, ["z"] = 1, ["name"] = "stairs:slab_stone_block"}, {["x"] = 18, ["param2"] = 1, ["y"] = 5, ["param1"] = 14, ["z"] = 9, ["name"] = "stairs:slab_stone_block"}, {["x"] = 19, ["param2"] = 21, ["y"] = 1, ["param1"] = 11, ["z"] = 4, ["name"] = "stairs:slab_stone"}, {["x"] = 19, ["y"] = 1, ["z"] = 5, ["name"] = "default:stone"}, {["x"] = 19, ["param2"] = 21, ["y"] = 1, ["param1"] = 11, ["z"] = 6, ["name"] = "stairs:slab_stone"}, {["x"] = 19, ["param2"] = 20, ["y"] = 2, ["param1"] = 14, ["z"] = 1, ["name"] = "stairs:slab_stone"}, {["x"] = 19, ["y"] = 2, ["z"] = 2, ["name"] = "default:stone"}, {["x"] = 19, ["y"] = 2, ["z"] = 3, ["name"] = "default:stone"}, {["x"] = 19, ["y"] = 2, ["z"] = 4, ["name"] = "default:stone"}, {["x"] = 19, ["y"] = 2, ["z"] = 5, ["name"] = "default:stone"}, {["x"] = 19, ["y"] = 2, ["z"] = 6, ["name"] = "default:stone"}, {["x"] = 19, ["y"] = 2, ["z"] = 7, ["name"] = "default:stone"}, {["x"] = 19, ["y"] = 2, ["z"] = 8, ["name"] = "default:stone"}, {["x"] = 19, ["param2"] = 21, ["y"] = 2, ["param1"] = 14, ["z"] = 9, ["name"] = "stairs:slab_stone"}, {["x"] = 19, ["y"] = 3, ["z"] = 1, ["name"] = "default:stone"}, {["x"] = 19, ["y"] = 3, ["z"] = 2, ["name"] = "default:stone"}, {["x"] = 19, ["y"] = 3, ["z"] = 3, ["name"] = "default:stone"}, {["x"] = 19, ["y"] = 3, ["z"] = 4, ["name"] = "default:stone"}, {["x"] = 19, ["y"] = 3, ["z"] = 5, ["name"] = "default:stone"}, {["x"] = 19, ["y"] = 3, ["z"] = 6, ["name"] = "default:stone"}, {["x"] = 19, ["y"] = 3, ["z"] = 7, ["name"] = "default:stone"}, {["x"] = 19, ["y"] = 3, ["z"] = 8, ["name"] = "default:stone"}, {["x"] = 19, ["y"] = 3, ["z"] = 9, ["name"] = "default:stone"}, {["x"] = 19, ["y"] = 4, ["z"] = 1, ["name"] = "default:stone_block"}, {["x"] = 19, ["param2"] = 1, ["y"] = 4, ["param1"] = 14, ["z"] = 2, ["name"] = "stairs:slab_stonebrick"}, {["x"] = 19, ["param2"] = 1, ["y"] = 4, ["param1"] = 14, ["z"] = 3, ["name"] = "stairs:slab_stonebrick"}, {["x"] = 19, ["param2"] = 1, ["y"] = 4, ["param1"] = 14, ["z"] = 4, ["name"] = "stairs:slab_stonebrick"}, {["x"] = 19, ["param2"] = 1, ["y"] = 4, ["param1"] = 14, ["z"] = 5, ["name"] = "stairs:slab_stonebrick"}, {["x"] = 19, ["param2"] = 1, ["y"] = 4, ["param1"] = 14, ["z"] = 6, ["name"] = "stairs:slab_stonebrick"}, {["x"] = 19, ["param2"] = 1, ["y"] = 4, ["param1"] = 14, ["z"] = 7, ["name"] = "stairs:slab_stonebrick"}, {["x"] = 19, ["param2"] = 1, ["y"] = 4, ["param1"] = 14, ["z"] = 8, ["name"] = "stairs:slab_stonebrick"}, {["x"] = 19, ["y"] = 4, ["z"] = 9, ["name"] = "default:stone_block"}, {["x"] = 19, ["param2"] = 1, ["y"] = 5, ["param1"] = 14, ["z"] = 1, ["name"] = "stairs:slab_stone_block"}, {["x"] = 19, ["param2"] = 1, ["y"] = 5, ["param1"] = 14, ["z"] = 9, ["name"] = "stairs:slab_stone_block"}, {["x"] = 20, ["param2"] = 21, ["y"] = 1, ["param1"] = 11, ["z"] = 4, ["name"] = "stairs:slab_stone"}, {["x"] = 20, ["param2"] = 21, ["y"] = 1, ["param1"] = 10, ["z"] = 5, ["name"] = "stairs:slab_stone"}, {["x"] = 20, ["param2"] = 21, ["y"] = 1, ["param1"] = 11, ["z"] = 6, ["name"] = "stairs:slab_stone"}, {["x"] = 20, ["param2"] = 20, ["y"] = 2, ["param1"] = 13, ["z"] = 2, ["name"] = "stairs:slab_stone"}, {["x"] = 20, ["y"] = 2, ["z"] = 3, ["name"] = "default:stone"}, {["x"] = 20, ["y"] = 2, ["z"] = 4, ["name"] = "default:stone"}, {["x"] = 20, ["y"] = 2, ["z"] = 5, ["name"] = "default:stone"}, {["x"] = 20, ["y"] = 2, ["z"] = 6, ["name"] = "default:stone"}, {["x"] = 20, ["y"] = 2, ["z"] = 7, ["name"] = "default:stone"}, {["x"] = 20, ["param2"] = 21, ["y"] = 2, ["param1"] = 13, ["z"] = 8, ["name"] = "stairs:slab_stone"}, {["x"] = 20, ["y"] = 3, ["z"] = 1, ["name"] = "default:stone"}, {["x"] = 20, ["y"] = 3, ["z"] = 2, ["name"] = "default:stone"}, {["x"] = 20, ["y"] = 3, ["z"] = 3, ["name"] = "default:stone"}, {["x"] = 20, ["y"] = 3, ["z"] = 4, ["name"] = "default:stone"}, {["x"] = 20, ["y"] = 3, ["z"] = 5, ["name"] = "default:stone"}, {["x"] = 20, ["y"] = 3, ["z"] = 6, ["name"] = "default:stone"}, {["x"] = 20, ["y"] = 3, ["z"] = 7, ["name"] = "default:stone"}, {["x"] = 20, ["y"] = 3, ["z"] = 8, ["name"] = "default:stone"}, {["x"] = 20, ["y"] = 3, ["z"] = 9, ["name"] = "default:stone"}, {["x"] = 20, ["y"] = 4, ["z"] = 1, ["name"] = "default:stone_block"}, {["x"] = 20, ["param2"] = 1, ["y"] = 4, ["param1"] = 14, ["z"] = 2, ["name"] = "stairs:slab_stonebrick"}, {["x"] = 20, ["param2"] = 1, ["y"] = 4, ["param1"] = 14, ["z"] = 3, ["name"] = "stairs:slab_stonebrick"}, {["x"] = 20, ["param2"] = 1, ["y"] = 4, ["param1"] = 14, ["z"] = 4, ["name"] = "stairs:slab_stonebrick"}, {["x"] = 20, ["param2"] = 1, ["y"] = 4, ["param1"] = 14, ["z"] = 5, ["name"] = "stairs:slab_stonebrick"}, {["x"] = 20, ["param2"] = 1, ["y"] = 4, ["param1"] = 14, ["z"] = 6, ["name"] = "stairs:slab_stonebrick"}, {["x"] = 20, ["param2"] = 1, ["y"] = 4, ["param1"] = 14, ["z"] = 7, ["name"] = "stairs:slab_stonebrick"}, {["x"] = 20, ["param2"] = 1, ["y"] = 4, ["param1"] = 14, ["z"] = 8, ["name"] = "stairs:slab_stonebrick"}, {["x"] = 20, ["y"] = 4, ["z"] = 9, ["name"] = "default:stone_block"}, {["x"] = 20, ["param2"] = 1, ["y"] = 5, ["param1"] = 14, ["z"] = 1, ["name"] = "stairs:slab_stone_block"}, {["x"] = 20, ["param2"] = 1, ["y"] = 5, ["param1"] = 14, ["z"] = 9, ["name"] = "stairs:slab_stone_block"}, {["x"] = 21, ["param2"] = 21, ["y"] = 1, ["param1"] = 11, ["z"] = 4, ["name"] = "stairs:slab_stone"}, {["x"] = 21, ["param2"] = 21, ["y"] = 1, ["param1"] = 10, ["z"] = 5, ["name"] = "stairs:slab_stone"}, {["x"] = 21, ["param2"] = 21, ["y"] = 1, ["param1"] = 11, ["z"] = 6, ["name"] = "stairs:slab_stone"}, {["x"] = 21, ["param2"] = 20, ["y"] = 2, ["param1"] = 13, ["z"] = 2, ["name"] = "stairs:slab_stone"}, {["x"] = 21, ["y"] = 2, ["z"] = 3, ["name"] = "default:stone"}, {["x"] = 21, ["y"] = 2, ["z"] = 4, ["name"] = "default:stone"}, {["x"] = 21, ["y"] = 2, ["z"] = 5, ["name"] = "default:stone"}, {["x"] = 21, ["y"] = 2, ["z"] = 6, ["name"] = "default:stone"}, {["x"] = 21, ["y"] = 2, ["z"] = 7, ["name"] = "default:stone"}, {["x"] = 21, ["param2"] = 21, ["y"] = 2, ["param1"] = 13, ["z"] = 8, ["name"] = "stairs:slab_stone"}, {["x"] = 21, ["y"] = 3, ["z"] = 1, ["name"] = "default:stone"}, {["x"] = 21, ["y"] = 3, ["z"] = 2, ["name"] = "default:stone"}, {["x"] = 21, ["y"] = 3, ["z"] = 3, ["name"] = "default:stone"}, {["x"] = 21, ["y"] = 3, ["z"] = 4, ["name"] = "default:stone"}, {["x"] = 21, ["y"] = 3, ["z"] = 5, ["name"] = "default:stone"}, {["x"] = 21, ["y"] = 3, ["z"] = 6, ["name"] = "default:stone"}, {["x"] = 21, ["y"] = 3, ["z"] = 7, ["name"] = "default:stone"}, {["x"] = 21, ["y"] = 3, ["z"] = 8, ["name"] = "default:stone"}, {["x"] = 21, ["y"] = 3, ["z"] = 9, ["name"] = "default:stone"}, {["x"] = 21, ["y"] = 4, ["z"] = 1, ["name"] = "default:stone"}, {["x"] = 21, ["param2"] = 1, ["y"] = 4, ["z"] = 2, ["name"] = "default:stonebrick"}, {["x"] = 21, ["param2"] = 1, ["y"] = 4, ["z"] = 3, ["name"] = "default:stonebrick"}, {["x"] = 21, ["param2"] = 1, ["y"] = 4, ["z"] = 4, ["name"] = "default:stonebrick"}, {["x"] = 21, ["param2"] = 1, ["y"] = 4, ["z"] = 5, ["name"] = "default:stonebrick"}, {["x"] = 21, ["param2"] = 1, ["y"] = 4, ["z"] = 6, ["name"] = "default:stonebrick"}, {["x"] = 21, ["param2"] = 1, ["y"] = 4, ["z"] = 7, ["name"] = "default:stonebrick"}, {["x"] = 21, ["param2"] = 1, ["y"] = 4, ["z"] = 8, ["name"] = "default:stonebrick"}, {["x"] = 21, ["y"] = 4, ["z"] = 9, ["name"] = "default:stone"}, {["x"] = 21, ["y"] = 5, ["z"] = 1, ["name"] = "default:stone_block"}, {["x"] = 21, ["y"] = 5, ["z"] = 9, ["name"] = "default:stone_block"}, {["x"] = 22, ["param2"] = 21, ["y"] = 1, ["param1"] = 10, ["z"] = 5, ["name"] = "stairs:slab_stone"}, {["x"] = 22, ["param2"] = 22, ["y"] = 2, ["param1"] = 12, ["z"] = 3, ["name"] = "stairs:slab_stone"}, {["x"] = 22, ["y"] = 2, ["z"] = 4, ["name"] = "default:stone"}, {["x"] = 22, ["y"] = 2, ["z"] = 5, ["name"] = "default:stone"}, {["x"] = 22, ["y"] = 2, ["z"] = 6, ["name"] = "default:stone"}, {["x"] = 22, ["param2"] = 22, ["y"] = 2, ["param1"] = 12, ["z"] = 7, ["name"] = "stairs:slab_stone"}, {["x"] = 22, ["y"] = 3, ["z"] = 1, ["name"] = "default:stone"}, {["x"] = 22, ["y"] = 3, ["z"] = 2, ["name"] = "default:stone"}, {["x"] = 22, ["y"] = 3, ["z"] = 3, ["name"] = "default:stone"}, {["x"] = 22, ["y"] = 3, ["z"] = 4, ["name"] = "default:stone"}, {["x"] = 22, ["y"] = 3, ["z"] = 5, ["name"] = "default:stone"}, {["x"] = 22, ["y"] = 3, ["z"] = 6, ["name"] = "default:stone"}, {["x"] = 22, ["y"] = 3, ["z"] = 7, ["name"] = "default:stone"}, {["x"] = 22, ["y"] = 3, ["z"] = 8, ["name"] = "default:stone"}, {["x"] = 22, ["y"] = 3, ["z"] = 9, ["name"] = "default:stone"}, {["x"] = 22, ["y"] = 4, ["z"] = 1, ["name"] = "default:stone"}, {["x"] = 22, ["param2"] = 1, ["y"] = 4, ["z"] = 2, ["name"] = "default:stonebrick"}, {["x"] = 22, ["param2"] = 1, ["y"] = 4, ["z"] = 3, ["name"] = "default:stonebrick"}, {["x"] = 22, ["param2"] = 1, ["y"] = 4, ["z"] = 4, ["name"] = "default:stonebrick"}, {["x"] = 22, ["param2"] = 1, ["y"] = 4, ["z"] = 5, ["name"] = "default:stonebrick"}, {["x"] = 22, ["param2"] = 1, ["y"] = 4, ["z"] = 6, ["name"] = "default:stonebrick"}, {["x"] = 22, ["param2"] = 1, ["y"] = 4, ["z"] = 7, ["name"] = "default:stonebrick"}, {["x"] = 22, ["param2"] = 1, ["y"] = 4, ["z"] = 8, ["name"] = "default:stonebrick"}, {["x"] = 22, ["y"] = 4, ["z"] = 9, ["name"] = "default:stone"}, {["x"] = 22, ["y"] = 5, ["z"] = 1, ["name"] = "default:stone_block"}, {["x"] = 22, ["y"] = 5, ["z"] = 9, ["name"] = "default:stone_block"}, {["x"] = 23, ["param2"] = 22, ["y"] = 2, ["param1"] = 12, ["z"] = 3, ["name"] = "stairs:slab_stone"}, {["x"] = 23, ["y"] = 2, ["z"] = 4, ["name"] = "default:stone"}, {["x"] = 23, ["y"] = 2, ["z"] = 5, ["name"] = "default:stone"}, {["x"] = 23, ["y"] = 2, ["z"] = 6, ["name"] = "default:stone"}, {["x"] = 23, ["param2"] = 22, ["y"] = 2, ["param1"] = 12, ["z"] = 7, ["name"] = "stairs:slab_stone"}, {["x"] = 23, ["y"] = 3, ["z"] = 1, ["name"] = "default:stone"}, {["x"] = 23, ["y"] = 3, ["z"] = 2, ["name"] = "default:stone"}, {["x"] = 23, ["y"] = 3, ["z"] = 3, ["name"] = "default:stone"}, {["x"] = 23, ["y"] = 3, ["z"] = 4, ["name"] = "default:stone"}, {["x"] = 23, ["y"] = 3, ["z"] = 5, ["name"] = "default:stone"}, {["x"] = 23, ["y"] = 3, ["z"] = 6, ["name"] = "default:stone"}, {["x"] = 23, ["y"] = 3, ["z"] = 7, ["name"] = "default:stone"}, {["x"] = 23, ["y"] = 3, ["z"] = 8, ["name"] = "default:stone"}, {["x"] = 23, ["y"] = 3, ["z"] = 9, ["name"] = "default:stone"}, {["x"] = 23, ["y"] = 4, ["z"] = 1, ["name"] = "default:stone"}, {["x"] = 23, ["param2"] = 1, ["y"] = 4, ["z"] = 2, ["name"] = "default:stonebrick"}, {["x"] = 23, ["param2"] = 1, ["y"] = 4, ["z"] = 3, ["name"] = "default:stonebrick"}, {["x"] = 23, ["param2"] = 1, ["y"] = 4, ["z"] = 4, ["name"] = "default:stonebrick"}, {["x"] = 23, ["param2"] = 1, ["y"] = 4, ["z"] = 5, ["name"] = "default:stonebrick"}, {["x"] = 23, ["param2"] = 1, ["y"] = 4, ["z"] = 6, ["name"] = "default:stonebrick"}, {["x"] = 23, ["param2"] = 1, ["y"] = 4, ["z"] = 7, ["name"] = "default:stonebrick"}, {["x"] = 23, ["param2"] = 1, ["y"] = 4, ["z"] = 8, ["name"] = "default:stonebrick"}, {["x"] = 23, ["y"] = 4, ["z"] = 9, ["name"] = "default:stone"}, {["x"] = 23, ["y"] = 5, ["z"] = 1, ["name"] = "default:stone_block"}, {["x"] = 23, ["y"] = 5, ["z"] = 9, ["name"] = "default:stone_block"}, {["x"] = 24, ["param2"] = 22, ["y"] = 2, ["param1"] = 12, ["z"] = 3, ["name"] = "stairs:slab_stone"}, {["x"] = 24, ["y"] = 2, ["z"] = 4, ["name"] = "default:stone"}, {["x"] = 24, ["y"] = 2, ["z"] = 5, ["name"] = "default:stone"}, {["x"] = 24, ["y"] = 2, ["z"] = 6, ["name"] = "default:stone"}, {["x"] = 24, ["param2"] = 22, ["y"] = 2, ["param1"] = 12, ["z"] = 7, ["name"] = "stairs:slab_stone"}, {["x"] = 24, ["param2"] = 20, ["y"] = 3, ["param1"] = 14, ["z"] = 1, ["name"] = "stairs:slab_stone"}, {["x"] = 24, ["y"] = 3, ["z"] = 2, ["name"] = "default:stone"}, {["x"] = 24, ["y"] = 3, ["z"] = 3, ["name"] = "default:stone"}, {["x"] = 24, ["y"] = 3, ["z"] = 4, ["name"] = "default:stone"}, {["x"] = 24, ["y"] = 3, ["z"] = 5, ["name"] = "default:stone"}, {["x"] = 24, ["y"] = 3, ["z"] = 6, ["name"] = "default:stone"}, {["x"] = 24, ["y"] = 3, ["z"] = 7, ["name"] = "default:stone"}, {["x"] = 24, ["y"] = 3, ["z"] = 8, ["name"] = "default:stone"}, {["x"] = 24, ["param2"] = 21, ["y"] = 3, ["param1"] = 14, ["z"] = 9, ["name"] = "stairs:slab_stone"}, {["x"] = 24, ["y"] = 4, ["z"] = 1, ["name"] = "default:stone"}, {["x"] = 24, ["y"] = 4, ["z"] = 2, ["name"] = "default:stone"}, {["x"] = 24, ["y"] = 4, ["z"] = 3, ["name"] = "default:stone"}, {["x"] = 24, ["y"] = 4, ["z"] = 4, ["name"] = "default:stone"}, {["x"] = 24, ["y"] = 4, ["z"] = 5, ["name"] = "default:stone"}, {["x"] = 24, ["y"] = 4, ["z"] = 6, ["name"] = "default:stone"}, {["x"] = 24, ["y"] = 4, ["z"] = 7, ["name"] = "default:stone"}, {["x"] = 24, ["y"] = 4, ["z"] = 8, ["name"] = "default:stone"}, {["x"] = 24, ["y"] = 4, ["z"] = 9, ["name"] = "default:stone"}, {["x"] = 24, ["y"] = 5, ["z"] = 1, ["name"] = "default:stone_block"}, {["x"] = 24, ["param2"] = 1, ["y"] = 5, ["param1"] = 14, ["z"] = 2, ["name"] = "stairs:slab_stonebrick"}, {["x"] = 24, ["param2"] = 1, ["y"] = 5, ["param1"] = 14, ["z"] = 3, ["name"] = "stairs:slab_stonebrick"}, {["x"] = 24, ["param2"] = 1, ["y"] = 5, ["param1"] = 14, ["z"] = 4, ["name"] = "stairs:slab_stonebrick"}, {["x"] = 24, ["param2"] = 1, ["y"] = 5, ["param1"] = 14, ["z"] = 5, ["name"] = "stairs:slab_stonebrick"}, {["x"] = 24, ["param2"] = 1, ["y"] = 5, ["param1"] = 14, ["z"] = 6, ["name"] = "stairs:slab_stonebrick"}, {["x"] = 24, ["param2"] = 1, ["y"] = 5, ["param1"] = 14, ["z"] = 7, ["name"] = "stairs:slab_stonebrick"}, {["x"] = 24, ["param2"] = 1, ["y"] = 5, ["param1"] = 14, ["z"] = 8, ["name"] = "stairs:slab_stonebrick"}, {["x"] = 24, ["y"] = 5, ["z"] = 9, ["name"] = "default:stone_block"}, {["x"] = 24, ["y"] = 6, ["param1"] = 14, ["z"] = 1, ["name"] = "stairs:slab_stone_block"}, {["x"] = 24, ["y"] = 6, ["param1"] = 14, ["z"] = 9, ["name"] = "stairs:slab_stone_block"}, {["x"] = 25, ["param2"] = 21, ["y"] = 2, ["param1"] = 11, ["z"] = 4, ["name"] = "stairs:slab_stone"}, {["x"] = 25, ["y"] = 2, ["z"] = 5, ["name"] = "default:stone"}, {["x"] = 25, ["param2"] = 21, ["y"] = 2, ["param1"] = 11, ["z"] = 6, ["name"] = "stairs:slab_stone"}, {["x"] = 25, ["param2"] = 20, ["y"] = 3, ["param1"] = 14, ["z"] = 1, ["name"] = "stairs:slab_stone"}, {["x"] = 25, ["y"] = 3, ["z"] = 2, ["name"] = "default:stone"}, {["x"] = 25, ["y"] = 3, ["z"] = 3, ["name"] = "default:stone"}, {["x"] = 25, ["y"] = 3, ["z"] = 4, ["name"] = "default:stone"}, {["x"] = 25, ["y"] = 3, ["z"] = 5, ["name"] = "default:stone"}, {["x"] = 25, ["y"] = 3, ["z"] = 6, ["name"] = "default:stone"}, {["x"] = 25, ["y"] = 3, ["z"] = 7, ["name"] = "default:stone"}, {["x"] = 25, ["y"] = 3, ["z"] = 8, ["name"] = "default:stone"}, {["x"] = 25, ["param2"] = 21, ["y"] = 3, ["param1"] = 14, ["z"] = 9, ["name"] = "stairs:slab_stone"}, {["x"] = 25, ["y"] = 4, ["z"] = 1, ["name"] = "default:stone"}, {["x"] = 25, ["y"] = 4, ["z"] = 2, ["name"] = "default:stone"}, {["x"] = 25, ["y"] = 4, ["z"] = 3, ["name"] = "default:stone"}, {["x"] = 25, ["y"] = 4, ["z"] = 4, ["name"] = "default:stone"}, {["x"] = 25, ["y"] = 4, ["z"] = 5, ["name"] = "default:stone"}, {["x"] = 25, ["y"] = 4, ["z"] = 6, ["name"] = "default:stone"}, {["x"] = 25, ["y"] = 4, ["z"] = 7, ["name"] = "default:stone"}, {["x"] = 25, ["y"] = 4, ["z"] = 8, ["name"] = "default:stone"}, {["x"] = 25, ["y"] = 4, ["z"] = 9, ["name"] = "default:stone"}, {["x"] = 25, ["y"] = 5, ["z"] = 1, ["name"] = "default:stone_block"}, {["x"] = 25, ["param2"] = 1, ["y"] = 5, ["param1"] = 14, ["z"] = 2, ["name"] = "stairs:slab_stonebrick"}, {["x"] = 25, ["param2"] = 1, ["y"] = 5, ["param1"] = 14, ["z"] = 3, ["name"] = "stairs:slab_stonebrick"}, {["x"] = 25, ["param2"] = 1, ["y"] = 5, ["param1"] = 14, ["z"] = 4, ["name"] = "stairs:slab_stonebrick"}, {["x"] = 25, ["param2"] = 1, ["y"] = 5, ["param1"] = 14, ["z"] = 5, ["name"] = "stairs:slab_stonebrick"}, {["x"] = 25, ["param2"] = 1, ["y"] = 5, ["param1"] = 14, ["z"] = 6, ["name"] = "stairs:slab_stonebrick"}, {["x"] = 25, ["param2"] = 1, ["y"] = 5, ["param1"] = 14, ["z"] = 7, ["name"] = "stairs:slab_stonebrick"}, {["x"] = 25, ["param2"] = 1, ["y"] = 5, ["param1"] = 14, ["z"] = 8, ["name"] = "stairs:slab_stonebrick"}, {["x"] = 25, ["y"] = 5, ["z"] = 9, ["name"] = "default:stone_block"}, {["x"] = 25, ["y"] = 6, ["param1"] = 14, ["z"] = 1, ["name"] = "stairs:slab_stone_block"}, {["x"] = 25, ["y"] = 6, ["param1"] = 14, ["z"] = 9, ["name"] = "stairs:slab_stone_block"}, {["x"] = 26, ["param2"] = 21, ["y"] = 2, ["param1"] = 11, ["z"] = 4, ["name"] = "stairs:slab_stone"}, {["x"] = 26, ["param2"] = 21, ["y"] = 2, ["param1"] = 10, ["z"] = 5, ["name"] = "stairs:slab_stone"}, {["x"] = 26, ["param2"] = 21, ["y"] = 2, ["param1"] = 11, ["z"] = 6, ["name"] = "stairs:slab_stone"}, {["x"] = 26, ["param2"] = 21, ["y"] = 3, ["param1"] = 13, ["z"] = 2, ["name"] = "stairs:slab_stone"}, {["x"] = 26, ["y"] = 3, ["z"] = 3, ["name"] = "default:stone"}, {["x"] = 26, ["y"] = 3, ["z"] = 4, ["name"] = "default:stone"}, {["x"] = 26, ["y"] = 3, ["z"] = 5, ["name"] = "default:stone"}, {["x"] = 26, ["y"] = 3, ["z"] = 6, ["name"] = "default:stone"}, {["x"] = 26, ["y"] = 3, ["z"] = 7, ["name"] = "default:stone"}, {["x"] = 26, ["param2"] = 22, ["y"] = 3, ["param1"] = 13, ["z"] = 8, ["name"] = "stairs:slab_stone"}, {["x"] = 26, ["y"] = 4, ["z"] = 1, ["name"] = "default:stone"}, {["x"] = 26, ["y"] = 4, ["z"] = 2, ["name"] = "default:stone"}, {["x"] = 26, ["y"] = 4, ["z"] = 3, ["name"] = "default:stone"}, {["x"] = 26, ["y"] = 4, ["z"] = 4, ["name"] = "default:stone"}, {["x"] = 26, ["y"] = 4, ["z"] = 5, ["name"] = "default:stone"}, {["x"] = 26, ["y"] = 4, ["z"] = 6, ["name"] = "default:stone"}, {["x"] = 26, ["y"] = 4, ["z"] = 7, ["name"] = "default:stone"}, {["x"] = 26, ["y"] = 4, ["z"] = 8, ["name"] = "default:stone"}, {["x"] = 26, ["y"] = 4, ["z"] = 9, ["name"] = "default:stone"}, {["x"] = 26, ["y"] = 5, ["z"] = 1, ["name"] = "default:stone_block"}, {["x"] = 26, ["param2"] = 1, ["y"] = 5, ["param1"] = 14, ["z"] = 2, ["name"] = "stairs:slab_stonebrick"}, {["x"] = 26, ["param2"] = 1, ["y"] = 5, ["param1"] = 14, ["z"] = 3, ["name"] = "stairs:slab_stonebrick"}, {["x"] = 26, ["param2"] = 1, ["y"] = 5, ["param1"] = 14, ["z"] = 4, ["name"] = "stairs:slab_stonebrick"}, {["x"] = 26, ["param2"] = 1, ["y"] = 5, ["param1"] = 14, ["z"] = 5, ["name"] = "stairs:slab_stonebrick"}, {["x"] = 26, ["param2"] = 1, ["y"] = 5, ["param1"] = 14, ["z"] = 6, ["name"] = "stairs:slab_stonebrick"}, {["x"] = 26, ["param2"] = 1, ["y"] = 5, ["param1"] = 14, ["z"] = 7, ["name"] = "stairs:slab_stonebrick"}, {["x"] = 26, ["param2"] = 1, ["y"] = 5, ["param1"] = 14, ["z"] = 8, ["name"] = "stairs:slab_stonebrick"}, {["x"] = 26, ["y"] = 5, ["z"] = 9, ["name"] = "default:stone_block"}, {["x"] = 26, ["y"] = 6, ["param1"] = 14, ["z"] = 1, ["name"] = "stairs:slab_stone_block"}, {["x"] = 26, ["y"] = 6, ["param1"] = 14, ["z"] = 9, ["name"] = "stairs:slab_stone_block"}, {["x"] = 27, ["param2"] = 21, ["y"] = 2, ["param1"] = 11, ["z"] = 4, ["name"] = "stairs:slab_stone"}, {["x"] = 27, ["param2"] = 21, ["y"] = 2, ["param1"] = 10, ["z"] = 5, ["name"] = "stairs:slab_stone"}, {["x"] = 27, ["param2"] = 21, ["y"] = 2, ["param1"] = 11, ["z"] = 6, ["name"] = "stairs:slab_stone"}, {["x"] = 27, ["param2"] = 21, ["y"] = 3, ["param1"] = 13, ["z"] = 2, ["name"] = "stairs:slab_stone"}, {["x"] = 27, ["y"] = 3, ["z"] = 3, ["name"] = "default:stone"}, {["x"] = 27, ["y"] = 3, ["z"] = 4, ["name"] = "default:stone"}, {["x"] = 27, ["y"] = 3, ["z"] = 5, ["name"] = "default:stone"}, {["x"] = 27, ["y"] = 3, ["z"] = 6, ["name"] = "default:stone"}, {["x"] = 27, ["y"] = 3, ["z"] = 7, ["name"] = "default:stone"}, {["x"] = 27, ["param2"] = 22, ["y"] = 3, ["param1"] = 13, ["z"] = 8, ["name"] = "stairs:slab_stone"}, {["x"] = 27, ["y"] = 4, ["z"] = 1, ["name"] = "default:stone"}, {["x"] = 27, ["y"] = 4, ["z"] = 2, ["name"] = "default:stone"}, {["x"] = 27, ["y"] = 4, ["z"] = 3, ["name"] = "default:stone"}, {["x"] = 27, ["y"] = 4, ["z"] = 4, ["name"] = "default:stone"}, {["x"] = 27, ["y"] = 4, ["z"] = 5, ["name"] = "default:stone"}, {["x"] = 27, ["y"] = 4, ["z"] = 6, ["name"] = "default:stone"}, {["x"] = 27, ["y"] = 4, ["z"] = 7, ["name"] = "default:stone"}, {["x"] = 27, ["y"] = 4, ["z"] = 8, ["name"] = "default:stone"}, {["x"] = 27, ["y"] = 4, ["z"] = 9, ["name"] = "default:stone"}, {["x"] = 27, ["y"] = 5, ["z"] = 1, ["name"] = "default:stone_block"}, {["x"] = 27, ["param2"] = 1, ["y"] = 5, ["z"] = 2, ["name"] = "default:stonebrick"}, {["x"] = 27, ["param2"] = 1, ["y"] = 5, ["z"] = 3, ["name"] = "default:stonebrick"}, {["x"] = 27, ["param2"] = 1, ["y"] = 5, ["z"] = 4, ["name"] = "default:stonebrick"}, {["x"] = 27, ["param2"] = 1, ["y"] = 5, ["z"] = 5, ["name"] = "default:stonebrick"}, {["x"] = 27, ["param2"] = 1, ["y"] = 5, ["z"] = 6, ["name"] = "default:stonebrick"}, {["x"] = 27, ["param2"] = 1, ["y"] = 5, ["z"] = 7, ["name"] = "default:stonebrick"}, {["x"] = 27, ["param2"] = 1, ["y"] = 5, ["z"] = 8, ["name"] = "default:stonebrick"}, {["x"] = 27, ["y"] = 5, ["z"] = 9, ["name"] = "default:stone_block"}, {["x"] = 27, ["y"] = 6, ["z"] = 1, ["name"] = "default:stone_block"}, {["x"] = 27, ["y"] = 6, ["z"] = 9, ["name"] = "default:stone_block"}, {["x"] = 28, ["param2"] = 21, ["y"] = 2, ["param1"] = 10, ["z"] = 5, ["name"] = "stairs:slab_stone"}, {["x"] = 28, ["param2"] = 22, ["y"] = 3, ["param1"] = 12, ["z"] = 3, ["name"] = "stairs:slab_stone"}, {["x"] = 28, ["y"] = 3, ["z"] = 4, ["name"] = "default:stone"}, {["x"] = 28, ["y"] = 3, ["z"] = 5, ["name"] = "default:stone"}, {["x"] = 28, ["y"] = 3, ["z"] = 6, ["name"] = "default:stone"}, {["x"] = 28, ["param2"] = 22, ["y"] = 3, ["param1"] = 12, ["z"] = 7, ["name"] = "stairs:slab_stone"}, {["x"] = 28, ["y"] = 4, ["z"] = 1, ["name"] = "default:stone"}, {["x"] = 28, ["y"] = 4, ["z"] = 2, ["name"] = "default:stone"}, {["x"] = 28, ["y"] = 4, ["z"] = 3, ["name"] = "default:stone"}, {["x"] = 28, ["y"] = 4, ["z"] = 4, ["name"] = "default:stone"}, {["x"] = 28, ["y"] = 4, ["z"] = 5, ["name"] = "default:stone"}, {["x"] = 28, ["y"] = 4, ["z"] = 6, ["name"] = "default:stone"}, {["x"] = 28, ["y"] = 4, ["z"] = 7, ["name"] = "default:stone"}, {["x"] = 28, ["y"] = 4, ["z"] = 8, ["name"] = "default:stone"}, {["x"] = 28, ["y"] = 4, ["z"] = 9, ["name"] = "default:stone"}, {["x"] = 28, ["y"] = 5, ["z"] = 1, ["name"] = "default:stone_block"}, {["x"] = 28, ["param2"] = 1, ["y"] = 5, ["z"] = 2, ["name"] = "default:stonebrick"}, {["x"] = 28, ["param2"] = 1, ["y"] = 5, ["z"] = 3, ["name"] = "default:stonebrick"}, {["x"] = 28, ["param2"] = 1, ["y"] = 5, ["z"] = 4, ["name"] = "default:stonebrick"}, {["x"] = 28, ["param2"] = 1, ["y"] = 5, ["z"] = 5, ["name"] = "default:stonebrick"}, {["x"] = 28, ["param2"] = 1, ["y"] = 5, ["z"] = 6, ["name"] = "default:stonebrick"}, {["x"] = 28, ["param2"] = 1, ["y"] = 5, ["z"] = 7, ["name"] = "default:stonebrick"}, {["x"] = 28, ["param2"] = 1, ["y"] = 5, ["z"] = 8, ["name"] = "default:stonebrick"}, {["x"] = 28, ["y"] = 5, ["z"] = 9, ["name"] = "default:stone_block"}, {["x"] = 28, ["y"] = 6, ["z"] = 1, ["name"] = "default:stone_block"}, {["x"] = 28, ["y"] = 6, ["z"] = 9, ["name"] = "default:stone_block"}, {["x"] = 29, ["param2"] = 22, ["y"] = 3, ["param1"] = 12, ["z"] = 3, ["name"] = "stairs:slab_stone"}, {["x"] = 29, ["y"] = 3, ["z"] = 4, ["name"] = "default:stone"}, {["x"] = 29, ["y"] = 3, ["z"] = 5, ["name"] = "default:stone"}, {["x"] = 29, ["y"] = 3, ["z"] = 6, ["name"] = "default:stone"}, {["x"] = 29, ["param2"] = 22, ["y"] = 3, ["param1"] = 12, ["z"] = 7, ["name"] = "stairs:slab_stone"}, {["x"] = 29, ["y"] = 4, ["z"] = 1, ["name"] = "default:stone"}, {["x"] = 29, ["y"] = 4, ["z"] = 2, ["name"] = "default:stone"}, {["x"] = 29, ["y"] = 4, ["z"] = 3, ["name"] = "default:stone"}, {["x"] = 29, ["y"] = 4, ["z"] = 4, ["name"] = "default:stone"}, {["x"] = 29, ["param2"] = 1, ["y"] = 4, ["z"] = 5, ["name"] = "default:stonebrick"}, {["x"] = 29, ["y"] = 4, ["z"] = 6, ["name"] = "default:stone"}, {["x"] = 29, ["y"] = 4, ["z"] = 7, ["name"] = "default:stone"}, {["x"] = 29, ["y"] = 4, ["z"] = 8, ["name"] = "default:stone"}, {["x"] = 29, ["y"] = 4, ["z"] = 9, ["name"] = "default:stone"}, {["x"] = 29, ["y"] = 5, ["z"] = 1, ["name"] = "default:stone_block"}, {["x"] = 29, ["param2"] = 1, ["y"] = 5, ["z"] = 2, ["name"] = "default:stonebrick"}, {["x"] = 29, ["param2"] = 1, ["y"] = 5, ["z"] = 3, ["name"] = "default:stonebrick"}, {["x"] = 29, ["param2"] = 1, ["y"] = 5, ["z"] = 4, ["name"] = "default:stonebrick"}, {["x"] = 29, ["param2"] = 1, ["y"] = 5, ["z"] = 5, ["name"] = "default:stonebrick"}, {["x"] = 29, ["param2"] = 1, ["y"] = 5, ["z"] = 6, ["name"] = "default:stonebrick"}, {["x"] = 29, ["param2"] = 1, ["y"] = 5, ["z"] = 7, ["name"] = "default:stonebrick"}, {["x"] = 29, ["param2"] = 1, ["y"] = 5, ["z"] = 8, ["name"] = "default:stonebrick"}, {["x"] = 29, ["y"] = 5, ["z"] = 9, ["name"] = "default:stone_block"}, {["x"] = 29, ["y"] = 6, ["z"] = 1, ["name"] = "default:stone_block"}, {["x"] = 29, ["y"] = 6, ["z"] = 9, ["name"] = "default:stone_block"}, {["x"] = 30, ["param2"] = 22, ["y"] = 3, ["param1"] = 12, ["z"] = 3, ["name"] = "stairs:slab_stone"}, {["x"] = 30, ["param2"] = 21, ["y"] = 3, ["param1"] = 11, ["z"] = 4, ["name"] = "stairs:slab_stone"}, {["x"] = 30, ["y"] = 3, ["z"] = 5, ["name"] = "default:stone"}, {["x"] = 30, ["param2"] = 21, ["y"] = 3, ["param1"] = 11, ["z"] = 6, ["name"] = "stairs:slab_stone"}, {["x"] = 30, ["param2"] = 22, ["y"] = 3, ["param1"] = 12, ["z"] = 7, ["name"] = "stairs:slab_stone"}, {["x"] = 30, ["y"] = 4, ["z"] = 1, ["name"] = "default:stone"}, {["x"] = 30, ["y"] = 4, ["z"] = 2, ["name"] = "default:stone"}, {["x"] = 30, ["y"] = 4, ["z"] = 3, ["name"] = "default:stone"}, {["x"] = 30, ["y"] = 4, ["z"] = 4, ["name"] = "default:stone"}, {["x"] = 30, ["y"] = 4, ["z"] = 5, ["name"] = "default:stone"}, {["x"] = 30, ["y"] = 4, ["z"] = 6, ["name"] = "default:stone"}, {["x"] = 30, ["y"] = 4, ["z"] = 7, ["name"] = "default:stone"}, {["x"] = 30, ["y"] = 4, ["z"] = 8, ["name"] = "default:stone"}, {["x"] = 30, ["y"] = 4, ["z"] = 9, ["name"] = "default:stone"}, {["x"] = 30, ["y"] = 5, ["z"] = 1, ["name"] = "default:stone_block"}, {["x"] = 30, ["param2"] = 1, ["y"] = 5, ["z"] = 2, ["name"] = "default:stonebrick"}, {["x"] = 30, ["param2"] = 1, ["y"] = 5, ["z"] = 3, ["name"] = "default:stonebrick"}, {["x"] = 30, ["param2"] = 1, ["y"] = 5, ["z"] = 4, ["name"] = "default:stonebrick"}, {["x"] = 30, ["param2"] = 1, ["y"] = 5, ["z"] = 5, ["name"] = "default:stonebrick"}, {["x"] = 30, ["param2"] = 1, ["y"] = 5, ["z"] = 6, ["name"] = "default:stonebrick"}, {["x"] = 30, ["param2"] = 1, ["y"] = 5, ["z"] = 7, ["name"] = "default:stonebrick"}, {["x"] = 30, ["param2"] = 1, ["y"] = 5, ["z"] = 8, ["name"] = "default:stonebrick"}, {["x"] = 30, ["y"] = 5, ["z"] = 9, ["name"] = "default:stone_block"}, {["x"] = 30, ["y"] = 6, ["z"] = 1, ["name"] = "default:stone_block"}, {["x"] = 30, ["y"] = 6, ["z"] = 9, ["name"] = "default:stone_block"}, {["x"] = 31, ["param2"] = 21, ["y"] = 3, ["param1"] = 11, ["z"] = 4, ["name"] = "stairs:slab_stone"}, {["x"] = 31, ["y"] = 3, ["z"] = 5, ["name"] = "default:stone"}, {["x"] = 31, ["param2"] = 21, ["y"] = 3, ["param1"] = 11, ["z"] = 6, ["name"] = "stairs:slab_stone"}, {["x"] = 31, ["y"] = 4, ["z"] = 1, ["name"] = "default:stone"}, {["x"] = 31, ["y"] = 4, ["z"] = 2, ["name"] = "default:stone"}, {["x"] = 31, ["y"] = 4, ["z"] = 3, ["name"] = "default:stone"}, {["x"] = 31, ["y"] = 4, ["z"] = 4, ["name"] = "default:stone"}, {["x"] = 31, ["y"] = 4, ["z"] = 5, ["name"] = "default:stone"}, {["x"] = 31, ["y"] = 4, ["z"] = 6, ["name"] = "default:stone"}, {["x"] = 31, ["y"] = 4, ["z"] = 7, ["name"] = "default:stone"}, {["x"] = 31, ["y"] = 4, ["z"] = 8, ["name"] = "default:stone"}, {["x"] = 31, ["y"] = 4, ["z"] = 9, ["name"] = "default:stone"}, {["x"] = 31, ["y"] = 5, ["z"] = 1, ["name"] = "default:stone_block"}, {["x"] = 31, ["param2"] = 1, ["y"] = 5, ["z"] = 2, ["name"] = "default:stonebrick"}, {["x"] = 31, ["param2"] = 1, ["y"] = 5, ["z"] = 3, ["name"] = "default:stonebrick"}, {["x"] = 31, ["param2"] = 1, ["y"] = 5, ["z"] = 4, ["name"] = "default:stonebrick"}, {["x"] = 31, ["param2"] = 1, ["y"] = 5, ["z"] = 5, ["name"] = "default:stonebrick"}, {["x"] = 31, ["param2"] = 1, ["y"] = 5, ["z"] = 6, ["name"] = "default:stonebrick"}, {["x"] = 31, ["param2"] = 1, ["y"] = 5, ["z"] = 7, ["name"] = "default:stonebrick"}, {["x"] = 31, ["param2"] = 1, ["y"] = 5, ["z"] = 8, ["name"] = "default:stonebrick"}, {["x"] = 31, ["y"] = 5, ["z"] = 9, ["name"] = "default:stone_block"}, {["x"] = 31, ["y"] = 6, ["z"] = 1, ["name"] = "default:stone_block"}, {["x"] = 31, ["y"] = 6, ["z"] = 9, ["name"] = "default:stone_block"}, {["x"] = 32, ["param2"] = 20, ["y"] = 3, ["param1"] = 11, ["z"] = 4, ["name"] = "stairs:slab_stone"}, {["x"] = 32, ["y"] = 3, ["z"] = 5, ["name"] = "default:stone"}, {["x"] = 32, ["param2"] = 22, ["y"] = 3, ["param1"] = 11, ["z"] = 6, ["name"] = "stairs:slab_stone"}, {["x"] = 32, ["y"] = 4, ["z"] = 1, ["name"] = "default:stone"}, {["x"] = 32, ["y"] = 4, ["z"] = 2, ["name"] = "default:stone"}, {["x"] = 32, ["y"] = 4, ["z"] = 3, ["name"] = "default:stone"}, {["x"] = 32, ["y"] = 4, ["z"] = 4, ["name"] = "default:stone"}, {["x"] = 32, ["y"] = 4, ["z"] = 5, ["name"] = "default:stone"}, {["x"] = 32, ["y"] = 4, ["z"] = 6, ["name"] = "default:stone"}, {["x"] = 32, ["y"] = 4, ["z"] = 7, ["name"] = "default:stone"}, {["x"] = 32, ["y"] = 4, ["z"] = 8, ["name"] = "default:stone"}, {["x"] = 32, ["y"] = 4, ["z"] = 9, ["name"] = "default:stone"}, {["x"] = 32, ["y"] = 5, ["z"] = 1, ["name"] = "default:stone_block"}, {["x"] = 32, ["param2"] = 1, ["y"] = 5, ["z"] = 2, ["name"] = "default:stonebrick"}, {["x"] = 32, ["param2"] = 1, ["y"] = 5, ["z"] = 3, ["name"] = "default:stonebrick"}, {["x"] = 32, ["param2"] = 1, ["y"] = 5, ["z"] = 4, ["name"] = "default:stonebrick"}, {["x"] = 32, ["param2"] = 1, ["y"] = 5, ["z"] = 5, ["name"] = "default:stonebrick"}, {["x"] = 32, ["param2"] = 1, ["y"] = 5, ["z"] = 6, ["name"] = "default:stonebrick"}, {["x"] = 32, ["param2"] = 1, ["y"] = 5, ["z"] = 7, ["name"] = "default:stonebrick"}, {["x"] = 32, ["param2"] = 1, ["y"] = 5, ["z"] = 8, ["name"] = "default:stonebrick"}, {["x"] = 32, ["y"] = 5, ["z"] = 9, ["name"] = "default:stone_block"}, {["x"] = 32, ["y"] = 6, ["z"] = 1, ["name"] = "default:stone_block"}, {["x"] = 32, ["y"] = 6, ["z"] = 9, ["name"] = "default:stone_block"}, {["x"] = 33, ["param2"] = 23, ["y"] = 3, ["param1"] = 11, ["z"] = 4, ["name"] = "stairs:slab_stone"}, {["x"] = 33, ["y"] = 3, ["z"] = 5, ["name"] = "default:stone"}, {["x"] = 33, ["param2"] = 23, ["y"] = 3, ["param1"] = 11, ["z"] = 6, ["name"] = "stairs:slab_stone"}, {["x"] = 33, ["y"] = 4, ["z"] = 1, ["name"] = "default:stone"}, {["x"] = 33, ["y"] = 4, ["z"] = 2, ["name"] = "default:stone"}, {["x"] = 33, ["y"] = 4, ["z"] = 3, ["name"] = "default:stone"}, {["x"] = 33, ["y"] = 4, ["z"] = 4, ["name"] = "default:stone"}, {["x"] = 33, ["y"] = 4, ["z"] = 5, ["name"] = "default:stone"}, {["x"] = 33, ["y"] = 4, ["z"] = 6, ["name"] = "default:stone"}, {["x"] = 33, ["y"] = 4, ["z"] = 7, ["name"] = "default:stone"}, {["x"] = 33, ["y"] = 4, ["z"] = 8, ["name"] = "default:stone"}, {["x"] = 33, ["y"] = 4, ["z"] = 9, ["name"] = "default:stone"}, {["x"] = 33, ["y"] = 5, ["z"] = 1, ["name"] = "default:stone_block"}, {["x"] = 33, ["param2"] = 1, ["y"] = 5, ["z"] = 2, ["name"] = "default:stonebrick"}, {["x"] = 33, ["param2"] = 1, ["y"] = 5, ["z"] = 3, ["name"] = "default:stonebrick"}, {["x"] = 33, ["param2"] = 1, ["y"] = 5, ["z"] = 4, ["name"] = "default:stonebrick"}, {["x"] = 33, ["param2"] = 1, ["y"] = 5, ["z"] = 5, ["name"] = "default:stonebrick"}, {["x"] = 33, ["param2"] = 1, ["y"] = 5, ["z"] = 6, ["name"] = "default:stonebrick"}, {["x"] = 33, ["param2"] = 1, ["y"] = 5, ["z"] = 7, ["name"] = "default:stonebrick"}, {["x"] = 33, ["param2"] = 1, ["y"] = 5, ["z"] = 8, ["name"] = "default:stonebrick"}, {["x"] = 33, ["y"] = 5, ["z"] = 9, ["name"] = "default:stone_block"}, {["x"] = 33, ["y"] = 6, ["z"] = 1, ["name"] = "default:stone_block"}, {["x"] = 33, ["y"] = 6, ["z"] = 9, ["name"] = "default:stone_block"}, {["x"] = 34, ["param2"] = 23, ["y"] = 3, ["param1"] = 11, ["z"] = 4, ["name"] = "stairs:slab_stone"}, {["x"] = 34, ["y"] = 3, ["z"] = 5, ["name"] = "default:stone"}, {["x"] = 34, ["param2"] = 23, ["y"] = 3, ["param1"] = 11, ["z"] = 6, ["name"] = "stairs:slab_stone"}, {["x"] = 34, ["y"] = 4, ["z"] = 1, ["name"] = "default:stone"}, {["x"] = 34, ["y"] = 4, ["z"] = 2, ["name"] = "default:stone"}, {["x"] = 34, ["y"] = 4, ["z"] = 3, ["name"] = "default:stone"}, {["x"] = 34, ["y"] = 4, ["z"] = 4, ["name"] = "default:stone"}, {["x"] = 34, ["y"] = 4, ["z"] = 5, ["name"] = "default:stone"}, {["x"] = 34, ["y"] = 4, ["z"] = 6, ["name"] = "default:stone"}, {["x"] = 34, ["y"] = 4, ["z"] = 7, ["name"] = "default:stone"}, {["x"] = 34, ["y"] = 4, ["z"] = 8, ["name"] = "default:stone"}, {["x"] = 34, ["y"] = 4, ["z"] = 9, ["name"] = "default:stone"}, {["x"] = 34, ["y"] = 5, ["z"] = 1, ["name"] = "default:stone_block"}, {["x"] = 34, ["param2"] = 1, ["y"] = 5, ["z"] = 2, ["name"] = "default:stonebrick"}, {["x"] = 34, ["param2"] = 1, ["y"] = 5, ["z"] = 3, ["name"] = "default:stonebrick"}, {["x"] = 34, ["param2"] = 1, ["y"] = 5, ["z"] = 4, ["name"] = "default:stonebrick"}, {["x"] = 34, ["param2"] = 1, ["y"] = 5, ["z"] = 5, ["name"] = "default:stonebrick"}, {["x"] = 34, ["param2"] = 1, ["y"] = 5, ["z"] = 6, ["name"] = "default:stonebrick"}, {["x"] = 34, ["param2"] = 1, ["y"] = 5, ["z"] = 7, ["name"] = "default:stonebrick"}, {["x"] = 34, ["param2"] = 1, ["y"] = 5, ["z"] = 8, ["name"] = "default:stonebrick"}, {["x"] = 34, ["y"] = 5, ["z"] = 9, ["name"] = "default:stone_block"}, {["x"] = 34, ["y"] = 6, ["z"] = 1, ["name"] = "default:stone_block"}, {["x"] = 34, ["y"] = 6, ["z"] = 9, ["name"] = "default:stone_block"}, {["x"] = 35, ["param2"] = 22, ["y"] = 3, ["param1"] = 12, ["z"] = 3, ["name"] = "stairs:slab_stone"}, {["x"] = 35, ["param2"] = 23, ["y"] = 3, ["param1"] = 11, ["z"] = 4, ["name"] = "stairs:slab_stone"}, {["x"] = 35, ["y"] = 3, ["z"] = 5, ["name"] = "default:stone"}, {["x"] = 35, ["param2"] = 22, ["y"] = 3, ["param1"] = 11, ["z"] = 6, ["name"] = "stairs:slab_stone"}, {["x"] = 35, ["param2"] = 23, ["y"] = 3, ["param1"] = 12, ["z"] = 7, ["name"] = "stairs:slab_stone"}, {["x"] = 35, ["y"] = 4, ["z"] = 1, ["name"] = "default:stone"}, {["x"] = 35, ["y"] = 4, ["z"] = 2, ["name"] = "default:stone"}, {["x"] = 35, ["y"] = 4, ["z"] = 3, ["name"] = "default:stone"}, {["x"] = 35, ["y"] = 4, ["z"] = 4, ["name"] = "default:stone"}, {["x"] = 35, ["y"] = 4, ["z"] = 5, ["name"] = "default:stone"}, {["x"] = 35, ["y"] = 4, ["z"] = 6, ["name"] = "default:stone"}, {["x"] = 35, ["y"] = 4, ["z"] = 7, ["name"] = "default:stone"}, {["x"] = 35, ["y"] = 4, ["z"] = 8, ["name"] = "default:stone"}, {["x"] = 35, ["y"] = 4, ["z"] = 9, ["name"] = "default:stone"}, {["x"] = 35, ["y"] = 5, ["z"] = 1, ["name"] = "default:stone_block"}, {["x"] = 35, ["param2"] = 1, ["y"] = 5, ["z"] = 2, ["name"] = "default:stonebrick"}, {["x"] = 35, ["param2"] = 1, ["y"] = 5, ["z"] = 3, ["name"] = "default:stonebrick"}, {["x"] = 35, ["param2"] = 1, ["y"] = 5, ["z"] = 4, ["name"] = "default:stonebrick"}, {["x"] = 35, ["param2"] = 1, ["y"] = 5, ["z"] = 5, ["name"] = "default:stonebrick"}, {["x"] = 35, ["param2"] = 1, ["y"] = 5, ["z"] = 6, ["name"] = "default:stonebrick"}, {["x"] = 35, ["param2"] = 1, ["y"] = 5, ["z"] = 7, ["name"] = "default:stonebrick"}, {["x"] = 35, ["param2"] = 1, ["y"] = 5, ["z"] = 8, ["name"] = "default:stonebrick"}, {["x"] = 35, ["y"] = 5, ["z"] = 9, ["name"] = "default:stone_block"}, {["x"] = 35, ["y"] = 6, ["z"] = 1, ["name"] = "default:stone_block"}, {["x"] = 35, ["y"] = 6, ["z"] = 9, ["name"] = "default:stone_block"}, {["x"] = 36, ["param2"] = 22, ["y"] = 3, ["param1"] = 12, ["z"] = 3, ["name"] = "stairs:slab_stone"}, {["x"] = 36, ["y"] = 3, ["z"] = 4, ["name"] = "default:stone"}, {["x"] = 36, ["y"] = 3, ["z"] = 5, ["name"] = "default:stone"}, {["x"] = 36, ["y"] = 3, ["z"] = 6, ["name"] = "default:stone"}, {["x"] = 36, ["param2"] = 22, ["y"] = 3, ["param1"] = 12, ["z"] = 7, ["name"] = "stairs:slab_stone"}, {["x"] = 36, ["y"] = 4, ["z"] = 1, ["name"] = "default:stone"}, {["x"] = 36, ["y"] = 4, ["z"] = 2, ["name"] = "default:stone"}, {["x"] = 36, ["y"] = 4, ["z"] = 3, ["name"] = "default:stone"}, {["x"] = 36, ["y"] = 4, ["z"] = 4, ["name"] = "default:stone"}, {["x"] = 36, ["y"] = 4, ["z"] = 5, ["name"] = "default:stone"}, {["x"] = 36, ["y"] = 4, ["z"] = 6, ["name"] = "default:stone"}, {["x"] = 36, ["y"] = 4, ["z"] = 7, ["name"] = "default:stone"}, {["x"] = 36, ["y"] = 4, ["z"] = 8, ["name"] = "default:stone"}, {["x"] = 36, ["y"] = 4, ["z"] = 9, ["name"] = "default:stone"}, {["x"] = 36, ["y"] = 5, ["z"] = 1, ["name"] = "default:stone_block"}, {["x"] = 36, ["param2"] = 1, ["y"] = 5, ["z"] = 2, ["name"] = "default:stonebrick"}, {["x"] = 36, ["param2"] = 1, ["y"] = 5, ["z"] = 3, ["name"] = "default:stonebrick"}, {["x"] = 36, ["param2"] = 1, ["y"] = 5, ["z"] = 4, ["name"] = "default:stonebrick"}, {["x"] = 36, ["param2"] = 1, ["y"] = 5, ["z"] = 5, ["name"] = "default:stonebrick"}, {["x"] = 36, ["param2"] = 1, ["y"] = 5, ["z"] = 6, ["name"] = "default:stonebrick"}, {["x"] = 36, ["param2"] = 1, ["y"] = 5, ["z"] = 7, ["name"] = "default:stonebrick"}, {["x"] = 36, ["param2"] = 1, ["y"] = 5, ["z"] = 8, ["name"] = "default:stonebrick"}, {["x"] = 36, ["y"] = 5, ["z"] = 9, ["name"] = "default:stone_block"}, {["x"] = 36, ["y"] = 6, ["z"] = 1, ["name"] = "default:stone_block"}, {["x"] = 36, ["y"] = 6, ["z"] = 9, ["name"] = "default:stone_block"}, {["x"] = 37, ["param2"] = 23, ["y"] = 2, ["param1"] = 10, ["z"] = 5, ["name"] = "stairs:slab_stone"}, {["x"] = 37, ["param2"] = 22, ["y"] = 3, ["param1"] = 12, ["z"] = 3, ["name"] = "stairs:slab_stone"}, {["x"] = 37, ["y"] = 3, ["z"] = 4, ["name"] = "default:stone"}, {["x"] = 37, ["y"] = 3, ["z"] = 5, ["name"] = "default:stone"}, {["x"] = 37, ["y"] = 3, ["z"] = 6, ["name"] = "default:stone"}, {["x"] = 37, ["param2"] = 22, ["y"] = 3, ["param1"] = 12, ["z"] = 7, ["name"] = "stairs:slab_stone"}, {["x"] = 37, ["y"] = 4, ["z"] = 1, ["name"] = "default:stone"}, {["x"] = 37, ["y"] = 4, ["z"] = 2, ["name"] = "default:stone"}, {["x"] = 37, ["y"] = 4, ["z"] = 3, ["name"] = "default:stone"}, {["x"] = 37, ["y"] = 4, ["z"] = 4, ["name"] = "default:stone"}, {["x"] = 37, ["y"] = 4, ["z"] = 5, ["name"] = "default:stone"}, {["x"] = 37, ["y"] = 4, ["z"] = 6, ["name"] = "default:stone"}, {["x"] = 37, ["y"] = 4, ["z"] = 7, ["name"] = "default:stone"}, {["x"] = 37, ["y"] = 4, ["z"] = 8, ["name"] = "default:stone"}, {["x"] = 37, ["y"] = 4, ["z"] = 9, ["name"] = "default:stone"}, {["x"] = 37, ["y"] = 5, ["z"] = 1, ["name"] = "default:stone_block"}, {["x"] = 37, ["param2"] = 1, ["y"] = 5, ["z"] = 2, ["name"] = "default:stonebrick"}, {["x"] = 37, ["param2"] = 1, ["y"] = 5, ["z"] = 3, ["name"] = "default:stonebrick"}, {["x"] = 37, ["param2"] = 1, ["y"] = 5, ["z"] = 4, ["name"] = "default:stonebrick"}, {["x"] = 37, ["param2"] = 1, ["y"] = 5, ["z"] = 5, ["name"] = "default:stonebrick"}, {["x"] = 37, ["param2"] = 1, ["y"] = 5, ["z"] = 6, ["name"] = "default:stonebrick"}, {["x"] = 37, ["param2"] = 1, ["y"] = 5, ["z"] = 7, ["name"] = "default:stonebrick"}, {["x"] = 37, ["param2"] = 1, ["y"] = 5, ["z"] = 8, ["name"] = "default:stonebrick"}, {["x"] = 37, ["y"] = 5, ["z"] = 9, ["name"] = "default:stone_block"}, {["x"] = 37, ["y"] = 6, ["z"] = 1, ["name"] = "default:stone_block"}, {["x"] = 37, ["y"] = 6, ["z"] = 9, ["name"] = "default:stone_block"}, {["x"] = 38, ["param2"] = 23, ["y"] = 2, ["param1"] = 11, ["z"] = 4, ["name"] = "stairs:slab_stone"}, {["x"] = 38, ["param2"] = 23, ["y"] = 2, ["param1"] = 10, ["z"] = 5, ["name"] = "stairs:slab_stone"}, {["x"] = 38, ["param2"] = 23, ["y"] = 2, ["param1"] = 11, ["z"] = 6, ["name"] = "stairs:slab_stone"}, {["x"] = 38, ["param2"] = 20, ["y"] = 3, ["param1"] = 13, ["z"] = 2, ["name"] = "stairs:slab_stone"}, {["x"] = 38, ["y"] = 3, ["z"] = 3, ["name"] = "default:stone"}, {["x"] = 38, ["y"] = 3, ["z"] = 4, ["name"] = "default:stone"}, {["x"] = 38, ["y"] = 3, ["z"] = 5, ["name"] = "default:stone"}, {["x"] = 38, ["y"] = 3, ["z"] = 6, ["name"] = "default:stone"}, {["x"] = 38, ["y"] = 3, ["z"] = 7, ["name"] = "default:stone"}, {["x"] = 38, ["param2"] = 22, ["y"] = 3, ["param1"] = 13, ["z"] = 8, ["name"] = "stairs:slab_stone"}, {["x"] = 38, ["y"] = 4, ["z"] = 1, ["name"] = "default:stone"}, {["x"] = 38, ["y"] = 4, ["z"] = 2, ["name"] = "default:stone"}, {["x"] = 38, ["y"] = 4, ["z"] = 3, ["name"] = "default:stone"}, {["x"] = 38, ["y"] = 4, ["z"] = 4, ["name"] = "default:stone"}, {["x"] = 38, ["y"] = 4, ["z"] = 5, ["name"] = "default:stone"}, {["x"] = 38, ["y"] = 4, ["z"] = 6, ["name"] = "default:stone"}, {["x"] = 38, ["y"] = 4, ["z"] = 7, ["name"] = "default:stone"}, {["x"] = 38, ["y"] = 4, ["z"] = 8, ["name"] = "default:stone"}, {["x"] = 38, ["y"] = 4, ["z"] = 9, ["name"] = "default:stone"}, {["x"] = 38, ["y"] = 5, ["z"] = 1, ["name"] = "default:stone_block"}, {["x"] = 38, ["param2"] = 1, ["y"] = 5, ["z"] = 2, ["name"] = "default:stonebrick"}, {["x"] = 38, ["param2"] = 1, ["y"] = 5, ["z"] = 3, ["name"] = "default:stonebrick"}, {["x"] = 38, ["param2"] = 1, ["y"] = 5, ["z"] = 4, ["name"] = "default:stonebrick"}, {["x"] = 38, ["param2"] = 1, ["y"] = 5, ["z"] = 5, ["name"] = "default:stonebrick"}, {["x"] = 38, ["param2"] = 1, ["y"] = 5, ["z"] = 6, ["name"] = "default:stonebrick"}, {["x"] = 38, ["param2"] = 1, ["y"] = 5, ["z"] = 7, ["name"] = "default:stonebrick"}, {["x"] = 38, ["param2"] = 1, ["y"] = 5, ["z"] = 8, ["name"] = "default:stonebrick"}, {["x"] = 38, ["y"] = 5, ["z"] = 9, ["name"] = "default:stone_block"}, {["x"] = 38, ["y"] = 6, ["z"] = 1, ["name"] = "default:stone_block"}, {["x"] = 38, ["y"] = 6, ["z"] = 9, ["name"] = "default:stone_block"}, {["x"] = 39, ["param2"] = 23, ["y"] = 2, ["param1"] = 11, ["z"] = 4, ["name"] = "stairs:slab_stone"}, {["x"] = 39, ["param2"] = 23, ["y"] = 2, ["param1"] = 10, ["z"] = 5, ["name"] = "stairs:slab_stone"}, {["x"] = 39, ["param2"] = 23, ["y"] = 2, ["param1"] = 11, ["z"] = 6, ["name"] = "stairs:slab_stone"}, {["x"] = 39, ["param2"] = 20, ["y"] = 3, ["param1"] = 13, ["z"] = 2, ["name"] = "stairs:slab_stone"}, {["x"] = 39, ["y"] = 3, ["z"] = 3, ["name"] = "default:stone"}, {["x"] = 39, ["y"] = 3, ["z"] = 4, ["name"] = "default:stone"}, {["x"] = 39, ["y"] = 3, ["z"] = 5, ["name"] = "default:stone"}, {["x"] = 39, ["y"] = 3, ["z"] = 6, ["name"] = "default:stone"}, {["x"] = 39, ["y"] = 3, ["z"] = 7, ["name"] = "default:stone"}, {["x"] = 39, ["param2"] = 22, ["y"] = 3, ["param1"] = 13, ["z"] = 8, ["name"] = "stairs:slab_stone"}, {["x"] = 39, ["y"] = 4, ["z"] = 1, ["name"] = "default:stone"}, {["x"] = 39, ["y"] = 4, ["z"] = 2, ["name"] = "default:stone"}, {["x"] = 39, ["y"] = 4, ["z"] = 3, ["name"] = "default:stone"}, {["x"] = 39, ["y"] = 4, ["z"] = 4, ["name"] = "default:stone"}, {["x"] = 39, ["y"] = 4, ["z"] = 5, ["name"] = "default:stone"}, {["x"] = 39, ["y"] = 4, ["z"] = 6, ["name"] = "default:stone"}, {["x"] = 39, ["y"] = 4, ["z"] = 7, ["name"] = "default:stone"}, {["x"] = 39, ["y"] = 4, ["z"] = 8, ["name"] = "default:stone"}, {["x"] = 39, ["y"] = 4, ["z"] = 9, ["name"] = "default:stone"}, {["x"] = 39, ["y"] = 5, ["z"] = 1, ["name"] = "default:stone_block"}, {["x"] = 39, ["param2"] = 1, ["y"] = 5, ["param1"] = 14, ["z"] = 2, ["name"] = "stairs:slab_stonebrick"}, {["x"] = 39, ["param2"] = 1, ["y"] = 5, ["param1"] = 14, ["z"] = 3, ["name"] = "stairs:slab_stonebrick"}, {["x"] = 39, ["param2"] = 1, ["y"] = 5, ["param1"] = 14, ["z"] = 4, ["name"] = "stairs:slab_stonebrick"}, {["x"] = 39, ["param2"] = 1, ["y"] = 5, ["param1"] = 14, ["z"] = 5, ["name"] = "stairs:slab_stonebrick"}, {["x"] = 39, ["param2"] = 1, ["y"] = 5, ["param1"] = 14, ["z"] = 6, ["name"] = "stairs:slab_stonebrick"}, {["x"] = 39, ["param2"] = 1, ["y"] = 5, ["param1"] = 14, ["z"] = 7, ["name"] = "stairs:slab_stonebrick"}, {["x"] = 39, ["param2"] = 1, ["y"] = 5, ["param1"] = 14, ["z"] = 8, ["name"] = "stairs:slab_stonebrick"}, {["x"] = 39, ["y"] = 5, ["z"] = 9, ["name"] = "default:stone_block"}, {["x"] = 39, ["param2"] = 2, ["y"] = 6, ["param1"] = 14, ["z"] = 1, ["name"] = "stairs:slab_stone_block"}, {["x"] = 39, ["param2"] = 2, ["y"] = 6, ["param1"] = 14, ["z"] = 9, ["name"] = "stairs:slab_stone_block"}, {["x"] = 40, ["param2"] = 23, ["y"] = 2, ["param1"] = 11, ["z"] = 4, ["name"] = "stairs:slab_stone"}, {["x"] = 40, ["y"] = 2, ["z"] = 5, ["name"] = "default:stone"}, {["x"] = 40, ["param2"] = 23, ["y"] = 2, ["param1"] = 11, ["z"] = 6, ["name"] = "stairs:slab_stone"}, {["x"] = 40, ["param2"] = 20, ["y"] = 3, ["param1"] = 14, ["z"] = 1, ["name"] = "stairs:slab_stone"}, {["x"] = 40, ["y"] = 3, ["z"] = 2, ["name"] = "default:stone"}, {["x"] = 40, ["y"] = 3, ["z"] = 3, ["name"] = "default:stone"}, {["x"] = 40, ["y"] = 3, ["z"] = 4, ["name"] = "default:stone"}, {["x"] = 40, ["y"] = 3, ["z"] = 5, ["name"] = "default:stone"}, {["x"] = 40, ["y"] = 3, ["z"] = 6, ["name"] = "default:stone"}, {["x"] = 40, ["y"] = 3, ["z"] = 7, ["name"] = "default:stone"}, {["x"] = 40, ["y"] = 3, ["z"] = 8, ["name"] = "default:stone"}, {["x"] = 40, ["param2"] = 22, ["y"] = 3, ["param1"] = 14, ["z"] = 9, ["name"] = "stairs:slab_stone"}, {["x"] = 40, ["y"] = 4, ["z"] = 1, ["name"] = "default:stone"}, {["x"] = 40, ["y"] = 4, ["z"] = 2, ["name"] = "default:stone"}, {["x"] = 40, ["y"] = 4, ["z"] = 3, ["name"] = "default:stone"}, {["x"] = 40, ["y"] = 4, ["z"] = 4, ["name"] = "default:stone"}, {["x"] = 40, ["y"] = 4, ["z"] = 5, ["name"] = "default:stone"}, {["x"] = 40, ["y"] = 4, ["z"] = 6, ["name"] = "default:stone"}, {["x"] = 40, ["y"] = 4, ["z"] = 7, ["name"] = "default:stone"}, {["x"] = 40, ["y"] = 4, ["z"] = 8, ["name"] = "default:stone"}, {["x"] = 40, ["y"] = 4, ["z"] = 9, ["name"] = "default:stone"}, {["x"] = 40, ["y"] = 5, ["z"] = 1, ["name"] = "default:stone_block"}, {["x"] = 40, ["param2"] = 1, ["y"] = 5, ["param1"] = 14, ["z"] = 2, ["name"] = "stairs:slab_stonebrick"}, {["x"] = 40, ["param2"] = 1, ["y"] = 5, ["param1"] = 14, ["z"] = 3, ["name"] = "stairs:slab_stonebrick"}, {["x"] = 40, ["param2"] = 1, ["y"] = 5, ["param1"] = 14, ["z"] = 4, ["name"] = "stairs:slab_stonebrick"}, {["x"] = 40, ["param2"] = 1, ["y"] = 5, ["param1"] = 14, ["z"] = 5, ["name"] = "stairs:slab_stonebrick"}, {["x"] = 40, ["param2"] = 1, ["y"] = 5, ["param1"] = 14, ["z"] = 6, ["name"] = "stairs:slab_stonebrick"}, {["x"] = 40, ["param2"] = 1, ["y"] = 5, ["param1"] = 14, ["z"] = 7, ["name"] = "stairs:slab_stonebrick"}, {["x"] = 40, ["param2"] = 1, ["y"] = 5, ["param1"] = 14, ["z"] = 8, ["name"] = "stairs:slab_stonebrick"}, {["x"] = 40, ["y"] = 5, ["z"] = 9, ["name"] = "default:stone_block"}, {["x"] = 40, ["param2"] = 2, ["y"] = 6, ["param1"] = 14, ["z"] = 1, ["name"] = "stairs:slab_stone_block"}, {["x"] = 40, ["param2"] = 2, ["y"] = 6, ["param1"] = 14, ["z"] = 9, ["name"] = "stairs:slab_stone_block"}, {["x"] = 41, ["param2"] = 22, ["y"] = 2, ["param1"] = 12, ["z"] = 3, ["name"] = "stairs:slab_stone"}, {["x"] = 41, ["y"] = 2, ["z"] = 4, ["name"] = "default:stone"}, {["x"] = 41, ["y"] = 2, ["z"] = 5, ["name"] = "default:stone"}, {["x"] = 41, ["y"] = 2, ["z"] = 6, ["name"] = "default:stone"}, {["x"] = 41, ["param2"] = 22, ["y"] = 2, ["param1"] = 12, ["z"] = 7, ["name"] = "stairs:slab_stone"}, {["x"] = 41, ["param2"] = 23, ["y"] = 3, ["param1"] = 14, ["z"] = 1, ["name"] = "stairs:slab_stone"}, {["x"] = 41, ["y"] = 3, ["z"] = 2, ["name"] = "default:stone"}, {["x"] = 41, ["y"] = 3, ["z"] = 3, ["name"] = "default:stone"}, {["x"] = 41, ["y"] = 3, ["z"] = 4, ["name"] = "default:stone"}, {["x"] = 41, ["y"] = 3, ["z"] = 5, ["name"] = "default:stone"}, {["x"] = 41, ["y"] = 3, ["z"] = 6, ["name"] = "default:stone"}, {["x"] = 41, ["y"] = 3, ["z"] = 7, ["name"] = "default:stone"}, {["x"] = 41, ["y"] = 3, ["z"] = 8, ["name"] = "default:stone"}, {["x"] = 41, ["param2"] = 22, ["y"] = 3, ["param1"] = 14, ["z"] = 9, ["name"] = "stairs:slab_stone"}, {["x"] = 41, ["y"] = 4, ["z"] = 1, ["name"] = "default:stone"}, {["x"] = 41, ["y"] = 4, ["z"] = 2, ["name"] = "default:stone"}, {["x"] = 41, ["y"] = 4, ["z"] = 3, ["name"] = "default:stone"}, {["x"] = 41, ["y"] = 4, ["z"] = 4, ["name"] = "default:stone"}, {["x"] = 41, ["y"] = 4, ["z"] = 5, ["name"] = "default:stone"}, {["x"] = 41, ["y"] = 4, ["z"] = 6, ["name"] = "default:stone"}, {["x"] = 41, ["y"] = 4, ["z"] = 7, ["name"] = "default:stone"}, {["x"] = 41, ["y"] = 4, ["z"] = 8, ["name"] = "default:stone"}, {["x"] = 41, ["y"] = 4, ["z"] = 9, ["name"] = "default:stone"}, {["x"] = 41, ["y"] = 5, ["z"] = 1, ["name"] = "default:stone_block"}, {["x"] = 41, ["param2"] = 1, ["y"] = 5, ["param1"] = 14, ["z"] = 2, ["name"] = "stairs:slab_stonebrick"}, {["x"] = 41, ["param2"] = 1, ["y"] = 5, ["param1"] = 14, ["z"] = 3, ["name"] = "stairs:slab_stonebrick"}, {["x"] = 41, ["param2"] = 1, ["y"] = 5, ["param1"] = 14, ["z"] = 4, ["name"] = "stairs:slab_stonebrick"}, {["x"] = 41, ["param2"] = 1, ["y"] = 5, ["param1"] = 14, ["z"] = 5, ["name"] = "stairs:slab_stonebrick"}, {["x"] = 41, ["param2"] = 1, ["y"] = 5, ["param1"] = 14, ["z"] = 6, ["name"] = "stairs:slab_stonebrick"}, {["x"] = 41, ["param2"] = 1, ["y"] = 5, ["param1"] = 14, ["z"] = 7, ["name"] = "stairs:slab_stonebrick"}, {["x"] = 41, ["param2"] = 1, ["y"] = 5, ["param1"] = 14, ["z"] = 8, ["name"] = "stairs:slab_stonebrick"}, {["x"] = 41, ["y"] = 5, ["z"] = 9, ["name"] = "default:stone_block"}, {["x"] = 41, ["param2"] = 2, ["y"] = 6, ["param1"] = 14, ["z"] = 1, ["name"] = "stairs:slab_stone_block"}, {["x"] = 41, ["param2"] = 2, ["y"] = 6, ["param1"] = 14, ["z"] = 9, ["name"] = "stairs:slab_stone_block"}, {["x"] = 42, ["param2"] = 22, ["y"] = 2, ["param1"] = 12, ["z"] = 3, ["name"] = "stairs:slab_stone"}, {["x"] = 42, ["y"] = 2, ["z"] = 4, ["name"] = "default:stone"}, {["x"] = 42, ["y"] = 2, ["z"] = 5, ["name"] = "default:stone"}, {["x"] = 42, ["y"] = 2, ["z"] = 6, ["name"] = "default:stone"}, {["x"] = 42, ["param2"] = 22, ["y"] = 2, ["param1"] = 12, ["z"] = 7, ["name"] = "stairs:slab_stone"}, {["x"] = 42, ["y"] = 3, ["z"] = 1, ["name"] = "default:stone"}, {["x"] = 42, ["y"] = 3, ["z"] = 2, ["name"] = "default:stone"}, {["x"] = 42, ["y"] = 3, ["z"] = 3, ["name"] = "default:stone"}, {["x"] = 42, ["y"] = 3, ["z"] = 4, ["name"] = "default:stone"}, {["x"] = 42, ["y"] = 3, ["z"] = 5, ["name"] = "default:stone"}, {["x"] = 42, ["y"] = 3, ["z"] = 6, ["name"] = "default:stone"}, {["x"] = 42, ["y"] = 3, ["z"] = 7, ["name"] = "default:stone"}, {["x"] = 42, ["y"] = 3, ["z"] = 8, ["name"] = "default:stone"}, {["x"] = 42, ["y"] = 3, ["z"] = 9, ["name"] = "default:stone"}, {["x"] = 42, ["y"] = 4, ["z"] = 1, ["name"] = "default:stone"}, {["x"] = 42, ["param2"] = 1, ["y"] = 4, ["z"] = 2, ["name"] = "default:stonebrick"}, {["x"] = 42, ["param2"] = 1, ["y"] = 4, ["z"] = 3, ["name"] = "default:stonebrick"}, {["x"] = 42, ["param2"] = 1, ["y"] = 4, ["z"] = 4, ["name"] = "default:stonebrick"}, {["x"] = 42, ["param2"] = 1, ["y"] = 4, ["z"] = 5, ["name"] = "default:stonebrick"}, {["x"] = 42, ["param2"] = 1, ["y"] = 4, ["z"] = 6, ["name"] = "default:stonebrick"}, {["x"] = 42, ["param2"] = 1, ["y"] = 4, ["z"] = 7, ["name"] = "default:stonebrick"}, {["x"] = 42, ["param2"] = 1, ["y"] = 4, ["z"] = 8, ["name"] = "default:stonebrick"}, {["x"] = 42, ["y"] = 4, ["z"] = 9, ["name"] = "default:stone"}, {["x"] = 42, ["y"] = 5, ["z"] = 1, ["name"] = "default:stone_block"}, {["x"] = 42, ["y"] = 5, ["z"] = 9, ["name"] = "default:stone_block"}, {["x"] = 43, ["param2"] = 23, ["y"] = 1, ["param1"] = 10, ["z"] = 5, ["name"] = "stairs:slab_stone"}, {["x"] = 43, ["param2"] = 22, ["y"] = 2, ["param1"] = 12, ["z"] = 3, ["name"] = "stairs:slab_stone"}, {["x"] = 43, ["y"] = 2, ["z"] = 4, ["name"] = "default:stone"}, {["x"] = 43, ["y"] = 2, ["z"] = 5, ["name"] = "default:stone"}, {["x"] = 43, ["y"] = 2, ["z"] = 6, ["name"] = "default:stone"}, {["x"] = 43, ["param2"] = 22, ["y"] = 2, ["param1"] = 12, ["z"] = 7, ["name"] = "stairs:slab_stone"}, {["x"] = 43, ["y"] = 3, ["z"] = 1, ["name"] = "default:stone"}, {["x"] = 43, ["y"] = 3, ["z"] = 2, ["name"] = "default:stone"}, {["x"] = 43, ["y"] = 3, ["z"] = 3, ["name"] = "default:stone"}, {["x"] = 43, ["y"] = 3, ["z"] = 4, ["name"] = "default:stone"}, {["x"] = 43, ["y"] = 3, ["z"] = 5, ["name"] = "default:stone"}, {["x"] = 43, ["y"] = 3, ["z"] = 6, ["name"] = "default:stone"}, {["x"] = 43, ["y"] = 3, ["z"] = 7, ["name"] = "default:stone"}, {["x"] = 43, ["y"] = 3, ["z"] = 8, ["name"] = "default:stone"}, {["x"] = 43, ["y"] = 3, ["z"] = 9, ["name"] = "default:stone"}, {["x"] = 43, ["y"] = 4, ["z"] = 1, ["name"] = "default:stone"}, {["x"] = 43, ["param2"] = 1, ["y"] = 4, ["z"] = 2, ["name"] = "default:stonebrick"}, {["x"] = 43, ["param2"] = 1, ["y"] = 4, ["z"] = 3, ["name"] = "default:stonebrick"}, {["x"] = 43, ["param2"] = 1, ["y"] = 4, ["z"] = 4, ["name"] = "default:stonebrick"}, {["x"] = 43, ["param2"] = 1, ["y"] = 4, ["z"] = 5, ["name"] = "default:stonebrick"}, {["x"] = 43, ["param2"] = 1, ["y"] = 4, ["z"] = 6, ["name"] = "default:stonebrick"}, {["x"] = 43, ["param2"] = 1, ["y"] = 4, ["z"] = 7, ["name"] = "default:stonebrick"}, {["x"] = 43, ["param2"] = 1, ["y"] = 4, ["z"] = 8, ["name"] = "default:stonebrick"}, {["x"] = 43, ["y"] = 4, ["z"] = 9, ["name"] = "default:stone"}, {["x"] = 43, ["y"] = 5, ["z"] = 1, ["name"] = "default:stone_block"}, {["x"] = 43, ["y"] = 5, ["z"] = 9, ["name"] = "default:stone_block"}, {["x"] = 44, ["param2"] = 23, ["y"] = 1, ["param1"] = 11, ["z"] = 4, ["name"] = "stairs:slab_stone"}, {["x"] = 44, ["param2"] = 23, ["y"] = 1, ["param1"] = 10, ["z"] = 5, ["name"] = "stairs:slab_stone"}, {["x"] = 44, ["param2"] = 23, ["y"] = 1, ["param1"] = 11, ["z"] = 6, ["name"] = "stairs:slab_stone"}, {["x"] = 44, ["param2"] = 20, ["y"] = 2, ["param1"] = 13, ["z"] = 2, ["name"] = "stairs:slab_stone"}, {["x"] = 44, ["y"] = 2, ["z"] = 3, ["name"] = "default:stone"}, {["x"] = 44, ["y"] = 2, ["z"] = 4, ["name"] = "default:stone"}, {["x"] = 44, ["y"] = 2, ["z"] = 5, ["name"] = "default:stone"}, {["x"] = 44, ["y"] = 2, ["z"] = 6, ["name"] = "default:stone"}, {["x"] = 44, ["y"] = 2, ["z"] = 7, ["name"] = "default:stone"}, {["x"] = 44, ["param2"] = 22, ["y"] = 2, ["param1"] = 13, ["z"] = 8, ["name"] = "stairs:slab_stone"}, {["x"] = 44, ["y"] = 3, ["z"] = 1, ["name"] = "default:stone"}, {["x"] = 44, ["y"] = 3, ["z"] = 2, ["name"] = "default:stone"}, {["x"] = 44, ["y"] = 3, ["z"] = 3, ["name"] = "default:stone"}, {["x"] = 44, ["y"] = 3, ["z"] = 4, ["name"] = "default:stone"}, {["x"] = 44, ["y"] = 3, ["z"] = 5, ["name"] = "default:stone"}, {["x"] = 44, ["y"] = 3, ["z"] = 6, ["name"] = "default:stone"}, {["x"] = 44, ["y"] = 3, ["z"] = 7, ["name"] = "default:stone"}, {["x"] = 44, ["y"] = 3, ["z"] = 8, ["name"] = "default:stone"}, {["x"] = 44, ["y"] = 3, ["z"] = 9, ["name"] = "default:stone"}, {["x"] = 44, ["y"] = 4, ["z"] = 1, ["name"] = "default:stone"}, {["x"] = 44, ["param2"] = 1, ["y"] = 4, ["z"] = 2, ["name"] = "default:stonebrick"}, {["x"] = 44, ["param2"] = 1, ["y"] = 4, ["z"] = 3, ["name"] = "default:stonebrick"}, {["x"] = 44, ["param2"] = 1, ["y"] = 4, ["z"] = 4, ["name"] = "default:stonebrick"}, {["x"] = 44, ["param2"] = 1, ["y"] = 4, ["z"] = 5, ["name"] = "default:stonebrick"}, {["x"] = 44, ["param2"] = 1, ["y"] = 4, ["z"] = 6, ["name"] = "default:stonebrick"}, {["x"] = 44, ["param2"] = 1, ["y"] = 4, ["z"] = 7, ["name"] = "default:stonebrick"}, {["x"] = 44, ["param2"] = 1, ["y"] = 4, ["z"] = 8, ["name"] = "default:stonebrick"}, {["x"] = 44, ["y"] = 4, ["z"] = 9, ["name"] = "default:stone"}, {["x"] = 44, ["y"] = 5, ["z"] = 1, ["name"] = "default:stone_block"}, {["x"] = 44, ["y"] = 5, ["z"] = 9, ["name"] = "default:stone_block"}, {["x"] = 45, ["param2"] = 23, ["y"] = 1, ["param1"] = 11, ["z"] = 4, ["name"] = "stairs:slab_stone"}, {["x"] = 45, ["param2"] = 23, ["y"] = 1, ["param1"] = 10, ["z"] = 5, ["name"] = "stairs:slab_stone"}, {["x"] = 45, ["param2"] = 23, ["y"] = 1, ["param1"] = 11, ["z"] = 6, ["name"] = "stairs:slab_stone"}, {["x"] = 45, ["param2"] = 20, ["y"] = 2, ["param1"] = 13, ["z"] = 2, ["name"] = "stairs:slab_stone"}, {["x"] = 45, ["y"] = 2, ["z"] = 3, ["name"] = "default:stone"}, {["x"] = 45, ["y"] = 2, ["z"] = 4, ["name"] = "default:stone"}, {["x"] = 45, ["y"] = 2, ["z"] = 5, ["name"] = "default:stone"}, {["x"] = 45, ["y"] = 2, ["z"] = 6, ["name"] = "default:stone"}, {["x"] = 45, ["y"] = 2, ["z"] = 7, ["name"] = "default:stone"}, {["x"] = 45, ["param2"] = 22, ["y"] = 2, ["param1"] = 13, ["z"] = 8, ["name"] = "stairs:slab_stone"}, {["x"] = 45, ["y"] = 3, ["z"] = 1, ["name"] = "default:stone"}, {["x"] = 45, ["y"] = 3, ["z"] = 2, ["name"] = "default:stone"}, {["x"] = 45, ["y"] = 3, ["z"] = 3, ["name"] = "default:stone"}, {["x"] = 45, ["y"] = 3, ["z"] = 4, ["name"] = "default:stone"}, {["x"] = 45, ["y"] = 3, ["z"] = 5, ["name"] = "default:stone"}, {["x"] = 45, ["y"] = 3, ["z"] = 6, ["name"] = "default:stone"}, {["x"] = 45, ["y"] = 3, ["z"] = 7, ["name"] = "default:stone"}, {["x"] = 45, ["y"] = 3, ["z"] = 8, ["name"] = "default:stone"}, {["x"] = 45, ["y"] = 3, ["z"] = 9, ["name"] = "default:stone"}, {["x"] = 45, ["y"] = 4, ["z"] = 1, ["name"] = "default:stone_block"}, {["x"] = 45, ["param2"] = 1, ["y"] = 4, ["param1"] = 14, ["z"] = 2, ["name"] = "stairs:slab_stonebrick"}, {["x"] = 45, ["param2"] = 1, ["y"] = 4, ["param1"] = 14, ["z"] = 3, ["name"] = "stairs:slab_stonebrick"}, {["x"] = 45, ["param2"] = 1, ["y"] = 4, ["param1"] = 14, ["z"] = 4, ["name"] = "stairs:slab_stonebrick"}, {["x"] = 45, ["param2"] = 1, ["y"] = 4, ["param1"] = 14, ["z"] = 5, ["name"] = "stairs:slab_stonebrick"}, {["x"] = 45, ["param2"] = 1, ["y"] = 4, ["param1"] = 14, ["z"] = 6, ["name"] = "stairs:slab_stonebrick"}, {["x"] = 45, ["param2"] = 1, ["y"] = 4, ["param1"] = 14, ["z"] = 7, ["name"] = "stairs:slab_stonebrick"}, {["x"] = 45, ["param2"] = 1, ["y"] = 4, ["param1"] = 14, ["z"] = 8, ["name"] = "stairs:slab_stonebrick"}, {["x"] = 45, ["y"] = 4, ["z"] = 9, ["name"] = "default:stone_block"}, {["x"] = 45, ["param2"] = 3, ["y"] = 5, ["param1"] = 14, ["z"] = 1, ["name"] = "stairs:slab_stone_block"}, {["x"] = 45, ["y"] = 5, ["param1"] = 14, ["z"] = 9, ["name"] = "stairs:slab_stone_block"}, {["x"] = 46, ["param2"] = 23, ["y"] = 1, ["param1"] = 11, ["z"] = 4, ["name"] = "stairs:slab_stone"}, {["x"] = 46, ["y"] = 1, ["z"] = 5, ["name"] = "default:stone"}, {["x"] = 46, ["param2"] = 23, ["y"] = 1, ["param1"] = 11, ["z"] = 6, ["name"] = "stairs:slab_stone"}, {["x"] = 46, ["param2"] = 23, ["y"] = 2, ["param1"] = 14, ["z"] = 1, ["name"] = "stairs:slab_stone"}, {["x"] = 46, ["y"] = 2, ["z"] = 2, ["name"] = "default:stone"}, {["x"] = 46, ["y"] = 2, ["z"] = 3, ["name"] = "default:stone"}, {["x"] = 46, ["y"] = 2, ["z"] = 4, ["name"] = "default:stone"}, {["x"] = 46, ["y"] = 2, ["z"] = 5, ["name"] = "default:stone"}, {["x"] = 46, ["y"] = 2, ["z"] = 6, ["name"] = "default:stone"}, {["x"] = 46, ["y"] = 2, ["z"] = 7, ["name"] = "default:stone"}, {["x"] = 46, ["y"] = 2, ["z"] = 8, ["name"] = "default:stone"}, {["x"] = 46, ["param2"] = 23, ["y"] = 2, ["param1"] = 14, ["z"] = 9, ["name"] = "stairs:slab_stone"}, {["x"] = 46, ["y"] = 3, ["z"] = 1, ["name"] = "default:stone"}, {["x"] = 46, ["y"] = 3, ["z"] = 2, ["name"] = "default:stone"}, {["x"] = 46, ["y"] = 3, ["z"] = 3, ["name"] = "default:stone"}, {["x"] = 46, ["y"] = 3, ["z"] = 4, ["name"] = "default:stone"}, {["x"] = 46, ["y"] = 3, ["z"] = 5, ["name"] = "default:stone"}, {["x"] = 46, ["y"] = 3, ["z"] = 6, ["name"] = "default:stone"}, {["x"] = 46, ["y"] = 3, ["z"] = 7, ["name"] = "default:stone"}, {["x"] = 46, ["y"] = 3, ["z"] = 8, ["name"] = "default:stone"}, {["x"] = 46, ["y"] = 3, ["z"] = 9, ["name"] = "default:stone"}, {["x"] = 46, ["y"] = 4, ["z"] = 1, ["name"] = "default:stone_block"}, {["x"] = 46, ["param2"] = 1, ["y"] = 4, ["param1"] = 14, ["z"] = 2, ["name"] = "stairs:slab_stonebrick"}, {["x"] = 46, ["param2"] = 1, ["y"] = 4, ["param1"] = 14, ["z"] = 3, ["name"] = "stairs:slab_stonebrick"}, {["x"] = 46, ["param2"] = 1, ["y"] = 4, ["param1"] = 14, ["z"] = 4, ["name"] = "stairs:slab_stonebrick"}, {["x"] = 46, ["param2"] = 1, ["y"] = 4, ["param1"] = 14, ["z"] = 5, ["name"] = "stairs:slab_stonebrick"}, {["x"] = 46, ["param2"] = 1, ["y"] = 4, ["param1"] = 14, ["z"] = 6, ["name"] = "stairs:slab_stonebrick"}, {["x"] = 46, ["param2"] = 1, ["y"] = 4, ["param1"] = 14, ["z"] = 7, ["name"] = "stairs:slab_stonebrick"}, {["x"] = 46, ["param2"] = 1, ["y"] = 4, ["param1"] = 14, ["z"] = 8, ["name"] = "stairs:slab_stonebrick"}, {["x"] = 46, ["y"] = 4, ["z"] = 9, ["name"] = "default:stone_block"}, {["x"] = 46, ["param2"] = 3, ["y"] = 5, ["param1"] = 14, ["z"] = 1, ["name"] = "stairs:slab_stone_block"}, {["x"] = 46, ["y"] = 5, ["param1"] = 14, ["z"] = 9, ["name"] = "stairs:slab_stone_block"}, {["x"] = 47, ["param2"] = 23, ["y"] = 0, ["param1"] = 10, ["z"] = 5, ["name"] = "stairs:slab_stone"}, {["x"] = 47, ["param2"] = 23, ["y"] = 1, ["param1"] = 12, ["z"] = 3, ["name"] = "stairs:slab_stone"}, {["x"] = 47, ["y"] = 1, ["z"] = 4, ["name"] = "default:stone"}, {["x"] = 47, ["y"] = 1, ["z"] = 5, ["name"] = "default:stone"}, {["x"] = 47, ["y"] = 1, ["z"] = 6, ["name"] = "default:stone"}, {["x"] = 47, ["param2"] = 23, ["y"] = 1, ["param1"] = 12, ["z"] = 7, ["name"] = "stairs:slab_stone"}, {["x"] = 47, ["param2"] = 23, ["y"] = 2, ["param1"] = 14, ["z"] = 1, ["name"] = "stairs:slab_stone"}, {["x"] = 47, ["y"] = 2, ["z"] = 2, ["name"] = "default:stone"}, {["x"] = 47, ["y"] = 2, ["z"] = 3, ["name"] = "default:stone"}, {["x"] = 47, ["y"] = 2, ["z"] = 4, ["name"] = "default:stone"}, {["x"] = 47, ["y"] = 2, ["z"] = 5, ["name"] = "default:stone"}, {["x"] = 47, ["y"] = 2, ["z"] = 6, ["name"] = "default:stone"}, {["x"] = 47, ["y"] = 2, ["z"] = 7, ["name"] = "default:stone"}, {["x"] = 47, ["y"] = 2, ["z"] = 8, ["name"] = "default:stone"},